Workbook

Sheet MRA - Cassiterite - Tin
A1: Mineral accounts: Flow accounts: Cassiterite
B2: Physical accounts | L2: Monetary accounts | T2: Exchange rate | U2: ='Basic data - source records'!AF5 -> 614.29514 | V2: ='Basic data - source records'!AG5 -> 646.63597 | W2: ='Basic data - source records'!AH5 -> 681.86172 | X2: ='Basic data - source records'!AI5 -> 720.97511 | Y2: ='Basic data - source records'!AJ5 -> 788
C3: Source | D3: Units | E3: 2012 | F3: 2013 | G3: 2014 | H3: 2015 | I3: 2016 | J3: Notes | M3: Source | N3: Units | O3: 2012 | P3: 2013 | Q3: 2014 | R3: 2015 | S3: 2016 | T3: Units | U3: 2012 | V3: 2013 | W3: 2014 | X3: 2015 | Y3: 2016 | Z3: Notes
B4: Mining operations | L4: Mining operations | T4: Mining operations
B5: Tagged production | C5: ITRI | D5: tons | E5: ='Basic data - source records'!C5 -> 3670.5237 | F5: ='Basic data - source records'!D5 -> 6112.1432 | G5: ='Basic data - source records'!E5 -> 7137.4683 | H5: ='Basic data - source records'!F5 -> 4714.1224 | I5: ='Basic data - source records'!G5 -> 2024 | J5: Data verified by RMB | L5: Production | M5: ITRI | N5: tons | O5: =E5 -> 3670.5237 | P5: =F5 -> 6112.1432 | Q5: =G5 -> 7137.4683 | R5: =H5 -> 4714.1224 | S5: =I5 -> 2024 | T5: tons | U5: =O5 -> 3670.5237 | V5: =P5 -> 6112.1432 | W5: =Q5 -> 7137.4683 | X5: =R5 -> 4714.1224 | Y5: =S5 -> 2024 | Z5: From physical accounts
B6: Employment (part time) | C6: NISR: LFS | D6: people | L6: Average price | M6: Calc | N6: USD/ton | O6: ='Mining price data'!BO40 -> 9213.9125 | P6: ='Mining price data'!BP40 -> 10196.272 | Q6: ='Mining price data'!BQ40 -> 10101.396 | R6: ='Mining price data'!BR40 -> 7003.4075 | S6: ='Mining price data'!BS40 -> 7573.3436 | T6: Frw/ton | U6: =O6*U2 -> 5660061.7 | V6: =P6*V2 -> 6593276.1 | W6: =Q6*W2 -> 6887755.1 | X6: =R6*X2 -> 5049282.5 | Y6: =S6*Y2 -> 5967794.7 | Z6: Based on avg. of 5 transactions/month per major trader
B7: Employment (full time) | C7: NISR: IBES | D7: people | L7: Sales | M7: Calc | N7: USD | O7: =O6*O5 -> 33819884 | P7: =P6*P5 -> 62321073 | Q7: =Q6*Q5 -> 72098392 | R7: =R6*R5 -> 33014920 | S7: =S6*S5 -> 15328447 | T7: Frw: billion | U7: =O7*U$2/1000000000 -> 20.775391 | V7: =P7*V$2/1000000000 -> 40.299048 | W7: =Q7*W$2/1000000000 -> 49.161134 | X7: =R7*X$2/1000000000 -> 23.802936 | Y7: =S7*Y$2/1000000000 -> 12.078817 | Z7: Calculated
L8: Less: Intermediate consumption (payments to sub-contractors & direct costs to production) | M8: IBES | N8: USD | O8: =O$7*'IBES data'!$U7 -> 28602849 | P8: =P$7*'IBES data'!$U7 -> 52707461 | Q8: =Q$7*'IBES data'!$U7 -> 60976537 | R8: =R$7*'IBES data'!$U7 -> 27922058 | S8: =S$7*'IBES data'!$U7 -> 12963890 | T8: Frw: billion | U8: =O8*U$2/1000000000 -> 17.570591 | V8: =P8*V$2/1000000000 -> 34.08254 | W8: =Q8*W$2/1000000000 -> 41.577566 | X8: =R8*X$2/1000000000 -> 20.131109 | Y8: =S8*Y$2/1000000000 -> 10.215545 | Z8: Derived from IBES structure
B9: Change in inventory | C9: Calc | D9: tons | E9: =E5-E12 -> 0 | F9: =F5-F12 -> 0 | G9: =G5-G12 -> 0 | H9: =H5-H12 -> 0 | I9: =I5-I12 -> 0 | L9: Less: Other operating and overhead costs | M9: IBES | N9: USD | O9: =O$7*'IBES data'!$U8 -> 5224160.7 | P9: =P$7*'IBES data'!$U8 -> 9626741.9 | Q9: =Q$7*'IBES data'!$U8 -> 11137045 | R9: =R$7*'IBES data'!$U8 -> 5099817.8 | S9: =S$7*'IBES data'!$U8 -> 2367786.7 | T9: Frw: billion | U9: =O9*U$2/1000000000 -> 3.2091765 | V9: =P9*V$2/1000000000 -> 6.2249977 | W9: =Q9*W$2/1000000000 -> 7.5939249 | X9: =R9*X$2/1000000000 -> 3.6768417 | Y9: =S9*Y$2/1000000000 -> 1.8658159 | Z9: Derived from IBES structure
L10: Less: Consumption of capital (Deprc) | M10: IBES | N10: USD | O10: =O$7*'IBES data'!$U9 -> 575397.56 | P10: =P$7*'IBES data'!$U9 -> 1060305 | Q10: =Q$7*'IBES data'!$U9 -> 1226652.3 | R10: =R$7*'IBES data'!$U9 -> 561702.23 | S10: =S$7*'IBES data'!$U9 -> 260791.88 | T10: Frw: billion | U10: =O10*U$2/1000000000 -> 0.35346393 | V10: =P10*V$2/1000000000 -> 0.68563137 | W10: =Q10*W$2/1000000000 -> 0.83640725 | X10: =R10*X$2/1000000000 -> 0.40497333 | Y10: =S10*Y$2/1000000000 -> 0.205504 | Z10: Derived from IBES structure
B11: Trading operations | L11: Less: Opportunity cost of capital ("normal profit") | M11: Calc | N11: USD | O11: =O10*'Basic data - source records'!Y5*'Basic data - source records'!$AR$2 -> 650199.24 | P11: =P10*'Basic data - source records'!Z5*'Basic data - source records'!$AR$2 -> 1113320.3 | Q11: =Q10*'Basic data - source records'!AA5*'Basic data - source records'!$AR$2 -> 1312518 | R11: =R10*'Basic data - source records'!AB5*'Basic data - source records'!$AR$2 -> 589787.35 | S11: =S10*'Basic data - source records'!AC5*'Basic data - source records'!$AR$2 -> 273831.48 | T11: Frw: billion | U11: =O11*U$2/1000000000 -> 0.39941424 | V11: =P11*V$2/1000000000 -> 0.71991294 | W11: =Q11*W$2/1000000000 -> 0.89495576 | X11: =R11*X$2/1000000000 -> 0.425222 | Y11: =S11*Y$2/1000000000 -> 0.2157792 | Z11: Derived from IBES structure
B12: Tagged purchases | C12: ITRI | D12: tons | E12: ='Basic data - source records'!C5 -> 3670.5237 | F12: ='Basic data - source records'!D5 -> 6112.1432 | G12: ='Basic data - source records'!E5 -> 7137.4683 | H12: ='Basic data - source records'!F5 -> 4714.1224 | I12: ='Basic data - source records'!G5 -> 2024 | J12: Data verified by RMB
L13: Equal: Resource rent | M13: Calc | N13: USD | O13: =O7-(O8+O9+O10+O11) -> -1232722.2 | P13: =P7-(P8+P9+P10+P11) -> -2186755.5 | Q13: =Q7-(Q8+Q9+Q10+Q11) -> -2554360.4 | R13: =R7-(R8+R9+R10+R11) -> -1158445.4 | S13: =S7-(S8+S9+S10+S11) -> -537852.85 | T13: Frw: billion | U13: =O13*U$2/1000000000 -> -0.75725525 | V13: =P13*V$2/1000000000 -> -1.4140348 | W13: =Q13*W$2/1000000000 -> -1.7417206 | X13: =R13*X$2/1000000000 -> -0.83521028 | Y13: =S13*Y$2/1000000000 -> -0.42382805 | Z13: Calculated
B14: Less: Waste or losses during processing by traders | C14: Calc | D14: tons | E14: =E12-E16 -> -910.02411 | F14: =F12-F16 -> 1317.596 | G14: =G12-G16 -> 1232.2722 | H14: =H12-H16 -> 1508.9454 | I14: =I12-I16 -> -1264 | L14: Unit rent | M14: Calc | N14: USD/ton | O14: =O13/O5 -> -335.84368 | P14: =P13/P5 -> -357.77229 | Q14: =Q13/Q5 -> -357.88046 | R14: =R13/R5 -> -245.73935 | S14: =S13/S5 -> -265.73758 | T14: Frw/ton | U14: =O14*U2 -> -206307.14 | V14: =P14*V2 -> -231348.44 | W14: =Q14*W2 -> -244024.99 | X14: =R14*X2 -> -177171.96 | Y14: =S14*Y2 -> -209401.21 | Z14: Calculated
L15: Inventory or sundry changes (residual change) | M15: Calc | N15: USD | O15: =O20-O7 -> 11388016 | P15: =P20-P7 -> -10124278 | Q15: =Q20-Q7 -> -10610670 | R15: =R20-R7 -> -3732124.1 | S15: =S20-S7 -> 14419838 | T15: Frw: billion | U15: =O15*U$2/1000000000 -> 6.995603 | V15: =P15*V$2/1000000000 -> -6.5467223 | W15: =Q15*W$2/1000000000 -> -7.2350096 | X15: =R15*X$2/1000000000 -> -2.6907686 | Y15: =S15*Y$2/1000000000 -> 11.362832 | Z15: Calculated
B16: Equal: Processed and tagged production | C16: ITRI | D16: tons | E16: ='Basic data - source records'!C6 -> 4580.5478 | F16: ='Basic data - source records'!D6 -> 4794.5472 | G16: ='Basic data - source records'!E6 -> 5905.1961 | H16: ='Basic data - source records'!F6 -> 3205.177 | I16: ='Basic data - source records'!G6 -> 3288 | J16: Data verified by RMB | L16: Trading operations | T16: Trading operations
L17: Production (exports) | M17: RMB | N17: tons | O17: =E20 -> 4636.6403 | P17: =F20 -> 4895.2675 | Q17: =G20 -> 5953.7963 | R17: =H20 -> 3845.6561 | S17: =I20 -> 3549.915 | T17: tons | U17: =O17 -> 4636.6403 | V17: =P17 -> 4895.2675 | W17: =Q17 -> 5953.7963 | X17: =R17 -> 3845.6561 | Y17: =S17 -> 3549.915 | Z17: From physical accounts
B18: Change in inventory | C18: Calc | D18: tons | E18: =E16-E20 -> -56.09248 | F18: =F16-F20 -> -100.72027 | G18: =G16-G20 -> -48.60026 | H18: =H16-H20 -> -640.47913 | I18: =I16-I20 -> -261.91505 | L18: Average price | M18: Calc | N18: USD/ton | O18: =O19/O17 -> 11408.456 | P18: =P19/P17 -> 12476.229 | Q18: =Q19/Q17 -> 12083.99 | R18: =R19/R17 -> 8909.5964 | S18: =S19/S17 -> 9805.278 | T18: Frw/ton | U18: =O18*U2 -> 7008159 | V18: =P18*V2 -> 8067578.6 | W18: =Q18*W2 -> 8239610.4 | X18: =R18*X2 -> 6423597.3 | Y18: =S18*Y2 -> 7726559.1 | Z18: Calculated
L19: Sales (exports) | M19: RMB | N19: USD | O19: ='Basic data - source records'!R5 -> 52896906 | P19: ='Basic data - source records'!S5 -> 61074479 | Q19: ='Basic data - source records'!T5 -> 71945617 | R19: ='Basic data - source records'!U5 -> 34263244 | S19: ='Basic data - source records'!V5 -> 34807904 | T19: Frw: billion | U19: =O19*U$2/1000000000 -> 32.494313 | V19: =P19*V$2/1000000000 -> 39.492955 | W19: =Q19*W$2/1000000000 -> 49.056962 | X19: =R19*X$2/1000000000 -> 24.702946 | Y19: =S19*Y$2/1000000000 -> 27.428628 | Z19: Published data
B20: Equal: Marketed production (exports) | C20: RMB | D20: tons | E20: ='Basic data - source records'!J5 -> 4636.6403 | F20: ='Basic data - source records'!K5 -> 4895.2675 | G20: ='Basic data - source records'!L5 -> 5953.7963 | H20: ='Basic data - source records'!M5 -> 3845.6561 | I20: ='Basic data - source records'!N5 -> 3549.915 | J20: RMB & RNB | L20: Less: Purchase of raw material | M20: IBES | N20: USD | O20: =O$19*'IBES data'!$U31 -> 45207900 | P20: =P$19*'IBES data'!$U31 -> 52196795 | Q20: =Q$19*'IBES data'!$U31 -> 61487723 | R20: =R$19*'IBES data'!$U31 -> 29282796 | S20: =S$19*'IBES data'!$U31 -> 29748285 | T20: Frw: billion | U20: =O20*U$2/1000000000 -> 27.770994 | V20: =P20*V$2/1000000000 -> 33.752325 | W20: =Q20*W$2/1000000000 -> 41.926124 | X20: =R20*X$2/1000000000 -> 21.112167 | Y20: =S20*Y$2/1000000000 -> 23.441649 | Z20: Derived from IBES structure
L21: Less: Intermediate consumption | M21: IBES | N21: USD | O21: =O$19*'IBES data'!$U32 -> 0 | P21: =P$19*'IBES data'!$U32 -> 0 | Q21: =Q$19*'IBES data'!$U32 -> 0 | R21: =R$19*'IBES data'!$U32 -> 0 | S21: =S$19*'IBES data'!$U32 -> 0 | T21: Frw: billion | U21: =O21*U$2/1000000000 -> 0 | V21: =P21*V$2/1000000000 -> 0 | W21: =Q21*W$2/1000000000 -> 0 | X21: =R21*X$2/1000000000 -> 0 | Y21: =S21*Y$2/1000000000 -> 0 | Z21: Derived from IBES structure
L22: Less: Other operating and overhead costs | M22: IBES | N22: USD | O22: =O$19*'IBES data'!$U33 -> 8582741.2 | P22: =P$19*'IBES data'!$U33 -> 9909586.1 | Q22: =Q$19*'IBES data'!$U33 -> 11673473 | R22: =R$19*'IBES data'!$U33 -> 5559352.6 | S22: =S$19*'IBES data'!$U33 -> 5647725.9 | T22: Frw: billion | U22: =O22*U$2/1000000000 -> 5.2723362 | V22: =P22*V$2/1000000000 -> 6.4078948 | W22: =Q22*W$2/1000000000 -> 7.9596944 | X22: =R22*X$2/1000000000 -> 4.0081548 | Y22: =S22*Y$2/1000000000 -> 4.450408 | Z22: Derived from IBES structure
B23: Key to colour coding: | L23: Less: Consumption of capital (Deprc) | M23: IBES | N23: USD | O23: =O$19*'IBES data'!$U34 -> 484941.81 | P23: =P$19*'IBES data'!$U34 -> 559911.17 | Q23: =Q$19*'IBES data'!$U34 -> 659574.27 | R23: =R$19*'IBES data'!$U34 -> 314114.39 | S23: =S$19*'IBES data'!$U34 -> 319107.66 | T23: Frw: billion | U23: =O23*U$2/1000000000 -> 0.2978974 | V23: =P23*V$2/1000000000 -> 0.3620587 | W23: =Q23*W$2/1000000000 -> 0.44973844 | X23: =R23*X$2/1000000000 -> 0.22646866 | Y23: =S23*Y$2/1000000000 -> 0.25145684 | Z23: Derived from IBES structure
B24: High quality data - published | L24: Less: Opportunity cost of capital ("normal profit") | M24: Calc | N24: USD | O24: =O23*'Basic data - source records'!Y5*'Basic data - source records'!$AR$2 -> 547984.25 | P24: =P23*'Basic data - source records'!Z5*'Basic data - source records'!$AR$2 -> 587906.73 | Q24: =Q23*'Basic data - source records'!AA5*'Basic data - source records'!$AR$2 -> 705744.46 | R24: =R23*'Basic data - source records'!AB5*'Basic data - source records'!$AR$2 -> 329820.11 | S24: =S23*'Basic data - source records'!AC5*'Basic data - source records'!$AR$2 -> 335063.04 | T24: Frw: billion | U24: =O24*U$2/1000000000 -> 0.33662406 | V24: =P24*V$2/1000000000 -> 0.38016164 | W24: =Q24*W$2/1000000000 -> 0.48122013 | X24: =R24*X$2/1000000000 -> 0.23779209 | Y24: =S24*Y$2/1000000000 -> 0.26402968 | Z24: Derived from IBES structure
B25: High quality input - derived from IBES structure
B26: Good quality data - derived from hard data | L26: Equal: Resource rent | M26: Calc | N26: USD | O26: =O19-(O20+O21+O22+O23+O24) -> -1926661.3 | P26: =P19-(P20+P21+P22+P23+P24) -> -2179719.7 | Q26: =Q19-(Q20+Q21+Q22+Q23+Q24) -> -2580897.1 | R26: =R19-(R20+R21+R22+R23+R24) -> -1222839.2 | S26: =S19-(S20+S21+S22+S23+S24) -> -1242277.9 | T26: Frw: billion | U26: =O26*U$2/1000000000 -> -1.1835387 | V26: =P26*V$2/1000000000 -> -1.4094852 | W26: =Q26*W$2/1000000000 -> -1.7598149 | X26: =R26*X$2/1000000000 -> -0.88163665 | Y26: =S26*Y$2/1000000000 -> -0.97891498 | Z26: Calculated
B27: Results/outcomes - based on formulas | L27: Unit rent | M27: Calc | N27: USD/ton | O27: =O26/O17 -> -415.52961 | P27: =P26/P17 -> -445.27081 | Q27: =Q26/Q17 -> -433.48764 | R27: =R26/R17 -> -317.97935 | S27: =S26/S17 -> -349.94581 | T27: Frw/ton | U27: =O27*U2 -> -255257.82 | V27: =P27*V2 -> -287928.13 | W27: =Q27*W2 -> -295578.62 | X27: =R27*X2 -> -229255.2 | Y27: =S27*Y2 -> -275757.3 | Z27: Calculated
L28: Royalty payments | M28: Calc | N28: USD | O28: =0*O19 -> 0 | P28: =0.02*P19 -> 1221489.6 | Q28: =0.04*Q19 -> 2877824.7 | R28: =0.04*R19 -> 1370529.8 | S28: =0.04*S19 -> 1392316.2 | T28: Frw: billion | U28: =O28*U2/1000000000 -> 0 | V28: =P28*V2/1000000000 -> 0.7898591 | W28: =Q28*W2/1000000000 -> 1.9622785 | X28: =R28*X2/1000000000 -> 0.98811784 | Y28: =S28*Y2/1000000000 -> 1.0971451 | Z28: Calculated as 4% of sales
L30: operators
L31: vol | O31: =O5 -> 3670.5237 | P31: =P5 -> 6112.1432 | Q31: =Q5 -> 7137.4683 | R31: =R5 -> 4714.1224 | S31: =S5 -> 2024
L32: price | O32: 9549.7561 | P32: 10554.044 | Q32: 10459.276 | R32: 7249.1469 | S32: 7839.0812 | T32: =AVERAGE(O32:S32) -> 9130.2609 | W32: =S19+'MRA - Coltan - Tantalum'!S19+'MRA - Wolfram - Tungsten'!S19 -> 86424093
L33: sales | O33: =O31*O32 -> 35052606 | P33: =P31*P32 -> 64507828 | Q33: =Q31*Q32 -> 74652753 | R33: =R31*R32 -> 34173365 | S33: =S31*S32 -> 15866300
L34: cost | O34: =SUM(O8:O11) -> 35052606 | P34: =SUM(P8:P11) -> 64507828 | Q34: =SUM(Q8:Q11) -> 74652753 | R34: =SUM(R8:R11) -> 34173365 | S34: =SUM(S8:S11) -> 15866300
L35: rent | O35: =O33-O34 -> 0 | P35: =P33-P34 -> 0 | Q35: =Q33-Q34 -> 0 | R35: =R33-R34 -> 0 | S35: =S33-S34 -> 0
L37: new price | O37: =O32 -> 9549.7561 | P37: =P32 -> 10554.044 | Q37: =Q32 -> 10459.276 | R37: =R32 -> 7249.1469 | S37: =S32 -> 7839.0812
L38: old price | O38: =O6 -> 9213.9125 | P38: =P6 -> 10196.272 | Q38: =Q6 -> 10101.396 | R38: =R6 -> 7003.4075 | S38: =S6 -> 7573.3436
O39: =(O37-O38)/O38 -> 0.036449628 | P39: =(P37-P38)/P38 -> 0.035088541 | Q39: =(Q37-Q38)/Q38 -> 0.035428813 | R39: =(R37-R38)/R38 -> 0.035088541 | S39: =(S37-S38)/S38 -> 0.035088541 | T39: =AVERAGE(O39:S39) -> 0.035428813
L42: traders
L43: vol | O43: =O17 -> 4636.6403 | P43: =P17 -> 4895.2675 | Q43: =Q17 -> 5953.7963 | R43: =R17 -> 3845.6561 | S43: =S17 -> 3549.915
L44: price | O44: 11823.985 | P44: 12921.5 | Q44: 12517.478 | R44: 9227.5758 | S44: 10155.224 | T44: =AVERAGE(O44:S44) -> 11329.153
...

Sheet MRA - Coltan - Tantalum
A1: Mineral accounts: Flow accounts: Coltan
B2: Physical accounts | L2: Monetary accounts | T2: Exchange rate | U2: ='Basic data - source records'!AF5 -> 614.29514 | V2: ='Basic data - source records'!AG5 -> 646.63597 | W2: ='Basic data - source records'!AH5 -> 681.86172 | X2: ='Basic data - source records'!AI5 -> 720.97511 | Y2: ='Basic data - source records'!AJ5 -> 788
C3: Source | D3: Units | E3: 2012 | F3: 2013 | G3: 2014 | H3: 2015 | I3: 2016 | J3: Notes | M3: Source | N3: Units | O3: 2012 | P3: 2013 | Q3: 2014 | R3: 2015 | S3: 2016 | T3: Units | U3: 2012 | V3: 2013 | W3: 2014 | X3: 2015 | Y3: 2016 | Z3: Notes
B4: Mining operations | L4: Mining operations | T4: Mining operations
B5: Tagged production | C5: ITRI | D5: tons | E5: ='Basic data - source records'!C7 -> 967.88761 | F5: ='Basic data - source records'!D7 -> 1924.3862 | G5: ='Basic data - source records'!E7 -> 2097.5135 | H5: ='Basic data - source records'!F7 -> 1332 | I5: ='Basic data - source records'!G7 -> 2553.6 | J5: Data verified by RMB | L5: Production | M5: ITRI | N5: tons | O5: =E5 -> 967.88761 | P5: =F5 -> 1924.3862 | Q5: =G5 -> 2097.5135 | R5: =H5 -> 1332 | S5: =I5 -> 2553.6 | T5: tons | U5: =O5 -> 967.88761 | V5: =P5 -> 1924.3862 | W5: =Q5 -> 2097.5135 | X5: =R5 -> 1332 | Y5: =S5 -> 2553.6 | Z5: From physical accounts
B6: Employment | C6: NISR: LFS | D6: people | L6: Average price | M6: Calc | N6: USD/ton | O6: ='Mining price data'!BO47 -> 49840 | P6: ='Mining price data'!BP47 -> 56141 | Q6: ='Mining price data'!BQ47 -> 44661.636 | R6: ='Mining price data'!BR47 -> 42300.37 | S6: ='Mining price data'!BS47 -> 35080.727 | T6: Frw/ton | U6: =O6*U2 -> 30616470 | V6: =P6*V2 -> 36302790 | W6: =Q6*W2 -> 30453060 | X6: =R6*X2 -> 30497514 | Y6: =S6*Y2 -> 27643613 | Z6: Based on avg. of 5 transactions/month per major trader
B7: Employment | C7: NISR: IBES | D7: people | L7: Sales | M7: Calc | N7: USD | O7: =O6*O5 -> 48239518 | P7: =P6*P5 -> 1.0803697e+08 | Q7: =Q6*Q5 -> 93678385 | R7: =R6*R5 -> 56344093 | S7: =S6*S5 -> 89582145 | T7: Frw: billion | U7: =O7*U$2/1000000000 -> 29.633302 | V7: =P7*V$2/1000000000 -> 69.860589 | W7: =Q7*W$2/1000000000 -> 63.875704 | X7: =R7*X$2/1000000000 -> 40.622689 | Y7: =S7*Y$2/1000000000 -> 70.59073 | Z7: Calculated
L8: Less: Intermediate consumption (payments to sub-contractors & direct costs to production) | M8: IBES | N8: USD | O8: =O$7*'IBES data'!$U7 -> 40798119 | P8: =P$7*'IBES data'!$U7 -> 91371247 | Q8: =Q$7*'IBES data'!$U7 -> 79227613 | R8: =R$7*'IBES data'!$U7 -> 47652487 | S8: =S$7*'IBES data'!$U7 -> 75763257 | T8: Frw: billion | U8: =O8*U$2/1000000000 -> 25.062086 | V8: =P8*V$2/1000000000 -> 59.083936 | W8: =Q8*W$2/1000000000 -> 54.022276 | X8: =R8*X$2/1000000000 -> 34.356257 | Y8: =S8*Y$2/1000000000 -> 59.701446 | Z8: Derived from IBES structure
B9: Change in inventory | C9: Calc | D9: tons | E9: =E5-E12 -> 0 | F9: =F5-F12 -> 0 | G9: =G5-G12 -> 0 | H9: =H5-H12 -> 0 | I9: =I5-I12 -> 0 | L9: Less: Other operating and overhead costs | M9: IBES | N9: USD | O9: =O$7*'IBES data'!$U8 -> 7451562.9 | P9: =P$7*'IBES data'!$U8 -> 16688480 | Q9: =Q$7*'IBES data'!$U8 -> 14470509 | R9: =R$7*'IBES data'!$U8 -> 8703477.4 | S9: =S$7*'IBES data'!$U8 -> 13837762 | T9: Frw: billion | U9: =O9*U$2/1000000000 -> 4.5774589 | V9: =P9*V$2/1000000000 -> 10.791372 | W9: =Q9*W$2/1000000000 -> 9.8668861 | X9: =R9*X$2/1000000000 -> 6.2749906 | Y9: =S9*Y$2/1000000000 -> 10.904157 | Z9: Derived from IBES structure
L10: Less: Consumption of capital (Deprc) | M10: IBES | N10: USD | O10: =O$7*'IBES data'!$U9 -> 820727.27 | P10: =P$7*'IBES data'!$U9 -> 1838096.4 | Q10: =Q$7*'IBES data'!$U9 -> 1593805.4 | R10: =R$7*'IBES data'!$U9 -> 958615.16 | S10: =S$7*'IBES data'!$U9 -> 1524113.7 | T10: Frw: billion | U10: =O10*U$2/1000000000 -> 0.50416877 | V10: =P10*V$2/1000000000 -> 1.1885792 | W10: =Q10*W$2/1000000000 -> 1.0867549 | X10: =R10*X$2/1000000000 -> 0.69113767 | Y10: =S10*Y$2/1000000000 -> 1.2010016 | Z10: Derived from IBES structure
B11: Trading operations | L11: Less: Opportunity cost of capital ("normal profit") | M11: Calc | N11: USD | O11: =O10*'Basic data - source records'!Y5*'Basic data - source records'!$AR$2 -> 927421.81 | P11: =P10*'Basic data - source records'!Z5*'Basic data - source records'!$AR$2 -> 1930001.2 | Q11: =Q10*'Basic data - source records'!AA5*'Basic data - source records'!$AR$2 -> 1705371.8 | R11: =R10*'Basic data - source records'!AB5*'Basic data - source records'!$AR$2 -> 1006545.9 | S11: =S10*'Basic data - source records'!AC5*'Basic data - source records'!$AR$2 -> 1600319.4 | T11: Frw: billion | U11: =O11*U$2/1000000000 -> 0.56971071 | V11: =P11*V$2/1000000000 -> 1.2480082 | W11: =Q11*W$2/1000000000 -> 1.1628277 | X11: =R11*X$2/1000000000 -> 0.72569456 | Y11: =S11*Y$2/1000000000 -> 1.2610517 | Z11: Derived from IBES structure
B12: Tagged purchases | C12: ITRI | D12: tons | E12: ='Basic data - source records'!C7 -> 967.88761 | F12: ='Basic data - source records'!D7 -> 1924.3862 | G12: ='Basic data - source records'!E7 -> 2097.5135 | H12: ='Basic data - source records'!F7 -> 1332 | I12: ='Basic data - source records'!G7 -> 2553.6 | J12: Data verified by RMB
L13: Equal: Resource rent | M13: Calc | N13: USD | O13: =O7-(O8+O9+O10+O11) -> -1758312.5 | P13: =P7-(P8+P9+P10+P11) -> -3790859.5 | Q13: =Q7-(Q8+Q9+Q10+Q11) -> -3318913.9 | R13: =R7-(R8+R9+R10+R11) -> -1977032 | S13: =S7-(S8+S9+S10+S11) -> -3143306.8 | T13: Frw: billion | U13: =O13*U$2/1000000000 -> -1.0801228 | V13: =P13*V$2/1000000000 -> -2.4513061 | W13: =Q13*W$2/1000000000 -> -2.2630404 | X13: =R13*X$2/1000000000 -> -1.4253909 | Y13: =S13*Y$2/1000000000 -> -2.4769257 | Z13: Calculated
B14: Less: Waste or losses during processing by traders | C14: Calc | D14: tons | E14: =E12-E16 -> 25.639905 | F14: =F12-F16 -> -122.37527 | G14: =G12-G16 -> -187.39354 | H14: =H12-H16 -> -258 | I14: =I12-I16 -> 1377.6 | L14: Unit rent | M14: Calc | N14: USD/ton | O14: =O13/O5 -> -1816.6495 | P14: =P13/P5 -> -1969.9058 | Q14: =Q13/Q5 -> -1582.3087 | R14: =R13/R5 -> -1484.2583 | S14: =S13/S5 -> -1230.9315 | T14: Frw/ton | U14: =O14*U2 -> -1115958.9 | V14: =P14*V2 -> -1273811.9 | W14: =Q14*W2 -> -1078915.8 | X14: =R14*X2 -> -1070113.3 | Y14: =S14*Y2 -> -969974.05 | Z14: Calculated
L15: Inventory or sundry changes (residual change) | M15: Calc | N15: USD | O15: =O20-O7 -> 399510.88 | P15: =P20-P7 -> 6973543.1 | Q15: =Q20-Q7 -> -4128747.9 | R15: =R20-R7 -> 233461.36 | S15: =S20-S7 -> -55616543 | T15: Frw: billion | U15: =O15*U$2/1000000000 -> 0.24541759 | V15: =P15*V$2/1000000000 -> 4.5093439 | W15: =Q15*W$2/1000000000 -> -2.8152351 | X15: =R15*X$2/1000000000 -> 0.16831983 | Y15: =S15*Y$2/1000000000 -> -43.825836 | Z15: Calculated
B16: Equal: Processed and tagged production | C16: ITRI | D16: tons | E16: ='Basic data - source records'!C8 -> 942.2477 | F16: ='Basic data - source records'!D8 -> 2046.7615 | G16: ='Basic data - source records'!E8 -> 2284.907 | H16: ='Basic data - source records'!F8 -> 1590 | I16: ='Basic data - source records'!G8 -> 1176 | J16: Data verified by RMB | L16: Trading operations | T16: Trading operations
L17: Production (exports) | M17: RMB | N17: tons | O17: =E20 -> 1144.6847 | P17: =F20 -> 2466.0237 | Q17: =G20 -> 2302.5189 | R17: =H20 -> 1651.7113 | S17: =I20 -> 1269.9392 | T17: tons | U17: =O17 -> 1144.6847 | V17: =P17 -> 2466.0237 | W17: =Q17 -> 2302.5189 | X17: =R17 -> 1651.7113 | Y17: =S17 -> 1269.9392 | Z17: From physical accounts
B18: Change in inventory | C18: Calc | D18: tons | E18: =E16-E20 -> -202.437 | F18: =F16-F20 -> -419.2622 | G18: =G16-G20 -> -17.61184 | H18: =H16-H20 -> -61.71126 | I18: =I16-I20 -> -93.9392 | L18: Average price | M18: Calc | N18: USD/ton | O18: =O19/O17 -> 49718.149 | P18: =P19/P17 -> 54570.285 | Q18: =Q19/Q17 -> 45506.828 | R18: =R19/R17 -> 40079.84 | S18: =S19/S17 -> 31294.811 | T18: Frw/ton | U18: =O18*U2 -> 30541618 | V18: =P18*V2 -> 35287109 | W18: =Q18*W2 -> 31029364 | X18: =R18*X2 -> 28896567 | Y18: =S18*Y2 -> 24660311 | Z18: Calculated
L19: Sales (exports) | M19: RMB | N19: USD | O19: ='Basic data - source records'!R6 -> 56911605 | P19: ='Basic data - source records'!S6 -> 1.3457161e+08 | Q19: ='Basic data - source records'!T6 -> 1.0478033e+08 | R19: ='Basic data - source records'!U6 -> 66200323 | S19: ='Basic data - source records'!V6 -> 39742507 | T19: Frw: billion | U19: =O19*U$2/1000000000 -> 34.960522 | V19: =P19*V$2/1000000000 -> 87.018847 | W19: =Q19*W$2/1000000000 -> 71.445696 | X19: =R19*X$2/1000000000 -> 47.728785 | Y19: =S19*Y$2/1000000000 -> 31.317095 | Z19: Published data
B20: Equal: Marketed production (exports) | C20: RMB | D20: tons | E20: ='Basic data - source records'!J6 -> 1144.6847 | F20: ='Basic data - source records'!K6 -> 2466.0237 | G20: ='Basic data - source records'!L6 -> 2302.5189 | H20: ='Basic data - source records'!M6 -> 1651.7113 | I20: ='Basic data - source records'!N6 -> 1269.9392 | J20: RMB & RNB | L20: Less: Purchase of raw material | M20: IBES | N20: USD | O20: =O$19*'IBES data'!$U31 -> 48639029 | P20: =P$19*'IBES data'!$U31 -> 1.1501051e+08 | Q20: =Q$19*'IBES data'!$U31 -> 89549637 | R20: =R$19*'IBES data'!$U31 -> 56577555 | S20: =S$19*'IBES data'!$U31 -> 33965602 | T20: Frw: billion | U20: =O20*U$2/1000000000 -> 29.878719 | V20: =P20*V$2/1000000000 -> 74.369932 | W20: =Q20*W$2/1000000000 -> 61.060469 | X20: =R20*X$2/1000000000 -> 40.791009 | Y20: =S20*Y$2/1000000000 -> 26.764895 | Z20: Derived from IBES structure
L21: Less: Intermediate consumption | M21: IBES | N21: USD | O21: =O$19*'IBES data'!$U32 -> 0 | P21: =P$19*'IBES data'!$U32 -> 0 | Q21: =Q$19*'IBES data'!$U32 -> 0 | R21: =R$19*'IBES data'!$U32 -> 0 | S21: =S$19*'IBES data'!$U32 -> 0 | T21: Frw: billion | U21: =O21*U$2/1000000000 -> 0 | V21: =P21*V$2/1000000000 -> 0 | W21: =Q21*W$2/1000000000 -> 0 | X21: =R21*X$2/1000000000 -> 0 | Y21: =S21*Y$2/1000000000 -> 0 | Z21: Derived from IBES structure
L22: Less: Other operating and overhead costs | M22: IBES | N22: USD | O22: =O$19*'IBES data'!$U33 -> 9234142.6 | P22: =P$19*'IBES data'!$U33 -> 21834799 | Q22: =Q$19*'IBES data'!$U33 -> 17001041 | R22: =R$19*'IBES data'!$U33 -> 10741275 | S22: =S$19*'IBES data'!$U33 -> 6448385.6 | T22: Frw: billion | U22: =O22*U$2/1000000000 -> 5.6724889 | V22: =P22*V$2/1000000000 -> 14.119167 | W22: =Q22*W$2/1000000000 -> 11.592359 | X22: =R22*X$2/1000000000 -> 7.7441922 | Y22: =S22*Y$2/1000000000 -> 5.0813279 | Z22: Derived from IBES structure
B23: Key to colour coding: | L23: Less: Consumption of capital (Deprc) | M23: IBES | N23: USD | O23: =O$19*'IBES data'!$U34 -> 521747.28 | P23: =P$19*'IBES data'!$U34 -> 1233709.2 | Q23: =Q$19*'IBES data'!$U34 -> 960592.35 | R23: =R$19*'IBES data'!$U34 -> 606903.26 | S23: =S$19*'IBES data'!$U34 -> 364346.51 | T23: Frw: billion | U23: =O23*U$2/1000000000 -> 0.32050682 | V23: =P23*V$2/1000000000 -> 0.79776078 | W23: =Q23*W$2/1000000000 -> 0.65499115 | X23: =R23*X$2/1000000000 -> 0.43756214 | Y23: =S23*Y$2/1000000000 -> 0.28710505 | Z23: Derived from IBES structure
B24: High quality data - published | L24: Less: Opportunity cost of capital ("normal profit") | M24: Calc | N24: USD | O24: =O23*'Basic data - source records'!Y5*'Basic data - source records'!$AR$2 -> 589574.42 | P24: =P23*'Basic data - source records'!Z5*'Basic data - source records'!$AR$2 -> 1295394.7 | Q24: =Q23*'Basic data - source records'!AA5*'Basic data - source records'!$AR$2 -> 1027833.8 | R24: =R23*'Basic data - source records'!AB5*'Basic data - source records'!$AR$2 -> 637248.42 | S24: =S23*'Basic data - source records'!AC5*'Basic data - source records'!$AR$2 -> 382563.84 | T24: Frw: billion | U24: =O24*U$2/1000000000 -> 0.36217271 | V24: =P24*V$2/1000000000 -> 0.83764882 | W24: =Q24*W$2/1000000000 -> 0.70084053 | X24: =R24*X$2/1000000000 -> 0.45944025 | Y24: =S24*Y$2/1000000000 -> 0.3014603 | Z24: Derived from IBES structure
B25: High quality input - derived from IBES structure
B26: Good quality data - derived from hard data | L26: Equal: Resource rent | M26: Calc | N26: USD | O26: =O19-(O20+O21+O22+O23+O24) -> -2072888.5 | P26: =P19-(P20+P21+P22+P23+P24) -> -4802798.3 | Q26: =Q19-(Q20+Q21+Q22+Q23+Q24) -> -3758773.1 | R26: =R19-(R20+R21+R22+R23+R24) -> -2362658.7 | S26: =S19-(S20+S21+S22+S23+S24) -> -1418391.6 | T26: Frw: billion | U26: =O26*U$2/1000000000 -> -1.2733653 | V26: =P26*V$2/1000000000 -> -3.1056621 | W26: =Q26*W$2/1000000000 -> -2.5629635 | X26: =R26*X$2/1000000000 -> -1.7034181 | Y26: =S26*Y$2/1000000000 -> -1.1176926 | Z26: Calculated
B27: Results/outcomes - based on formulas | L27: Unit rent | M27: Calc | N27: USD/ton | O27: =O26/O17 -> -1810.8816 | P27: =P26/P17 -> -1947.5881 | Q27: =Q26/Q17 -> -1632.4614 | R27: =R26/R17 -> -1430.4308 | S27: =S26/S17 -> -1116.8972 | T27: Frw/ton | U27: =O27*U2 -> -1112415.8 | V27: =P27*V2 -> -1259380.5 | W27: =Q27*W2 -> -1113112.9 | X27: =R27*X2 -> -1031305 | Y27: =S27*Y2 -> -880115.02 | Z27: Calculated
L28: Royalty payments | M28: Calc | N28: USD | O28: =0*O19 -> 0 | P28: =0.02*P19 -> 2691432.3 | Q28: =0.04*Q19 -> 4191213.2 | R28: =0.04*R19 -> 2648012.9 | S28: =0.04*S19 -> 1589700.3 | T28: Frw: billion | U28: =O28*U2/1000000000 -> 0 | V28: =P28*V2/1000000000 -> 1.7403769 | W28: =Q28*W2/1000000000 -> 2.8578279 | X28: =R28*X2/1000000000 -> 1.9091514 | Y28: =S28*Y2/1000000000 -> 1.2526838 | Z28: Calculated as 4% of sales

Sheet MRA - Wolfram - Tungsten
A1: Mineral accounts: Flow accounts: Wolfram
B2: Physical accounts | L2: Monetary accounts | T2: Exchange rate | U2: ='Basic data - source records'!AF5 -> 614.29514 | V2: ='Basic data - source records'!AG5 -> 646.63597 | W2: ='Basic data - source records'!AH5 -> 681.86172 | X2: ='Basic data - source records'!AI5 -> 720.97511 | Y2: ='Basic data - source records'!AJ5 -> 788
C3: Source | D3: Units | E3: 2012 | F3: 2013 | G3: 2014 | H3: 2015 | I3: 2016 | J3: Notes | M3: Source | N3: Units | O3: 2012 | P3: 2013 | Q3: 2014 | R3: 2015 | S3: 2016 | T3: Units | U3: 2012 | V3: 2013 | W3: 2014 | X3: 2015 | Y3: 2016 | Z3: Notes
B4: Mining operations | L4: Mining operations | T4: Mining operations
B5: Tagged production | C5: ITRI | D5: tons | E5: ='Basic data - source records'!C9 -> 1771.2722 | F5: ='Basic data - source records'!D9 -> 2264.212 | G5: ='Basic data - source records'!E9 -> 2534.869 | H5: ='Basic data - source records'!F9 -> 2169.4109 | I5: ='Basic data - source records'!G9 -> 1498 | J5: Data verified by RMB | L5: Production | M5: ITRI | N5: tons | O5: =E5 -> 1771.2722 | P5: =F5 -> 2264.212 | Q5: =G5 -> 2534.869 | R5: =H5 -> 2169.4109 | S5: =I5 -> 1498 | T5: tons | U5: =O5 -> 1771.2722 | V5: =P5 -> 2264.212 | W5: =Q5 -> 2534.869 | X5: =R5 -> 2169.4109 | Y5: =S5 -> 1498 | Z5: From physical accounts
B6: Employment | C6: NISR: LFS | D6: people | L6: Average price | M6: Calc | N6: USD/ton | O6: ='Mining price data'!BO60 -> 12737.778 | P6: ='Mining price data'!BP60 -> 11327.25 | Q6: ='Mining price data'!BQ60 -> 10091.2 | R6: ='Mining price data'!BR60 -> 7377.5 | S6: ='Mining price data'!BS60 -> 5573.1053 | T6: Frw/ton | U6: =O6*U2 -> 7824755 | V6: =P6*V2 -> 7324607.3 | W6: =Q6*W2 -> 6880803 | X6: =R6*X2 -> 5318993.9 | Y6: =S6*Y2 -> 4391607 | Z6: Based on avg. of 5 transactions/month per major trader
B7: Employment | C7: NISR: IBES | D7: people | L7: Sales | M7: Calc | N7: USD | O7: =O6*O5 -> 22562072 | P7: =P6*P5 -> 25647295 | Q7: =Q6*Q5 -> 25579870 | R7: =R6*R5 -> 16004829 | S7: =S6*S5 -> 8348511.8 | T7: Frw: billion | U7: =O7*U$2/1000000000 -> 13.859771 | V7: =P7*V$2/1000000000 -> 16.584464 | W7: =Q7*W$2/1000000000 -> 17.441934 | X7: =R7*X$2/1000000000 -> 11.539083 | Y7: =S7*Y$2/1000000000 -> 6.5786273 | Z7: Calculated
L8: Less: Intermediate consumption (payments to sub-contractors & direct costs to production) | M8: IBES | N8: USD | O8: =O$7*'IBES data'!$U7 -> 19081660 | P8: =P$7*'IBES data'!$U7 -> 21690959 | Q8: =Q$7*'IBES data'!$U7 -> 21633934 | R8: =R$7*'IBES data'!$U7 -> 13535934 | S8: =S$7*'IBES data'!$U7 -> 7060675.3 | T8: Frw: billion | U8: =O8*U$2/1000000000 -> 11.721771 | V8: =P8*V$2/1000000000 -> 14.026154 | W8: =Q8*W$2/1000000000 -> 14.751352 | X8: =R8*X$2/1000000000 -> 9.7590713 | Y8: =S8*Y$2/1000000000 -> 5.5638122 | Z8: Derived from IBES structure
B9: Change in inventory | C9: Calc | D9: tons | E9: =E5-E12 -> 0 | F9: =F5-F12 -> 0 | G9: =G5-G12 -> 0 | H9: =H5-H12 -> 0 | I9: =I5-I12 -> 0 | L9: Less: Other operating and overhead costs | M9: IBES | N9: USD | O9: =O$7*'IBES data'!$U8 -> 3485165.3 | P9: =P$7*'IBES data'!$U8 -> 3961740.1 | Q9: =Q$7*'IBES data'!$U8 -> 3951324.9 | R9: =R$7*'IBES data'!$U8 -> 2472267.5 | S9: =S$7*'IBES data'!$U8 -> 1289595.4 | T9: Frw: billion | U9: =O9*U$2/1000000000 -> 2.1409201 | V9: =P9*V$2/1000000000 -> 2.5618037 | W9: =Q9*W$2/1000000000 -> 2.6942572 | X9: =R9*X$2/1000000000 -> 1.7824433 | Y9: =S9*Y$2/1000000000 -> 1.0162012 | Z9: Derived from IBES structure
L10: Less: Consumption of capital (Deprc) | M10: IBES | N10: USD | O10: =O$7*'IBES data'!$U9 -> 383861.78 | P10: =P$7*'IBES data'!$U9 -> 436352.51 | Q10: =Q$7*'IBES data'!$U9 -> 435205.36 | R10: =R$7*'IBES data'!$U9 -> 272299.56 | S10: =S$7*'IBES data'!$U9 -> 142038.14 | T10: Frw: billion | U10: =O10*U$2/1000000000 -> 0.23580443 | V10: =P10*V$2/1000000000 -> 0.28216123 | W10: =Q10*W$2/1000000000 -> 0.29674987 | X10: =R10*X$2/1000000000 -> 0.19632121 | Y10: =S10*Y$2/1000000000 -> 0.11192605 | Z10: Derived from IBES structure
B11: Trading operations | L11: Less: Opportunity cost of capital ("normal profit") | M11: Calc | N11: USD | O11: =O10*'Basic data - source records'!Y5*'Basic data - source records'!$AR$2 -> 433763.81 | P11: =P10*'Basic data - source records'!Z5*'Basic data - source records'!$AR$2 -> 458170.13 | Q11: =Q10*'Basic data - source records'!AA5*'Basic data - source records'!$AR$2 -> 465669.73 | R11: =R10*'Basic data - source records'!AB5*'Basic data - source records'!$AR$2 -> 285914.54 | S11: =S10*'Basic data - source records'!AC5*'Basic data - source records'!$AR$2 -> 149140.04 | T11: Frw: billion | U11: =O11*U$2/1000000000 -> 0.266459 | V11: =P11*V$2/1000000000 -> 0.29626929 | W11: =Q11*W$2/1000000000 -> 0.31752236 | X11: =R11*X$2/1000000000 -> 0.20613727 | Y11: =S11*Y$2/1000000000 -> 0.11752235 | Z11: Derived from IBES structure
B12: Tagged purchases | C12: ITRI | D12: tons | E12: ='Basic data - source records'!C9 -> 1771.2722 | F12: ='Basic data - source records'!D9 -> 2264.212 | G12: ='Basic data - source records'!E9 -> 2534.869 | H12: ='Basic data - source records'!F9 -> 2169.4109 | I12: ='Basic data - source records'!G9 -> 1498 | J12: Data verified by RMB
L13: Equal: Resource rent | M13: Calc | N13: USD | O13: =O7-(O8+O9+O10+O11) -> -822379.12 | P13: =P7-(P8+P9+P10+P11) -> -899926.17 | Q13: =Q7-(Q8+Q9+Q10+Q11) -> -906264.41 | R13: =R7-(R8+R9+R10+R11) -> -561586.1 | S13: =S7-(S8+S9+S10+S11) -> -292937.1 | T13: Frw: billion | U13: =O13*U$2/1000000000 -> -0.5051835 | V13: =P13*V$2/1000000000 -> -0.58192464 | W13: =Q13*W$2/1000000000 -> -0.61794701 | X13: =R13*X$2/1000000000 -> -0.4048896 | Y13: =S13*Y$2/1000000000 -> -0.23083443 | Z13: Calculated
B14: Less: Waste or losses during processing by traders | C14: Calc | D14: tons | E14: =E12-E16 -> 186.51019 | F14: =F12-F16 -> -5.75276 | G14: =G12-G16 -> 475.9909 | H14: =H12-H16 -> 846.41094 | I14: =I12-I16 -> -141 | L14: Unit rent | M14: Calc | N14: USD/ton | O14: =O13/O5 -> -464.28726 | P14: =P13/P5 -> -397.45667 | Q14: =Q13/Q5 -> -357.51923 | R14: =R13/R5 -> -258.86571 | S14: =S13/S5 -> -195.55213 | T14: Frw/ton | U14: =O14*U2 -> -285209.41 | V14: =P14*V2 -> -257009.78 | W14: =Q14*W2 -> -243778.68 | X14: =R14*X2 -> -186635.73 | Y14: =S14*Y2 -> -154095.08 | Z14: Calculated
L15: Inventory or sundry changes (residual change) | M15: Calc | N15: USD | O15: =O20-O7 -> -117077.29 | P15: =P20-P7 -> 37919.316 | Q15: =Q20-Q7 -> -2852967 | R15: =R20-R7 -> -1182668.7 | S15: =S20-S7 -> 1799232.1 | T15: Frw: billion | U15: =O15*U$2/1000000000 -> -0.071920012 | V15: =P15*V$2/1000000000 -> 0.024519994 | W15: =Q15*W$2/1000000000 -> -1.945329 | X15: =R15*X$2/1000000000 -> -0.85267471 | Y15: =S15*Y$2/1000000000 -> 1.4177949 | Z15: Calculated
B16: Equal: Processed and tagged production | C16: ITRI | D16: tons | E16: ='Basic data - source records'!C10 -> 1584.762 | F16: ='Basic data - source records'!D10 -> 2269.9648 | G16: ='Basic data - source records'!E10 -> 2058.8781 | H16: ='Basic data - source records'!F10 -> 1323 | I16: ='Basic data - source records'!G10 -> 1639 | J16: Data verified by RMB | L16: Trading operations | T16: Trading operations
L17: Production (exports) | M17: RMB | N17: tons | O17: =E20 -> 1750.5665 | P17: =F20 -> 2217.928 | Q17: =G20 -> 2214.4937 | R17: =H20 -> 1784.4011 | S17: =I20 -> 1715.9599 | T17: tons | U17: =O17 -> 1750.5665 | V17: =P17 -> 2217.928 | W17: =Q17 -> 2214.4937 | X17: =R17 -> 1784.4011 | Y17: =S17 -> 1715.9599 | Z17: From physical accounts
B18: Change in inventory | C18: Calc | D18: tons | E18: =E16-E20 -> -165.80449 | F18: =F16-F20 -> 52.03672 | G18: =G16-G20 -> -155.61557 | H18: =H16-H20 -> -461.40112 | I18: =I16-I20 -> -76.95995 | L18: Average price | M18: Calc | N18: USD/ton | O18: =O19/O17 -> 15002.265 | P18: =P19/P17 -> 13550.387 | Q18: =Q19/Q17 -> 12008.306 | R18: =R19/R17 -> 9719.2994 | S18: =S19/S17 -> 6919.5569 | T18: Frw/ton | U18: =O18*U2 -> 9215818.3 | V18: =P18*V2 -> 8762167.4 | W18: =Q18*W2 -> 8188004.3 | X18: =R18*X2 -> 7007372.9 | Y18: =S18*Y2 -> 5452610.9 | Z18: Calculated
L19: Sales (exports) | M19: RMB | N19: USD | O19: ='Basic data - source records'!R7 -> 26262462 | P19: ='Basic data - source records'!S7 -> 30053782 | Q19: ='Basic data - source records'!T7 -> 26592318 | R19: ='Basic data - source records'!U7 -> 17343129 | S19: ='Basic data - source records'!V7 -> 11873683 | T19: Frw: billion | U19: =O19*U$2/1000000000 -> 16.132903 | V19: =P19*V$2/1000000000 -> 19.433857 | W19: =Q19*W$2/1000000000 -> 18.132283 | X19: =R19*X$2/1000000000 -> 12.503964 | Y19: =S19*Y$2/1000000000 -> 9.3564619 | Z19: Published data
B20: Equal: Marketed production (exports) | C20: RMB | D20: tons | E20: ='Basic data - source records'!J7 -> 1750.5665 | F20: ='Basic data - source records'!K7 -> 2217.928 | G20: ='Basic data - source records'!L7 -> 2214.4937 | H20: ='Basic data - source records'!M7 -> 1784.4011 | I20: ='Basic data - source records'!N7 -> 1715.9599 | J20: RMB & RNB | L20: Less: Purchase of raw material | M20: IBES | N20: USD | O20: =O$19*'IBES data'!$U31 -> 22444994 | P20: =P$19*'IBES data'!$U31 -> 25685215 | Q20: =Q$19*'IBES data'!$U31 -> 22726903 | R20: =R$19*'IBES data'!$U31 -> 14822160 | S20: =S$19*'IBES data'!$U31 -> 10147744 | T20: Frw: billion | U20: =O20*U$2/1000000000 -> 13.787851 | V20: =P20*V$2/1000000000 -> 16.608984 | W20: =Q20*W$2/1000000000 -> 15.496605 | X20: =R20*X$2/1000000000 -> 10.686409 | Y20: =S20*Y$2/1000000000 -> 7.9964222 | Z20: Derived from IBES structure
L21: Less: Intermediate consumption | M21: IBES | N21: USD | O21: =O$19*'IBES data'!$U32 -> 0 | P21: =P$19*'IBES data'!$U32 -> 0 | Q21: =Q$19*'IBES data'!$U32 -> 0 | R21: =R$19*'IBES data'!$U32 -> 0 | S21: =S$19*'IBES data'!$U32 -> 0 | T21: Frw: billion | U21: =O21*U$2/1000000000 -> 0 | V21: =P21*V$2/1000000000 -> 0 | W21: =Q21*W$2/1000000000 -> 0 | X21: =R21*X$2/1000000000 -> 0 | Y21: =S21*Y$2/1000000000 -> 0 | Z21: Derived from IBES structure
L22: Less: Other operating and overhead costs | M22: IBES | N22: USD | O22: =O$19*'IBES data'!$U33 -> 4261192.7 | P22: =P$19*'IBES data'!$U33 -> 4876350.1 | Q22: =Q$19*'IBES data'!$U33 -> 4314713.2 | R22: =R$19*'IBES data'!$U33 -> 2813994.1 | S22: =S$19*'IBES data'!$U33 -> 1926554 | T22: Frw: billion | U22: =O22*U$2/1000000000 -> 2.61763 | V22: =P22*V$2/1000000000 -> 3.1532234 | W22: =Q22*W$2/1000000000 -> 2.9420378 | X22: =R22*X$2/1000000000 -> 2.0288197 | Y22: =S22*Y$2/1000000000 -> 1.5181245 | Z22: Derived from IBES structure
B23: Key to colour coding: | L23: Less: Consumption of capital (Deprc) | M23: IBES | N23: USD | O23: =O$19*'IBES data'!$U34 -> 240765.8 | P23: =P$19*'IBES data'!$U34 -> 275523.4 | Q23: =Q$19*'IBES data'!$U34 -> 243789.81 | R23: =R$19*'IBES data'!$U34 -> 158996.22 | S23: =S$19*'IBES data'!$U34 -> 108854.1 | T23: Frw: billion | U23: =O23*U$2/1000000000 -> 0.14790126 | V23: =P23*V$2/1000000000 -> 0.17816334 | W23: =Q23*W$2/1000000000 -> 0.16623094 | X23: =R23*X$2/1000000000 -> 0.11463232 | Y23: =S23*Y$2/1000000000 -> 0.085777031 | Z23: Derived from IBES structure
B24: High quality data - published | L24: Less: Opportunity cost of capital ("normal profit") | M24: Calc | N24: USD | O24: =O23*'Basic data - source records'!Y5*'Basic data - source records'!$AR$2 -> 272065.35 | P24: =P23*'Basic data - source records'!Z5*'Basic data - source records'!$AR$2 -> 289299.57 | Q24: =Q23*'Basic data - source records'!AA5*'Basic data - source records'!$AR$2 -> 260855.1 | R24: =R23*'Basic data - source records'!AB5*'Basic data - source records'!$AR$2 -> 166946.03 | S24: =S23*'Basic data - source records'!AC5*'Basic data - source records'!$AR$2 -> 114296.81 | T24: Frw: billion | U24: =O24*U$2/1000000000 -> 0.16712843 | V24: =P24*V$2/1000000000 -> 0.18707151 | W24: =Q24*W$2/1000000000 -> 0.17786711 | X24: =R24*X$2/1000000000 -> 0.12036393 | Y24: =S24*Y$2/1000000000 -> 0.090065883 | Z24: Derived from IBES structure
B25: High quality input - derived from IBES structure
B26: Good quality data - derived from hard data | L26: Equal: Resource rent | M26: Calc | N26: USD | O26: =O19-(O20+O21+O22+O23+O24) -> -956556.31 | P26: =P19-(P20+P21+P22+P23+P24) -> -1072605.5 | Q26: =Q19-(Q20+Q21+Q22+Q23+Q24) -> -953943.24 | R26: =R19-(R20+R21+R22+R23+R24) -> -618968.19 | S26: =S19-(S20+S21+S22+S23+S24) -> -423766.21 | T26: Frw: billion | U26: =O26*U$2/1000000000 -> -0.5876079 | V26: =P26*V$2/1000000000 -> -0.69358531 | W26: =Q26*W$2/1000000000 -> -0.65045738 | X26: =R26*X$2/1000000000 -> -0.44626066 | Y26: =S26*Y$2/1000000000 -> -0.33392777 | Z26: Calculated
B27: Results/outcomes - based on formulas | L27: Unit rent | M27: Calc | N27: USD/ton | O27: =O26/O17 -> -546.42672 | P27: =P26/P17 -> -483.60699 | Q27: =Q26/Q17 -> -430.77263 | R27: =R26/R17 -> -346.87727 | S27: =S26/S17 -> -246.95577 | T27: Frw/ton | U27: =O27*U2 -> -335667.28 | V27: =P27*V2 -> -312717.68 | W27: =Q27*W2 -> -293727.36 | X27: =R27*X2 -> -250089.88 | Y27: =S27*Y2 -> -194601.15 | Z27: Calculated
L28: Royalty payments | M28: Calc | N28: USD | O28: =0*O19 -> 0 | P28: =0.02*P19 -> 601075.65 | Q28: =0.04*Q19 -> 1063692.7 | R28: =0.04*R19 -> 693725.15 | S28: =0.04*S19 -> 474947.3 | T28: Frw: billion | U28: =O28*U2/1000000000 -> 0 | V28: =P28*V2/1000000000 -> 0.38867714 | W28: =Q28*W2/1000000000 -> 0.72529134 | X28: =R28*X2/1000000000 -> 0.50015856 | Y28: =S28*Y2/1000000000 -> 0.37425847 | Z28: Calculated as 4% of sales

Sheet Graphs
AO1: R_GDP National Accounts 2018_r | AW1: Year | AX1: GDP in current prices | AY1: Mining GDP in current prices | AZ1: Mining GDP as % of GDP | BA1: Population (millions) | BB1: GDP/cap ('000RwF) | BC1: GDP/capita (US$) | BE1: Exchange rate (RwF:US$)
C2: Production and exports of minerals | W2: Rwanda: Export prices and volumes of minerals | AO2: GDP in RwF billions (current prices) | AP2: GDP in RwF billions (constant prices) | AQ2: mining GDP in RwF billions (current p) | AS2: Goods export (fob) US$ | AT2: FOB exports in current prices (US$ million) | AU2: Exchange rate | AV2: 3T export | AX2: (million US$) | AY2: (million US$)
D3: 2012 | E3: 2013 | F3: 2014 | G3: 2015 | H3: 2016 | W3: =D3 -> 2012 | X3: =E3 -> 2013 | Y3: =F3 -> 2014 | Z3: =G3 -> 2015 | AA3: =H3 -> 2016 | AO3: 607 | AP3: 1760 | AQ3: 1 | AR3: 1999 | AS3: 62874251 | AT3: 62.874251 | AU3: 334 | AW3: 1999 | AX3: =(AO3*1000000000)/(BE3*1000000) -> 1817.3653 | AY3: =(AQ3*1000000000)/(BE3*1000000) -> 2.994012 | AZ3: =AY3/AX3 -> 0.0016474465 | BA3: =AO3/BB3 -> 7.4938272 | BB3: 81 | BC3: 242 | BE3: 334
C4: Cassiterite production | D4: ='MRA - Cassiterite - Tin'!E5 -> 3670.5237 | E4: ='MRA - Cassiterite - Tin'!F5 -> 6112.1432 | F4: ='MRA - Cassiterite - Tin'!G5 -> 7137.4683 | G4: ='MRA - Cassiterite - Tin'!H5 -> 4714.1224 | H4: ='MRA - Cassiterite - Tin'!I5 -> 2024 | V4: =C5 -> Cassiterite exports | W4: =D5 -> 4636.6403 | X4: =E5 -> 4895.2675 | Y4: =F5 -> 5953.7963 | Z4: =G5 -> 3845.6561 | AA4: =H5 -> 3549.915 | AO4: 676 | AP4: 1907 | AQ4: 1 | AR4: 2000 | AS4: 69230769 | AT4: 69.230769 | AU4: 390 | AW4: 2000 | AX4: =(AO4*1000000000)/(BE4*1000000) -> 1733.3333 | AY4: =(AQ4*1000000000)/(BE4*1000000) -> 2.5641026 | AZ4: =AY4/AX4 -> 0.0014792899 | BA4: =AO4/BB4 -> 7.6818182 | BB4: 88 | BC4: 225 | BE4: 390
C5: Cassiterite exports | D5: ='MRA - Cassiterite - Tin'!E20 -> 4636.6403 | E5: ='MRA - Cassiterite - Tin'!F20 -> 4895.2675 | F5: ='MRA - Cassiterite - Tin'!G20 -> 5953.7963 | G5: ='MRA - Cassiterite - Tin'!H20 -> 3845.6561 | H5: ='MRA - Cassiterite - Tin'!I20 -> 3549.915 | V5: =C7 -> Coltan exports | W5: =D7 -> 1144.6847 | X5: =E7 -> 2466.0237 | Y5: =F7 -> 2302.5189 | Z5: =G7 -> 1651.7113 | AA5: =H7 -> 1269.9392 | AO5: 742 | AP5: 2069 | AQ5: 6 | AR5: 2001 | AS5: 92550790 | AT5: 92.55079 | AU5: 443 | AW5: 2001 | AX5: =(AO5*1000000000)/(BE5*1000000) -> 1674.9436 | AY5: =(AQ5*1000000000)/(BE5*1000000) -> 13.544018 | AZ5: =AY5/AX5 -> 0.0080862534 | BA5: =AO5/BB5 -> 7.893617 | BB5: 94 | BC5: 211 | BE5: 443
C6: Coltan production | D6: ='MRA - Coltan - Tantalum'!E5 -> 967.88761 | E6: ='MRA - Coltan - Tantalum'!F5 -> 1924.3862 | F6: ='MRA - Coltan - Tantalum'!G5 -> 2097.5135 | G6: ='MRA - Coltan - Tantalum'!H5 -> 1332 | H6: ='MRA - Coltan - Tantalum'!I5 -> 2553.6 | V6: =C9 -> Wolfram exports | W6: =D9 -> 1750.5665 | X6: =E9 -> 2217.928 | Y6: =F9 -> 2214.4937 | Z6: =G9 -> 1784.4011 | AA6: =H9 -> 1715.9599 | AO6: 797 | AP6: 2342 | AQ6: 2 | AR6: 2002 | AS6: 67368421 | AT6: 67.368421 | AU6: 475 | AW6: 2002 | AX6: =(AO6*1000000000)/(BE6*1000000) -> 1677.8947 | AY6: =(AQ6*1000000000)/(BE6*1000000) -> 4.2105263 | AZ6: =AY6/AX6 -> 0.0025094103 | BA6: =AO6/BB6 -> 8.1326531 | BB6: 98 | BC6: 206 | BE6: 475
C7: Coltan exports | D7: ='MRA - Coltan - Tantalum'!E20 -> 1144.6847 | E7: ='MRA - Coltan - Tantalum'!F20 -> 2466.0237 | F7: ='MRA - Coltan - Tantalum'!G20 -> 2302.5189 | G7: ='MRA - Coltan - Tantalum'!H20 -> 1651.7113 | H7: ='MRA - Coltan - Tantalum'!I20 -> 1269.9392 | V7: =C20 -> Cassiterite export prices | W7: =D20 -> 11408.456 | X7: =E20 -> 12476.229 | Y7: =F20 -> 12083.99 | Z7: =G20 -> 8909.5964 | AA7: =H20 -> 9805.278 | AO7: 993 | AP7: 2393 | AQ7: 3 | AR7: 2003 | AS7: 61338290 | AT7: 61.33829 | AU7: 538 | AW7: 2003 | AX7: =(AO7*1000000000)/(BE7*1000000) -> 1845.7249 | AY7: =(AQ7*1000000000)/(BE7*1000000) -> 5.5762082 | AZ7: =AY7/AX7 -> 0.003021148 | BA7: =AO7/BB7 -> 8.3445378 | BB7: 119 | BC7: 221 | BE7: 538
C8: Wolfram production | D8: ='MRA - Wolfram - Tungsten'!E5 -> 1771.2722 | E8: ='MRA - Wolfram - Tungsten'!F5 -> 2264.212 | F8: ='MRA - Wolfram - Tungsten'!G5 -> 2534.869 | G8: ='MRA - Wolfram - Tungsten'!H5 -> 2169.4109 | H8: ='MRA - Wolfram - Tungsten'!I5 -> 1498 | V8: =C22 -> Coltan export prices | W8: =D22 -> 49718.149 | X8: =E22 -> 54570.285 | Y8: =F22 -> 45506.828 | Z8: =G22 -> 40079.84 | AA8: =H22 -> 31294.811 | AO8: 1206 | AP8: 2572 | AQ8: 8 | AR8: 2004 | AS8: 95652174 | AT8: 95.652174 | AU8: 575 | AW8: 2004 | AX8: =(AO8*1000000000)/(BE8*1000000) -> 2097.3913 | AY8: =(AQ8*1000000000)/(BE8*1000000) -> 13.913043 | AZ8: =AY8/AX8 -> 0.0066334992 | BA8: =AO8/BB8 -> 8.5531915 | BB8: 141 | BC8: 245 | BE8: 575
C9: Wolfram exports | D9: ='MRA - Wolfram - Tungsten'!E20 -> 1750.5665 | E9: ='MRA - Wolfram - Tungsten'!F20 -> 2217.928 | F9: ='MRA - Wolfram - Tungsten'!G20 -> 2214.4937 | G9: ='MRA - Wolfram - Tungsten'!H20 -> 1784.4011 | H9: ='MRA - Wolfram - Tungsten'!I20 -> 1715.9599 | V9: =C24 -> Wolfram export prices | W9: =D24 -> 15002.265 | X9: =E24 -> 13550.387 | Y9: =F24 -> 12008.306 | Z9: =G24 -> 9719.2994 | AA9: =H24 -> 6919.5569 | AO9: 1440 | AP9: 2813 | AQ9: 10 | AR9: 2005 | AS9: 1.2028725e+08 | AT9: 120.28725 | AU9: 557 | AW9: 2005 | AX9: =(AO9*1000000000)/(BE9*1000000) -> 2585.2783 | AY9: =(AQ9*1000000000)/(BE9*1000000) -> 17.953321 | AZ9: =AY9/AX9 -> 0.0069444444 | BA9: =AO9/BB9 -> 8.7804878 | BB9: 164 | BC9: 295 | BE9: 557
AO10: 1762 | AP10: 3072 | AQ10: 23 | AR10: 2006 | AS10: 1.4311594e+08 | AT10: 143.11594 | AU10: 552 | AW10: 2006 | AX10: =(AO10*1000000000)/(BE10*1000000) -> 3192.029 | AY10: =(AQ10*1000000000)/(BE10*1000000) -> 41.666667 | AZ10: =AY10/AX10 -> 0.013053348 | BA10: =AO10/BB10 -> 8.9897959 | BB10: 196 | BC10: 355 | BE10: 552
AO11: 2120 | AP11: 3307 | AQ11: 43 | AR11: 2007 | AS11: 1.7915905e+08 | AT11: 179.15905 | AU11: 547 | AW11: 2007 | AX11: =(AO11*1000000000)/(BE11*1000000) -> 3875.6856 | AY11: =(AQ11*1000000000)/(BE11*1000000) -> 78.610603 | AZ11: =AY11/AX11 -> 0.020283019 | BA11: =AO11/BB11 -> 9.2173913 | BB11: 230 | BC11: 420 | BE11: 547
AO12: 2693 | AP12: 3676 | AQ12: 51 | AR12: 2008 | AS12: 2.6873857e+08 | AT12: 268.73857 | AU12: 547 | AW12: 2008 | AX12: =(AO12*1000000000)/(BE12*1000000) -> 4923.2176 | AY12: =(AQ12*1000000000)/(BE12*1000000) -> 93.235832 | AZ12: =AY12/AX12 -> 0.018937987 | BA12: =AO12/BB12 -> 9.4823944 | BB12: 284 | BC12: 520 | BE12: 547
AO13: 3097 | AP13: 3906 | AQ13: 33 | AR13: 2009 | AS13: 2.0070423e+08 | AT13: 200.70423 | AU13: 568 | AW13: 2009 | AX13: =(AO13*1000000000)/(BE13*1000000) -> 5452.4648 | AY13: =(AQ13*1000000000)/(BE13*1000000) -> 58.098592 | AZ13: =AY13/AX13 -> 0.010655473 | BA13: =AO13/BB13 -> 9.7084639 | BB13: 319 | BC13: 561 | BE13: 568
AA14: 532.40152 | AO14: 3411 | AP14: 4192 | AQ14: 45 | AR14: 2010 | AS14: 2.6929674e+08 | AT14: 269.29674 | AU14: 583 | AW14: 2010 | AX14: =(AO14*1000000000)/(BE14*1000000) -> 5850.7719 | AY14: =(AQ14*1000000000)/(BE14*1000000) -> 77.186964 | AZ14: =AY14/AX14 -> 0.013192612 | BA14: =AO14/BB14 -> 9.9736842 | BB14: 342 | BC14: 587 | BE14: 583
AO15: 3990 | AP15: 4526 | AQ15: 102 | AR15: 2011 | AS15: 465000000 | AT15: 465 | AU15: 600 | AW15: 2011 | AX15: =(AO15*1000000000)/(BE15*1000000) -> 6650 | AY15: =(AQ15*1000000000)/(BE15*1000000) -> 170 | AZ15: =AY15/AX15 -> 0.02556391 | BA15: =AO15/BB15 -> 10.230769 | BB15: 390 | BC15: 650 | BE15: 600
V16: US$ | AO16: 4564 | AP16: 4917 | AQ16: 97 | AR16: 2012 | AS16: 5.1302932e+08 | AT16: 513.02932 | AU16: 614 | AW16: 2012 | AX16: =(AO16*1000000000)/(BE16*1000000) -> 7433.2248 | AY16: =(AQ16*1000000000)/(BE16*1000000) -> 157.98046 | AZ16: =AY16/AX16 -> 0.021253287 | BA16: =AO16/BB16 -> 10.491954 | BB16: 435 | BC16: 709 | BE16: 614
C17: Producer and export prices of minerals | V17: Cassiterite exports | W17: ='MRA - Cassiterite - Tin'!O19/1000000 -> 52.896906 | X17: ='MRA - Cassiterite - Tin'!P19/1000000 -> 61.074479 | Y17: ='MRA - Cassiterite - Tin'!Q19/1000000 -> 71.945617 | Z17: ='MRA - Cassiterite - Tin'!R19/1000000 -> 34.263244 | AA17: ='MRA - Cassiterite - Tin'!S19/1000000 -> 34.807904 | AB17: ='Basic data - source records'!W5/1000000 -> 50.154998 | AO17: 4929 | AP17: 5149 | AQ17: 124 | AR17: 2013 | AS17: 6.0587326e+08 | AT17: 605.87326 | AU17: 647 | AW17: 2013 | AX17: =(AO17*1000000000)/(BE17*1000000) -> 7618.238 | AY17: =(AQ17*1000000000)/(BE17*1000000) -> 191.65379 | AZ17: =AY17/AX17 -> 0.025157233 | BA17: =AO17/BB17 -> 10.738562 | BB17: 459 | BC17: 710 | BE17: 647
D18: 2012 | E18: 2013 | F18: 2014 | G18: 2015 | H18: 2016 | V18: Coltan exports | W18: ='MRA - Coltan - Tantalum'!O19/1000000 -> 56.911605 | X18: ='MRA - Coltan - Tantalum'!P19/1000000 -> 134.57161 | Y18: ='MRA - Coltan - Tantalum'!Q19/1000000 -> 104.78033 | Z18: ='MRA - Coltan - Tantalum'!R19/1000000 -> 66.200323 | AA18: ='MRA - Coltan - Tantalum'!S19/1000000 -> 39.742507 | AB18: ='Basic data - source records'!W6/1000000 -> 62.209186 | AO18: 5466 | AP18: 5466 | AQ18: 147 | AR18: 2014 | AS18: 5.8565154e+08 | AT18: 585.65154 | AU18: 683 | AW18: 2014 | AX18: =(AO18*1000000000)/(BE18*1000000) -> 8002.9283 | AY18: =(AQ18*1000000000)/(BE18*1000000) -> 215.22694 | AZ18: =AY18/AX18 -> 0.026893524 | BA18: =AO18/BB18 -> 10.997988 | BB18: 497 | BC18: 728 | BE18: 683
C19: Cassiterite producer prices | D19: ='MRA - Cassiterite - Tin'!O6 -> 9213.9125 | E19: ='MRA - Cassiterite - Tin'!P6 -> 10196.272 | F19: ='MRA - Cassiterite - Tin'!Q6 -> 10101.396 | G19: ='MRA - Cassiterite - Tin'!R6 -> 7003.4075 | H19: ='MRA - Cassiterite - Tin'!S6 -> 7573.3436 | V19: Wolfram exports | W19: ='MRA - Wolfram - Tungsten'!O19/1000000 -> 26.262462 | X19: ='MRA - Wolfram - Tungsten'!P19/1000000 -> 30.053782 | Y19: ='MRA - Wolfram - Tungsten'!Q19/1000000 -> 26.592318 | Z19: ='MRA - Wolfram - Tungsten'!R19/1000000 -> 17.343129 | AA19: ='MRA - Wolfram - Tungsten'!S19/1000000 -> 11.873683 | AB19: ='Basic data - source records'!W7/1000000 -> 12.604563 | AO19: 5968 | AP19: 5951 | AQ19: 132 | AR19: 2015 | AS19: 5.2222222e+08 | AT19: 522.22222 | AU19: 720 | AW19: 2015 | AX19: =(AO19*1000000000)/(BE19*1000000) -> 8288.8889 | AY19: =(AQ19*1000000000)/(BE19*1000000) -> 183.33333 | AZ19: =AY19/AX19 -> 0.022117962 | BA19: =AO19/BB19 -> 11.260377 | BB19: 530 | BC19: 736 | BE19: 720
C20: Cassiterite export prices | D20: ='MRA - Cassiterite - Tin'!O18 -> 11408.456 | E20: ='MRA - Cassiterite - Tin'!P18 -> 12476.229 | F20: ='MRA - Cassiterite - Tin'!Q18 -> 12083.99 | G20: ='MRA - Cassiterite - Tin'!R18 -> 8909.5964 | H20: ='MRA - Cassiterite - Tin'!S18 -> 9805.278 | W20: =SUM(W17:W19) -> 136.07097 | X20: =SUM(X17:X19) -> 225.69987 | Y20: =SUM(Y17:Y19) -> 203.31827 | Z20: =SUM(Z17:Z19) -> 117.8067 | AA20: =SUM(AA17:AA19) -> 86.424093 | AB20: =SUM(AB17:AB19) -> 124.96875 | AO20: 6672 | AP20: 6307 | AQ20: 137 | AR20: 2016 | AS20: 5.3240152e+08 | AT20: 532.40152 | AU20: 787 | AW20: 2016 | AX20: =(AO20*1000000000)/(BE20*1000000) -> 8477.7637 | AY20: =(AQ20*1000000000)/(BE20*1000000) -> 174.07878 | AZ20: =AY20/AX20 -> 0.020533573 | BA20: =AO20/BB20 -> 11.523316 | BB20: 579 | BC20: 735 | BE20: 787
C21: Coltan producer prices | D21: ='MRA - Coltan - Tantalum'!O6 -> 49840 | E21: ='MRA - Coltan - Tantalum'!P6 -> 56141 | F21: ='MRA - Coltan - Tantalum'!Q6 -> 44661.636 | G21: ='MRA - Coltan - Tantalum'!R6 -> 42300.37 | H21: ='MRA - Coltan - Tantalum'!S6 -> 35080.727 | V21: Total exports | W21: =AT16 -> 513.02932 | X21: =AT17 -> 605.87326 | Y21: =AT18 -> 585.65154 | Z21: =AT19 -> 522.22222 | AA21: =AT20 -> 532.40152 | AB21: =AT21 -> 855.76923 | AO21: 7600 | AP21: 6693 | AQ21: 182 | AR21: 2017 | AS21: 8.5576923e+08 | AT21: 855.76923 | AU21: 832 | AW21: 2017 | AX21: =(AO21*1000000000)/(BE21*1000000) -> 9134.6154 | AY21: =(AQ21*1000000000)/(BE21*1000000) -> 218.75 | AZ21: =AY21/AX21 -> 0.023947368 | BA21: =AO21/BB21 -> 11.801242 | BB21: 644 | BC21: 774 | BE21: 832
C22: Coltan export prices | D22: ='MRA - Coltan - Tantalum'!O18 -> 49718.149 | E22: ='MRA - Coltan - Tantalum'!P18 -> 54570.285 | F22: ='MRA - Coltan - Tantalum'!Q18 -> 45506.828 | G22: ='MRA - Coltan - Tantalum'!R18 -> 40079.84 | H22: ='MRA - Coltan - Tantalum'!S18 -> 31294.811 | V22: 3T to total exports | W22: =W20/W21 -> 0.2652304 | X22: =X20/X21 -> 0.37251995 | Y22: =Y20/Y21 -> 0.34716594 | Z22: =Z20/Z21 -> 0.22558729 | AA22: =AA20/AA21 -> 0.16232879 | AO22: 8189 | AP22: 7269 | AQ22: 204 | AR22: 2018 | AW22: 2018 | AX22: =(AO22*1000000000)/(BE22*1000000) -> 9511.0337 | AY22: =(AQ22*1000000000)/(BE22*1000000) -> 236.9338 | AZ22: =AY22/AX22 -> 0.024911467 | BA22: =AO22/BB22 -> 12.096012 | BB22: 677 | BC22: 787 | BE22: 861
C23: Wolfram production prices | D23: ='MRA - Wolfram - Tungsten'!O6 -> 12737.778 | E23: ='MRA - Wolfram - Tungsten'!P6 -> 11327.25 | F23: ='MRA - Wolfram - Tungsten'!Q6 -> 10091.2 | G23: ='MRA - Wolfram - Tungsten'!R6 -> 7377.5 | H23: ='MRA - Wolfram - Tungsten'!S6 -> 5573.1053
C24: Wolfram export prices | D24: ='MRA - Wolfram - Tungsten'!O18 -> 15002.265 | E24: ='MRA - Wolfram - Tungsten'!P18 -> 13550.387 | F24: ='MRA - Wolfram - Tungsten'!Q18 -> 12008.306 | G24: ='MRA - Wolfram - Tungsten'!R18 -> 9719.2994 | H24: ='MRA - Wolfram - Tungsten'!S18 -> 6919.5569 | W24: 2012 | X24: 2013 | Y24: 2014 | Z24: 2015 | AA24: 2016 | AB24: 2017
V25: Cassiterite | W25: =W17/W$21 -> 0.10310699 | X25: =X17/X$21 -> 0.10080405 | Y25: =Y17/Y$21 -> 0.12284714 | Z25: =Z17/Z$21 -> 0.065610467 | AA25: =AA17/AA$21 -> 0.065379046 | AB25: =AB17/AB$21 -> 0.058608087
V26: Coltan | W26: =W18/W$21 -> 0.11093246 | X26: =X18/X$21 -> 0.22211182 | Y26: =Y18/Y$21 -> 0.17891241 | Z26: =Z18/Z$21 -> 0.12676658 | AA26: =AA18/AA$21 -> 0.07464762 | AB26: =AB18/AB$21 -> 0.072693881
V27: Wolfram | W27: =W19/W$21 -> 0.051190958 | X27: =X19/X$21 -> 0.049604074 | Y27: =Y19/Y$21 -> 0.045406383 | Z27: =Z19/Z$21 -> 0.033210246 | AA27: =AA19/AA$21 -> 0.02230212 | AB27: =AB19/AB$21 -> 0.014728928
V28: Mining GDP as % to total GDP | W28: =AZ16 -> 0.021253287 | X28: =AZ17 -> 0.025157233 | Y28: =AZ18 -> 0.026893524 | Z28: =AZ19 -> 0.022117962 | AA28: =AZ20 -> 0.020533573 | AB28: =AZ21 -> 0.023947368
W29: =W20/W$21 -> 0.2652304 | X29: =X20/X$21 -> 0.37251995 | Y29: =Y20/Y$21 -> 0.34716594 | Z29: =Z20/Z$21 -> 0.22558729 | AA29: =AA20/AA$21 -> 0.16232879 | AB29: =AB20/AB$21 -> 0.1460309 | AQ29: 1999 | AR29: 2000 | AS29: 2001 | AT29: 2002 | AU29: 2003 | AV29: 2004 | AW29: 2005 | AX29: 2006 | AY29: 2007 | AZ29: 2008 | BA29: 2009 | BB29: 2010 | BC29: 2011 | BD29: 2012 | BE29: 2013 | BF29: 2014 | BG29: 2015 | BH29: 2016 | BI29: 2017
AP30: Mining GDP as % of GDP | AQ30: 0.001 | AR30: 0.002 | AS30: 0.008 | AT30: 0.003 | AU30: 0.003 | AV30: 0.007 | AW30: 0.007 | AX30: 0.013 | AY30: 0.021 | AZ30: 0.019 | BA30: 0.011 | BB30: 0.014 | BC30: 0.026 | BD30: 0.021 | BE30: 0.025 | BF30: 0.027 | BG30: 0.022 | BH30: 0.021 | BI30: 0.023 | BJ30: 0.023
C35: Resource rents
D36: 2012 | E36: 2013 | F36: 2014 | G36: 2015 | H36: 2016
C37: Cassiterite resource rent: producers | D37: ='MRA - Cassiterite - Tin'!O13/1000000 -> -1.2327222 | E37: ='MRA - Cassiterite - Tin'!P13/1000000 -> -2.1867555 | F37: ='MRA - Cassiterite - Tin'!Q13/1000000 -> -2.5543604 | G37: ='MRA - Cassiterite - Tin'!R13/1000000 -> -1.1584454 | H37: ='MRA - Cassiterite - Tin'!S13/1000000 -> -0.53785285
C38: Cassiterite resource rent: traders | D38: ='MRA - Cassiterite - Tin'!O26/1000000 -> -1.9266613 | E38: ='MRA - Cassiterite - Tin'!P26/1000000 -> -2.1797197 | F38: ='MRA - Cassiterite - Tin'!Q26/1000000 -> -2.5808971 | G38: ='MRA - Cassiterite - Tin'!R26/1000000 -> -1.2228392 | H38: ='MRA - Cassiterite - Tin'!S26/1000000 -> -1.2422779
C39: Coltan resource rent: producers | D39: ='MRA - Coltan - Tantalum'!O13/1000000 -> -1.7583125 | E39: ='MRA - Coltan - Tantalum'!P13/1000000 -> -3.7908595 | F39: ='MRA - Coltan - Tantalum'!Q13/1000000 -> -3.3189139 | G39: ='MRA - Coltan - Tantalum'!R13/1000000 -> -1.977032 | H39: ='MRA - Coltan - Tantalum'!S13/1000000 -> -3.1433068
C40: Coltan resource rent: traders | D40: ='MRA - Coltan - Tantalum'!O26/1000000 -> -2.0728885 | E40: ='MRA - Coltan - Tantalum'!P26/1000000 -> -4.8027983 | F40: ='MRA - Coltan - Tantalum'!Q26/1000000 -> -3.7587731 | G40: ='MRA - Coltan - Tantalum'!R26/1000000 -> -2.3626587 | H40: ='MRA - Coltan - Tantalum'!S26/1000000 -> -1.4183916
C41: Wolfram resource rent: producers | D41: ='MRA - Wolfram - Tungsten'!O13/1000000 -> -0.82237912 | E41: ='MRA - Wolfram - Tungsten'!P13/1000000 -> -0.89992617 | F41: ='MRA - Wolfram - Tungsten'!Q13/1000000 -> -0.90626441 | G41: ='MRA - Wolfram - Tungsten'!R13/1000000 -> -0.5615861 | H41: ='MRA - Wolfram - Tungsten'!S13/1000000 -> -0.2929371 | AD41: GROSS DOMESTIC PRODUCT (GDP) | AE41: =GDP!AY7 -> 8189
C42: Wolfram resource rent: traders | D42: ='MRA - Wolfram - Tungsten'!O26/1000000 -> -0.95655631 | E42: ='MRA - Wolfram - Tungsten'!P26/1000000 -> -1.0726055 | F42: ='MRA - Wolfram - Tungsten'!Q26/1000000 -> -0.95394324 | G42: ='MRA - Wolfram - Tungsten'!R26/1000000 -> -0.61896819 | H42: ='MRA - Wolfram - Tungsten'!S26/1000000 -> -0.42376621 | AD42: AGRICULTURE, FORESTRY & FISHING | AE42: =GDP!AY9 -> 2378 | AF42: Agriculture | AG42: =AE42/$AE$41 -> 0.29038955
AD43: Mining & quarrying | AE43: =GDP!AY16 -> 204 | AF43: Mining & quarrying | AG43: =AE43/$AE$41 -> 0.024911467
AD44: TOTAL MANUFACTURING | AE44: =GDP!AY17 -> 482 | AF44: Manufacturng | AG44: =AE44/$AE$41 -> 0.058859446
...

Sheet GDP
D1: Table 2 | AC1: Table 1
D2: Gross Domestic product by Kind of Activity | AC2: Gross Domestic product by Kind of Activity
D3: at constant 2014 prices | AC3: at current prices
D4: ( in billion Rwf) | AC4: ( in billion Rwf)
D5: Activity description | E5: ISIC4 | G5: 1999 | H5: 2000 | I5: 2001 | J5: 2002 | K5: 2003 | L5: 2004 | M5: 2005 | N5: 2006 | O5: 2007 | P5: 2008 | Q5: 2009 | R5: 2010 | S5: 2011 | T5: 2012 | U5: 2013 | V5: 2014 | W5: 2015 | X5: 2016 | Y5: 2017 | Z5: 2018 | AC5: Activity description | AD5: ISIC4 | AF5: 1999 | AG5: 2000 | AH5: 2001 | AI5: 2002 | AJ5: 2003 | AK5: 2004 | AL5: 2005 | AM5: 2006 | AN5: 2007 | AO5: 2008 | AP5: 2009 | AQ5: 2010 | AR5: 2011 | AS5: 2012 | AT5: 2013 | AU5: 2014 | AV5: 2015 | AW5: 2016 | AX5: 2017 | AY5: 2018
