Workbook
Name ADDITIVE: #REF!
Name AGRICULT: #REF!
Name ANTCOAL: #REF!
Name AUTOCHP: #REF!
Name AUTOELEC: #REF!
Name AUTOHEAT: #REF!
Name AVBUNK: #REF!
Name AVGAS: #REF!
Name BIODIESEL: #REF!
Name BIOGASES: #REF!
Name BIOGASOL: #REF!
Name BIOJETKERO: #REF!
Name BITCOAL: #REF!
Name BITUMEN: #REF!
Name BKB: #REF!
Name BLFURGS: #REF!
Name BOILER: #REF!
Name CFHeadings: #REF!
Name CHARCOAL: #REF!
Name CHEMHEAT: #REF!
Name CHEMICAL: #REF!
Name COALTAR: #REF!
Name COKCOAL: #REF!
Name COKEOVGS: #REF!
Name COMMPUB: #REF!
Name CONSTRUC: #REF!
Name ConversionFactors: OFFSET(#REF!,0,0,100,16)
Name Countries: #REF!
Name CountryName: #REF!
Name CRUDEOIL: #REF!
Name DataYear: #REF!
Name DBDef1: #REF!
Name DBDef2: #REF!
Name DBDef2a: #REF!
Name DBDef3: #REF!
Name DBLinks: #REF!
Name dbsourcefiles: #REF!
Name DISTLOSS: #REF!
Name DOMESAIR: #REF!
Name DOMESNAV: #REF!
Name DOMSUP: #REF!
Name EBIOGAS: #REF!
Name EBKB: #REF!
Name EBLASTFUR: #REF!
Name ECHARCOAL: #REF!
Name ECOALLIQ: #REF!
Name ECOKEOVS: #REF!
Name EGASWKS: #REF!
Name EGTL: #REF!
Name ELECTR: #REF!
Name ELNG: #REF!
Name ELOUTPUT: #REF!
Name EMINES: #REF!
Name ENONSPEC: #REF!
Name ENUC: #REF!
Name EOILGASEX: #REF!
Name EPATFUEL: #REF!
Name EPOWERPLT: #REF!
Name EPUMPST: #REF!
Name EREFINER: #REF!

Sheet HS Code
A1: PCT CODE | D1: DESCRIPTION | E1: CD (%) | F1: chrome-extension://efaidnbmnnnibpcajpcglclefindmkaj/https://download1.fbr.gov.pk/Docs/2017112112112348253CustomsTariff2017-18Ch1-99.pdf
A2: Heading / | B2: Statistical | K2: Lookup Table
A3: Sub- | B3: suffix | L3: HS Code | M3: Category | N3: Product Name
A4: heading | L4: 27149000 | M4: Coal and Coke | N4: Coal; briquettes, ovoids and similar solid fuels manufactured from coal. | O4: Other of (Bitumen and asphalt, natural; bituminous or oil shale and tar sands; asphaltites and asphaltic rocks.
A5: -1 | B5: -2 | D5: -3 | E5: -4 | L5: 27011100 | M5: Coal and Coke | N5: Coal; briquettes, ovoids and similar solid fuels manufactured from coal. | O5: Anthracite
A6: 101 | C6: Live horses, asses, mules and hinnies. | L6: 27011200 | M6: Coal and Coke | N6: Coal; briquettes, ovoids and similar solid fuels manufactured from coal. | O6: Bituminous coal
C7: - Horses: | L7: 27011900 | M7: Coal and Coke | N7: Coal; briquettes, ovoids and similar solid fuels manufactured from coal. | O7: Other coal
A8: 1012100 | C8: - - Pure-bred breeding animals | E8: 3 | L8: 27012000 | M8: Coal and Coke | N8: Coal; briquettes, ovoids and similar solid fuels manufactured from coal. | O8: Briquettes, ovoids and similar soild fuels manufactured from coal
A9: 10129 | C9: - - Other | E9: 3 | L9: 27030000 | M9: Coal and Coke | N9: Peat (including peat litter), whether or not agglomerated. | O9: Peat (including peat litter), whether or not agglomerated.
A10: 1013 | C10: - Asses | E10: 3 | L10: 27040000 | M10: Coal and Coke | N10: Coke and semi- coke of coal, of lignite or of peat, whether or not agglomerated; retort carbon. | O10: Coke and semi- coke of coal, of lignite or of peat, whether or not agglomerated; retort carbon.
A11: 1019 | C11: - Other | E11: 3 | L11: 27060000 | M11: Coal and Coke | N11: Tar distilled from coal, from lignite or from peat, and other mineral tars, whether or not dehydrated or partially distilled, including reconstituted tars. | O11: Tar distilled from coal, from lignite or from peat, and other mineral tars, whether or not dehydrated or partially distilled, including reconstituted tars.
A12: 102 | C12: Live bovine animals. | L12: 27072000 | M12: Oils | N12: Oils and other products of the distillation of high temperature coal tar; similar products in which the weight of the aromatic constituents exceeds that of the non- aromatic constituents. | O12: Toluol (toluene)
C13: - Cattle: | L13: 27073000 | M13: Oils | N13: Oils and other products of the distillation of high temperature coal tar; similar products in which the weight of the aromatic constituents exceeds that of the non- aromatic constituents. | O13: Xylol (xylenes)
C14: - - Pure-bred breeding animals: | L14: 27074000 | M14: Oils | N14: Oils and other products of the distillation of high temperature coal tar; similar products in which the weight of the aromatic constituents exceeds that of the non- aromatic constituents. | O14: Naphthalene
A15: 1022110 | C15: - - - Bulls | E15: 3 | L15: 27075000 | M15: Oils | N15: Oils and other products of the distillation of high temperature coal tar; similar products in which the weight of the aromatic constituents exceeds that of the non- aromatic constituents. | O15: Other aromatic hydrocarbon mixtures of which 65 % or more by volume (including losses) distils at 250oC by the ISO 3405 method (equivalent to the ASTM D 86 method)
A16: 102212 | C16: - - - Cows | E16: 3 | L16: 27079100 | M16: Oils | N16: Oils and other products of the distillation of high temperature coal tar; similar products in which the weight of the aromatic constituents exceeds that of the non- aromatic constituents. | O16: Creosote oils
A17: 102213 | C17: - - - Oxen | E17: 3 | L17: 27079900 | M17: Oils | N17: Oils and other products of the distillation of high temperature coal tar; similar products in which the weight of the aromatic constituents exceeds that of the non- aromatic constituents. | O17: Carbon black oil (carbon black feedstock)
A18: 102219 | C18: - - - Other | E18: 3 | L18: 27082000 | M18: Oils | N18: Pitch and pitch coke, obtained from coal tar or from other mineral tars. | O18: Pitch coke
C19: - - | D19: Other: | L19: 27090000 | M19: Petroleum | N19: Petroleum oils and oils obtained from bituminous minerals, crude | O19: Petroleum oils and oils obtained from bituminous minerals, crude
A20: 102291 | C20: - - - Bulls | E20: 3 | L20: 27101210 | M20: Petroleum | N20: Petroleum oils and oils obtained from bituminous minerals, other than crude; preparations not elsewhere specified or included, containing by weight 70 % or more of petroleum oils or of oils obtained from bituminous minerals, these oils being the basic constituents of the preparations; waste oils. | O20: Motor spirit
A21: 102292 | C21: - - - Cows | E21: 3 | L21: 27101220 | M21: Petroleum | N21: Petroleum oils and oils obtained from bituminous minerals, other than crude; preparations not elsewhere specified or included, containing by weight 70 % or more of petroleum oils or of oils obtained from bituminous minerals, these oils being the basic constituents of the preparations; waste oils. | O21: Aviation spirit
A22: 102293 | C22: - - - Oxen | E22: 3 | L22: 27101230 | M22: Petroleum | N22: Petroleum oils and oils obtained from bituminous minerals, other than crude; preparations not elsewhere specified or included, containing by weight 70 % or more of petroleum oils or of oils obtained from bituminous minerals, these oils being the basic constituents of the preparations; waste oils. | O22: Spirit type jet fuel
A23: 102299 | C23: - - - Other | E23: 3 | L23: 27101240 | M23: White spirit and special boiling point industrial spirits | N23: Petroleum oils and oils obtained from bituminous minerals, other than crude; preparations not elsewhere specified or included, containing by weight 70 % or more of petroleum oils or of oils obtained from bituminous minerals, these oils being the basic constituents of the preparations; waste oils. | O23: White spirit
C24: - Buffalo: | L24: 27101250 | M24: Petroleum | N24: Petroleum oils and oils obtained from bituminous minerals, other than crude; preparations not elsewhere specified or included, containing by weight 70 % or more of petroleum oils or of oils obtained from bituminous minerals, these oils being the basic constituents of the preparations; waste oils. | O24: Solvent oil (non-composite)
A25: 1023100 | C25: - - Pure-bred breeding animals | E25: 3 | L25: 27101290 | M25: Petroleum | N25: Petroleum oils and oils obtained from bituminous minerals, other than crude; preparations not elsewhere specified or included, containing by weight 70 % or more of petroleum oils or of oils obtained from bituminous minerals, these oils being the basic constituents of the preparations; waste oils. | O25: Other
A26: 10239 | C26: - - Other | E26: 3 | L26: 27101910 | M26: Petroleum | N26: Kerosene, including kerosene type jet fuel: | O26: Kerosene
L27: 27101921 | M27: Petroleum | N27: Kerosene, including kerosene type jet fuel: | O27: Light diesel oil
A28: PCT CODE | D28: DESCRIPTION | E28: CD (%) | L28: 27101922 | M28: Petroleum | N28: Kerosene, including kerosene type jet fuel:
A29: Heading / | B29: Statistical | L29: 27101929 | M29: Petroleum | N29: Kerosene, including kerosene type jet fuel:
A30: Sub- | B30: suffix | L30: 27101931 | M30: Petroleum | N30: Kerosene, including kerosene type jet fuel:
A31: heading | L31: 27101932 | M31: Petroleum | N31: Kerosene, including kerosene type jet fuel:
A32: -1 | B32: -2 | D32: -3 | E32: -4 | L32: 27101939 | M32: Petroleum | N32: Kerosene, including kerosene type jet fuel:
A33: 1029 | C33: - Other | E33: 3 | L33: 27101941 | M33: Petroleum | N33: Kerosene, including kerosene type jet fuel:
A34: 103 | C34: Live swine. | L34: 27101942 | M34: Petroleum | N34: Kerosene, including kerosene type jet fuel:
A35: 1031 | C35: - Pure- bred breeding animals | E35: 20 | L35: 27101943 | M35: Petroleum | N35: Kerosene, including kerosene type jet fuel:
C36: - Other: | L36: 27101949 | M36: Petroleum | N36: Kerosene, including kerosene type jet fuel:
A37: 1039100 | C37: - - Weighing less than 50 kg | E37: 20 | L37: 27101951 | M37: Petroleum | N37: Kerosene, including kerosene type jet fuel:
A38: 10392 | C38: - - Weighing 50 kg or more | E38: 20 | L38: 27101952 | M38: Petroleum | N38: Kerosene, including kerosene type jet fuel:
A39: 104 | C39: Live sheep and goats. | L39: 27101953 | M39: Petroleum | N39: Kerosene, including kerosene type jet fuel:
A40: 1041 | C40: - Sheep | E40: 3 | L40: 27101954 | M40: Petroleum | N40: Kerosene, including kerosene type jet fuel:
...

Sheet Cover Page
F4: Kenya Energy Accounts
J9: Draft V 1.1 | M9: 45814
J11: Prepared For:
J24: Prepared By:
J35: Contact Person: Jackie Crafford j.crafford@primeafrica.net

Sheet Colour coding
B2: Data Cell Colour Codes within Water Accounts
B3: White | C3: Expected empty cells
B4: Green | C4: Official statistics from KNBS and other government departments
B5: Light Green | C5: Data estimates by KNBS based on official statistics
B6: Orange | C6: Data derived from Green and Light Green statistics
B7: Red | C7: Literature estimates
B9: Data Text Colour Codes within Water Accounts
B10: Black Text | C10: Calculations
B11: Blue Text | C11: Data entered from data input sources
B12: Red Text | C12: Work in progress

Sheet Conversions
B2: GWh | C2: 1 | D2: GWh | E2: 3.6 | F2: TJ
B3: Gasoline | C3: 1 | D3: MT | E3: 44.4 | F3: GJ
C4: 1 | D4: GJ | E4: =1/1000 -> 0.001 | F4: TJ
B5: 1 litre of Motor Gasoline Premium ≈ 0.00003256 TJ | C5: 1 | D5: Litre | E5: 3.2e-05 | F5: TJ
B6: AGO (Automotive Gas Oil or Light Diesel Oil) 1 MT of AGO ≈ 0.043 to 0.0455 TJ | C6: 1 | D6: MT | E6: 0.043 | F6: TJ
C7: 1 | D7: Lite | E7: 3.58e-05 | F7: TJ
B8: Jet fuel | C8: 1 | D8: MT | E8: 0.0431 | F8: TJ
C9: 1 | D9: Litre | E9: 3.5e-05 | F9: TJ
B10: Iluminating kerosene | C10: 1 | D10: MT | E10: 0.0438 | F10: TJ
B11: Iluminating kerosene ( kerosene ≈ 0.0000344 TJ) | C11: 1 | D11: Litre | E11: 3.44e-05 | F11: TJ
C12: 1 | D12: Litre | E12: 3.74e-05 | F12: TJ
B13: LPG (Liquefied Petroleum Gas) 1 MT ≈ 0.0461 to 0.0500 TJ | C13: 1 | D13: MT | E13: 0.0461 | F13: TJ
B14: LPG 13 kg of LPG ≈ 0.00065 TJ. | C14: 13 | D14: Kg | E14: 0.00065 | F14: TJ
B15: White spirit (1 Litre of White Spirit ≈ 0.000033 to 0.0000345 TJ | C15: 1 | D15: Litre | E15: 3.3e-05 | F15: TJ
B16: Motor spirit | C16: 1 | D16: Lite | E16: 3.42e-05 | F16: TJ
B17: Coal and coke | C17: 1 | D17: Kg | E17: 2.6e-05 | F17: TJ
B18: Avaition spirit | C18: 1 | D18: Litre | E18: 3.35e-05 | F18: TJ
B19: Volume in MT | C19: 1000 | D19: MT | E19: 4.184 | F19: TJ
B20: Charcoal 1 kg of charcoal ≈ 0.00003 TJ | C20: 1 | D20: kg | E20: 3e-05 | F20: TJ
B21: Firewood | C21: 1 | D21: Tonne | E21: 0.016 | F21: TJ
B22: Electricity 1 kWh=0.0000036 TJ | C22: 1 | D22: Kwh | E22: 3.6e-06 | F22: TJ
B23: 1 litre of Light Diesel Oil ≈ 0.0000358 TJ | C23: 1 | D23: l | E23: 3.58e-05 | F23: TJ

Sheet Kenya Monetary Energy Accou
Q1: red text | T1: additional rows added to SEEA
A2: Core Account 2: Monetary Supply and Use Table for Energy | T2: TJ, needs prices to be KSH, later
B4: MONETARY SUPPLY AND USE TABLE (UNIT: KSH ) | D4: Industries (by ISIC) | P4: Final consumption and other | T4: Taxes less subsidies on products | U4: Trade and transport margins | V4: TOTAL | W4: Residuals
D5: Agriculture Forestry & Fishery | E5: Mining & Quarrying | F5: Manufacturing | G5: Electricity, gas, steam & air conditioning supply | H5: Construction | I5: Transportation & Storage | J5: Accommodation and Food Service Activities | K5: Other Commercial Sectors | L5: Public Administration and Defense | M5: Undefined | N5: Total Industry | P5: Households | Q5: Accumulation/Stock | R5: Rest of the world | S5: Flows from/to the environment (and other economic sectors)
B6: Supply of energy products (unit: KSH)
B7: NATURAL AND OTHER INPUTS:
B8: Solar | N8: =SUM(D8:M8) -> 0 | S8: ='Table 9.13(a)'!E5*'Price Summary'!G11 -> 7.4600856e+09 | U8: =V49-SUM(N8:T8) -> 0 | V8: =SUM(N8:U8) -> 7.4600856e+09 | W8: =V8-V49 -> 0
B9: Wind | N9: =SUM(D9:M9) -> 0 | S9: ='Table 9.13(a)'!E6*'Price Summary'!G9 -> 2.615142e+10 | U9: =V50-SUM(N9:T9) -> 0 | V9: =SUM(N9:U9) -> 2.615142e+10 | W9: =V9-V50 -> 0
B10: Hydro | N10: =SUM(D10:M10) -> 0 | S10: ='Table 9.13(a)'!E7*'Price Summary'!G5 -> 1.227942e+10 | U10: =V51-SUM(N10:T10) -> 0 | V10: =SUM(N10:U10) -> 1.227942e+10 | W10: =V10-V51 -> 0
B11: Geo-Thermal | N11: =SUM(D11:M11) -> 0 | S11: ='Table 9.13(a)'!E8*'Price Summary'!G7 -> 5.5179978e+10 | U11: =V52-SUM(N11:T11) -> 0 | V11: =SUM(N11:U11) -> 5.5179978e+10 | W11: =V11-V52 -> 0
B12: Biofuel: Bagasse | D12: ='Table 9.13(a)'!E9*'Price Summary'!G15 -> 255454.55 | N12: =SUM(D12:M12) -> 255454.55 | U12: =V53-SUM(N12:T12) -> 0 | V12: =SUM(N12:U12) -> 255454.55 | W12: =V12-V53 -> 0
B13: Biofuel: Biomass Wood | N13: =SUM(D13:M13) -> 0 | S13: ='Table 9.13(a)'!E10*'Price Summary'!$J$27 -> 754606293750 | U13: 0 | V13: =SUM(N13:U13) -> 754606293750 | W13: =V13-V54 -> 133706250
B14: Sub-Total (All Inputs) | D14: =SUM(D8:D13) -> 255454.55 | E14: =SUM(E8:E13) -> 0 | F14: =SUM(F8:F13) -> 0 | G14: =SUM(G8:G13) -> 0 | H14: =SUM(H8:H13) -> 0 | I14: =SUM(I8:I13) -> 0 | J14: =SUM(J8:J13) -> 0 | K14: =SUM(K8:K13) -> 0 | ... M14: =SUM(M8:M13) -> 0 | P14: =SUM(P8:P13) -> 0 | R14: =SUM(R8:R13) -> 0 | S14: =SUM(S8:S13) -> 8.556772e+11 | U14: =SUM(U8:U13) -> 0 | V14: =SUM(V8:V13) -> 8.5567745e+11 | W14: =SUM(W8:W13) -> 133706250
B15: ='Table 9.13(a)'!A12 -> IMPORTS: | U15: =V56-SUM(N15:T15) -> 0 | V15: =SUM(N15:U15) -> 0 | W15: =V15-V56 -> 0
B16: Coal and Coke | N16: =SUM(D16:M16) -> 0 | R16: ='Table 9.13(a)'!D14*'Price Summary'!H19 -> 2.2921498e+10 | U16: =(V58+('Table 9.13(a)'!I14*'Price Summary'!J19))-SUM(N16:T16) -> 2.0211738e+10 | V16: =SUM(N16:U16) -> 4.3133236e+10 | W16: =V16-V58 -> -42494423
B17: Motor Spirit Premium | N17: =SUM(D17:M17) -> 0 | R17: ='Table 9.13(a)'!D15*'Price Summary'!H29 -> 2.8554392e+10 | U17: =V59-SUM(N17:T17) -> 2.5053325e+09 | V17: =SUM(N17:U17) -> 3.1059725e+10 | W17: =V17-V59 -> 0
B18: Aviation gasoline | N18: =SUM(D18:M18) -> 0 | R18: ='Table 9.13(a)'!D16*'Price Summary'!H21 -> 18692696 | U18: =V60-SUM(N18:T18) -> 2211304.1 | V18: =SUM(N18:U18) -> 20904000 | W18: =V18-V60 -> 0
B19: Jet fuel | N19: =SUM(D19:M19) -> 0 | R19: ='Table 9.13(a)'!D17*'Price Summary'!H23 -> 2.9437082e+10 | U19: =V61-SUM(N19:T19) -> 4.3528255e+10 | V19: =SUM(N19:U19) -> 7.2965337e+10 | W19: =V19-V61 -> 0
B20: Illuminating Kerosene | N20: =SUM(D20:M20) -> 0 | R20: ='Table 9.13(a)'!D18*'Price Summary'!H37 -> 23033227 | U20: =V62-SUM(N20:T20) -> 13659933 | V20: =SUM(N20:U20) -> 36693160 | W20: =V20-V62 -> 0
B21: White spirit and special boiling point industrial spirits | N21: =SUM(D21:M21) -> 0 | R21: ='Table 9.13(a)'!D19*'Price Summary'!H25 -> 1.376021e+08 | U21: =V63-SUM(N21:T21) -> 1.2037345e+08 | V21: =SUM(N21:U21) -> 2.5797555e+08 | W21: =V21-V63 -> 0
B22: Oil shale / oil sands | N22: =SUM(D22:M22) -> 0 | U22: =V64-SUM(N22:T22) -> 0 | V22: =SUM(N22:U22) -> 0 | W22: =V22-V64 -> 0
B23: Fuel oils n.e.c. | N23: =SUM(D23:M23) -> 0 | R23: ='Table 9.13(a)'!D22*'Price Summary'!H35 -> 6.2469631e+08 | U23: =V65-SUM(N23:T23) -> 5.8517761e+09 | V23: =SUM(N23:U23) -> 6.4764724e+09 | W23: =V23-V65 -> 0
B24: Lubricating Oils | N24: =SUM(D24:M24) -> 0 | R24: ='Table 9.13(a)'!D23*'Price Summary'!H53 -> 1.6364382e+09 | U24: =V66-SUM(N24:T24) -> 6.4791287e+08 | V24: =SUM(N24:U24) -> 2.2843511e+09 | W24: =V24-V66 -> 0
B25: Lubricating Greases | N25: =SUM(D25:M25) -> 0 | R25: ='Table 9.13(a)'!D24*'Price Summary'!H55 -> 6.2526851e+08 | U25: =V67-SUM(N25:T25) -> 4.7926423e+08 | V25: =SUM(N25:U25) -> 1.1045327e+09 | W25: =V25-V67 -> 0
B26: Liquified Petroleum Gas (L.P.G) | N26: =SUM(D26:M26) -> 0 | R26: ='Table 9.13(a)'!D25*'Price Summary'!H39 -> 9.2953851e+09 | U26: =V68-SUM(N26:T26) -> 1895.03 | V26: =SUM(N26:U26) -> 9.295387e+09 | W26: =V26-V68 -> 0
B27: Natural gas | N27: =SUM(D27:M27) -> 0 | U27: =V69-SUM(N27:T27) -> 0 | V27: =SUM(N27:U27) -> 0 | W27: =V27-V69 -> 0
B28: Oil: Light Diesel Oil | N28: =SUM(D28:M28) -> 0 | R28: ='Table 9.13(a)'!D20*'Price Summary'!H31 -> 1.1583804e+10 | U28: =(V70+('Table 9.13(a)'!I20*'Price Summary'!J31))-SUM(N28:T28) -> 3.8124307e+10 | V28: =SUM(N28:U28) -> 4.9708111e+10 | W28: =V28-V70 -> -249049.12
B29: Oil: Heavy Diesel Oil | N29: =SUM(D29:M29) -> 0 | R29: ='Table 9.13(a)'!D21*'Price Summary'!H33 -> 116075.42 | U29: =V71-SUM(N29:T29) -> 531452.28 | V29: =SUM(N29:U29) -> 647527.7 | W29: =V29-V71 -> 0
B30: Electricity | N30: =SUM(D30:M30) -> 0 | R30: ='Table 9.13(a)'!D13*'Price Summary'!J51 -> 1.6225927e+10 | V30: =SUM(N30:U30) -> 1.6225927e+10
B31: Sub-Total (All Imports) | D31: =SUM(D16:D30) -> 0 | E31: =SUM(E16:E30) -> 0 | F31: =SUM(F16:F30) -> 0 | G31: =SUM(G16:G30) -> 0 | H31: =SUM(H16:H30) -> 0 | I31: =SUM(I16:I30) -> 0 | J31: =SUM(J16:J30) -> 0 | K31: =SUM(K16:K30) -> 0 | ... M31: =SUM(M16:M30) -> 0 | N31: =SUM(D31:M31) -> 0 | P31: =SUM(P16:P30) -> 0 | R31: =SUM(R16:R30) -> 1.2108394e+11 | S31: =SUM(S24:S30) -> 0 | U31: =SUM(U16:U29) -> 1.1148536e+11 | V31: =SUM(V16:V30) -> 2.325693e+11 | W31: =SUM(W16:W30) -> -42743472
B32: ='Table 9.13(a)'!A27 -> ENERGY PRODUCTS: | V32: =SUM(N32:U32) -> 0
B33: Electricity plants (Kengen) | G33: ='Table 9.13(a)'!B28*(SUM($S$8:$S$11)/SUM('Table 9.13(a)'!$B$28:$B$31)) -> 6.8141974e+10 | N33: =SUM(D33:M33) -> 6.8141974e+10 | V33: =SUM(N33:U33) -> 6.8141974e+10
B34: Electricity plants (Independent Power Producers (IPPs)) | G34: ='Table 9.13(a)'!B29*(SUM($S$8:$S$11)/SUM('Table 9.13(a)'!$B$28:$B$31)) -> 3.1539607e+10 | N34: =SUM(D34:M34) -> 3.1539607e+10 | V34: =SUM(N34:U34) -> 3.1539607e+10 | W34: =W37 -> 3.4375655e+08
B35: Electricity plants (REREC) | G35: ='Table 9.13(a)'!B30*(SUM($S$8:$S$11)/SUM('Table 9.13(a)'!$B$28:$B$31)) -> 6.6026274e+08 | N35: =SUM(D35:M35) -> 6.6026274e+08 | V35: =SUM(N35:U35) -> 6.6026274e+08
B36: Electricity plants (Off-grid)) | G36: ='Table 9.13(a)'!B31*'Price Summary'!J65 -> 7.2850883e+08 | N36: =SUM(D36:M36) -> 7.2850883e+08 | V36: =SUM(N36:U36) -> 7.2850883e+08
B37: Sub-Total (All Electricity) | D37: =SUM(D30:D36) -> 0 | E37: =SUM(E30:E36) -> 0 | F37: =SUM(F30:F36) -> 0 | G37: =SUM(G30:G36) -> 1.0107035e+11 | H37: =SUM(H30:H36) -> 0 | I37: =SUM(I30:I36) -> 0 | J37: =SUM(J30:J36) -> 0 | K37: =SUM(K30:K36) -> 0 | ... M37: =SUM(M30:M36) -> 0 | N37: =SUM(N32:N36,N30) -> 1.0107035e+11 | P37: =SUM(P30:P36) -> 0 | R37: =SUM(R32:R36,R30) -> 1.6225927e+10 | S37: =SUM(S30:S36) -> 0 | T37: =SUM(T30:T36) -> 0 | U37: =(V80+('Table 9.13(a)'!I29*(SUM($S$8:$S$11)/SUM('Table 9.13(a)'!$B$28:$B$31))))-SUM(N37:T37) -> 1.222512e+11 | V37: =SUM(N37:U37) -> 2.3954748e+11 | W37: =V37-V80 -> 3.4375655e+08
B38: BIOMASS PRODUCTS:
B39: Charcoal | D39: ='Table 9.13(a)'!B32*'Price Summary'!G17 -> 3.6023365e+08 | N39: =SUM(D39:M39) -> 3.6023365e+08 | P39: ='Table 9.13(a)'!C32*'Price Summary'!G17 -> 4.434663e+10 | U39: =V82-SUM(N39:T39) -> 2.3906665e+11 | V39: =SUM(N39:U39) -> 2.8377351e+11 | W39: =V39-V82 -> 0
B40: Firewood | D40: ='Table 9.13(a)'!B33*'Price Summary'!G27 -> 3.2239471e+09 | N40: =SUM(D40:M40) -> 3.2239471e+09 | P40: ='Table 9.13(a)'!C33*'Price Summary'!G27 -> 5.139979e+11 | U40: =V83-SUM(N40:T40) -> 155166553125 | V40: =SUM(N40:U40) -> 672388396875 | W40: =V40-V83 -> 0
B41: Sun-Total (All Biomass) | D41: =SUM(D39:D40) -> 3.5841808e+09 | E41: =SUM(E39:E40) -> 0 | F41: =SUM(F39:F40) -> 0 | G41: =SUM(G39:G40) -> 0 | H41: =SUM(H39:H40) -> 0 | I41: =SUM(I39:I40) -> 0 | J41: =SUM(J39:J40) -> 0 | K41: =SUM(K39:K40) -> 0 | ... N41: =SUM(N39:N40) -> 3.5841808e+09 | P41: =SUM(P39:P40) -> 5.5834453e+11 | R41: =SUM(R39:R40) -> 0 | U41: =SUM(U39:U40) -> 3.942332e+11 | V41: =SUM(V39:V40) -> 9.5616191e+11 | W41: =SUM(W39:W40) -> 0
...

Sheet Price Summary
B2: 2024 Energy Pricing
C3: Energy commodity | D3: Notes | E3: Source | F3: Unit | G3: Primary price | H3: Import price | I3: Wholesale price | J3: Retail price
B4: 1 | C4: Hydro | D4: Average price Kenya Power pays to purchase electricity from hydro sources | E4: Kenya Power Integrated Report | F4: KSh/GWh | G4: ='Price.Data.Inputs'!F96 -> 3382118.4
F5: Ksh/TJ | G5: ='Price.Data.Inputs'!F97 -> 939477.33
B6: 2 | C6: Geothermal | D6: Average price Kenya Power pays to purchase electricity from geothermal sources | E6: Kenya Power Integrated Report | F6: KSh/GWh | G6: ='Price.Data.Inputs'!F98 -> 9940532.3
F7: Ksh/TJ | G7: ='Price.Data.Inputs'!F99 -> 2761259
B8: 3 | C8: Wind | D8: Average price Kenya Power pays to purchase electricity from wind sources | E8: Kenya Power Integrated Report | F8: KSh/GWh | G8: ='Price.Data.Inputs'!F100 -> 14547379
F9: Ksh/TJ | G9: ='Price.Data.Inputs'!F101 -> 4040938.7
B10: 4 | C10: Solar | D10: Average price Kenya Power pays to purchase electricity from solar sources | E10: Kenya Power Integrated Report | F10: KSh/GWh | G10: ='Price.Data.Inputs'!F102 -> 16202021
F11: Ksh/TJ | G11: ='Price.Data.Inputs'!F103 -> 4500561.4
B12: 5 | C12: Co-generation | D12: Average price Kenya Power pays to purchase electricity from co-generation | E12: Kenya Power Integrated Report | F12: KSh/GWh | G12: ='Price.Data.Inputs'!F105 -> 15327273
F13: Ksh/TJ | G13: ='Price.Data.Inputs'!F106 -> 4257575.8
C14: Biofuel: Bagasse | D14: Average price Kenya Power pays to purchase electricity from co-generation | E14: Kenya Power Integrated Report | F14: KSh/GWh | G14: ='Price.Data.Inputs'!F105 -> 15327273
F15: Ksh/TJ | G15: ='Price.Data.Inputs'!F106 -> 4257575.8
C16: Charcoal | D16: Average price Kenya Power pays to purchase electricity from co-generation | E16: Kenya Power Integrated Report | F16: KSh/GWh
F17: Ksh/TJ | G17: =G27 -> 432692.31 | J17: ='Price.Data.Inputs'!I17 -> 2746482.4
B18: 6 | C18: Coal and coke | E18: Customs data | F18: Ksh/kg | H18: 80.43 | J18: 151.35
F19: Ksh/TJ | H19: =H18/Conversions!$E$17 -> 3093461.5 | J19: =J18/Conversions!$E$17 -> 5821153.8
B20: 7 | C20: Aviation spirit | E20: Customs data | F20: Ksh/litre | H20: 120.4241 | J20: 134.67
F21: Ksh/TJ | H21: =H20/Conversions!$E$18 -> 3594749.2 | J21: =J20/Conversions!$E$18 -> 4020000
B22: 8 | C22: Spirit type jet fuel | E22: Customs data | F22: Ksh/litre | H22: 326.37 | J22: 808.96935
F23: Ksh/TJ | H23: =H22/Conversions!$E$9 -> 9324857.1 | J23: =J22/Conversions!$E$9 -> 23113410
B24: 9 | C24: White spirit and special boiling point industrial spirits | E24: Customs data | F24: Ksh/litre | H24: 328.0975 | J24: 615.11511
F25: Ksh/TJ | H25: =H24/Conversions!$E$15 -> 9942348.5 | J25: =J24/Conversions!$E$15 -> 18639852
B26: 10 | C26: Firewood | E26: https://www.pigiame.co.ke/listings/dry-firewood-6045399#:~:text=We%20sell%20dry%20firewood%20price,free%20transport%20within%20Nairobi%20county%20. | F26: Ksh/tonne | J26: 9000
F27: Ksh/TJ | G27: =J27/1.3 -> 432692.31 | J27: =J26/Conversions!$E$21 -> 562500
B28: 11 | C28: Motor spirit premium | D28: 12 month average | E28: KNBS | F28: Ksh/litre | H28: 176.29 | J28: ='Table 9.6'!C41 -> 191.76
E29: Table 9.6 converted to TJ | F29: Ksh/TJ | H29: =H28/Conversions!E16 -> 5154678.4 | J29: ='Table 9.6'!K41 -> 5606944.4
B30: 12 | C30: Light Diesel Oil | D30: 12 month average | E30: KNBS | F30: Ksh/litre | H30: ='Price.Data.Inputs'!N316 -> 41.555 | J30: ='Table 9.6'!D41 -> 178.32
E31: Table 9.6 converted to TJ | F31: Ksh/TJ | H31: =H30/Conversions!E23 -> 1160754.2 | J31: ='Table 9.6'!L41 -> 4980982.3
C32: Heavy Diesel Oil | D32: 12 month average | E32: KNBS | F32: Ksh/litre | H32: =H30 -> 41.555 | J32: =J30 -> 178.32
E33: Table 9.6 converted to TJ | F33: Ksh/TJ | H33: =H31 -> 1160754.2 | J33: =J31 -> 4980982.3
C34: Fuel Oils | E34: Customs data | F34: Ksh/litre | H34: ='Price.Data.Inputs'!N341 -> 17.2 | J34: =J32 -> 178.32
F35: Ksh/TJ | H35: =H34/Conversions!E23 -> 480446.93 | J35: =J33 -> 4980982.3
B36: 13 | C36: Illuminating Kerosene | D36: 12 month average | E36: KNBS | F36: Ksh/litre | H36: 97.22 | J36: ='Table 9.6'!E41 -> 168.38
E37: Table 9.6 converted to TJ | F37: Ksh/TJ | H37: =H36/Conversions!E11 -> 2826162.8 | J37: ='Table 9.6'!M41 -> 4502228.2
B38: 14 | C38: Liqufied Petroleum Gas (LPG) | D38: 12 month average | E38: KNBS | F38: Ksh/13 kg cylinder | H38: =J38 -> 3188.34 | J38: ='Table 9.6'!F41 -> 3188.34
E39: Table 9.6 converted to TJ | F39: Ksh/TJ | H39: =J39-1 -> 4905138.7 | J39: ='Table 9.6'!N41 -> 4905139.7
B40: 15 | C40: Domestic | E40: KNBS | F40: KSh/kWh | J40: ='Table 9.11'!F4 -> 24.97
E41: Table 9.11 converted to TJ | F41: Ksh/TJ | J41: ='Table 9.11'!H4 -> 6936111.1 | L41: Average
...

Sheet Price.Data.Inputs
B2: Source: Kenya National Bureau of Statistics (KNBS) via email from Christine Mukami Magu on 25 Apr 2025
B3: Descriptions/ Period | C3: Motor Gasoline Premium (KSh per Litre) | D3: Light Diesel Oil (KSh per Litre) | E3: Illuminating Kerosene (KSh per Litre) | F3: L.P.G (KSh per 13 Kg) | G3: Charcoal (KSh per Kg ) | I3: Charcoal (Ksh/TJ)
B4: CPI, 2024
B5: January | C5: 207.9728 | D5: 197.2056 | E5: 194.957 | F5: 3055.511 | G5: 76.893715 | I5: =G5/Conversions!$E$20 -> 2563123.8
B6: February | C6: 206.9728 | D6: 196.2056 | E6: 193.957 | F6: 3187.0987 | G6: 77.461246 | I6: =G6/Conversions!$E$20 -> 2582041.5
B7: March | C7: 199.7666 | D7: 191.1128 | E7: 189.4826 | F7: 3231.8376 | G7: 78.639919 | I7: =G7/Conversions!$E$20 -> 2621330.6
B8: April | C8: 194.4566 | D8: 181.1128 | E8: 171.18 | F8: 3242.1143 | G8: 79.502414 | I8: =G8/Conversions!$E$20 -> 2650080.5
B9: May | C9: 193.4566 | D9: 179.9128 | E9: 169.5182 | F9: 3221.285 | G9: 82.323685 | I9: =G9/Conversions!$E$20 -> 2744122.8
B10: June | C10: 190.4566 | D10: 173.8328 | E10: 163.8224 | F10: 3213.9658 | G10: 83.802682 | I10: =G10/Conversions!$E$20 -> 2793422.7
B11: July | C11: 189.4566 | D11: 172.3328 | E11: 162.5226 | F11: 3219.5847 | G11: 84.407368 | I11: =G11/Conversions!$E$20 -> 2813578.9
B12: August | C12: 189.4566 | D12: 172.3328 | E12: 162.5226 | F12: 3217.8521 | G12: 84.169763 | I12: =G12/Conversions!$E$20 -> 2805658.8
B13: September | C13: 189.4566 | D13: 172.3328 | E13: 159.099 | F13: 3196.0417 | G13: 85.324763 | I13: =G13/Conversions!$E$20 -> 2844158.8
B14: October | C14: 181.3276 | D14: 168.818 | E14: 152.1794 | F14: 3183.2891 | G14: 85.255107 | I14: =G14/Conversions!$E$20 -> 2841836.9
B15: November | C15: 181.3276 | D15: 168.818 | E15: 152.1794 | F15: 3147.6603 | G15: 85.291648 | I15: =G15/Conversions!$E$20 -> 2843054.9
B16: December | C16: 176.9606 | D16: 165.818 | E16: 149.1794 | F16: 3143.8466 | G16: 85.661364 | I16: =G16/Conversions!$E$20 -> 2855378.8
B17: Average | I17: =AVERAGE(I5:I16) -> 2746482.4
B21: Source: Kenya National Bureau of Statistics (KNBS) via email from Christine Mukami Magu on 25 Apr 2025
B22: Domestic and Small Commercial | C22: Ksh/TJ | D22: =AVERAGE(I33:I40) -> 4444444.4
B23: Large and Medium | C23: Ksh/TJ | D23: =AVERAGE(I44,I47:I48,I50,I53:I54,I56,I59:I60,I62,I65:I66,I68,I71:I72,I74,I77) -> 2912908.5
B24: Street Lighting | C24: Ksh/TJ | D24: =I84 -> 2566666.7
B25: E-mobility | C25: Ksh/TJ | D25: =AVERAGE(I41,I43) -> 3333333.3
B26: Rural electrification | C26: Ksh/TJ | D26: =AVERAGE(I79,I82) -> 2419444.4
B27: Other | C27: Ksh/TJ
B30: Source: Kenya National Bureau of Statistics (KNBS) via email from Christine Mukami Magu on 25 Apr 2025
B31: Existing Code | C31: Proposed Code | D31: Customer | E31: Energy Limit kWh/month | F31: Charge Method | G31: Unit | H31: July 2023 - June 2024 | I31: Ksh/TJ
D32: Type (Code Name)
B33: DC | C33: DC-1 | D33: Domestic Lifeline | E33: 0-30 | F33: Energy | G33: KSh/kWh | H33: 12.24 | I33: =H33/Conversions!$E$22 -> 3400000
C34: DC-2 | D34: Domestic Ordinary | E34: >30-100 | F34: Energy | G34: KSh/kWh | H34: 16.58 | I34: =H34/Conversions!$E$22 -> 4605555.6
C35: DC-3 | D35: Domestic Ordinary | E35: >100 | F35: Energy | G35: KSh/kWh | H35: 20.58 | I35: =H35/Conversions!$E$22 -> 5716666.7
B36: SC | C36: SC-1 | D36: Small Commercial | E36: 0-30 | F36: Energy | G36: KSh/ kWh | H36: 12.24 | I36: =H36/Conversions!$E$22 -> 3400000
C37: SC-2 | D37: Small Commercial | E37: >30-100 | F37: Energy | G37: KSh/kWh | H37: 16.36 | I37: =H37/Conversions!$E$22 -> 4544444.4
C38: SC-3 | D38: Small Commercial | E38: >100 | F38: Energy | G38: KSh/kWh | H38: 20 | I38: =H38/Conversions!$E$22 -> 5555555.6
C39: TOU | D39: Time of Use for SC | E39: >100 | F39: Energy | G39: KSh/kWh | H39: 10 | I39: =H39/Conversions!$E$22 -> 2777777.8
C40: BULK TARIFF | D40: Bulk Tariff for SC | E40: 1,000-15,000 | F40: Energy | G40: KSh/kWh | H40: 20 | I40: =H40/Conversions!$E$22 -> 5555555.6
B41: EM | C41: E-mobility | D41: Electric Mobility | E41: 0 – 15,000 | F41: Energy | G41: KSh/kWh | H41: 16 | I41: =H41/Conversions!$E$22 -> 4444444.4
I42: =H42/Conversions!$E$22 -> 0
D43: Electric Mobility (TOU) | F43: Energy | G43: KSh/kWh | H43: 8 | I43: =H43/Conversions!$E$22 -> 2222222.2
B44: CI1 | C44: CI1 | D44: Comm./industrial | E44: >15,000 | F44: Energy | G44: KSh/kWh | H44: 14.5 | I44: =H44/Conversions!$E$22 -> 4027777.8
I45: =H45/Conversions!$E$22 -> 0
I46: =H46/Conversions!$E$22 -> 0
...

Sheet Customs_Energy Products
A1: Back
A3: Year | B3: Month | C3: Country_Code | D3: Country | E3: HS_C | F3: HS product name | G3: SITC_C | H3: BEC | I3: Unit | J3: Quantity | K3: Net weight | L3: Value in KSh | M3: Trade Flow | N3: Source | P3: Pricing
A4: 2024 | B4: 1 | D4: CHINA | E4: 27149000 | F4: =VLOOKUP(E4,'HS Code'!$L$4:$O$65,2,0) -> Coal and Coke | G4: 27897000 | H4: 21 | I4: kg | J4: 522650 | K4: 522650 | L4: 37658839 | M4: Imports | N4: Customs | P4: =L4/J4 -> 72.053648
A5: 2024 | B5: 1 | D5: ITALY | E5: 27131200 | F5: =VLOOKUP(E5,'HS Code'!$L$4:$O$65,2,0) -> 0 | G5: 33542900 | H5: 22 | I5: kg | J5: 2837 | K5: 2837 | L5: 11820720 | M5: Imports | N5: Customs | P5: =L5/J5 -> 4166.6268
A6: 2024 | B6: 1 | D6: UNITED ARAB EMIRATES | E6: 27101951 | F6: =VLOOKUP(E6,'HS Code'!$L$4:$O$65,2,0) -> Petroleum | G6: 33450910 | H6: 322 | I6: l | J6: 379006.08 | K6: 378526.08 | L6: 71152087 | M6: Imports | N6: Customs | P6: =L6/J6 -> 187.73337
A7: 2024 | B7: 1 | D7: UNITED ARAB EMIRATES | E7: 27101952 | F7: =VLOOKUP(E7,'HS Code'!$L$4:$O$65,2,0) -> Petroleum | G7: 33450920 | H7: 322 | I7: kg | J7: 1944 | K7: 1944 | L7: 350155.93 | M7: Imports | N7: Customs | P7: =L7/J7 -> 180.12136
A8: 2024 | B8: 1 | D8: UNITED ARAB EMIRATES | E8: 27101956 | F8: =VLOOKUP(E8,'HS Code'!$L$4:$O$65,2,0) -> Petroleum | G8: 33450960 | H8: 322 | I8: l | J8: 70260 | K8: 70260 | L8: 23643528 | M8: Imports | N8: Customs | P8: =L8/J8 -> 336.51477
A9: 2024 | B9: 1 | D9: UNITED ARAB EMIRATES | E9: 27101957 | F9: =VLOOKUP(E9,'HS Code'!$L$4:$O$65,2,0) -> Petroleum | G9: 33450970 | H9: 322 | I9: l | J9: 134006 | K9: 134006 | L9: 23419323 | M9: Imports | N9: Customs | P9: =L9/J9 -> 174.76324
A10: 2024 | B10: 1 | D10: UNITED ARAB EMIRATES | E10: 27101959 | F10: =VLOOKUP(E10,'HS Code'!$L$4:$O$65,2,0) -> Petroleum | G10: 33450990 | H10: 322 | I10: l | J10: 176280 | K10: 176280 | L10: 26818811 | M10: Imports | N10: Customs | P10: =L10/J10 -> 152.13757
A11: 2024 | B11: 1 | D11: UNITED ARAB EMIRATES | E11: 27129000 | F11: =VLOOKUP(E11,'HS Code'!$L$4:$O$65,2,0) -> 0 | G11: 33512900 | H11: 22 | I11: kg | J11: 83250 | K11: 83250 | L11: 16042525 | M11: Imports | N11: Customs | P11: =L11/J11 -> 192.703
A12: 2024 | B12: 1 | D12: UNITED ARAB EMIRATES | E12: 27132000 | F12: =VLOOKUP(E12,'HS Code'!$L$4:$O$65,2,0) -> 0 | G12: 33541100 | H12: 22 | I12: kg | J12: 599550 | K12: 599550 | L12: 42575805 | M12: Imports | N12: Customs | P12: =L12/J12 -> 71.012935
A13: 2024 | B13: 1 | D13: ARGENTINA | E13: 27101951 | F13: =VLOOKUP(E13,'HS Code'!$L$4:$O$65,2,0) -> Petroleum | G13: 33450910 | H13: 322 | I13: l | J13: 10368 | K13: 10368 | L13: 10364597 | M13: Imports | N13: Customs | P13: =L13/J13 -> 999.67179
A14: 2024 | B14: 1 | D14: ARGENTINA | E14: 27101952 | F14: =VLOOKUP(E14,'HS Code'!$L$4:$O$65,2,0) -> Petroleum | G14: 33450920 | H14: 322 | I14: kg | J14: 3860 | K14: 3860 | L14: 7067052.5 | M14: Imports | N14: Customs | P14: =L14/J14 -> 1830.8426
A15: 2024 | B15: 1 | D15: BELGIUM | E15: 27101951 | F15: =VLOOKUP(E15,'HS Code'!$L$4:$O$65,2,0) -> Petroleum | G15: 33450910 | H15: 322 | I15: l | J15: 7331 | K15: 7331 | L15: 4310070.8 | M15: Imports | N15: Customs | P15: =L15/J15 -> 587.924
A16: 2024 | B16: 1 | D16: SWITZERLAND | E16: 27101952 | F16: =VLOOKUP(E16,'HS Code'!$L$4:$O$65,2,0) -> Petroleum | G16: 33450920 | H16: 322 | I16: kg | J16: 26 | K16: 26 | L16: 451917.04 | M16: Imports | N16: Customs | P16: =L16/J16 -> 17381.425
... A152: 2024 | B152: 1 | D152: OMAN | E152: 27101931 | F152: =VLOOKUP(E152,'HS Code'!$L$4:$O$65,2,0) -> Petroleum | G152: 33430100 | H152: 322 | I152: l | J152: 52668115 | K152: 52668115 | L152: 7.3543567e+09 | M152: Imports | N152: Customs | P152: =L152/J152 -> 139.63584
A153: 2024 | B153: 1 | D153: SOUTH SUDAN | E153: 27150000 | F153: =VLOOKUP(E153,'HS Code'!$L$4:$O$65,2,0) -> 0 | G153: 33543000 | H153: 22 | I153: kg | J153: 548380 | K153: 548380 | L153: 24067371 | M153: Re-Exports | N153: Customs
A154: 2024 | B154: 1 | D154: AIRCRAFT & SHIPSTORES | E154: 27101921 | F154: =VLOOKUP(E154,'HS Code'!$L$4:$O$65,2,0) -> Petroleum | G154: 33421100 | H154: 322 | I154: l | J154: 29658659 | K154: 27982298 | L154: 3.4833844e+09 | M154: Re-Exports | N154: Customs
A155: 2024 | B155: 1 | D155: AIRCRAFT & SHIPSTORES | E155: 27101921 | F155: =VLOOKUP(E155,'HS Code'!$L$4:$O$65,2,0) -> Petroleum | G155: 33421100 | H155: 322 | I155: l | J155: 32418500 | K155: 32418500 | L155: 4.0096465e+09 | M155: Re-Exports | N155: Customs
A156: 2024 | B156: 1 | D156: AIRCRAFT & SHIPSTORES | E156: 27101931 | F156: =VLOOKUP(E156,'HS Code'!$L$4:$O$65,2,0) -> Petroleum | G156: 33430100 | H156: 322 | I156: l | J156: 527125 | K156: 440203 | L156: 61585690 | M156: Re-Exports | N156: Customs
A157: 2024 | B157: 1 | D157: AIRCRAFT & SHIPSTORES | E157: 27101942 | F157: =VLOOKUP(E157,'HS Code'!$L$4:$O$65,2,0) -> Petroleum | G157: 33450200 | H157: 322 | I157: l | J157: 1531115 | K157: 1498605 | L157: 2.1897038e+08 | M157: Re-Exports | N157: Customs
A158: 2024 | B158: 1 | D158: OTHER COUNTRIES N.E.S | E158: 27101931 | F158: =VLOOKUP(E158,'HS Code'!$L$4:$O$65,2,0) -> Petroleum | G158: 33430100 | H158: 322 | I158: l | J158: 735579 | K158: 735579 | L158: 1.0680589e+08 | M158: Re-Exports | N158: Customs
A159: 2024 | B159: 1 | D159: AIRCRAFT & SHIPSTORES | E159: 27101921 | F159: =VLOOKUP(E159,'HS Code'!$L$4:$O$65,2,0) -> Petroleum | G159: 33421100 | H159: 322 | I159: l | J159: 5420104 | K159: 4281881 | L159: 524423887 | M159: Re-Exports | N159: Customs
A160: 2024 | B160: 1 | D160: RWANDA | E160: 27101951 | F160: =VLOOKUP(E160,'HS Code'!$L$4:$O$65,2,0) -> Petroleum | G160: 33450910 | H160: 322 | I160: l | J160: 57428 | K160: 56691 | L160: 20832031 | M160: Re-Exports | N160: Customs
A161: 2024 | B161: 1 | D161: UGANDA | E161: 27101951 | F161: =VLOOKUP(E161,'HS Code'!$L$4:$O$65,2,0) -> Petroleum | G161: 33450910 | H161: 322 | I161: l | J161: 79002 | K161: 70434 | L161: 27109645 | M161: Re-Exports | N161: Customs
A162: 2024 | B162: 1 | D162: UGANDA | E162: 27150000 | F162: =VLOOKUP(E162,'HS Code'!$L$4:$O$65,2,0) -> 0 | G162: 33543000 | H162: 22 | I162: kg | J162: 42750 | K162: 42750 | L162: 7446253.5 | M162: Re-Exports | N162: Customs
A163: 2024 | B163: 1 | D163: UGANDA | E163: 27101230 | F163: =VLOOKUP(E163,'HS Code'!$L$4:$O$65,2,0) -> Petroleum | G163: 33411230 | H163: 321 | I163: l | J163: 19607 | K163: 19607 | L163: 6457203 | M163: Re-Exports | N163: Customs | P163: =L163/J163 -> 329.33151
A164: 2024 | B164: 1 | D164: BURUNDI | E164: 27101959 | F164: =VLOOKUP(E164,'HS Code'!$L$4:$O$65,2,0) -> Petroleum | G164: 33450990 | H164: 322 | I164: l | J164: 250 | K164: 250 | L164: 268258.86 | M164: Domestic Exports | N164: Customs
A165: 2024 | B165: 1 | D165: RWANDA | E165: 27030000 | F165: =VLOOKUP(E165,'HS Code'!$L$4:$O$65,2,0) -> Coal and Coke | G165: 32230000 | H165: 31 | I165: kg | J165: 600 | K165: 600 | L165: 75705.13 | M165: Domestic Exports | N165: Customs | P165: =L165/J165 -> 126.17522
A166: 2024 | B166: 1 | D166: RWANDA | E166: 27073000 | F166: =VLOOKUP(E166,'HS Code'!$L$4:$O$65,2,0) -> Oils | G166: 33524000 | H166: 22 | I166: kg | J166: 170 | K166: 170 | L166: 42244.666 | M166: Domestic Exports | N166: Customs
A167: 2024 | B167: 1 | D167: RWANDA | E167: 27101250 | F167: =VLOOKUP(E167,'HS Code'!$L$4:$O$65,2,0) -> Petroleum | G167: 33411250 | H167: 322 | I167: l | J167: 360 | K167: 360 | L167: 68252.8 | M167: Domestic Exports | N167: Customs
A168: 2024 | B168: 1 | D168: RWANDA | E168: 27101951 | F168: =VLOOKUP(E168,'HS Code'!$L$4:$O$65,2,0) -> Petroleum | G168: 33450910 | H168: 322 | I168: l | J168: 23349 | K168: 23349 | L168: 9366332.6 | M168: Domestic Exports | N168: Customs
A169: 2024 | B169: 1 | D169: RWANDA | E169: 27122000 | F169: =VLOOKUP(E169,'HS Code'!$L$4:$O$65,2,0) -> 0 | G169: 33512100 | H169: 22 | I169: kg | J169: 500 | K169: 500 | L169: 85785.11 | M169: Domestic Exports | N169: Customs
A170: 2024 | B170: 1 | D170: RWANDA | E170: 27150000 | F170: =VLOOKUP(E170,'HS Code'!$L$4:$O$65,2,0) -> 0 | G170: 33543000 | H170: 22 | I170: kg | J170: 900 | K170: 900 | L170: 206846.34 | M170: Domestic Exports | N170: Customs
A171: 2024 | B171: 1 | D171: TANZANIA | E171: 27101951 | F171: =VLOOKUP(E171,'HS Code'!$L$4:$O$65,2,0) -> Petroleum | G171: 33450910 | H171: 322 | I171: l | J171: 275835 | K171: 275835 | L171: 88345939 | M171: Domestic Exports | N171: Customs
A172: 2024 | B172: 1 | D172: UGANDA | E172: 27101240 | F172: =VLOOKUP(E172,'HS Code'!$L$4:$O$65,2,0) -> White spirit and special boiling point industrial spirits | G172: 33411240 | H172: 321 | I172: l | J172: 27723 | K172: 20440 | L172: 11033136 | M172: Domestic Exports | N172: Customs | P172: =L172/J172 -> 397.97771
A173: 2024 | B173: 1 | D173: UGANDA | E173: 27101951 | F173: =VLOOKUP(E173,'HS Code'!$L$4:$O$65,2,0) -> Petroleum | G173: 33450910 | H173: 322 | I173: l | J173: 1343153 | K173: 1219997.2 | L173: 4.8780497e+08 | M173: Domestic Exports | N173: Customs
A174: 2024 | B174: 1 | D174: UGANDA | E174: 27101956 | F174: =VLOOKUP(E174,'HS Code'!$L$4:$O$65,2,0) -> Petroleum | G174: 33450960 | H174: 322 | I174: l | J174: 12800 | K174: 12800 | L174: 6329411.5 | M174: Domestic Exports | N174: Customs
A175: 2024 | B175: 1 | D175: UGANDA | E175: 27150000 | F175: =VLOOKUP(E175,'HS Code'!$L$4:$O$65,2,0) -> 0 | G175: 33543000 | H175: 22 | I175: kg | J175: 6045 | K175: 6045 | L175: 576150 | M175: Domestic Exports | N175: Customs
A176: 2024 | B176: 1 | D176: RWANDA | E176: 27101951 | F176: =VLOOKUP(E176,'HS Code'!$L$4:$O$65,2,0) -> Petroleum | G176: 33450910 | H176: 322 | I176: l | J176: 84116 | K176: 79297 | L176: 26307934 | M176: Domestic Exports | N176: Customs
...

Sheet Table 9.1
A1: Table 9.1 Quantity and Value of Imports, Exports and Re-exports of Petroleum Products, 2020-2024
A2: Petroleum Products | B2: Quantity ('000 Tonnes) | G2: Value (KSh Million) | M2: Unit value (KSh/TJ)
B3: 2020 | C3: 2021 | D3: 2022 | E3: 2023 | F3: 2024* | G3: 2020 | H3: 2021 | I3: 2022 | J3: 2023 | K3: 2024* | M3: 2020 | N3: 2021 | O3: 2022 | P3: 2023 | Q3: 2024
A4: IMPORTS
A5: Petroleum Fuels 1 ……………. | B5: 5723 | C5: 6409.3 | D5: 5924.8 | E5: 4287.4 | F5: 5230.6 | G5: 206826 | H5: 345447.2 | I5: 625585.6 | J5: 623335.1 | K5: 573251.8 | M5: =(G5*1000000)/(B5*1000*(Conversions!$E$19/1000)) -> 8637532.8 | N5: =(H5*1000000)/(C5*1000*(Conversions!$E$19/1000)) -> 12881885 | O5: =(I5*1000000)/(D5*1000*(Conversions!$E$19/1000)) -> 25236050 | P5: =(J5*1000000)/(E5*1000*(Conversions!$E$19/1000)) -> 34748487 | Q5: =(K5*1000000)/(F5*1000*(Conversions!$E$19/1000)) -> 26194025
A6: Lubricating Oils ……….. | B6: 9.4 | C6: 9.2 | D6: 6 | E6: 5.6 | F6: 5.3 | G6: 1796.3 | H6: 2046.9 | I6: 1976.2 | J6: 2372.5 | K6: 1638.3 | M6: =(G6*1000000)/(B6*1000*(Conversions!$E$19/1000)) -> 45672979 | N6: =(H6*1000000)/(C6*1000*(Conversions!$E$19/1000)) -> 53176178 | O6: =(I6*1000000)/(D6*1000*(Conversions!$E$19/1000)) -> 78720523 | P6: =(J6*1000000)/(E6*1000*(Conversions!$E$19/1000)) -> 1.0125734e+08 | Q6: =(K6*1000000)/(F6*1000*(Conversions!$E$19/1000)) -> 73879830
A7: Lubricating Greases ……… | B7: 2.7 | C7: 3.4 | D7: 2.7 | E7: 2.3 | F7: 2.6 | G7: 510 | H7: 812.9 | I7: 823.6 | J7: 689.1 | K7: 635.1 | M7: =(G7*1000000)/(B7*1000*(Conversions!$E$19/1000)) -> 45145528 | N7: =(H7*1000000)/(C7*1000*(Conversions!$E$19/1000)) -> 57143460 | O7: =(I7*1000000)/(D7*1000*(Conversions!$E$19/1000)) -> 72905602 | P7: =(J7*1000000)/(E7*1000*(Conversions!$E$19/1000)) -> 71608197 | Q7: =(K7*1000000)/(F7*1000*(Conversions!$E$19/1000)) -> 58381747
A8: TOTAL | B8: 5735.1 | C8: 6421.9 | D8: 5933.5 | E8: 4295.3 | F8: 5238.5 | G8: 209132.3 | H8: 348307 | I8: 628385.5 | J8: 626396.7 | K8: 575525.3
A9: DOMESTIC EXPORTS
A10: Petroleum Fuels 1 ……………. | B10: 2.3 | C10: 0.4 | D10: 8 | E10: 9.5 | F10: 7.7 | G10: 169.5 | H10: 35.8 | I10: 297.5 | J10: 976.5 | K10: 831.4
A11: Lubricating Oils ……… | B11: 25.8 | C11: 22.4 | D11: 24.2 | E11: 29.1 | F11: 37.4 | G11: 5001.3 | H11: 5210.9 | I11: 7817.7 | J11: 11224.6 | K11: 12962.7
A12: Lubricating Greases ……… | B12: 0.1 | C12: 0.1 | D12: 0 | E12: 0.1 | F12: 0.1 | G12: 19 | H12: 16.6 | I12: 22.3 | J12: 37.1 | K12: 38
A13: TOTAL……………….. | B13: 28.2 | C13: 22.9 | D13: 32.3 | E13: 38.7 | F13: 45.2 | G13: 5189.8 | H13: 5263.3 | I13: 8137.6 | J13: 12238.2 | K13: 13832
A14: RE-EXPORTS
A15: Petroleum Fuels 1 ……………. | B15: 802.7 | C15: 581.7 | D15: 471.2 | E15: 271.2 | F15: 950 | G15: 37145.8 | H15: 22848.9 | I15: 41635.2 | J15: 37397.8 | K15: 128338.9 | M15: =(G15*1000000)/(B15*1000*(Conversions!$E$19/1000)) -> 11060246 | N15: =(H15*1000000)/(C15*1000*(Conversions!$E$19/1000)) -> 9388031.9 | O15: =(I15*1000000)/(D15*1000*(Conversions!$E$19/1000)) -> 21118531 | P15: =(J15*1000000)/(E15*1000*(Conversions!$E$19/1000)) -> 32958292 | Q15: =(K15*1000000)/(F15*1000*(Conversions!$E$19/1000)) -> 32288140
A16: Lubricating Oils ……… | B16: 1.3 | C16: 6.3 | D16: 0.7 | E16: 0.3 | F16: 0.2 | G16: 241.4 | H16: 1430.4 | I16: 212.2 | J16: 117 | K16: 86.3 | M16: =(G16*1000000)/(B16*1000*(Conversions!$E$19/1000)) -> 44381527 | N16: =(H16*1000000)/(C16*1000*(Conversions!$E$19/1000)) -> 54265683 | O16: =(I16*1000000)/(D16*1000*(Conversions!$E$19/1000)) -> 72452882 | P16: =(J16*1000000)/(E16*1000*(Conversions!$E$19/1000)) -> 93212237 | Q16: =(K16*1000000)/(F16*1000*(Conversions!$E$19/1000)) -> 1.0313098e+08
A17: Lubricating Greases …….. | B17: 0 | C17: 0 | D17: 0 | E17: 0 | F17: 0 | G17: 3.5 | H17: 0 | I17: 1.1 | J17: 1.9 | K17: 0.2 | M17: =(G17*1000000)/(B17*1000*(Conversions!$E$19/1000)) -> #DIV/0! | N17: =(H17*1000000)/(C17*1000*(Conversions!$E$19/1000)) -> #DIV/0! | O17: =(I17*1000000)/(D17*1000*(Conversions!$E$19/1000)) -> #DIV/0! | P17: =(J17*1000000)/(E17*1000*(Conversions!$E$19/1000)) -> #DIV/0! | Q17: =(K17*1000000)/(F17*1000*(Conversions!$E$19/1000)) -> #DIV/0!
A18: TOTAL……………….. | B18: 803.9 | C18: 587.9 | D18: 472 | E18: 271.5 | F18: 950.2 | G18: 37390.7 | H18: 24279.3 | I18: 41848.4 | J18: 37516.6 | K18: 128425.4
A19: TOTAL EXPORTS…… | B19: 832.1 | C19: 610.8 | D19: 504.2 | E19: 310.2 | F19: 995.4 | G19: 42580.5 | H19: 29542.6 | I19: 49986 | J19: 49754.8 | K19: 142257.4
A20: NET BALANCE2…… | G20: -166551.9 | H20: -318764.4 | I20: -578399.4 | J20: -576642 | K20: -433267.8
A21: *Provisional
A22: 1 Petroleum fuels refer to liquified petroleum gas, motor spirit premium, aviation spirit, jet fuel, illuminating kerosene, light and heavy diesel oils, and fuel oils.
A23: 2 Net balance refers to the difference in monetary value of a nation's exports and imports over a certain period.

Sheet Table 9.2
A1: Table 9.2 Petroleum Supply and Demand, 2020-2024
E2: ‘000 Tonnes
A3: Petroleum Fuels | B3: 2020 | C3: 2021 | D3: 2022 | E3: 2023 | F3: 2024*
A4: DEMAND -
A5: Liquefied Petroleum Gas …………...……………………. | B5: 326.2 | C5: 371.4 | D5: 333.8 | E5: 365.3 | F5: 414.9
A6: Motor gasoline (premium) ………………………………. | B6: 1395.3 | C6: 1554.4 | D6: 1561.3 | E6: 1446.6 | F6: 1492.6
A7: Aviation spirit …………………..…………………………………... | B7: 1.9 | C7: 1.4 | D7: 0.9 | E7: 1.3 | F7: 2.2
A8: Jet/turbo fuel ………………………..…………………………………. | B8: 394.8 | C8: 506.8 | D8: 592.3 | E8: 669 | F8: 735.5
A9: Illuminating kerosene ……………………………………………. | B9: 127 | C9: 111.3 | D9: 89 | E9: 55 | F9: 36.7
A10: Light diesel oil ……………………..………………………………. | B10: 2157.6 | C10: 2305.7 | D10: 2219.7 | E10: 2186.9 | F10: 2208.4
A11: Heavy diesel oil …………………..……………………………….. | B11: 1.8 | C11: 0.8 | D11: 0 | E11: 1.3 | F11: 0
A12: Fuel oil ………………………………………...………………………………. | B12: 273.9 | C12: 340.3 | D12: 337.1 | E12: 377 | F12: 309.2
A13: TOTAL DOMESTIC DEMAND…………………… | B13: 4678.5 | C13: 5192.1 | D13: 5134.1 | E13: 5102.4 | F13: 5199.4
A14: Exports of petroleum fuels ……………………………………………….… | B14: 2.3 | C14: 0.4 | D14: 8 | E14: 9.5 | F14: 7.7
A15: TOTAL DEMAND………………………………………………… | B15: 4680.8 | C15: 5192.5 | D15: 5142.1 | E15: 5111.9 | F15: 5207.1
A16: SUPPLY -
A17: Net imports of petroleum fuels …………………..………………………………… | B17: 4920.4 | C17: 5827.6 | D17: 5453.6 | E17: 4016.2 | F17: 4280.6
A18: Adjustment1 ……………………………………………………………………..…. | B18: 239.5 | C18: 635.1 | D18: 311.5 | E18: -1095.7 | F18: -926.5
A19: TOTAL SUPPLY…………………………………………………… | B19: 4680.8 | C19: 5192.5 | D19: 5142.1 | E19: 5111.9 | F19: 5207.1
A20: Source: Ministry of Energy and Petroleum; and Energy & Petroleum Regulatory Authority
A21: * Provisional.
A22: 1 Adjustment for inventory changes and losses

Sheet Table 9.3
A1: Chapter 3 Employment, Earnings and Consumer Price Indices Tables
F2: ‘000 Tonnes
A3: Category | B3: 2020 | C3: 2021 | D3: 2022 | E3: 2023 | F3: 2024*
A4: Agriculture .. .. .. .. .. .. .. .. ……... .. | B4: 24.8 | C4: 26.6 | D4: 29 | E4: 35.1 | F4: 42.8
A5: Retail pump outlets and road transport.. … … .. .. | B5: 3650.5 | C5: 3937.8 | D5: 3849.3 | E5: 3665.6 | F5: 3777.7
A6: Rail transport .. .. .. .. .. .. .. …….. .. .. .. .. | B6: 11.4 | C6: 19.4 | D6: 19 | E6: 15.1 | F6: 20
A7: Tourism1 .. .. .. .. .. .. …... .. .. .. .. .. .. | B7: 6.5 | C7: 6 | D7: 4.9 | E7: 4 | F7: 4.7
A8: Marine (excl. Naval Forces) .. .... .. .. .. .. | B8: 1.1 | C8: 2.1 | D8: 1.5 | E8: 8.5 | F8: 9.9
A9: Aviation (excl. Government) .. ... .. .. .. .. | B9: 392.7 | C9: 499.4 | D9: 570.3 | E9: 668.9 | F9: 722.9
A10: Power Generation .. .. .. .. .. .. .. ……. .. | B10: 75.8 | C10: 147.5 | D10: 189.9 | E10: 228.8 | F10: 129.6
A11: Industrial, Commercial and Other .. .. .. .. | B11: 494.4 | C11: 530.5 | D11: 446.3 | E11: 445.2 | F11: 457.1
A12: Government .. .. .. .. .. .. .. .. .. .. ….. .. .. | B12: 21.5 | C12: 22.8 | D12: 23.8 | E12: 31.2 | F12: 34.7
A13: TOTAL .. .. .. .. .. .. .. ………... .. | B13: 4678.5 | C13: 5192.1 | D13: 5134.1 | E13: 5102.4 | F13: 5199.4
A14: Source: Ministry of Petroleum and Mining; Energy & Petroleum Regulatory Authority
A15: * Provisional
A16: 1 Comprises sales to tour operators

Sheet Table 9.4
A1: Table 9.4 Wholesale Prices of Petroleum Fuels in Mombasa, December, 2020-2024
F2: KSh per Tonne
A3: Product | B3: 2020 | C3: 2021 | D3: 20222 | E3: 20232 | F3: 20242
A4: Motor spirit (premium).. .. .. .. .. .. | B4: 95000 | C4: 113166 | D4: 146068 | E4: 165788 | F4: 165378
A5: Illuminating kerosene.. .. ….. .. .. .. .. | B5: 71740 | C5: 87543 | D5: 115692 | E5: 153407 | F5: 152818
A6: Light diesel oil .. .. .. .. .. .. .. ……... | B6: 80010 | C6: 95925 | D6: 128362 | E6: 172390 | F6: 143031
A7: Source: Energy and Petroleum Regulatory Authority
A8: 1Prices include duties and VAT.
A9: 2 Applicable maximum wholesale prices not published. EPRA did not cap the wholesale price in 2022 as a result of the stabilisation of the retail pump prices. Assumed wholesale price is pump price less KSh 8.19 per litre

Sheet Table 9.5
A1: Table 9.5 Average Murban ADNOC_OPEC Reference Basket Prices, 2020-2024
F2: US$/BBL
A3: Month/Year | B3: 2020 | C3: 2021 | D3: 2022 | E3: 2023 | F3: 2024
A4: January………………. | B4: 66.09 | C4: 54.38 | D4: 85.41 | E4: 81.62 | F4: 80.04
A5: February…………….. | B5: 55.53 | C5: 61.05 | D5: 93.95 | E5: 81.88 | F5: 81.23
A6: March……………..… | B6: 33.92 | C6: 64.56 | D6: 113.48 | E6: 78.45 | F6: 84.22
A7: April…………………. | B7: 17.66 | C7: 63.24 | D7: 105.64 | E7: 84.13 | F7: 89.12
A8: May…………...…….. | B8: 25.17 | C8: 66.91 | D8: 113.87 | E8: 75.82 | F8: 83.59
A9: June…………...……. | B9: 37.05 | C9: 71.89 | D9: 117.72 | E9: 75.19 | F9: 83.22
A10: July…………….……. | B10: 43.42 | C10: 73.53 | D10: 108.55 | E10: 81.06 | F10: 84.43
A11: August…………...….. | B11: 45.19 | C11: 70.33 | D11: 101.9 | E11: 87.33 | F11: 78.41
A12: September……..……. | B12: 41.54 | C12: 73.88 | D12: 95.32 | E12: 94.6 | F12: 73.59
A13: October……..……..… | B13: 40.08 | C13: 82.11 | D13: 93.62 | E13: 91.78 | F13: 74.45
A14: November………..….. | B14: 42.61 | C14: 80.37 | D14: 89.73 | E14: 84.92 | F14: 72.98
... A16: Annual average | B16: 41.45 | C16: 69.719167 | D16: 99.9 | E16: 82.981667 | F16: 79.8625
A17: Source : OPEC Monthly Oil Market Report
A18: US$/ BBL: US Dollar per Barrel
A19: 1 Abu Dhabi free on board (fob) Prices
A20: ADNOC: Abu Dhabi National Oil Company

Sheet Table 9.6
A1: Table 9.6 Average1 Retail Prices of Selected Petroleum Fuels, 2020-2024
A2: Year | B2: Month | C2: KSh per Litre | F2: KSh per 13 Kg cylinder | I2: Year | J2: Month | K2: KSh per TJ | N2: KSh per TJ
C3: Motor Spirit Premium | E3: Illuminating Kerosene | F3: Liqufied Petroleum Gas (LPG) | K3: Motor Spirit Premium | M3: Illuminating Kerosene | N3: Liqufied Petroleum Gas (LPG)
D4: Light Diesel Oil | L4: Light Diesel Oil
A5: 2020 | B5: January | C5: 110.61 | D5: 102.81 | E5: 104.46 | F5: 2144.81 | I5: 2020 | J5: January
B6: March | C6: 112.07 | D6: 102.93 | E6: 96.72 | F6: 2065.98 | J6: March
B7: June | C7: 90.34 | D7: 75.88 | E7: 63.79 | F7: 2078.5 | J7: June
B8: September | C8: 106.3 | D8: 95.45 | E8: 84.09 | F8: 2033.57 | J8: September
B9: December | C9: 107.69 | D9: 92.75 | E9: 84.5 | F9: 1977.36 | J9: December
B10: Annual Average | C10: 103.28 | D10: 93.96 | E10: 84.6 | F10: 2056.84 | J10: Annual Average
A11: 2021 | B11: January | C11: 107.86 | D11: 97.33 | E11: 88.07 | F11: 2018.93 | I11: 2021 | J11: January
B12: March | C12: 123.66 | D12: 108.58 | E12: 98.78 | F12: 2074.23 | J12: March
B13: June | C13: 127.98 | D13: 108.58 | E13: 98.78 | F13: 2074.23 | J13: June
B14: September | C14: 135.54 | D14: 116.51 | E14: 111.74 | F14: 2445.23 | J14: September
B15: December | C15: 130.54 | D15: 111.51 | E15: 106.46 | F15: 2638.83 | J15: December
B16: Annual Average | C16: 125.79 | D16: 108.56 | E16: 100.19 | F16: 2280.91 | J16: Annual Average
A17: 2022 | B17: January | C17: 130.54 | D17: 111.51 | E17: 106.46 | F17: 2659.24 | I17: 2022 | J17: January
B18: March | C18: 135.54 | D18: 116.51 | E18: 104.46 | F18: 2866.2 | J18: March
B19: June | C19: 159.94 | D19: 140.91 | E19: 128.86 | F19: 3218.22 | J19: June
B20: September | C20: 180.05 | D20: 165.91 | E20: 148.86 | F20: 3106.66 | J20: September
B21: December | C21: 178.05 | D21: 162.91 | E21: 146.86 | F21: 2980.8 | J21: December
B22: Annual Average | C22: 157.34 | D22: 139.69 | E22: 127.38 | F22: 2990.41 | J22: Annual Average
A23: 2023 | B23: January | C23: 178.05 | D23: 162.91 | E23: 146.86 | F23: 2961.93 | I23: 2023 | J23: January
B24: March | C24: 180.05 | D24: 162.91 | E24: 146.86 | F24: 3137.7 | J24: March
B25: June | C25: 182.63 | D25: 167.98 | E25: 162.19 | F25: 3069.01 | J25: June
B26: September | C26: 212.25 | D26: 201.73 | E26: 203.34 | F26: 2795.69 | J26: September
B27: December | C27: 212.97 | D27: 202.21 | E27: 199.78 | F27: 3032.62 | J27: December
B28: Annual Average | C28: 194.5 | D28: 180.33 | E28: 172.05 | F28: 2990.7 | J28: Annual Average
A29: 2024 | B29: January | C29: 207.97 | D29: 197.21 | E29: 194.96 | F29: 3055.51 | I29: 2024 | J29: January | K29: =C29/Conversions!$E$16 -> 6080994.2 | L29: =D29/Conversions!$E$7 -> 5508659.2 | M29: =E29/Conversions!$E$12 -> 5212834.2 | N29: =F29/Conversions!$E$14 -> 4700784.6
B30: February | C30: 206.97 | D30: 196.21 | E30: 193.96 | F30: 3187.1 | J30: February | K30: =C30/Conversions!$E$16 -> 6051754.4 | L30: =D30/Conversions!$E$7 -> 5480726.3 | M30: =E30/Conversions!$E$12 -> 5186096.3 | N30: =F30/Conversions!$E$14 -> 4903230.8
B31: March | C31: 199.77 | D31: 191.11 | E31: 189.48 | F31: 3231.84 | J31: March | K31: =C31/Conversions!$E$16 -> 5841228.1 | L31: =D31/Conversions!$E$7 -> 5338268.2 | M31: =E31/Conversions!$E$12 -> 5066310.2 | N31: =F31/Conversions!$E$14 -> 4972061.5
B32: April | C32: 194.46 | D32: 181.11 | E32: 171.18 | F32: 3242.11 | J32: April | K32: =C32/Conversions!$E$16 -> 5685964.9 | L32: =D32/Conversions!$E$7 -> 5058938.5 | M32: =E32/Conversions!$E$12 -> 4577005.3 | N32: =F32/Conversions!$E$14 -> 4987861.5
B33: May | C33: 193.46 | D33: 179.91 | E33: 169.52 | F33: 3221.29 | J33: May | K33: =C33/Conversions!$E$16 -> 5656725.1 | L33: =D33/Conversions!$E$7 -> 5025419 | M33: =E33/Conversions!$E$12 -> 4532620.3 | N33: =F33/Conversions!$E$14 -> 4955830.8
B34: June | C34: 190.46 | D34: 173.83 | E34: 163.82 | F34: 3213.97 | J34: June | K34: =C34/Conversions!$E$16 -> 5569005.8 | L34: =D34/Conversions!$E$7 -> 4855586.6 | M34: =E34/Conversions!$E$12 -> 4380213.9 | N34: =F34/Conversions!$E$14 -> 4944569.2
B35: July | C35: 189.46 | D35: 172.33 | E35: 162.52 | F35: 3219.58 | J35: July | K35: =C35/Conversions!$E$16 -> 5539766.1 | L35: =D35/Conversions!$E$7 -> 4813687.2 | M35: =E35/Conversions!$E$12 -> 4345454.5 | N35: =F35/Conversions!$E$14 -> 4953200
B36: August | C36: 189.46 | D36: 172.33 | E36: 162.52 | F36: 3217.85 | J36: August | K36: =C36/Conversions!$E$16 -> 5539766.1 | L36: =D36/Conversions!$E$7 -> 4813687.2 | M36: =E36/Conversions!$E$12 -> 4345454.5 | N36: =F36/Conversions!$E$14 -> 4950538.5
B37: September | C37: 189.46 | D37: 172.33 | E37: 159.1 | F37: 3196.04 | J37: September | K37: =C37/Conversions!$E$16 -> 5539766.1 | L37: =D37/Conversions!$E$7 -> 4813687.2 | M37: =E37/Conversions!$E$12 -> 4254010.7 | N37: =F37/Conversions!$E$14 -> 4916984.6
B38: October | C38: 181.33 | D38: 168.82 | E38: 152.18 | F38: 3183.29 | J38: October | K38: =C38/Conversions!$E$16 -> 5302046.8 | L38: =D38/Conversions!$E$7 -> 4715642.5 | M38: =E38/Conversions!$E$12 -> 4068984 | N38: =F38/Conversions!$E$14 -> 4897369.2
B39: November | C39: 181.33 | D39: 168.82 | E39: 152.18 | F39: 3147.66 | J39: November | K39: =C39/Conversions!$E$16 -> 5302046.8 | L39: =D39/Conversions!$E$7 -> 4715642.5 | M39: =E39/Conversions!$E$12 -> 4068984 | N39: =F39/Conversions!$E$14 -> 4842553.8
B40: December | C40: 176.96 | D40: 165.82 | E40: 149.18 | F40: 3143.85 | J40: December | K40: =C40/Conversions!$E$16 -> 5174269 | L40: =D40/Conversions!$E$7 -> 4631843.6 | M40: =E40/Conversions!$E$12 -> 3988770.1 | N40: =F40/Conversions!$E$14 -> 4836692.3
...

Sheet Table 9.7
A1: Table 9.7 Installed and Effective Capacity of Electricity by Source as at 31st December, 2020-2024
Q2: MW
B3: INSTALLED CAPACITY | J3: EFFECTIVE CAPACITY
B4: Hydro | C4: Thermal Oil | D4: Geo thermal | F4: Co- gene- ration | G4: Solar | H4: Ethiopia HVDC | I4: Total | J4: Hydro | K4: Thermal Oil | L4: Geo thermal | N4: Co- gene- ration | O4: Solar | P4: Ethiopia HVDC | Q4: Total
A5: Year | E5: Wind | M5: Wind
A6: 2020 | B6: 834 | C6: 749.1 | D6: 863.1 | E6: 336.1 | F6: 2 | G6: 52.5 | I6: 2836.7 | J6: 805 | K6: 715.5 | L6: 805.1 | M6: 325.5 | N6: 2 | O6: 52.2 | Q6: 2705.3
A7: 2021 | B7: 838.1 | C7: 677.8 | D7: 863.1 | E7: 436.1 | F7: 2 | G7: 172.5 | I7: 2989.6 | J7: 809.1 | K7: 643.7 | L7: 805.1 | M7: 425.5 | N7: 2 | O7: 172.2 | Q7: 2857.6
A8: 2022 | B8: 838.9 | C8: 681.9 | D8: 950 | E8: 436.1 | F8: 2 | G8: 212.5 | H8: 200 | I8: 3321.3 | J8: 809.9 | K8: 645.5 | L8: 871.1 | M8: 425.5 | N8: 2 | O8: 212.2 | P8: 200 | Q8: 3166.2
A9: 2023 | B9: 839.3 | C9: 613.8 | D9: 940 | E9: 436.1 | F9: 2 | G9: 212.5 | H9: 200 | I9: 3243.6 | J9: 810.4 | K9: 586.6 | L9: 876.1 | M9: 425.5 | N9: 2 | O9: 212.2 | P9: 200 | Q9: 3112.7
A10: 2024* | B10: 839.2 | C10: 605.8 | D10: 940 | E10: 436.1 | F10: 2 | G10: 212.5 | H10: 200 | I10: 3235.5 | J10: 809.7 | K10: 582.6 | L10: 876.1 | M10: 425.5 | N10: 2 | O10: 211.9 | P10: 200 | Q10: 3107.8
A11: Source: Kenya Power & Lighting Company Ltd and Kenya Electricity Generation Company Ltd
A12: * Provisional
A13: Notes:
A14: 1. 1 Megawatt = 1,000 kilowatts = 1,000,000 watts
A15: 2. Installed capacity refers to the maximum theoretical electric output a power station could produce when operating at 100 per cent
A16: 3. Effective capacity refers to the maximum electric output a power station is expected to achieve given current operating constraints
A17: 4. HVDC: High Voltage Direct Current
A18: 5. HVDC commenced in 2022

Sheet Table 9.8
A1: Table 9.8 Generation and Imports of Electricity, 2020-2024
K2: GWh
C3: GENERATION | J3: IMPORTS | K3: TOTAL
B4: Hydro | C4: Thermal oil | F4: Geo thermal | G4: Co- gene- ration | H4: Wind | I4: Solar
A5: Year | C5: KenGen | D5: IPPs and Off-Grid | E5: Total
A6: 2020 | B6: 4232.6603 | C6: 120.58344 | D6: 633.91755 | E6: 754.50099 | F6: 5059.7817 | G6: 0.181606 | H6: 1331.3607 | I6: 88.418894 | J6: 136.67957 | K6: =B6+E6+F6+G6+H6+I6+J6 -> 11603.584
A7: 2021 | B7: 3674.9899 | C7: 434.32539 | D7: 760.0221 | E7: 1262.0171 | F7: 5037.0477 | G7: 0.464559 | H7: 1984.7964 | I7: 167.41781 | J7: 287.96138 | K7: =B7+E7+F7+G7+H7+I7+J7 -> 12414.695
A8: 2022 | B8: 3039.8756 | C8: 494.9 | D8: 1090.0216 | E8: 1584.9216 | F8: 5517.5492 | G8: 0.268151 | H8: 2143.0313 | I8: 383.72196 | J8: 316.00193 | K8: =B8+E8+F8+G8+H8+I8+J8 -> 12985.37
A9: 2023 | B9: 2666.6819 | C9: 353.46234 | D9: 952.19557 | E9: 1305.6579 | F9: 6032.0808 | G9: 0.2044591 | H9: 2008.1385 | I9: 491.4648 | J9: 919.32733 | K9: =B9+E9+F9+G9+H9+I9+J9 -> 13423.556
A10: 2024* | B10: 3630.6884 | C10: 411.18557 | D10: 718.29272 | E10: 1129.4783 | F10: 5551.0081 | G10: 0.0169487 | H10: 1797.6717 | I10: 460.44289 | J10: 1532.6243 | K10: =B10+E10+F10+G10+H10+I10+J10 -> 14101.931
A11: Source: Kenya Power & Lighting Company Ltd and Kenya Electricity Generation Company Ltd
A12: * Provisional
A13: Notes:
A14: IPP: Independent Power Producers
A15: 1 Gigawatt hour = 1,000,000 kilowatt hours

Sheet Table 9.9
A1: Table 9.9 Licensed Captive Power Capacities1 by Type of Technology, 2020-2024
F2: MW
A3: Type of Technology | B3: 2020 | C3: 2021 | D3: 2022 | E3: 2023 | F3: 2024*
A4: Hydro | B4: 26 | C4: 28.3 | D4: 32.4 | E4: 30.2 | F4: 30.2
A5: Coal | B5: 30 | C5: 30 | D5: 30 | E5: 30 | F5: 30
A6: Cogeneration | B6: 32 | C6: 32 | D6: 32 | E6: 32 | F6: 32
A7: Waste Heat Recovery | B7: 0 | C7: 28.5 | D7: 83.5 | E7: 83.5 | F7: 83.5
A8: Bagasse | B8: 15.7 | C8: 60.2 | D8: 60.2 | E8: 60.2 | F8: 60.2
A9: Solar | B9: 35 | C9: 35 | D9: 46.3 | E9: 88.2 | F9: 88.2
A10: Biomass | B10: 1.5 | C10: 2.9 | D10: 2.9 | E10: 19.5 | F10: 19.5
A11: Thermal | B11: 18.5 | C11: 46.1 | D11: 53.9 | E11: 42.9 | F11: 42.9
A12: Biogas | B12: 2.6 | C12: 2.8 | D12: 2.8 | E12: 0.2 | F12: 0.2
A13: Biothermal | B13: - | C13: - | D13: 2.1 | E13: 0 | F13: 0
