Workbook

Sheet NationalSummary_Services
E3: Potential or realized | F3: Ecosystem service supply | G3: Unit | H3: National 2013 | I3: National 2022 | J3: % Change | K3: National per ha (2022) | L3: Top 3 provinces (per ha, 2022) | M3: Bottom 3 provinces (per ha, 2022)
E4: Potential (realised only in cropland) | F4: Soil protection (avoided erosion) | G4: Tons | H4: 29.69 B | I4: 29.70 B | J4: 0.0005 | K4: 262 t/ha | L4: South West Ethiopia (746), Amhara (509), South Ethiopia (435) | M4: Somali (38), Afar (49), Sidama (56)
E5: Potential | F5: Water quality (avoided sediment) | G5: Tons | H5: 6.72 B | I5: 6.70 B | J5: –0.23% | K5: 59 t/ha | L5: South West Ethiopia (151), Amhara (130), South Ethiopia (99) | M5: Somali (7.7), Sidama (12.9), Addis Ababa (17.4)
E6: Potential | F6: Baseflow (sustained dry-season water) | G6: m³ | H6: 165.32 B | I6: 163.16 B | J6: –1.31% | K6: 1,440 m³/ha | L6: South West Ethiopia (5,039), Benishangul Gumz (3,527), Gambela (2,734) | M6: Somali (176), Dire Dawa (352), Sidama (371)
E7: Potential | F7: Flood regulation (avoided quickflow) | G7: m³ | H7: 190.36 B | I7: 185.16 B | J7: –2.73% | K7: 1,635 m³/ha | L7: South West Ethiopia (5,038), Benishangul Gumz (3,943), Gambela (2,493) | M7: Addis Ababa (–2,691), Afar (228), Sidama (274)
E8: Potential | F8: Water yield | G8: m³ | H8: 343.96 B | I8: 347.00 B | J8: 0.0088 | K8: 3,062 m³/ha | L8: Addis Ababa (7,906), South West Ethiopia (7,831), Benishangul Gumz (5,914) | M8: Somali (767), Sidama (800), Afar (1,204)
E9: Realized | F9: Carbon sequestration (annual rate) | G9: Tons C/yr | H9: –0.006 t/ha/yr | L9: Tigray (+1.98), Harari (+1.93), Central Ethiopia (+1.66) | M9: South West Ethiopia (–5.13), Addis Ababa (–3.93), South Ethiopia (–0.65)

Sheet Land cover account 2012 t0 2022
B2: Land cover account 2013 to 2022, km2
C3: Moderate forest | D3: Perennial cropland | E3: Annual cropland | F3: Open grassland | G3: Closed grassland | H3: Dense forest | I3: Sparse forest | J3: Wetland | K3: Built up | L3: Open shrub land | M3: Closed shrub land | N3: Water body | O3: Bare land | P3: Total
B4: Opening area 2013 | C4: 9090569 | D4: 90994 | E4: 20503194 | F4: 7532182 | G4: 5439232 | H4: 12688242 | I4: 1798242 | J4: 453013 | K4: 118216 | L4: 33713753 | M4: 12884237 | N4: 776070 | O4: 8257782 | P4: 113345726
B6: Additions
B7: Managed | C7: 995013 | D7: 109398 | E7: 13214659 | F7: 277987 | G7: 208825 | H7: 767233 | I7: 168417 | J7: 1239 | K7: 206154 | L7: 2556074 | M7: 1802972 | N7: 20922 | O7: 105851 | P7: 20434745
B8: Natural | P8: -
B9: Unknown | C9: 8103738 | F9: 2225077 | G9: 3045961 | H9: 5391306 | I9: 1524376 | J9: 11231 | L9: 6948061 | M9: 4996543 | N9: 240433 | O9: 3170004 | P9: 35656729
B10: Total additions | C10: 9098750 | D10: 109398 | E10: 13214659 | F10: 2503064 | G10: 3254786 | H10: 6158539 | I10: 1692792 | J10: 12470 | K10: 206154 | L10: 9504135 | M10: 6799516 | N10: 261355 | O10: 3275855 | P10: 56091474
B12: Reductions
B13: Managed | C13: 1961708 | D13: 35849 | E13: 6968300 | F13: 248368 | G13: 1764432 | H13: 824934 | I13: 280636 | J13: 316 | K13: 4532 | L13: 4518984 | M13: 3177360 | N13: 5776 | O13: 643550 | P13: 20434745
B14: Natural | P14: -
B15: Unknown | C15: 4634121 | F15: 2728371 | G15: 1993343 | H15: 4121748 | I15: 1287778 | J15: 2997 | L15: 12197840 | M15: 6755806 | N15: 45220 | O15: 1889505 | P15: 35656729
B16: Total reductions | C16: 6595829 | D16: 35849 | E16: 6968300 | F16: 2976740 | G16: 3757775 | H16: 4946681 | I16: 1568414 | J16: 3313 | K16: 4532 | L16: 16716825 | M16: 9933166 | N16: 50996 | O16: 2533054 | P16: 56091474
B18: Closing area 2022 | C18: 11593490 | D18: 164544 | E18: 26749554 | F18: 7058507 | G18: 4936243 | H18: 13900099 | I18: 1922620 | J18: 462170 | K18: 319838 | L18: 26501063 | M18: 9750587 | N18: 986429 | O18: 9000583 | P18: 113345726
B19: Net change | C19: 2502921 | D19: 73549 | E19: 6246359 | F19: -473675 | G19: -502989 | H19: 1211858 | I19: 124378 | J19: 9157 | K19: 201622 | L19: -7212690 | M19: -3133650 | N19: 210359 | O19: 742801 | P19: 0
B20: Percentage change | C20: 0.28 | D20: 0.81 | E20: 0.3 | F20: -0.06 | G20: -0.09 | H20: 0.1 | I20: 0.07 | J20: 0.02 | K20: 1.71 | L20: -0.21 | M20: -0.24 | N20: 0.27 | O20: 0.09 | P20: 0

Sheet Realized_FullTable
D2: Full extended realized soil protection service Ethiopia | W2: Full extended realized carbon sequestration service Ethiopia
E4: Accounting period | F4: units of measure | G4: Economic units(selected) | H4: Ecosystem type | X4: Accounting period | Y4: units of measure | Z4: Economic units(selected) | AA4: Ecosystem type | AN4: National
G5: Agriculture | H5: Perennial crop | I5: Annual crop | Z5: Government | AA5: Moderate forest | AB5: Perennial crop | AC5: Annual crop | AD5: Open grassland | AE5: Closed grassland | AF5: Dense forest | AG5: Sparse forest | AH5: Wetland | AI5: Built up area | AJ5: Open shrubland | AK5: Closed shrubland | AL5: Water body | AM5: Bare land
D6: Supply | W6: Supply
D7: Soil protection (avoided erosion) | E7: 2013 | F7: Tons | H7: =MainDatabase!E106 -> 200456580 | I7: =MainDatabase!F106 -> 8267790000 | W7: Carbon sequestration | X7: 2022 | Y7: MT C Yr-1 | AA7: 93.560728 | AB7: 10.201546 | AC7: 166.48964 | AD7: -10.082344 | AE7: 18.131336 | AF7: 18.241723 | AG7: -34.371905 | AH7: -0.14173843 | AI7: 2.8852324 | AJ7: -194.82166 | AK7: -75.235764 | AL7: 0.013982216 | AM7: 4.4838504 | AN7: =SUM(AA7:AM7) -> -0.64537511
E8: 2022 | F8: Tons | H8: =MainDatabase!E107 -> 280791460 | I8: =MainDatabase!F107 -> 8807426000 | W8: Use
D9: Use | W9: Carbon sequestration | X9: 2022 | Y9: MT C Yr-1 | Z9: =SUM(AA7:AM7) -> -0.64537511
D10: Soil protection (avoided erosion) | E10: 2013 | F10: Tons | G10: 8468246580
E11: 2022 | F11: Tons | G11: 9088217460
D14: Accounting period | E14: Units | F14: Ecosystem type/Economic units | G14: Regions
G15: Central Ethiopia | H15: Addis Ababa | I15: Afar | J15: Amhara | K15: Benishangul Gumz | L15: Dire Dawa | M15: Gambela | N15: Harari | O15: Oromia | P15: Sidama | Q15: South Ethiopia | R15: Somali | S15: South West Ethiopia | T15: Tigray | U15: National total
D16: Supply side
D17: 2013 | E17: Million tons | F17: Annual crop | G17: 252.18505 | H17: 1.8267502 | I17: 8.733546 | J17: 3094.2234 | K17: 169.86285 | L17: 12.312507 | M17: 11.951915 | N17: 2.9047651 | O17: 3389.751 | P17: 76.674421 | Q17: 556.90893 | R17: 22.802339 | S17: 451.17728 | T17: 216.47774 | U17: =SUM(G17:T17) -> 8267.7925
F18: Perennial crop | G18: 53.143956 | H18: 0 | I18: 0.28891883 | J18: 0 | K18: 0 | L18: 0.21705234 | M18: 0 | N18: 1.7882223 | O18: 142.82685 | P18: 0.0575489 | Q18: 0.010330574 | R18: 2.1055143 | S18: 0.00010658508 | T18: 0.018071529 | U18: =SUM(G18:T18) -> 200.45657
D19: 2013 | F19: Total | G19: 305.329 | H19: 1.8267502 | I19: 9.0224648 | J19: 3094.2234 | K19: 169.86285 | L19: 12.529559 | M19: 11.951915 | N19: 4.6929874 | O19: 3532.5779 | P19: 76.73197 | Q19: 556.91926 | R19: 24.907854 | S19: 451.17739 | T19: 216.49581 | U19: =SUM(G19:T19) -> 8468.2491
D20: 2022 | E20: Million tons | F20: Annual crop | G20: 216.49076 | H20: 1.2324677 | I20: 9.5902602 | J20: 3639.6532 | K20: 196.38713 | L20: 10.424983 | M20: 3.8684258 | N20: 2.580893 | O20: 3152.6268 | P20: 159.15476 | Q20: 594.01344 | R20: 26.107959 | S20: 292.63803 | T20: 502.6583 | U20: =SUM(G20:T20) -> 8807.4274
F21: Perennial crop | G21: 53.190397 | H21: 0 | I21: 0.55456929 | J21: 0.41154756 | K21: 0.18590685 | L21: 0.23772136 | M21: 0 | N21: 1.8000776 | O21: 216.12047 | P21: 0.01414099 | Q21: 1.5240239 | R21: 2.0970306 | S21: 4.5916822 | T21: 0.063889763 | U21: =SUM(G21:T21) -> 280.79145
D22: 2022 | F22: Total | G22: 269.68116 | H22: 1.2324677 | I22: 10.144829 | J22: 3640.0647 | K22: 196.57304 | L22: 10.662704 | M22: 3.8684258 | N22: 4.3809706 | O22: 3368.7472 | P22: 159.1689 | Q22: 595.53746 | R22: 28.20499 | S22: 297.22972 | T22: 502.72218 | U22: =SUM(G22:T22) -> 9088.2188
D23: Use side
D24: 2013 | E24: Million tons | F24: Agriculture sector | G24: =G19 -> 305.329 | H24: =H19 -> 1.8267502 | I24: =I19 -> 9.0224648 | J24: =J19 -> 3094.2234 | K24: =K19 -> 169.86285 | L24: =L19 -> 12.529559 | M24: =M19 -> 11.951915 | N24: =N19 -> 4.6929874 | ... U24: =U19 -> 8468.2491
D25: 2022 | E25: Million tons | F25: Agriculture sector | G25: =G22 -> 269.68116 | H25: =H22 -> 1.2324677 | I25: =I22 -> 10.144829 | J25: =J22 -> 3640.0647 | K25: =K22 -> 196.57304 | L25: =L22 -> 10.662704 | M25: =M22 -> 3.8684258 | N25: =N22 -> 4.3809706 | ... U25: =U22 -> 9088.2188
D29: Accounting period | E29: Units | F29: Ecosystem type/Economic units | G29: Basin (watershed)
G30: Abbay | H30: Awash & north | I30: Baro Akobo | J30: Denakil & Ayisha | K30: Genale Dawa | L30: Ogaden | M30: Omo Gibe | N30: Rift Valley | O30: Tekeze & Mereb Gash | P30: Wabi Shebele | Q30: National total
D31: Supply side
D32: 2013 | E32: Million tons | F32: Annual crop | G32: 3920.4821 | H32: 389.08244 | I32: 438.1551 | J32: 18.770132 | K32: 176.13151 | L32: 1.1467446 | M32: 1319.7643 | N32: 460.01379 | O32: 954.72701 | P32: 589.51958 | Q32: =SUM(G32:P32) -> 8267.7927
E33: Million tons | F33: Perennial crop | G33: 1.1685555 | H33: 16.897436 | I33: 0.14575352 | J33: 0 | K33: 0.054123634 | L33: 0 | M33: 43.646386 | N33: 13.296205 | O33: 0.018071529 | P33: 125.23004 | Q33: =SUM(G33:P33) -> 200.45657
D34: 2013 | F34: Total | G34: 3921.6507 | H34: 405.97987 | I34: 438.30086 | J34: 18.770132 | K34: 176.18564 | L34: 1.1467446 | M34: 1363.4107 | N34: 473.31 | O34: 954.74508 | P34: 714.74962 | Q34: =SUM(G34:P34) -> 8468.2493
D35: 2022 | E35: Million tons | F35: Annual crop | G35: 3873.4221 | H35: 518.86021 | I35: 340.09259 | J35: 66.038241 | K35: 390.60133 | L35: 5.0927713 | M35: 1128.7521 | N35: 544.08023 | O35: 1477.5047 | P35: 462.98379 | Q35: =SUM(G35:P35) -> 8807.428
E36: Million tons | F36: Perennial crop | G36: 2.109301 | H36: 35.577833 | I36: 4.0249044 | J36: 0 | K36: 0.017525595 | L36: 0 | M36: 44.594254 | N36: 14.599634 | O36: 0.063889763 | P36: 179.80411 | Q36: =SUM(G36:P36) -> 280.79145
D37: 2022 | F37: Total | G37: 3875.5314 | H37: 554.43804 | I37: 344.11749 | J37: 66.038241 | K37: 390.61886 | L37: 5.0927713 | M37: 1173.3464 | N37: 558.67986 | O37: 1477.5685 | P37: 642.7879 | Q37: =SUM(G37:P37) -> 9088.2195
D38: Use side
D39: 2013 | E39: Million tons | F39: Agriculture sector | G39: =G34 -> 3921.6507 | H39: =H34 -> 405.97987 | I39: =I34 -> 438.30086 | J39: =J34 -> 18.770132 | K39: =K34 -> 176.18564 | L39: =L34 -> 1.1467446 | M39: =M34 -> 1363.4107 | N39: =N34 -> 473.31 | ... P39: =P34 -> 714.74962 | Q39: =SUM(G39:P39) -> 8468.2493
D40: 2022 | E40: Million tons | F40: Agriculture sector | G40: =G37 -> 3875.5314 | H40: =H37 -> 554.43804 | I40: =I37 -> 344.11749 | J40: =J37 -> 66.038241 | K40: =K37 -> 390.61886 | L40: =L37 -> 5.0927713 | M40: =M37 -> 1173.3464 | N40: =N37 -> 558.67986 | ... P40: =P37 -> 642.7879 | Q40: =SUM(G40:P40) -> 9088.2195

Sheet ServPotSupply_byEcType
D2: Full extended ecosystem capacity table for Ethiopia
D4: Potential supply | F4: Ecosystem type
E5: Year | F5: Moderate forest | G5: Perennial crop | H5: Annual crop | I5: Open grassland | J5: Closed grassland | K5: Dense forest | L5: Sparse forest | M5: Wetland | N5: Built up area | O5: Open shrubland | P5: Closed shrubland | Q5: Water body | R5: Bare land | S5: National
D6: Provisioning
D7: =MainDatabase!C112 -> Water yield (Cubic meter) | E7: 2013 | F7: =MainDatabase!D112 -> 18669963000 | G7: =MainDatabase!E112 -> 1728662970 | H7: =MainDatabase!F112 -> 118579421000 | I7: =MainDatabase!G112 -> 11840980400 | J7: =MainDatabase!H112 -> 7361508500 | K7: =MainDatabase!I112 -> 37051753000 | L7: =MainDatabase!J112 -> 9226119100 | M7: =MainDatabase!K112 -> 1368027500 | ... R7: =MainDatabase!P112 -> 20293586000 | S7: =MainDatabase!R112 -> 340705564094
E8: 2022 | F8: =MainDatabase!D113 -> 22959048000 | G8: =MainDatabase!E113 -> 2910176800 | H8: =MainDatabase!F113 -> 132281580000 | I8: =MainDatabase!G113 -> 9387662400 | J8: =MainDatabase!H113 -> 14845182600 | K8: =MainDatabase!I113 -> 38051637000 | L8: =MainDatabase!J113 -> 5164445300 | M8: =MainDatabase!K113 -> 1388244670 | ... R8: =MainDatabase!P113 -> 19316823000 | S8: =MainDatabase!R113 -> 343844206600
D9: Regulating and maintenance
D10: =MainDatabase!C108 -> Sustained water in dry periods (baseflow) (Cubic meter) | E10: 2013 | F10: =MainDatabase!D108 -> 10565424000 | G10: =MainDatabase!E108 -> 1136641400 | H10: =MainDatabase!F108 -> 43559526000 | I10: =MainDatabase!G108 -> 4060378400 | J10: =MainDatabase!H108 -> 4155934500 | K10: =MainDatabase!I108 -> 22682612000 | L10: =MainDatabase!J108 -> 5577697000 | M10: =MainDatabase!K108 -> 657747600 | ... R10: =MainDatabase!P108 -> 10920666000 | S10: =MainDatabase!R108 -> 162157784024
E11: 2022 | F11: =MainDatabase!D109 -> 12444460000 | G11: =MainDatabase!E109 -> 1858265700 | H11: =MainDatabase!F109 -> 47355810000 | I11: =MainDatabase!G109 -> 2932598800 | J11: =MainDatabase!H109 -> 9845071000 | K11: =MainDatabase!I109 -> 23192455000 | L11: =MainDatabase!J109 -> 2920160300 | M11: =MainDatabase!K109 -> 675061500 | ... R11: =MainDatabase!P109 -> 10001707000 | S11: =MainDatabase!R109 -> 160087317530
D12: =MainDatabase!$C$110 -> Flood mitigation (avoided quick flow) (Cubic meter) | E12: 2013 | F12: =MainDatabase!D110 -> 21296992000 | G12: =MainDatabase!E110 -> 1717478000 | H12: =MainDatabase!F110 -> 34435437000 | I12: =MainDatabase!G110 -> 6428749300 | J12: =MainDatabase!H110 -> 5378880500 | K12: =MainDatabase!I110 -> 45113926000 | L12: =MainDatabase!J110 -> 6469452300 | M12: =MainDatabase!K110 -> 746481000 | ... R12: =MainDatabase!P110 -> 117762440 | S12: =MainDatabase!R110 -> 190358640140
E13: 2022 | F13: =MainDatabase!D111 -> 25659288000 | G13: =MainDatabase!E111 -> 2778805000 | H13: =MainDatabase!F111 -> 39265440000 | I13: =MainDatabase!G111 -> 5248267000 | J13: =MainDatabase!H111 -> 9197194000 | K13: =MainDatabase!I111 -> 45600535000 | L13: =MainDatabase!J111 -> 3908062500 | M13: =MainDatabase!K111 -> 740717440 | ... R13: =MainDatabase!P111 -> 193771140 | S13: =MainDatabase!R111 -> 185162955480
D14: =MainDatabase!C106 -> Soil protection (avoided erosion) (Tons) | E14: 2013 | F14: =MainDatabase!D106 -> 2957460000 | G14: =MainDatabase!E106 -> 200456580 | H14: =MainDatabase!F106 -> 8267790000 | I14: =MainDatabase!G106 -> 564001500 | J14: =MainDatabase!H106 -> 500332740 | K14: =MainDatabase!I106 -> 6416423400 | L14: =MainDatabase!J106 -> 1001627260 | M14: =MainDatabase!K106 -> 14772930 | ... R14: =MainDatabase!P106 -> 327421730 | S14: =MainDatabase!R106 -> 29685133520
E15: 2022 | F15: =MainDatabase!D107 -> 3835871500 | G15: =MainDatabase!E107 -> 280791460 | H15: =MainDatabase!F107 -> 8807426000 | I15: =MainDatabase!G107 -> 444920830 | J15: =MainDatabase!H107 -> 683705600 | K15: =MainDatabase!I107 -> 6149960700 | L15: =MainDatabase!J107 -> 683910200 | M15: =MainDatabase!K107 -> 15030653 | ... R15: =MainDatabase!P107 -> 374208480 | S15: =MainDatabase!R107 -> 29698866177
D16: =MainDatabase!C104 -> Water quality (avoided sediment) (Tons) | E16: 2013 | F16: =MainDatabase!D104 -> 574558900 | G16: =MainDatabase!E104 -> 50101736 | H16: =MainDatabase!F104 -> 1992846100 | I16: =MainDatabase!G104 -> 150714600 | J16: =MainDatabase!H104 -> 108447370 | K16: =MainDatabase!I104 -> 1179619700 | L16: =MainDatabase!J104 -> 201630930 | M16: =MainDatabase!K104 -> 5617067.5 | ... R16: =MainDatabase!P104 -> 179114000 | S16: =MainDatabase!R104 -> 6.7166889e+09
E17: 2022 | F17: =MainDatabase!D105 -> 731190000 | G17: =MainDatabase!E105 -> 72172760 | H17: =MainDatabase!F105 -> 2153354200 | I17: =MainDatabase!G105 -> 124331480 | J17: =MainDatabase!H105 -> 135459400 | K17: =MainDatabase!I105 -> 1119644900 | L17: =MainDatabase!J105 -> 131087310 | M17: =MainDatabase!K105 -> 5764907 | ... R17: =MainDatabase!P105 -> 207367140 | S17: =MainDatabase!R105 -> 6700929411
D18: =MainDatabase!C101 -> Carbon sequestration ( Tons of carbon per year) | F18: =MainDatabase!D101 -> 93560728 | G18: =MainDatabase!E101 -> 10201546 | H18: =MainDatabase!F101 -> 1.6648964e+08 | I18: =MainDatabase!G101 -> -10082344 | J18: =MainDatabase!H101 -> 18131336 | K18: =MainDatabase!I101 -> 18241723 | L18: =MainDatabase!J101 -> -34371905 | M18: =MainDatabase!K101 -> -141738.43 | ... R18: =MainDatabase!P101 -> 4483850.4 | S18: =MainDatabase!R101 -> -645375.11
D21: =D4 -> Potential supply | F21: =F4 -> Ecosystem type
E22: =E5 -> Year | F22: =F5 -> Moderate forest | G22: =G5 -> Perennial crop | H22: =H5 -> Annual crop | I22: =I5 -> Open grassland | J22: =J5 -> Closed grassland | K22: =K5 -> Dense forest | L22: =L5 -> Sparse forest | ... S22: =S5 -> National
D23: =D6 -> Provisioning
D24: Water yield (Million m3) | E24: =E7 -> 2013 | F24: =F7/1000000 -> 18669.963 | G24: =G7/1000000 -> 1728.663 | H24: =H7/1000000 -> 118579.42 | I24: =I7/1000000 -> 11840.98 | J24: =J7/1000000 -> 7361.5085 | K24: =K7/1000000 -> 37051.753 | L24: =L7/1000000 -> 9226.1191 | M24: =M7/1000000 -> 1368.0275 | ... S24: =S7/1000000 -> 340705.56
E25: =E8 -> 2022 | F25: =F8/1000000 -> 22959.048 | G25: =G8/1000000 -> 2910.1768 | H25: =H8/1000000 -> 132281.58 | I25: =I8/1000000 -> 9387.6624 | J25: =J8/1000000 -> 14845.183 | K25: =K8/1000000 -> 38051.637 | L25: =L8/1000000 -> 5164.4453 | M25: =M8/1000000 -> 1388.2447 | ... S25: =S8/1000000 -> 343844.21
D26: Regulating and maintenance
D27: Sustained water in dry periods (baseflow) (Million m3) | E27: =E10 -> 2013 | F27: =F10/1000000 -> 10565.424 | G27: =G10/1000000 -> 1136.6414 | H27: =H10/1000000 -> 43559.526 | I27: =I10/1000000 -> 4060.3784 | J27: =J10/1000000 -> 4155.9345 | K27: =K10/1000000 -> 22682.612 | L27: =L10/1000000 -> 5577.697 | M27: =M10/1000000 -> 657.7476 | ... S27: =S10/1000000 -> 162157.78
E28: =E11 -> 2022 | F28: =F11/1000000 -> 12444.46 | G28: =G11/1000000 -> 1858.2657 | H28: =H11/1000000 -> 47355.81 | I28: =I11/1000000 -> 2932.5988 | J28: =J11/1000000 -> 9845.071 | K28: =K11/1000000 -> 23192.455 | L28: =L11/1000000 -> 2920.1603 | M28: =M11/1000000 -> 675.0615 | ... S28: =S11/1000000 -> 160087.32
D29: Flood mitigation (avoided quick flow) (Million m3) | E29: =E12 -> 2013 | F29: =F12/1000000 -> 21296.992 | G29: =G12/1000000 -> 1717.478 | H29: =H12/1000000 -> 34435.437 | I29: =I12/1000000 -> 6428.7493 | J29: =J12/1000000 -> 5378.8805 | K29: =K12/1000000 -> 45113.926 | L29: =L12/1000000 -> 6469.4523 | M29: =M12/1000000 -> 746.481 | ... S29: =S12/1000000 -> 190358.64
E30: =E13 -> 2022 | F30: =F13/1000000 -> 25659.288 | G30: =G13/1000000 -> 2778.805 | H30: =H13/1000000 -> 39265.44 | I30: =I13/1000000 -> 5248.267 | J30: =J13/1000000 -> 9197.194 | K30: =K13/1000000 -> 45600.535 | L30: =L13/1000000 -> 3908.0625 | M30: =M13/1000000 -> 740.71744 | ... S30: =S13/1000000 -> 185162.96
D31: Soil protection (avoided erosion) (Million Tons) | E31: =E14 -> 2013 | F31: =F14/1000000 -> 2957.46 | G31: =G14/1000000 -> 200.45658 | H31: =H14/1000000 -> 8267.79 | I31: =I14/1000000 -> 564.0015 | J31: =J14/1000000 -> 500.33274 | K31: =K14/1000000 -> 6416.4234 | L31: =L14/1000000 -> 1001.6273 | M31: =M14/1000000 -> 14.77293 | ... S31: =S14/1000000 -> 29685.134
E32: =E15 -> 2022 | F32: =F15/1000000 -> 3835.8715 | G32: =G15/1000000 -> 280.79146 | H32: =H15/1000000 -> 8807.426 | I32: =I15/1000000 -> 444.92083 | J32: =J15/1000000 -> 683.7056 | K32: =K15/1000000 -> 6149.9607 | L32: =L15/1000000 -> 683.9102 | M32: =M15/1000000 -> 15.030653 | ... S32: =S15/1000000 -> 29698.866
D33: Water quality regulation (avoided sediment) (Million Tons) | E33: =E16 -> 2013 | F33: =F16/1000000 -> 574.5589 | G33: =G16/1000000 -> 50.101736 | H33: =H16/1000000 -> 1992.8461 | I33: =I16/1000000 -> 150.7146 | J33: =J16/1000000 -> 108.44737 | K33: =K16/1000000 -> 1179.6197 | L33: =L16/1000000 -> 201.63093 | M33: =M16/1000000 -> 5.6170675 | ... S33: =S16/1000000 -> 6716.6889
E34: =E17 -> 2022 | F34: =F17/1000000 -> 731.19 | G34: =G17/1000000 -> 72.17276 | H34: =H17/1000000 -> 2153.3542 | I34: =I17/1000000 -> 124.33148 | J34: =J17/1000000 -> 135.4594 | K34: =K17/1000000 -> 1119.6449 | L34: =L17/1000000 -> 131.08731 | M34: =M17/1000000 -> 5.764907 | ... S34: =S17/1000000 -> 6700.9294
D35: Carbon sequestration (million Tons of carbon per year since 2013 to 2022) | F35: =F18/1000000 -> 93.560728 | G35: =G18/1000000 -> 10.201546 | H35: =H18/1000000 -> 166.48964 | I35: 0 | J35: =J18/1000000 -> 18.131336 | K35: =K18/1000000 -> 18.241723 | L35: 0 | M35: 0 | N35: =N18/1000000 -> 2.8852324 | O35: 0 | P35: 0 | Q35: =Q18/1000000 -> 0.013982216 | R35: =R18/1000000 -> 4.4838504 | S35: 0
D45: 2013 | E45: Economy | J45: Ecosystem types
E46: Agriculture | F46: Other industres | G46: Government | H46: Households | I46: ROW | J46: =F22 -> Moderate forest | K46: =G22 -> Perennial crop | L46: =H22 -> Annual crop | M46: =I22 -> Open grassland | N46: =J22 -> Closed grassland | O46: =K22 -> Dense forest | P46: =L22 -> Sparse forest | Q46: =M22 -> Wetland | ... W46: =S22 -> National
D47: POTENTIAL SUPPLY
D48: =D31 -> Soil protection (avoided erosion) (Million Tons) | J48: =F31 -> 2957.46 | K48: =G31 -> 200.45658 | L48: =H31 -> 8267.79 | M48: =I31 -> 564.0015 | N48: =J31 -> 500.33274 | O48: =K31 -> 6416.4234 | P48: =L31 -> 1001.6273 | Q48: =M31 -> 14.77293 | ... W48: =S31 -> 29685.134
D49: =D29 -> Flood mitigation (avoided quick flow) (Million m3) | J49: =F29 -> 21296.992 | K49: =G29 -> 1717.478 | L49: =H29 -> 34435.437 | M49: =I29 -> 6428.7493 | N49: =J29 -> 5378.8805 | O49: =K29 -> 45113.926 | P49: =L29 -> 6469.4523 | Q49: =M29 -> 746.481 | ... W49: =S29 -> 190358.64
D50: =D27 -> Sustained water in dry periods (baseflow) (Million m3) | J50: =F27 -> 10565.424 | K50: =G27 -> 1136.6414 | L50: =H27 -> 43559.526 | M50: =I27 -> 4060.3784 | N50: =J27 -> 4155.9345 | O50: =K27 -> 22682.612 | P50: =L27 -> 5577.697 | Q50: =M27 -> 657.7476 | ... W50: =S27 -> 162157.78
D51: =D33 -> Water quality regulation (avoided sediment) (Million Tons) | J51: =F33 -> 574.5589 | K51: =G33 -> 50.101736 | L51: =H33 -> 1992.8461 | M51: =I33 -> 150.7146 | N51: =J33 -> 108.44737 | O51: =K33 -> 1179.6197 | P51: =L33 -> 201.63093 | Q51: =M33 -> 5.6170675 | ... W51: =S33 -> 6716.6889
D52: =D24 -> Water yield (Million m3) | J52: =F24 -> 18669.963 | K52: =G24 -> 1728.663 | L52: =H24 -> 118579.42 | M52: =I24 -> 11840.98 | N52: =J24 -> 7361.5085 | O52: =K24 -> 37051.753 | P52: =L24 -> 9226.1191 | Q52: =M24 -> 1368.0275 | ... W52: =S24 -> 340705.56
D53: USE
...

Sheet ES SUT
B3: 2013 | C3: Economy | H3: Ecosystem
C4: Agriculture | D4: Other industres | E4: Government | F4: Households | G4: ROW | H4: Moderate forest | I4: Perennial cropland | J4: Annual cropland | K4: Open grassland | L4: Closed grassland | M4: Dense forest | N4: Sparse forest | O4: Wetland | P4: Built up | Q4: Open shrub land | R4: Closed shrub land | S4: Water body | T4: Bare land | U4: Total
B5: SUPPLY
B7: Global climate regulation
B8: Soil protection (avoided erosion)
B10: USE
B12: Global climate regulation
B13: Soil protection (avoided erosion)
B16: Grey : nil by definition
B19: 2022 | C19: Economy | H19: Ecosystem
C20: Agriculture | D20: Other industres | E20: Government | F20: Households | G20: ROW | H20: Moderate forest | I20: Perennial cropland | J20: Annual cropland | K20: Open grassland | L20: Closed grassland | M20: Dense forest | N20: Sparse forest | O20: Wetland | P20: Built up | Q20: Open shrub land | R20: Closed shrub land | S20: Water body | T20: Bare land | U20: Total
B21: SUPPLY
B23: Global climate regulation
B24: Soil protection (avoided erosion)
B26: USE
B28: Global climate regulation
B29: Soil protection (avoided erosion)

Sheet ServPotSupply_byRiverBasin
A2: Watershed | B2: Period | C2: Abbay | D2: Awash & north | E2: Baro Akobo | F2: Denakil & Ayisha | G2: Genale Dawa | H2: Ogaden | I2: Omo Gibe | J2: Rift Valley | K2: Tekeze & Mereb Gash | L2: Wabi Shebele | M2: National
A3: Soil protection (avoided erosion) (tons) | B3: 2013 | C3: 9452212224 | D3: 1771867904 | E3: 3083602176 | F3: 710422848 | G3: 2712563712 | H3: 54218332 | I3: 4743874560 | J3: 1426229248 | K3: 3353309952 | L3: 2378451968 | M3: =SUBTOTAL(9,C3:L3) -> 29686752924
A4: Soil protection (avoided erosion) (tons) | B4: 2022 | C4: 9491033088 | D4: 1782416256 | E4: 3096582912 | F4: 688770816 | G4: 2710088448 | H4: 54680460 | I4: 4738170368 | J4: 1420339072 | K4: 3367543808 | L4: 2351723520 | M4: =SUBTOTAL(9,C4:L4) -> 29701348748
A5: Flood regulation (avoided quick flow) (Cubic meter) | B5: 2013 | C5: 60435075072 | D5: 9482027008 | E5: 27054131200 | F5: 2185268736 | G5: 21603753984 | H5: 3923958016 | I5: 26813345792 | J5: 7712193536 | K5: 12460766208 | L5: 18687379456 | M5: =SUBTOTAL(9,C5:L5) -> 190357899008
A6: Flood regulation (avoided quick flow) (Cubic meter) | B6: 2022 | C6: 58379915264 | D6: 8769882112 | E6: 28028143616 | F6: 1869210112 | G6: 20999348224 | H6: 3786143744 | I6: 27276242944 | J6: 6826515456 | K6: 11106921472 | L6: 18120753152 | M6: =SUBTOTAL(9,C6:L6) -> 185163076096
A7: Sustained water in dry periods (baseflow) (Cubic meter) | B7: 2013 | C7: 66426433536 | D7: 9340621824 | E7: 28730511360 | F7: 2682900480 | G7: 8974980096 | H7: 333276544 | I7: 24233783296 | J7: 7724255744 | K7: 10900576256 | L7: 5973232128 | M7: =SUBTOTAL(9,C7:L7) -> 165320571264
A8: Sustained water in dry periods (baseflow) (Cubic meter) | B8: 2022 | C8: 62831718400 | D8: 8418752000 | E8: 29487880192 | F8: 2870369280 | G8: 8809398272 | H8: 245542944 | I8: 26057603072 | J8: 7730486784 | K8: 8651671552 | L8: 8054067712 | M8: =SUBTOTAL(9,C8:L8) -> 163157490208
A9: Water quality regulation (avoided sediment) (tons) | B9: 2013 | C9: 2218744064 | D9: 444264800 | E9: 548382144 | F9: 244428944 | G9: 492824544 | H9: 9924839 | I9: 1024118592 | J9: 302604544 | K9: 884835456 | L9: 546707456 | M9: =SUBTOTAL(9,C9:L9) -> 6716835383
A10: Water quality regulation (avoided sediment) (tons) | B10: 2022 | C10: 2167183104 | D10: 435813056 | E10: 537544064 | F10: 257575248 | G10: 499626592 | H10: 9495551 | I10: 1032808448 | J10: 311447360 | K10: 877821952 | L10: 571759680 | M10: =SUBTOTAL(9,C10:L10) -> 6701075055
A11: Water yield (Cubic meter) | B11: 2013 | C11: 131202932736 | D11: 22905791488 | E11: 44156446720 | F11: 7985887232 | G11: 23902480384 | H11: 4229106304 | I11: 45536620544 | J11: 18212853248 | K11: 23179860992 | L11: 22649133568 | M11: =SUBTOTAL(9,C11:L11) -> 343961113216
A12: Water yield (Cubic meter) | B12: 2022 | C12: 129663250432 | D12: 22696073728 | E12: 43940946944 | F12: 8489487872 | G12: 24343774208 | H12: 4279051296 | I12: 46899068928 | J12: 19104788992 | K12: 22289369088 | L12: 25296574976 | M12: =SUBTOTAL(9,C12:L12) -> 347002386464
A13: Climate regulation: Carbon retention ( tons of carbon) | B13: 2013 | C13: 8699236352 | D13: 2473657344 | E13: 3693455360 | F13: 772051328 | G13: 4456863744 | H13: 1285530496 | I13: 3583552768 | J13: 2108742656 | K13: 2917859072 | L13: 4054808064 | M13: =SUBTOTAL(9,C13:L13) -> 34045757184
A14: Climate regulation: Carbon retention ( tons of carbon) | B14: 2022 | C14: 8791343104 | D14: 2504052992 | E14: 3617610752 | F14: 763242432 | G14: 4515055616 | H14: 1337093504 | I14: 3459295232 | J14: 2051774208 | K14: 3043002624 | L14: 3957607168 | M14: =SUBTOTAL(9,C14:L14) -> 34040077632
A15: Climate regulation: Carbon sequestration ( tons of carbon per year) | B15: 2013 to 2022 | C15: 10234084 | D15: 3377294.2 | E15: -8427178.7 | F15: -978766.22 | G15: 6465763.6 | H15: 5729223.1 | I15: -13806393 | J15: -6329827.6 | K15: 13904839 | L15: -10800100 | M15: =SUBTOTAL(9,C15:L15) -> -631061.33
A19: Watershed | B19: Period | C19: Abbay | D19: Awash & north | E19: Baro Akobo | F19: Denakil & Ayisha | G19: Genale Dawa | H19: Ogaden | I19: Omo Gibe | J19: Rift Valley | K19: Tekeze & Mereb Gash | L19: Wabi Shebele | M19: National
A20: Soil protection (avoided erosion) (Million tons) | B20: 2013 | C20: =C3/1000000 -> 9452.2122 | D20: =D3/1000000 -> 1771.8679 | E20: =E3/1000000 -> 3083.6022 | F20: =F3/1000000 -> 710.42285 | G20: =G3/1000000 -> 2712.5637 | H20: =H3/1000000 -> 54.218332 | I20: =I3/1000000 -> 4743.8746 | J20: =J3/1000000 -> 1426.2292 | ... M20: =M3/1000000 -> 29686.753
A21: Soil protection (avoided erosion) (Million tons) | B21: 2022 | C21: =C4/1000000 -> 9491.0331 | D21: =D4/1000000 -> 1782.4163 | E21: =E4/1000000 -> 3096.5829 | F21: =F4/1000000 -> 688.77082 | G21: =G4/1000000 -> 2710.0884 | H21: =H4/1000000 -> 54.68046 | I21: =I4/1000000 -> 4738.1704 | J21: =J4/1000000 -> 1420.3391 | ... M21: =M4/1000000 -> 29701.349
A22: Flood mitigation (avoided quick flow) (Million cubic meter) | B22: 2013 | C22: =C5/1000000 -> 60435.075 | D22: =D5/1000000 -> 9482.027 | E22: =E5/1000000 -> 27054.131 | F22: =F5/1000000 -> 2185.2687 | G22: =G5/1000000 -> 21603.754 | H22: =H5/1000000 -> 3923.958 | I22: =I5/1000000 -> 26813.346 | J22: =J5/1000000 -> 7712.1935 | ... M22: =M5/1000000 -> 190357.9
A23: Flood mitigation (avoided quick flow) (Million cubic meter) | B23: 2022 | C23: =C6/1000000 -> 58379.915 | D23: =D6/1000000 -> 8769.8821 | E23: =E6/1000000 -> 28028.144 | F23: =F6/1000000 -> 1869.2101 | G23: =G6/1000000 -> 20999.348 | H23: =H6/1000000 -> 3786.1437 | I23: =I6/1000000 -> 27276.243 | J23: =J6/1000000 -> 6826.5155 | ... M23: =M6/1000000 -> 185163.08
A24: Sustained water in dry periods (baseflow) (Million cubic meter) | B24: 2013 | C24: =C7/1000000 -> 66426.434 | D24: =D7/1000000 -> 9340.6218 | E24: =E7/1000000 -> 28730.511 | F24: =F7/1000000 -> 2682.9005 | G24: =G7/1000000 -> 8974.9801 | H24: =H7/1000000 -> 333.27654 | I24: =I7/1000000 -> 24233.783 | J24: =J7/1000000 -> 7724.2557 | ... M24: =M7/1000000 -> 165320.57
A25: Sustained water in dry periods (baseflow) (Million cubic meter) | B25: 2022 | C25: =C8/1000000 -> 62831.718 | D25: =D8/1000000 -> 8418.752 | E25: =E8/1000000 -> 29487.88 | F25: =F8/1000000 -> 2870.3693 | G25: =G8/1000000 -> 8809.3983 | H25: =H8/1000000 -> 245.54294 | I25: =I8/1000000 -> 26057.603 | J25: =J8/1000000 -> 7730.4868 | ... M25: =M8/1000000 -> 163157.49
A26: Water quality (avoided sediment) (Million tons) | B26: 2013 | C26: =C9/1000000 -> 2218.7441 | D26: =D9/1000000 -> 444.2648 | E26: =E9/1000000 -> 548.38214 | F26: =F9/1000000 -> 244.42894 | G26: =G9/1000000 -> 492.82454 | H26: =H9/1000000 -> 9.924839 | I26: =I9/1000000 -> 1024.1186 | J26: =J9/1000000 -> 302.60454 | ... M26: =M9/1000000 -> 6716.8354
A27: Water quality (avoided sediment) (Million tons) | B27: 2022 | C27: =C10/1000000 -> 2167.1831 | D27: =D10/1000000 -> 435.81306 | E27: =E10/1000000 -> 537.54406 | F27: =F10/1000000 -> 257.57525 | G27: =G10/1000000 -> 499.62659 | H27: =H10/1000000 -> 9.495551 | I27: =I10/1000000 -> 1032.8084 | J27: =J10/1000000 -> 311.44736 | ... M27: =M10/1000000 -> 6701.0751
A28: Water yield (Million cubic meter) | B28: 2013 | C28: =C11/1000000 -> 131202.93 | D28: =D11/1000000 -> 22905.791 | E28: =E11/1000000 -> 44156.447 | F28: =F11/1000000 -> 7985.8872 | G28: =G11/1000000 -> 23902.48 | H28: =H11/1000000 -> 4229.1063 | I28: =I11/1000000 -> 45536.621 | J28: =J11/1000000 -> 18212.853 | ... M28: =M11/1000000 -> 343961.11
A29: Water yield (Million cubic meter) | B29: 2022 | C29: =C12/1000000 -> 129663.25 | D29: =D12/1000000 -> 22696.074 | E29: =E12/1000000 -> 43940.947 | F29: =F12/1000000 -> 8489.4879 | G29: =G12/1000000 -> 24343.774 | H29: =H12/1000000 -> 4279.0513 | I29: =I12/1000000 -> 46899.069 | J29: =J12/1000000 -> 19104.789 | ... M29: =M12/1000000 -> 347002.39
A30: Climate regulation: Carbon retention ( Million tons of carbon) | B30: 2013 | C30: =C13/1000000 -> 8699.2364 | D30: =D13/1000000 -> 2473.6573 | E30: =E13/1000000 -> 3693.4554 | F30: =F13/1000000 -> 772.05133 | G30: =G13/1000000 -> 4456.8637 | H30: =H13/1000000 -> 1285.5305 | I30: =I13/1000000 -> 3583.5528 | J30: =J13/1000000 -> 2108.7427 | ... M30: =M13/1000000 -> 34045.757
A31: Climate regulation: Carbon retention ( Million tons of carbon) | B31: 2022 | C31: =C14/1000000 -> 8791.3431 | D31: =D14/1000000 -> 2504.053 | E31: =E14/1000000 -> 3617.6108 | F31: =F14/1000000 -> 763.24243 | G31: =G14/1000000 -> 4515.0556 | H31: =H14/1000000 -> 1337.0935 | I31: =I14/1000000 -> 3459.2952 | J31: =J14/1000000 -> 2051.7742 | ... M31: =M14/1000000 -> 34040.078
A32: Climate regulation: Carbon sequestration ( Million tons of carbon per year) | B32: 2013 to 2022 | C32: =C15/1000000 -> 10.234084 | D32: =D15/1000000 -> 3.3772942 | E32: =E15/1000000 -> -8.4271787 | F32: =F15/1000000 -> -0.97876622 | G32: =G15/1000000 -> 6.4657636 | H32: =H15/1000000 -> 5.7292231 | I32: =I15/1000000 -> -13.806393 | J32: =J15/1000000 -> -6.3298276 | ... M32: =M15/1000000 -> -0.63106133
A36: =A20 -> Soil protection (avoided erosion) (Million tons) | C36: =(C21-C20)/C20 -> 0.0041070665 | D36: =(D21-D20)/D20 -> 0.0059532384 | E36: =(E21-E20)/E20 -> 0.0042096014 | F36: =(F21-F20)/F20 -> -0.030477668 | G36: =(G21-G20)/G20 -> -0.00091251829 | H36: =(H21-H20)/H20 -> 0.008523464 | I36: =(I21-I20)/I20 -> -0.0012024331 | J36: =(J21-J20)/J20 -> -0.0041298943 | ... M36: =(M21-M20)/M20 -> 0.00049166118
A37: =A22 -> Flood mitigation (avoided quick flow) (Million cubic meter) | C37: =(C23-C22)/C22 -> -0.034006077 | D37: =(D23-D22)/D22 -> -0.075104711 | E37: =(E23-E22)/E22 -> 0.036002354 | F37: =(F23-F22)/F22 -> -0.14463147 | G37: =(G23-G22)/G22 -> -0.027976886 | H37: =(H23-H22)/H22 -> -0.03512124 | I37: =(I23-I22)/I22 -> 0.017263685 | J37: =(J23-J22)/J22 -> -0.11484127 | ... M37: =(M23-M22)/M22 -> -0.027289768
A38: =A24 -> Sustained water in dry periods (baseflow) (Million cubic meter) | C38: =(C25-C24)/C24 -> -0.054115733 | D38: =(D25-D24)/D24 -> -0.098694695 | E38: =(E25-E24)/E24 -> 0.026361133 | F38: =(F25-F24)/F24 -> 0.069875421 | G38: =(G25-G24)/G24 -> -0.018449269 | H38: =(H25-H24)/H24 -> -0.26324565 | I38: =(I25-I24)/I24 -> 0.075259391 | J38: =(J25-J24)/J24 -> 0.00080668484 | ... M38: =(M25-M24)/M24 -> -0.013084162
A39: =A26 -> Water quality (avoided sediment) (Million tons) | C39: =(C27-C26)/C26 -> -0.023238805 | D39: =(D27-D26)/D26 -> -0.019024114 | E39: =(E27-E26)/E26 -> -0.019763736 | F39: =(F27-F26)/F26 -> 0.053783745 | G39: =(G27-G26)/G26 -> 0.01380217 | H39: =(H27-H26)/H26 -> -0.043253901 | I39: =(I27-I26)/I26 -> 0.0084852048 | J39: =(J27-J26)/J26 -> 0.02922235 | ... M39: =(M27-M26)/M26 -> -0.0023463919
A40: =A28 -> Water yield (Million cubic meter) | C40: =(C29-C28)/C28 -> -0.011735121 | D40: =(D29-D28)/D28 -> -0.0091556653 | E40: =(E29-E28)/E28 -> -0.0048803695 | F40: =(F29-F28)/F28 -> 0.063061326 | G40: =(G29-G28)/G28 -> 0.018462261 | H40: =(H29-H28)/H28 -> 0.011809822 | I40: =(I29-I28)/I28 -> 0.02991984 | J40: =(J29-J28)/J28 -> 0.048972873 | ... M40: =(M29-M28)/M28 -> 0.0088419101
A41: =A30 -> Climate regulation: Carbon retention ( Million tons of carbon) | C41: =(C31-C30)/C30 -> 0.010587912 | D41: =(D31-D30)/D30 -> 0.012287736 | E41: =(E31-E30)/E30 -> -0.020534865 | F41: =(F31-F30)/F30 -> -0.011409728 | G41: =(G31-G30)/G30 -> 0.013056686 | H41: =(H31-H30)/H30 -> 0.040110295 | I41: =(I31-I30)/I30 -> -0.034674398 | J41: =(J31-J30)/J30 -> -0.027015363 | ... M41: =(M31-M30)/M30 -> -0.00016682114
B52: 2013 | C52: Economy | H52: River basin (watershed)
C53: Agriculture | D53: Other industres | E53: Government | F53: Households | G53: ROW | H53: =C19 -> Abbay | I53: =D19 -> Awash & north | J53: =E19 -> Baro Akobo | K53: =F19 -> Denakil & Ayisha | L53: =G19 -> Genale Dawa | M53: =H19 -> Ogaden | N53: =I19 -> Omo Gibe | O53: =J19 -> Rift Valley | ... R53: =M19 -> National
B54: POTENTIAL SUPPLY
B55: Soil protection (avoided erosion) (Million tons) | H55: =C20 -> 9452.2122 | I55: =D20 -> 1771.8679 | J55: =E20 -> 3083.6022 | K55: =F20 -> 710.42285 | L55: =G20 -> 2712.5637 | M55: =H20 -> 54.218332 | N55: =I20 -> 4743.8746 | O55: =J20 -> 1426.2292 | ... R55: =M20 -> 29686.753
B56: Flood mitigation (avoided quick flow) (Million cubic meter) | H56: =C22 -> 60435.075 | I56: =D22 -> 9482.027 | J56: =E22 -> 27054.131 | K56: =F22 -> 2185.2687 | L56: =G22 -> 21603.754 | M56: =H22 -> 3923.958 | N56: =I22 -> 26813.346 | O56: =J22 -> 7712.1935 | ... R56: =M22 -> 190357.9
B57: Sustained water in dry periods (baseflow) (Million cubic meter) | H57: =C24 -> 66426.434 | I57: =D24 -> 9340.6218 | J57: =E24 -> 28730.511 | K57: =F24 -> 2682.9005 | L57: =G24 -> 8974.9801 | M57: =H24 -> 333.27654 | N57: =I24 -> 24233.783 | O57: =J24 -> 7724.2557 | ... R57: =M24 -> 165320.57
...

Sheet ServPotSupply_byRegion
B2: Regions | C2: Period | D2: Central Ethiopia | E2: Addis Ababa | F2: Afar | G2: Amhara | H2: Benishangul Gumz | I2: Dire Dawa | J2: Gambela | K2: Harari | L2: Oromia | M2: Sidama | N2: South Ethiopia | O2: Somali | P2: South West Ethiopia | Q2: Tigray | R2: National
B3: Soil protection (avoided erosion) (tons) | C3: 2013 | D3: 467460160 | E3: 11284668 | F3: 470548864 | G3: 7906476544 | H3: 1838702080 | I3: 22122812 | J3: 485293568 | K3: 6703134 | L3: 10582815744 | M3: 275323360 | N3: 2099035008 | O3: 1179824128 | P3: 2922224896 | Q3: 1418912256 | R3: =SUM(D3:Q3) -> 29686727222
B4: Soil protection (avoided erosion) (tons) | C4: 2022 | D4: 470970368 | E4: 11565920 | F4: 465773056 | G4: 7920613376 | H4: 1861481216 | I4: 22035842 | J4: 489878400 | K4: 6770849 | L4: 10565665792 | M4: 271991808 | N4: 2099785344 | O4: 1176355072 | P4: 2913199104 | Q4: 1425274368 | R4: =SUM(D4:Q4) -> 29701360515
B5: Flood mitigation (avoided quick flow) (Cubic meter) | C5: 2013 | D5: 3051862528 | E5: -95213376 | F5: 2084096000 | G5: 34101839872 | H5: 20390125568 | I5: 37676444 | J5: 7439709184 | K5: 31583864 | L5: 69775597568 | M5: 1686770560 | N5: 11052518400 | O5: 16500699136 | P5: 19032971264 | Q5: 5267421184 | R5: =SUM(D5:Q5) -> 190357658196
B6: Flood mitigation (avoided quick flow) (Cubic meter) | C6: 2022 | D6: 3062937344 | E6: -145227280 | F6: 2163162112 | G6: 30190915584 | H6: 19808010240 | I6: 36458320 | J6: 7790137856 | K6: 30743508 | L6: 69244280832 | M6: 1321052288 | N6: 11103072256 | O6: 16145696768 | P6: 19664224256 | Q6: 4747422208 | R6: =SUM(D6:Q6) -> 185162886292
B7: Sustained water in dry periods (baseflow) (Cubic meter) | C7: 2013 | D7: 3281717760 | E7: 36328784 | F7: 4347826176 | G7: 34298286080 | H7: 19719507968 | I7: 28843122 | J7: 8610195456 | K7: 16855590 | L7: 57443065856 | M7: 1853257088 | N7: 9467627520 | O7: 4111051776 | P7: 17309761536 | Q7: 4794139648 | R7: =SUM(D7:Q7) -> 165318464360
B8: Sustained water in dry periods (baseflow) (Cubic meter) | C8: 2022 | D8: 3103173888 | E8: 20769602 | F8: 4056365312 | G8: 30710927360 | H8: 17720352768 | I8: 37063224 | J8: 8543104000 | K8: 14871951 | L8: 58737152000 | M8: 1792466048 | N8: 9764314112 | O8: 5488828928 | P8: 19670601728 | Q8: 3495469056 | R8: =SUM(D8:Q8) -> 163155459977
B9: Water quality regulation (avoided sediment) (tons) | C9: 2013 | D9: 114559584 | E9: 1431261.8 | F9: 199458256 | G9: 2040249344 | H9: 350517984 | I9: 5817723.5 | J9: 78319856 | K9: 1526333.5 | L9: 2202098432 | M9: 57389040 | N9: 475537088 | O9: 238826272 | P9: 573947904 | Q9: 377151424 | R9: =SUM(D9:Q9) -> 6.7168305e+09
B10: Water quality regulation (avoided sediment) (tons) | C10: 2022 | D10: 108671264 | E10: 936559.44 | F10: 200330208 | G10: 2027658112 | H10: 322244032 | I10: 5880873 | J10: 73350344 | K10: 1457279 | L10: 2218972416 | M10: 62093792 | N10: 478165792 | O10: 240669648 | P10: 588853376 | Q10: 371798560 | R10: =SUM(D10:Q10) -> 6.7010823e+09
B11: Water yield (Cubic meter) | C11: 2013 | D11: 6846035456 | E11: 392167760 | F11: 11793271296 | G11: 75526516736 | H11: 31126650880 | I11: 137902250 | J11: 11964691712 | K11: 56510182 | L11: 121163919360 | M11: 3555877888 | N11: 19818129408 | O11: 22119529472 | P11: 28835768320 | Q11: 10621853696 | R11: =SUM(D11:Q11) -> 343958824416
B12: Water yield (Cubic meter) | C12: 2022 | D12: 6656413696 | E12: 426622530 | F12: 11422765824 | G12: 75850465280 | H12: 29710028800 | I12: 147340480 | J12: 11547138560 | K12: 55366895 | L12: 122990149632 | M12: 3860806272 | N12: 20064714752 | O12: 23854301696 | P12: 30567110656 | Q12: 9847319552 | R12: =SUM(D12:Q12) -> 347000544625
B13: Climate regulation: Carbon retention ( tons of carbon) | C13: 2013 | D13: 680737920 | E13: 11971667 | F13: 1062897984 | G13: 6127053824 | H13: 2185844480 | I13: 24579192 | J13: 1326648192 | K13: 10389429 | L13: 12307325952 | M13: 354623776 | N13: 1794382976 | O13: 4645522944 | P13: 2071972096 | Q13: 1441754240 | R13: =SUM(D13:Q13) -> 34045704672
B14: Climate regulation: Carbon retention ( tons of carbon) | C14: 2022 | D14: 703273408 | E14: 10063700 | F14: 1075958400 | G14: 6213792768 | H14: 2257760512 | I14: 24594352 | J14: 1310737792 | K14: 11034828 | L14: 12137361408 | M14: 332336608 | N14: 1766240256 | O14: 4769181696 | P14: 1891781760 | Q14: 1535775872 | R14: =SUM(D14:Q14) -> 34039893360
B15: Climate regulation: Carbon sequestration ( tons of carbon per year) | C15: 2013 to 2022 | D15: =(D14-D13)/9 -> 2503943.1 | E15: =(E14-E13)/9 -> -211996.33 | F15: =(F14-F13)/9 -> 1451157.3 | G15: =(G14-G13)/9 -> 9637660.4 | H15: =(H14-H13)/9 -> 7990670.2 | I15: =(I14-I13)/9 -> 1684.4444 | J15: =(J14-J13)/9 -> -1767822.2 | K15: =(K14-K13)/9 -> 71711 | ... Q15: =(Q14-Q13)/9 -> 10446848 | R15: =SUM(D15:Q15) -> -645701.33
B19: Potential supply | C19: Period | D19: Central Ethiopia | E19: Addis Ababa | F19: Afar | G19: Amhara | H19: Benishangul Gumz | I19: Dire Dawa | J19: Gambela | K19: Harari | L19: Oromia | M19: Sidama | N19: South Ethiopia | O19: Somali | P19: South West Ethiopia | Q19: Tigray | R19: National
B21: Soil protection (avoided erosion) (Million tons) | C21: 2013 | D21: =D3/1000000 -> 467.46016 | E21: =E3/1000000 -> 11.284668 | F21: =F3/1000000 -> 470.54886 | G21: =G3/1000000 -> 7906.4765 | H21: =H3/1000000 -> 1838.7021 | I21: =I3/1000000 -> 22.122812 | J21: =J3/1000000 -> 485.29357 | K21: =K3/1000000 -> 6.703134 | ... R21: =R3/1000000 -> 29686.727
B22: Soil protection (avoided erosion) (Million tons) | C22: 2022 | D22: =D4/1000000 -> 470.97037 | E22: =E4/1000000 -> 11.56592 | F22: =F4/1000000 -> 465.77306 | G22: =G4/1000000 -> 7920.6134 | H22: =H4/1000000 -> 1861.4812 | I22: =I4/1000000 -> 22.035842 | J22: =J4/1000000 -> 489.8784 | K22: =K4/1000000 -> 6.770849 | ... R22: =R4/1000000 -> 29701.361
B23: Flood mitigation (avoided quick flow) (Million cubic meter) | C23: 2013 | D23: =D5/1000000 -> 3051.8625 | E23: =E5/1000000 -> -95.213376 | F23: =F5/1000000 -> 2084.096 | G23: =G5/1000000 -> 34101.84 | H23: =H5/1000000 -> 20390.126 | I23: =I5/1000000 -> 37.676444 | J23: =J5/1000000 -> 7439.7092 | K23: =K5/1000000 -> 31.583864 | ... R23: =R5/1000000 -> 190357.66
B24: Flood mitigation (avoided quick flow) (Million cubic meter) | C24: 2022 | D24: =D6/1000000 -> 3062.9373 | E24: =E6/1000000 -> -145.22728 | F24: =F6/1000000 -> 2163.1621 | G24: =G6/1000000 -> 30190.916 | H24: =H6/1000000 -> 19808.01 | I24: =I6/1000000 -> 36.45832 | J24: =J6/1000000 -> 7790.1379 | K24: =K6/1000000 -> 30.743508 | ... R24: =R6/1000000 -> 185162.89
B25: Sustained water in dry periods (baseflow) (Million cubic meter) | C25: 2013 | D25: =D7/1000000 -> 3281.7178 | E25: =E7/1000000 -> 36.328784 | F25: =F7/1000000 -> 4347.8262 | G25: =G7/1000000 -> 34298.286 | H25: =H7/1000000 -> 19719.508 | I25: =I7/1000000 -> 28.843122 | J25: =J7/1000000 -> 8610.1955 | K25: =K7/1000000 -> 16.85559 | ... R25: =R7/1000000 -> 165318.46
B26: Sustained water in dry periods (baseflow) (Million cubic meter) | C26: 2022 | D26: =D8/1000000 -> 3103.1739 | E26: =E8/1000000 -> 20.769602 | F26: =F8/1000000 -> 4056.3653 | G26: =G8/1000000 -> 30710.927 | H26: =H8/1000000 -> 17720.353 | I26: =I8/1000000 -> 37.063224 | J26: =J8/1000000 -> 8543.104 | K26: =K8/1000000 -> 14.871951 | ... R26: =R8/1000000 -> 163155.46
B27: Water quality regulation (avoided sediment) (Million tons) | C27: 2013 | D27: =D9/1000000 -> 114.55958 | E27: =E9/1000000 -> 1.4312617 | F27: =F9/1000000 -> 199.45826 | G27: =G9/1000000 -> 2040.2493 | H27: =H9/1000000 -> 350.51798 | I27: =I9/1000000 -> 5.8177235 | J27: =J9/1000000 -> 78.319856 | K27: =K9/1000000 -> 1.5263335 | ... R27: =R9/1000000 -> 6716.8305
B28: Water quality regulation (avoided sediment) (Million tons) | C28: 2022 | D28: =D10/1000000 -> 108.67126 | E28: =E10/1000000 -> 0.93655944 | F28: =F10/1000000 -> 200.33021 | G28: =G10/1000000 -> 2027.6581 | H28: =H10/1000000 -> 322.24403 | I28: =I10/1000000 -> 5.880873 | J28: =J10/1000000 -> 73.350344 | K28: =K10/1000000 -> 1.457279 | ... R28: =R10/1000000 -> 6701.0823
B29: Water yield (Million cubic meter) | C29: 2013 | D29: =D11/1000000 -> 6846.0355 | E29: =E11/1000000 -> 392.16776 | F29: =F11/1000000 -> 11793.271 | G29: =G11/1000000 -> 75526.517 | H29: =H11/1000000 -> 31126.651 | I29: =I11/1000000 -> 137.90225 | J29: =J11/1000000 -> 11964.692 | K29: =K11/1000000 -> 56.510182 | ... R29: =R11/1000000 -> 343958.82
B30: Water yield (Million cubic meter) | C30: 2022 | D30: =D12/1000000 -> 6656.4137 | E30: =E12/1000000 -> 426.62253 | F30: =F12/1000000 -> 11422.766 | G30: =G12/1000000 -> 75850.465 | H30: =H12/1000000 -> 29710.029 | I30: =I12/1000000 -> 147.34048 | J30: =J12/1000000 -> 11547.139 | K30: =K12/1000000 -> 55.366895 | ... R30: =R12/1000000 -> 347000.54
B31: Climate regulation: Carbon retention ( Million tons of carbon) | C31: 2013 | D31: =D13/1000000 -> 680.73792 | E31: =E13/1000000 -> 11.971667 | F31: =F13/1000000 -> 1062.898 | G31: =G13/1000000 -> 6127.0538 | H31: =H13/1000000 -> 2185.8445 | I31: =I13/1000000 -> 24.579192 | J31: =J13/1000000 -> 1326.6482 | K31: =K13/1000000 -> 10.389429 | ... R31: =R13/1000000 -> 34045.705
B32: Climate regulation: Carbon retention ( Million tons of carbon) | C32: 2022 | D32: =D14/1000000 -> 703.27341 | E32: =E14/1000000 -> 10.0637 | F32: =F14/1000000 -> 1075.9584 | G32: =G14/1000000 -> 6213.7928 | H32: =H14/1000000 -> 2257.7605 | I32: =I14/1000000 -> 24.594352 | J32: =J14/1000000 -> 1310.7378 | K32: =K14/1000000 -> 11.034828 | ... R32: =R14/1000000 -> 34039.893
B33: Climate regulation: Carbon sequestration ( Million tons of carbon per year) | C33: 2013 to 2022 | D33: =D15/1000000 -> 2.5039431 | E33: =E15/1000000 -> -0.21199633 | F33: =F15/1000000 -> 1.4511573 | G33: =G15/1000000 -> 9.6376604 | H33: =H15/1000000 -> 7.9906702 | I33: =I15/1000000 -> 0.0016844444 | J33: =J15/1000000 -> -1.7678222 | K33: =K15/1000000 -> 0.071711 | ... R33: =R15/1000000 -> -0.64570133
B37: =B21 -> Soil protection (avoided erosion) (Million tons) | D37: =(D22-D21)/D21 -> 0.0075091062 | E37: =(E22-E21)/E21 -> 0.024923374 | F37: =(F22-F21)/F21 -> -0.010149441 | G37: =(G22-G21)/G21 -> 0.0017880066 | H37: =(H22-H21)/H21 -> 0.012388704 | I37: =(I22-I21)/I21 -> -0.0039312362 | J37: =(J22-J21)/J21 -> 0.0094475433 | K37: =(K22-K21)/K21 -> 0.010101991 | ... R37: =(R22-R21)/R21 -> 0.00049292375
B38: =B23 -> Flood mitigation (avoided quick flow) (Million cubic meter) | D38: =(D24-D23)/D23 -> 0.0036288712 | E38: =(E24-E23)/E23 -> 0.52528233 | F38: =(F24-F23)/F23 -> 0.037937845 | G38: =(G24-G23)/G23 -> -0.11468367 | H38: =(H24-H23)/H23 -> -0.028548884 | I38: =(I24-I23)/I23 -> -0.032331183 | J38: =(J24-J23)/J23 -> 0.047102469 | K38: =(K24-K23)/K23 -> -0.026607131 | ... R38: =(R24-R23)/R23 -> -0.027289535
B39: =B25 -> Sustained water in dry periods (baseflow) (Million cubic meter) | D39: =(D26-D25)/D25 -> -0.054405615 | E39: =(E26-E25)/E25 -> -0.42828799 | F39: =(F26-F25)/F25 -> -0.067035997 | G39: =(G26-G25)/G25 -> -0.10459294 | H39: =(H26-H25)/H25 -> -0.10137957 | I39: =(I26-I25)/I25 -> 0.28499349 | J39: =(J26-J25)/J25 -> -0.0077920944 | K39: =(K26-K25)/K25 -> -0.11768434 | ... R39: =(R26-R25)/R25 -> -0.013083864
B40: =B27 -> Water quality regulation (avoided sediment) (Million tons) | D40: =(D28-D27)/D27 -> -0.051399628 | E40: =(E28-E27)/E27 -> -0.3456407 | F40: =(F28-F27)/F27 -> 0.0043716014 | G40: =(G28-G27)/G27 -> -0.0061714182 | H40: =(H28-H27)/H27 -> -0.080663342 | I40: =(I28-I27)/I27 -> 0.010854675 | J40: =(J28-J27)/J27 -> -0.063451496 | K40: =(K28-K27)/K27 -> -0.045242078 | ... R40: =(R28-R27)/R27 -> -0.002344595
B41: =B29 -> Water yield (Million cubic meter) | D41: =(D30-D29)/D29 -> -0.027698039 | E41: =(E30-E29)/E29 -> 0.087857222 | F41: =(F30-F29)/F29 -> -0.031416684 | G41: =(G30-G29)/G29 -> 0.0042892028 | H41: =(H30-H29)/H29 -> -0.045511548 | I41: =(I30-I29)/I29 -> 0.06844145 | J41: =(J30-J29)/J29 -> -0.034898781 | K41: =(K30-K29)/K29 -> -0.020231522 | ... R41: =(R30-R29)/R29 -> 0.0088432684
B42: =B31 -> Climate regulation: Carbon retention ( Million tons of carbon) | D42: =(D32-D31)/D31 -> 0.033104499 | E42: =(E32-E31)/E31 -> -0.15937354 | F42: =(F32-F31)/F31 -> 0.012287554 | G42: =(G32-G31)/G31 -> 0.014156713 | H42: =(H32-H31)/H31 -> 0.0329008 | I42: =(I32-I31)/I31 -> 0.00061678187 | J42: =(J32-J31)/J31 -> -0.011992931 | K42: =(K32-K31)/K31 -> 0.062120738 | ... R42: =(R32-R31)/R31 -> -0.00017069149
E53: 2013 | F53: Economy | K53: Regions
F54: Agriculture | G54: Other industres | H54: Government | I54: Households | J54: ROW | K54: =D2 -> Central Ethiopia | L54: =E2 -> Addis Ababa | M54: =F2 -> Afar | N54: =G2 -> Amhara | O54: =H2 -> Benishangul Gumz | P54: =I2 -> Dire Dawa | Q54: =J2 -> Gambela | R54: =K2 -> Harari | ... Y54: =R2 -> National
E55: POTENTIAL SUPPLY
E56: =B37 -> Soil protection (avoided erosion) (Million tons) | K56: =D21 -> 467.46016 | L56: =E21 -> 11.284668 | M56: =F21 -> 470.54886 | N56: =G21 -> 7906.4765 | O56: =H21 -> 1838.7021 | P56: =I21 -> 22.122812 | Q56: =J21 -> 485.29357 | R56: =K21 -> 6.703134 | ... Y56: =R21 -> 29686.727
E57: =B38 -> Flood mitigation (avoided quick flow) (Million cubic meter) | K57: =D23 -> 3051.8625 | L57: =E23 -> -95.213376 | M57: =F23 -> 2084.096 | N57: =G23 -> 34101.84 | O57: =H23 -> 20390.126 | P57: =I23 -> 37.676444 | Q57: =J23 -> 7439.7092 | R57: =K23 -> 31.583864 | ... X57: =Q23 -> 5267.4212 | Y57: =R22 -> 29701.361
E58: =B39 -> Sustained water in dry periods (baseflow) (Million cubic meter) | K58: =D25 -> 3281.7178 | L58: =E25 -> 36.328784 | M58: =F25 -> 4347.8262 | N58: =G25 -> 34298.286 | O58: =H25 -> 19719.508 | P58: =I25 -> 28.843122 | Q58: =J25 -> 8610.1955 | R58: =K25 -> 16.85559 | ... X58: =Q25 -> 4794.1396 | Y58: =R23 -> 190357.66
...

Sheet CarbAsset_byRegions
B2: Regions | C2: Period | D2: Central Ethiopia | E2: Addis Ababa | F2: Afar | G2: Amhara | H2: Benishangul Gumz | I2: Dire Dawa | J2: Gambela | K2: Harari | L2: Oromia | M2: Sidama | N2: South Ethiopia | O2: Somali | P2: South West Ethiopia | Q2: Tigray | R2: National
B4: Climate regulation: Carbon retention ( tons of carbon) | C4: 2013 | D4: 680737920 | E4: 11971667 | F4: 1062897984 | G4: 6127053824 | H4: 2185844480 | I4: 24579192 | J4: 1326648192 | K4: 10389429 | L4: 12307325952 | M4: 354623776 | N4: 1794382976 | O4: 4645522944 | P4: 2071972096 | Q4: 1441754240 | R4: =SUM(D4:Q4) -> 34045704672
B5: Climate regulation: Carbon retention ( tons of carbon) | C5: 2022 | D5: 703273408 | E5: 10063700 | F5: 1075958400 | G5: 6213792768 | H5: 2257760512 | I5: 24594352 | J5: 1310737792 | K5: 11034828 | L5: 12137361408 | M5: 332336608 | N5: 1766240256 | O5: 4769181696 | P5: 1891781760 | Q5: 1535775872 | R5: =SUM(D5:Q5) -> 34039893360
C9: Period | D9: Central Ethiopia | E9: Addis Ababa | F9: Afar | G9: Amhara | H9: Benishangul Gumz | I9: Dire Dawa | J9: Gambela | K9: Harari | L9: Oromia | M9: Sidama | N9: South Ethiopia | O9: Somali | P9: South West Ethiopia | Q9: Tigray | R9: National
B11: Climate regulation: Carbon retention ( Million tons of carbon) | C11: 2013 | D11: =D4/1000000 -> 680.73792 | E11: =E4/1000000 -> 11.971667 | F11: =F4/1000000 -> 1062.898 | G11: =G4/1000000 -> 6127.0538 | H11: =H4/1000000 -> 2185.8445 | I11: =I4/1000000 -> 24.579192 | J11: =J4/1000000 -> 1326.6482 | K11: =K4/1000000 -> 10.389429 | ... R11: =R4/1000000 -> 34045.705
B12: Climate regulation: Carbon retention ( Million tons of carbon) | C12: 2022 | D12: =D5/1000000 -> 703.27341 | E12: =E5/1000000 -> 10.0637 | F12: =F5/1000000 -> 1075.9584 | G12: =G5/1000000 -> 6213.7928 | H12: =H5/1000000 -> 2257.7605 | I12: =I5/1000000 -> 24.594352 | J12: =J5/1000000 -> 1310.7378 | K12: =K5/1000000 -> 11.034828 | ... R12: =R5/1000000 -> 34039.893
B13: =B11 -> Climate regulation: Carbon retention ( Million tons of carbon) | D13: =(D12-D11)/D11 -> 0.033104499 | E13: =(E12-E11)/E11 -> -0.15937354 | F13: =(F12-F11)/F11 -> 0.012287554 | G13: =(G12-G11)/G11 -> 0.014156713 | H13: =(H12-H11)/H11 -> 0.0329008 | I13: =(I12-I11)/I11 -> 0.00061678187 | J13: =(J12-J11)/J11 -> -0.011992931 | K13: =(K12-K11)/K11 -> 0.062120738 | ... R13: =(R12-R11)/R11 -> -0.00017069149

Sheet CarbAsset_byBasin
B2: Period | C2: Abbay | D2: Awash & north | E2: Baro Akobo | F2: Denakil & Ayisha | G2: Genale Dawa | H2: Ogaden | I2: Omo Gibe | J2: Rift Valley | K2: Tekeze & Mereb Gash | L2: Wabi Shebele | M2: National
A4: Carbon Asset (stock)( tons of carbon) | B4: 2013 | C4: 8699236352 | D4: 2473657344 | E4: 3693455360 | F4: 772051328 | G4: 4456863744 | H4: 1285530496 | I4: 3583552768 | J4: 2108742656 | K4: 2917859072 | L4: 4054808064 | M4: =SUBTOTAL(9,C4:L4) -> 34045757184
A5: Carbon Asset (stock)( tons of carbon) | B5: 2022 | C5: 8791343104 | D5: 2504052992 | E5: 3617610752 | F5: 763242432 | G5: 4515055616 | H5: 1337093504 | I5: 3459295232 | J5: 2051774208 | K5: 3043002624 | L5: 3957607168 | M5: =SUBTOTAL(9,C5:L5) -> 34040077632
A9: River basin (Watershed) | B9: Period | C9: Abbay | D9: Awash & north | E9: Baro Akobo | F9: Denakil & Ayisha | G9: Genale Dawa | H9: Ogaden | I9: Omo Gibe | J9: Rift Valley | K9: Tekeze & Mereb Gash | L9: Wabi Shebele | M9: National
A10: Carbon Asset (stock) ( Million tons of carbon) | B10: 2013 | C10: =C4/1000000 -> 8699.2364 | D10: =D4/1000000 -> 2473.6573 | E10: =E4/1000000 -> 3693.4554 | F10: =F4/1000000 -> 772.05133 | G10: =G4/1000000 -> 4456.8637 | H10: =H4/1000000 -> 1285.5305 | I10: =I4/1000000 -> 3583.5528 | J10: =J4/1000000 -> 2108.7427 | ... M10: =M4/1000000 -> 34045.757
A11: Carbon Asset (stock) ( Million tons of carbon) | B11: 2022 | C11: =C5/1000000 -> 8791.3431 | D11: =D5/1000000 -> 2504.053 | E11: =E5/1000000 -> 3617.6108 | F11: =F5/1000000 -> 763.24243 | G11: =G5/1000000 -> 4515.0556 | H11: =H5/1000000 -> 1337.0935 | I11: =I5/1000000 -> 3459.2952 | J11: =J5/1000000 -> 2051.7742 | ... M11: =M5/1000000 -> 34040.078

Sheet CarbonAsset_Stock
F2: Table: Carbon stock account for Terrestrial Ecosystems (2013–2022)(Tonnes of C)
F3: Accounting Item | G3: Ecosystem type
G4: Moderate forest | H4: Perennial crop | I4: Annual crop | J4: Open grass land | K4: Closed grass land | L4: Dense forest | M4: Sparse forest | N4: Wet land | O4: Built up area | P4: Open shrub land | Q4: Closed shrub land | R4: Water body | S4: Bare land | T4: National (Accounting area)
F5: Opening Stock (2013) (Tonnes of carbon) | G5: =MainDatabase!D78 -> 2973051860 | H5: =MainDatabase!E78 -> 1.8170202e+08 | I5: =MainDatabase!F78 -> 9015407730 | J5: =MainDatabase!G78 -> 820160267 | K5: =MainDatabase!H78 -> 5.8762193e+08 | L5: =MainDatabase!I78 -> 6567804910 | M5: =MainDatabase!J78 -> 894072235 | N5: =MainDatabase!K78 -> 2.3264971e+08 | ... S5: =MainDatabase!P78 -> 7.1388965e+08 | T5: =SUM(G5:S5) -> 3.4045842e+10
F6: Additions to Stock (Tonnes of carbon) | G6: =MainDatabase!D79 -> 429956380 | H6: =MainDatabase!E79 -> 188727.45 | I6: =MainDatabase!F79 -> 236970300 | J6: =MainDatabase!G79 -> 5304209.5 | K6: =MainDatabase!H79 -> 3664567.5 | L6: =MainDatabase!I79 -> 740757250 | M6: =MainDatabase!J79 -> 98667704 | N6: =MainDatabase!K79 -> 13380874 | ... S6: =MainDatabase!P79 -> 3572726.5 | T6: =SUM(G6:S6) -> 2.4178862e+09
F7: Reductions in Stock (Tonnes of carbon) | G7: =MainDatabase!D80 -> 59066764 | H7: =MainDatabase!E80 -> 10507495 | I7: =MainDatabase!F80 -> 311527230 | J7: =MainDatabase!G80 -> 369414560 | K7: =MainDatabase!H80 -> 355960600 | L7: =MainDatabase!I80 -> 316958 | M7: =MainDatabase!J80 -> 52676684 | N7: =MainDatabase!K80 -> 307 | ... S7: =MainDatabase!P80 -> 237305600 | T7: =SUM(G7:S7) -> 2407452611
F8: Closing Stock (2022) (Tonnes of carbon) | G8: =MainDatabase!D81 -> 3815098410 | H8: =MainDatabase!E81 -> 273515930 | I8: =MainDatabase!F81 -> 10513814500 | J8: =MainDatabase!G81 -> 7.2941917e+08 | K8: =MainDatabase!H81 -> 7.5080396e+08 | L8: =MainDatabase!I81 -> 6731980420 | M8: =MainDatabase!J81 -> 584725088 | N8: =MainDatabase!K81 -> 2.3137407e+08 | ... S8: =MainDatabase!P81 -> 7.542443e+08 | T8: =SUM(G8:S8) -> 3.4040034e+10
F9: Net change (based on Stocks) (Tonnes of carbon) | G9: =G8-G5 -> 842046550 | H9: =H8-H5 -> 91813912 | I9: =I8-I5 -> 1498406770 | J9: =J8-J5 -> -90741098 | K9: =K8-K5 -> 163182028 | L9: =L8-L5 -> 164175510 | M9: =M8-M5 -> -309347147 | N9: =N8-N5 -> -1275645.9 | ... S9: =S8-S5 -> 40354654 | T9: =SUM(G9:S9) -> -5808376
F11: Net change (based on redutions and additions) (Tonnes of carbon) | G11: =G8-G5 -> 842046550 | H11: =H8-H5 -> 91813912 | I11: =I8-I5 -> 1498406770 | J11: =J8-J5 -> -90741098 | K11: =K8-K5 -> 163182028 | L11: =L8-L5 -> 164175510 | M11: =M8-M5 -> -309347147 | N11: =N8-N5 -> -1275645.9 | ... T11: =T8-T5 -> -5808376
F17: Accounting Item (carbon million tonnes) | G17: Ecosystem type
G18: Moderate forest | H18: Perennial crop | I18: Annual crop | J18: Open grass land | K18: Closed grass land | L18: Dense forest | M18: Sparse forest | N18: Wet land | O18: Built up area | P18: Open shrub land | Q18: Closed shrub land | R18: Water body | S18: Bare land | T18: National (Accounting area)
F19: Opening Stock (2013) | G19: =G5/1000000 -> 2973.0519 | H19: =H5/1000000 -> 181.70202 | I19: =I5/1000000 -> 9015.4077 | J19: =J5/1000000 -> 820.16027 | K19: =K5/1000000 -> 587.62193 | L19: =L5/1000000 -> 6567.8049 | M19: =M5/1000000 -> 894.07223 | N19: =N5/1000000 -> 232.64971 | ... T19: =T5/1000000 -> 34045.842
F20: Additions to Stock | G20: =G6/1000000 -> 429.95638 | H20: =H6/1000000 -> 0.18872745 | I20: =I6/1000000 -> 236.9703 | J20: =J6/1000000 -> 5.3042095 | K20: =K6/1000000 -> 3.6645675 | L20: =L6/1000000 -> 740.75725 | M20: =M6/1000000 -> 98.667704 | N20: =N6/1000000 -> 13.380874 | ... T20: =T6/1000000 -> 2417.8862
F21: Reductions in Stock | G21: =G7/1000000 -> 59.066764 | H21: =H7/1000000 -> 10.507495 | I21: =I7/1000000 -> 311.52723 | J21: =J7/1000000 -> 369.41456 | K21: =K7/1000000 -> 355.9606 | L21: =L7/1000000 -> 0.316958 | M21: =M7/1000000 -> 52.676684 | N21: =N7/1000000 -> 0.000307 | ... T21: =T7/1000000 -> 2407.4526
F22: Closing Stock (2022) | G22: =G8/1000000 -> 3815.0984 | H22: =H8/1000000 -> 273.51593 | I22: =I8/1000000 -> 10513.815 | J22: =J8/1000000 -> 729.41917 | K22: =K8/1000000 -> 750.80396 | L22: =L8/1000000 -> 6731.9804 | M22: =M8/1000000 -> 584.72509 | N22: =N8/1000000 -> 231.37407 | ... T22: =T8/1000000 -> 34040.034
F23: Net change (based on Stocks) (Tonnes of carbon) | G23: =G22-G19 -> 842.04655 | H23: =H22-H19 -> 91.813912 | I23: =I22-I19 -> 1498.4068 | J23: =J22-J19 -> -90.741098 | K23: =K22-K19 -> 163.18203 | L23: =L22-L19 -> 164.17551 | M23: =M22-M19 -> -309.34715 | N23: =N22-N19 -> -1.2756459 | ... S23: =S22-S19 -> 40.354654 | T23: =SUM(G23:S23) -> -5.808376

Sheet Sheet1

Sheet MainDatabase
C3: Table1. Carbon asset (stock) in Ethiopia, 2013 and 2022, in Tons
F4: 2013 | M4: 2022
C5: Raster name | D5: Ecosystem extent | F5: c_above_2013TonOfC | G5: c_below_2013TonOfC | H5: c_dead_2013TonOfC | I5: c_soil_2013TonOfC | L5: c_storage_2013TonOfC | M5: c_above_2022TonOfC | N5: c_below_2022TonOfC | O5: c_dead_2022TonOfC | P5: c_soil_2022TonOfC | S5: c_storage_2022TonOfC | V5: Carbon stock flow
C6: Ecosystem type | D6: 2013 Ha | E6: 2022 Ha | F6: Above ground carbon (AGC) | G6: Belowground Biomass Carbon (BGC) | H6: Dead Organic Matter (DOM) | I6: Soil Organic Carbon (SOC) | J6: Non Soil carbon | K6: Soil carbon | L6: Total carbon | M6: AGC(Above ground carbon) | N6: Belowground Biomass Carbon (BGC) | O6: Dead Organic Matter (DOM) | P6: Soil Organic Carbon (SOC) | Q6: Non Soil carbon | R6: Soil carbon | S6: Total carbon | T6: Open stock 2013 | U6: Closing stock 2022 | V6: Reduction (Tons) | W6: Additional (Tons) | X6: Ecosystem type | Y6: 2013 Ha | Z6: 2022 Ha | AA6: Carbon sequestration
