Workbook
Name DBDef1: #REF!
Name DBDef2: #REF!
Name DBDef2a: #REF!
Name DBDef3: #REF!
Name DBLinks: #REF!
Name dbsourcefiles: #REF!
Name FinalUse: #REF!
Name Input_A: #REF!
Name Output: #REF!
Name Prod_acc: #REF!
Name Supply: #REF!
Name TabDef1: #REF!
Name TabDef2: #REF!
Name TabDef3: #REF!
Name TabDef4: #REF!

Sheet RiftValley_Subbasin_Monthly
A1: system:index | B1: Year | C1: Month | D1: Subbasin_ID | E1: area_m2 | F1: mean_rf_mm | G1: .geo
A2: 0 | B2: 2018 | C2: 1 | D2: 2CC | E2: 1.1471729e+10 | F2: 1.6203466 | G2: {"type":"MultiPoint","coordinates":[]} | J2: Year | K2: Year | L2: Year | M2: Year | N2: Year | O2: Year | P2: Year
A3: 1 | B3: 2018 | C3: 1 | D3: 2BC | E3: 3.6876892e+09 | F3: 3.2524273 | G3: {"type":"MultiPoint","coordinates":[]} | I3: Month | J3: 2018 | K3: 2019 | L3: 2020 | M3: 2021 | N3: 2022 | O3: 2023 | P3: 2024
A4: 2 | B4: 2018 | C4: 1 | D4: 2BA | E4: 1.328346e+09 | F4: 7.4607196 | G4: {"type":"MultiPoint","coordinates":[]} | I4: 1 | J4: =AVERAGEIFS($F:$F,$B:$B,J$3,$C:$C,$I4) -> 21.859691 | K4: =AVERAGEIFS($F:$F,$B:$B,K$3,$C:$C,$I4) -> 14.297515 | L4: =AVERAGEIFS($F:$F,$B:$B,L$3,$C:$C,$I4) -> 59.2462 | M4: =AVERAGEIFS($F:$F,$B:$B,M$3,$C:$C,$I4) -> 38.606003 | N4: =AVERAGEIFS($F:$F,$B:$B,N$3,$C:$C,$I4) -> 32.898476 | O4: =AVERAGEIFS($F:$F,$B:$B,O$3,$C:$C,$I4) -> 11.768009 | P4: =AVERAGEIFS($F:$F,$B:$B,P$3,$C:$C,$I4) -> 80.549755
A5: 3 | B5: 2018 | C5: 1 | D5: 2CB | E5: 2.3869168e+09 | F5: 11.624084 | G5: {"type":"MultiPoint","coordinates":[]} | I5: 2 | J5: =AVERAGEIFS($F:$F,$B:$B,J$3,$C:$C,$I5) -> 16.669364 | K5: =AVERAGEIFS($F:$F,$B:$B,K$3,$C:$C,$I5) -> 12.940036 | L5: =AVERAGEIFS($F:$F,$B:$B,L$3,$C:$C,$I5) -> 36.766511 | M5: =AVERAGEIFS($F:$F,$B:$B,M$3,$C:$C,$I5) -> 36.270469 | N5: =AVERAGEIFS($F:$F,$B:$B,N$3,$C:$C,$I5) -> 45.422258 | O5: =AVERAGEIFS($F:$F,$B:$B,O$3,$C:$C,$I5) -> 4.543465 | P5: =AVERAGEIFS($F:$F,$B:$B,P$3,$C:$C,$I5) -> 43.802893
A6: 4 | B6: 2018 | C6: 1 | D6: 2EG2 | E6: 1.2676252e+09 | F6: 9.3202006 | G6: {"type":"MultiPoint","coordinates":[]} | I6: 3 | J6: =AVERAGEIFS($F:$F,$B:$B,J$3,$C:$C,$I6) -> 167.5725 | K6: =AVERAGEIFS($F:$F,$B:$B,K$3,$C:$C,$I6) -> 30.085817 | L6: =AVERAGEIFS($F:$F,$B:$B,L$3,$C:$C,$I6) -> 160.17506 | M6: =AVERAGEIFS($F:$F,$B:$B,M$3,$C:$C,$I6) -> 36.605287 | N6: =AVERAGEIFS($F:$F,$B:$B,N$3,$C:$C,$I6) -> 36.561251 | O6: =AVERAGEIFS($F:$F,$B:$B,O$3,$C:$C,$I6) -> 104.57488 | P6: =AVERAGEIFS($F:$F,$B:$B,P$3,$C:$C,$I6) -> 61.563138
A7: 5 | B7: 2018 | C7: 1 | D7: 2EF | E7: 3.9105834e+08 | F7: 10.287612 | G7: {"type":"MultiPoint","coordinates":[]} | I7: 4 | J7: =AVERAGEIFS($F:$F,$B:$B,J$3,$C:$C,$I7) -> 303.32268 | K7: =AVERAGEIFS($F:$F,$B:$B,K$3,$C:$C,$I7) -> 102.34294 | L7: =AVERAGEIFS($F:$F,$B:$B,L$3,$C:$C,$I7) -> 236.71626 | M7: =AVERAGEIFS($F:$F,$B:$B,M$3,$C:$C,$I7) -> 91.500688 | N7: =AVERAGEIFS($F:$F,$B:$B,N$3,$C:$C,$I7) -> 113.69134 | O7: =AVERAGEIFS($F:$F,$B:$B,O$3,$C:$C,$I7) -> 157.56115 | P7: =AVERAGEIFS($F:$F,$B:$B,P$3,$C:$C,$I7) -> 261.75326
A8: 6 | B8: 2018 | C8: 1 | D8: 2ED | E8: 4.2208576e+08 | F8: 16.599725 | G8: {"type":"MultiPoint","coordinates":[]} | I8: 5 | J8: =AVERAGEIFS($F:$F,$B:$B,J$3,$C:$C,$I8) -> 221.24155 | K8: =AVERAGEIFS($F:$F,$B:$B,K$3,$C:$C,$I8) -> 64.771971 | L8: =AVERAGEIFS($F:$F,$B:$B,L$3,$C:$C,$I8) -> 115.52796 | M8: =AVERAGEIFS($F:$F,$B:$B,M$3,$C:$C,$I8) -> 173.16863 | N8: =AVERAGEIFS($F:$F,$B:$B,N$3,$C:$C,$I8) -> 84.4881 | O8: =AVERAGEIFS($F:$F,$B:$B,O$3,$C:$C,$I8) -> 78.324768 | P8: =AVERAGEIFS($F:$F,$B:$B,P$3,$C:$C,$I8) -> 202.12392
A9: 7 | B9: 2018 | C9: 1 | D9: 2EG1 | E9: 3.9769475e+08 | F9: 15.01732 | G9: {"type":"MultiPoint","coordinates":[]} | I9: 6 | J9: =AVERAGEIFS($F:$F,$B:$B,J$3,$C:$C,$I9) -> 161.528 | K9: =AVERAGEIFS($F:$F,$B:$B,K$3,$C:$C,$I9) -> 114.81653 | L9: =AVERAGEIFS($F:$F,$B:$B,L$3,$C:$C,$I9) -> 111.67158 | M9: =AVERAGEIFS($F:$F,$B:$B,M$3,$C:$C,$I9) -> 41.652293 | N9: =AVERAGEIFS($F:$F,$B:$B,N$3,$C:$C,$I9) -> 41.668222 | O9: =AVERAGEIFS($F:$F,$B:$B,O$3,$C:$C,$I9) -> 58.351639 | P9: =AVERAGEIFS($F:$F,$B:$B,P$3,$C:$C,$I9) -> 39.050899
A10: 8 | B10: 2018 | C10: 1 | D10: 2FC | E10: 1.5173549e+09 | F10: 28.544382 | G10: {"type":"MultiPoint","coordinates":[]} | I10: 7 | J10: =AVERAGEIFS($F:$F,$B:$B,J$3,$C:$C,$I10) -> 69.252752 | K10: =AVERAGEIFS($F:$F,$B:$B,K$3,$C:$C,$I10) -> 94.007435 | L10: =AVERAGEIFS($F:$F,$B:$B,L$3,$C:$C,$I10) -> 117.02844 | M10: =AVERAGEIFS($F:$F,$B:$B,M$3,$C:$C,$I10) -> 75.470816 | N10: =AVERAGEIFS($F:$F,$B:$B,N$3,$C:$C,$I10) -> 45.556247 | O10: =AVERAGEIFS($F:$F,$B:$B,O$3,$C:$C,$I10) -> 41.874304 | P10: =AVERAGEIFS($F:$F,$B:$B,P$3,$C:$C,$I10) -> 112.60966
A11: 9 | B11: 2018 | C11: 1 | D11: 2KA | E11: 5.1064914e+09 | F11: 72.205398 | G11: {"type":"MultiPoint","coordinates":[]} | I11: 8 | J11: =AVERAGEIFS($F:$F,$B:$B,J$3,$C:$C,$I11) -> 71.941013 | K11: =AVERAGEIFS($F:$F,$B:$B,K$3,$C:$C,$I11) -> 100.89376 | L11: =AVERAGEIFS($F:$F,$B:$B,L$3,$C:$C,$I11) -> 121.83942 | M11: =AVERAGEIFS($F:$F,$B:$B,M$3,$C:$C,$I11) -> 67.770147 | N11: =AVERAGEIFS($F:$F,$B:$B,N$3,$C:$C,$I11) -> 94.632327 | O11: =AVERAGEIFS($F:$F,$B:$B,O$3,$C:$C,$I11) -> 41.244459 | P11: =AVERAGEIFS($F:$F,$B:$B,P$3,$C:$C,$I11) -> 86.816223
A12: 10 | B12: 2018 | C12: 1 | D12: 2KB | E12: 1.6403244e+09 | F12: 66.117834 | G12: {"type":"MultiPoint","coordinates":[]} | I12: 9 | J12: =AVERAGEIFS($F:$F,$B:$B,J$3,$C:$C,$I12) -> 31.04461 | K12: =AVERAGEIFS($F:$F,$B:$B,K$3,$C:$C,$I12) -> 58.267881 | L12: =AVERAGEIFS($F:$F,$B:$B,L$3,$C:$C,$I12) -> 70.812841 | M12: =AVERAGEIFS($F:$F,$B:$B,M$3,$C:$C,$I12) -> 73.475875 | N12: =AVERAGEIFS($F:$F,$B:$B,N$3,$C:$C,$I12) -> 71.742297 | O12: =AVERAGEIFS($F:$F,$B:$B,O$3,$C:$C,$I12) -> 73.582851 | P12: =AVERAGEIFS($F:$F,$B:$B,P$3,$C:$C,$I12) -> 40.103428
A13: 11 | B13: 2018 | C13: 1 | D13: 2KC | E13: 1.9961974e+09 | F13: 102.11902 | G13: {"type":"MultiPoint","coordinates":[]} | I13: 10 | J13: =AVERAGEIFS($F:$F,$B:$B,J$3,$C:$C,$I13) -> 50.474487 | K13: =AVERAGEIFS($F:$F,$B:$B,K$3,$C:$C,$I13) -> 135.92471 | L13: =AVERAGEIFS($F:$F,$B:$B,L$3,$C:$C,$I13) -> 98.162708 | M13: =AVERAGEIFS($F:$F,$B:$B,M$3,$C:$C,$I13) -> 62.81794 | N13: =AVERAGEIFS($F:$F,$B:$B,N$3,$C:$C,$I13) -> 47.307848 | O13: =AVERAGEIFS($F:$F,$B:$B,O$3,$C:$C,$I13) -> 88.415097 | P13: =AVERAGEIFS($F:$F,$B:$B,P$3,$C:$C,$I13) -> 74.185622
A14: 12 | B14: 2018 | C14: 1 | D14: 2EC | E14: 8.2788451e+08 | F14: 11.242805 | G14: {"type":"MultiPoint","coordinates":[]} | I14: 11 | J14: =AVERAGEIFS($F:$F,$B:$B,J$3,$C:$C,$I14) -> 39.575555 | K14: =AVERAGEIFS($F:$F,$B:$B,K$3,$C:$C,$I14) -> 122.84125 | L14: =AVERAGEIFS($F:$F,$B:$B,L$3,$C:$C,$I14) -> 99.608536 | M14: =AVERAGEIFS($F:$F,$B:$B,M$3,$C:$C,$I14) -> 36.742754 | N14: =AVERAGEIFS($F:$F,$B:$B,N$3,$C:$C,$I14) -> 107.31512 | O14: =AVERAGEIFS($F:$F,$B:$B,O$3,$C:$C,$I14) -> 132.92189 | P14: =AVERAGEIFS($F:$F,$B:$B,P$3,$C:$C,$I14) -> 127.3144
A15: 13 | B15: 2018 | C15: 1 | D15: 2J | E15: 2.7925067e+10 | F15: 0.075005581 | G15: {"type":"MultiPoint","coordinates":[]} | I15: 12 | J15: =AVERAGEIFS($F:$F,$B:$B,J$3,$C:$C,$I15) -> 76.954583 | K15: =AVERAGEIFS($F:$F,$B:$B,K$3,$C:$C,$I15) -> 134.42385 | L15: =AVERAGEIFS($F:$F,$B:$B,L$3,$C:$C,$I15) -> 25.103619 | M15: =AVERAGEIFS($F:$F,$B:$B,M$3,$C:$C,$I15) -> 35.858952 | N15: =AVERAGEIFS($F:$F,$B:$B,N$3,$C:$C,$I15) -> 41.007349 | O15: =AVERAGEIFS($F:$F,$B:$B,O$3,$C:$C,$I15) -> 30.266499 | P15: =AVERAGEIFS($F:$F,$B:$B,P$3,$C:$C,$I15) -> 28.65843
A16: 14 | B16: 2018 | C16: 1 | D16: 2AB | E16: 9.9916307e+09 | F16: 0.0056829504 | G16: {"type":"MultiPoint","coordinates":[]}
A17: 15 | B17: 2018 | C17: 1 | E17: 7.2926614e+09 | F17: 2.8131334 | G17: {"type":"MultiPoint","coordinates":[]} | I17: TotalAnnual Rf from Monthly Avg | J17: =SUM(J4:J15) -> 1231.4368 | K17: =SUM(K4:K15) -> 985.61369 | L17: =SUM(L4:L15) -> 1252.6591 | M17: =SUM(M4:M15) -> 769.93985 | N17: =SUM(N4:N15) -> 762.29084 | O17: =SUM(O4:O15) -> 823.42901 | P17: =SUM(P4:P15) -> 1158.5316
A18: 16 | B18: 2018 | C18: 1 | D18: 2BD | E18: 1.325639e+10 | F18: 0.081960801 | G18: {"type":"MultiPoint","coordinates":[]}
A19: 17 | B19: 2018 | C19: 1 | D19: 2CA | E19: 3.5811966e+09 | F19: 0.6972395 | G19: {"type":"MultiPoint","coordinates":[]} | I19: Lake Area | J19: ='Lakes Area'!$D$7/1000000 -> 7854.5441 | K19: ='Lakes Area'!$D$7/1000000 -> 7854.5441 | L19: ='Lakes Area'!$D$7/1000000 -> 7854.5441 | M19: ='Lakes Area'!$D$7/1000000 -> 7854.5441 | N19: ='Lakes Area'!$D$7/1000000 -> 7854.5441 | O19: ='Lakes Area'!$D$7/1000000 -> 7854.5441 | P19: ='Lakes Area'!$D$7/1000000 -> 7854.5441
A20: 18 | B20: 2018 | C20: 1 | E20: 37247153 | F20: 6.6883787 | G20: {"type":"MultiPoint","coordinates":[]} | I20: Basin_Area_sqkm | J20: 131423 | K20: 131423 | L20: 131423 | M20: 131423 | N20: 131423 | O20: 131423 | P20: 131423
A21: 19 | B21: 2018 | C21: 1 | E21: 25322285 | F21: 0 | G21: {"type":"MultiPoint","coordinates":[]} | I21: proportion(WB/BA)
A22: 20 | B22: 2018 | C22: 1 | D22: 2BB | E22: 2.0410183e+09 | F22: 2.6888181 | G22: {"type":"MultiPoint","coordinates":[]} | I22: TotalRf_mm | J22: =J17 -> 1231.4368 | K22: =K17 -> 985.61369 | L22: =L17 -> 1252.6591 | M22: =M17 -> 769.93985 | N22: =N17 -> 762.29084 | O22: =O17 -> 823.42901 | P22: =P17 -> 1158.5316
A23: 21 | B23: 2018 | C23: 1 | D23: 2EH | E23: 6.0593036e+08 | F23: 10.995113 | G23: {"type":"MultiPoint","coordinates":[]} | I23: Rainfall_MCM_on_Lake | J23: =(J22*100*J19*10)/1000000 -> 9672.3746 | K23: =(K22*100*K19*10)/1000000 -> 7741.5463 | L23: =(L22*100*L19*10)/1000000 -> 9839.0665 | M23: =(M22*100*M19*10)/1000000 -> 6047.5266 | N23: =(N22*100*N19*10)/1000000 -> 5987.447 | O23: =(O22*100*O19*10)/1000000 -> 6467.6595 | P23: =(P22*100*P19*10)/1000000 -> 9099.7378
A24: 22 | B24: 2018 | C24: 1 | E24: 1.3103515e+08 | F24: 8.788273 | G24: {"type":"MultiPoint","coordinates":[]} | I24: BASIN_MAR
A25: 23 | B25: 2018 | C25: 1 | D25: 2EE | E25: 6.1143635e+08 | F25: 11.326632 | G25: {"type":"MultiPoint","coordinates":[]}
A26: 24 | B26: 2018 | C26: 1 | E26: 35239045 | F26: 8.9521121 | G26: {"type":"MultiPoint","coordinates":[]} | I26: Estimated ET_mm | M26: 2335
A27: 25 | B27: 2018 | C27: 1 | D27: 2EA | E27: 4.1157222e+08 | F27: 9.7967795 | G27: {"type":"MultiPoint","coordinates":[]} | I27: MCM | M27: =(M26*100*M19*10)/1000000 -> 18340.361
A28: 26 | B28: 2018 | C28: 1 | D28: 2FB | E28: 1.4260991e+08 | F28: 12.639265 | G28: {"type":"MultiPoint","coordinates":[]}
A29: 27 | B29: 2018 | C29: 1 | D29: 2GA | E29: 3.2524186e+08 | F29: 32.539953 | G29: {"type":"MultiPoint","coordinates":[]}
A30: 28 | B30: 2018 | C30: 1 | D30: 2FA | E30: 5.4986672e+08 | F30: 28.759558 | G30: {"type":"MultiPoint","coordinates":[]}
A31: 29 | B31: 2018 | C31: 1 | E31: 51177524 | F31: 22.382852 | G31: {"type":"MultiPoint","coordinates":[]}
A32: 30 | B32: 2018 | C32: 1 | E32: 18918004 | F32: 29.532958 | G32: {"type":"MultiPoint","coordinates":[]}
A33: 31 | B33: 2018 | C33: 1 | E33: 1.6796886e+08 | F33: 50.150468 | G33: {"type":"MultiPoint","coordinates":[]}
A34: 32 | B34: 2018 | C34: 1 | E34: 81433392 | F34: 82.904693 | G34: {"type":"MultiPoint","coordinates":[]}
A35: 33 | B35: 2018 | C35: 1 | D35: 2AA | E35: 1.1550168e+10 | F35: 1.4830465 | G35: {"type":"MultiPoint","coordinates":[]}
A36: 34 | B36: 2018 | C36: 1 | D36: 2D | E36: 1.3014403e+10 | F36: 2.6929251 | G36: {"type":"MultiPoint","coordinates":[]}
A37: 35 | B37: 2018 | C37: 1 | D37: 2EJ | E37: 1.4230694e+09 | F37: 8.3253827 | G37: {"type":"MultiPoint","coordinates":[]}
A38: 36 | B38: 2018 | C38: 1 | D38: 2EK | E38: 6.0435638e+08 | F38: 10.572256 | G38: {"type":"MultiPoint","coordinates":[]}
A39: 37 | B39: 2018 | C39: 1 | D39: 2EB | E39: 7.2885378e+08 | F39: 10.958256 | G39: {"type":"MultiPoint","coordinates":[]}
A40: 38 | B40: 2018 | C40: 1 | D40: 2GD | E40: 1.1569536e+09 | F40: 54.220483 | G40: {"type":"MultiPoint","coordinates":[]}
...

Sheet TanaRiver_Subbasin_Monthly
A1: system:index | B1: Year | C1: Month | D1: Subbasin_ID | E1: area_m2 | F1: mean_rf_mm | G1: .geo
A2: 0 | B2: 2018 | C2: 1 | D2: 4GC | E2: 1.8338258e+09 | F2: 0.61726873 | G2: {"type":"MultiPoint","coordinates":[]} | J2: Year | K2: Year | L2: Year | M2: Year | N2: Year | O2: Year | P2: Year
A3: 1 | B3: 2018 | C3: 1 | D3: 4EA | E3: 7.4866526e+08 | F3: 13.228085 | G3: {"type":"MultiPoint","coordinates":[]} | I3: Month | J3: 2018 | K3: 2019 | L3: 2020 | M3: 2021 | N3: 2022 | O3: 2023 | P3: 2024
A4: 2 | B4: 2018 | C4: 1 | D4: 4KA | E4: 8.2691711e+09 | F4: 4.6051588 | G4: {"type":"MultiPoint","coordinates":[]} | I4: 1 | J4: =AVERAGEIFS($F:$F,$B:$B,J$3,$C:$C,$I4) -> 14.516938 | K4: =AVERAGEIFS($F:$F,$B:$B,K$3,$C:$C,$I4) -> 29.906756 | L4: =AVERAGEIFS($F:$F,$B:$B,L$3,$C:$C,$I4) -> 79.878943 | M4: =AVERAGEIFS($F:$F,$B:$B,M$3,$C:$C,$I4) -> 36.889523 | N4: =AVERAGEIFS($F:$F,$B:$B,N$3,$C:$C,$I4) -> 23.682735 | O4: =AVERAGEIFS($F:$F,$B:$B,O$3,$C:$C,$I4) -> 22.765883 | P4: =AVERAGEIFS($F:$F,$B:$B,P$3,$C:$C,$I4) -> 52.061099
A5: 3 | B5: 2018 | C5: 1 | D5: 4DA | E5: 7.2138355e+08 | F5: 16.192916 | G5: {"type":"MultiPoint","coordinates":[]} | I5: 2 | J5: =AVERAGEIFS($F:$F,$B:$B,J$3,$C:$C,$I5) -> 11.129098 | K5: =AVERAGEIFS($F:$F,$B:$B,K$3,$C:$C,$I5) -> 17.798898 | L5: =AVERAGEIFS($F:$F,$B:$B,L$3,$C:$C,$I5) -> 41.621456 | M5: =AVERAGEIFS($F:$F,$B:$B,M$3,$C:$C,$I5) -> 28.40047 | N5: =AVERAGEIFS($F:$F,$B:$B,N$3,$C:$C,$I5) -> 19.445685 | O5: =AVERAGEIFS($F:$F,$B:$B,O$3,$C:$C,$I5) -> 4.9831213 | P5: =AVERAGEIFS($F:$F,$B:$B,P$3,$C:$C,$I5) -> 40.352366
A6: 4 | B6: 2018 | C6: 1 | D6: 4BB | E6: 2.5828756e+08 | F6: 22.848785 | G6: {"type":"MultiPoint","coordinates":[]} | I6: 3 | J6: =AVERAGEIFS($F:$F,$B:$B,J$3,$C:$C,$I6) -> 189.45065 | K6: =AVERAGEIFS($F:$F,$B:$B,K$3,$C:$C,$I6) -> 19.952317 | L6: =AVERAGEIFS($F:$F,$B:$B,L$3,$C:$C,$I6) -> 130.66147 | M6: =AVERAGEIFS($F:$F,$B:$B,M$3,$C:$C,$I6) -> 41.538713 | N6: =AVERAGEIFS($F:$F,$B:$B,N$3,$C:$C,$I6) -> 31.320183 | O6: =AVERAGEIFS($F:$F,$B:$B,O$3,$C:$C,$I6) -> 83.858737 | P6: =AVERAGEIFS($F:$F,$B:$B,P$3,$C:$C,$I6) -> 54.201932
A7: 5 | B7: 2018 | C7: 1 | D7: 4EC | E7: 6.1097463e+08 | F7: 7.277723 | G7: {"type":"MultiPoint","coordinates":[]} | I7: 4 | J7: =AVERAGEIFS($F:$F,$B:$B,J$3,$C:$C,$I7) -> 394.53917 | K7: =AVERAGEIFS($F:$F,$B:$B,K$3,$C:$C,$I7) -> 142.78302 | L7: =AVERAGEIFS($F:$F,$B:$B,L$3,$C:$C,$I7) -> 404.1967 | M7: =AVERAGEIFS($F:$F,$B:$B,M$3,$C:$C,$I7) -> 144.20306 | N7: =AVERAGEIFS($F:$F,$B:$B,N$3,$C:$C,$I7) -> 158.09437 | O7: =AVERAGEIFS($F:$F,$B:$B,O$3,$C:$C,$I7) -> 317.58338 | P7: =AVERAGEIFS($F:$F,$B:$B,P$3,$C:$C,$I7) -> 427.49048
A8: 6 | B8: 2018 | C8: 1 | D8: 4BC | E8: 2.2721178e+08 | F8: 19.491538 | G8: {"type":"MultiPoint","coordinates":[]} | I8: 5 | J8: =AVERAGEIFS($F:$F,$B:$B,J$3,$C:$C,$I8) -> 274.23927 | K8: =AVERAGEIFS($F:$F,$B:$B,K$3,$C:$C,$I8) -> 141.7351 | L8: =AVERAGEIFS($F:$F,$B:$B,L$3,$C:$C,$I8) -> 147.96822 | M8: =AVERAGEIFS($F:$F,$B:$B,M$3,$C:$C,$I8) -> 144.62814 | N8: =AVERAGEIFS($F:$F,$B:$B,N$3,$C:$C,$I8) -> 76.844798 | O8: =AVERAGEIFS($F:$F,$B:$B,O$3,$C:$C,$I8) -> 68.374231 | P8: =AVERAGEIFS($F:$F,$B:$B,P$3,$C:$C,$I8) -> 199.14891
A9: 7 | B9: 2018 | C9: 1 | D9: 4ED | E9: 3.1779501e+09 | F9: 9.7686319 | G9: {"type":"MultiPoint","coordinates":[]} | I9: 6 | J9: =AVERAGEIFS($F:$F,$B:$B,J$3,$C:$C,$I9) -> 80.671388 | K9: =AVERAGEIFS($F:$F,$B:$B,K$3,$C:$C,$I9) -> 37.073572 | L9: =AVERAGEIFS($F:$F,$B:$B,L$3,$C:$C,$I9) -> 56.179629 | M9: =AVERAGEIFS($F:$F,$B:$B,M$3,$C:$C,$I9) -> 23.076413 | N9: =AVERAGEIFS($F:$F,$B:$B,N$3,$C:$C,$I9) -> 26.613912 | O9: =AVERAGEIFS($F:$F,$B:$B,O$3,$C:$C,$I9) -> 32.619744 | P9: =AVERAGEIFS($F:$F,$B:$B,P$3,$C:$C,$I9) -> 26.517022
A10: 8 | B10: 2018 | C10: 1 | D10: 4GD | E10: 7.4432996e+09 | F10: 2.6740172 | G10: {"type":"MultiPoint","coordinates":[]} | I10: 7 | J10: =AVERAGEIFS($F:$F,$B:$B,J$3,$C:$C,$I10) -> 46.195614 | K10: =AVERAGEIFS($F:$F,$B:$B,K$3,$C:$C,$I10) -> 35.499837 | L10: =AVERAGEIFS($F:$F,$B:$B,L$3,$C:$C,$I10) -> 47.530334 | M10: =AVERAGEIFS($F:$F,$B:$B,M$3,$C:$C,$I10) -> 35.245025 | N10: =AVERAGEIFS($F:$F,$B:$B,N$3,$C:$C,$I10) -> 32.262213 | O10: =AVERAGEIFS($F:$F,$B:$B,O$3,$C:$C,$I10) -> 31.232928 | P10: =AVERAGEIFS($F:$F,$B:$B,P$3,$C:$C,$I10) -> 39.346364
A11: 9 | B11: 2018 | C11: 1 | D11: 4BA | E11: 3.2081475e+08 | F11: 29.361146 | G11: {"type":"MultiPoint","coordinates":[]} | I11: 8 | J11: =AVERAGEIFS($F:$F,$B:$B,J$3,$C:$C,$I11) -> 28.846234 | K11: =AVERAGEIFS($F:$F,$B:$B,K$3,$C:$C,$I11) -> 31.000674 | L11: =AVERAGEIFS($F:$F,$B:$B,L$3,$C:$C,$I11) -> 31.915019 | M11: =AVERAGEIFS($F:$F,$B:$B,M$3,$C:$C,$I11) -> 22.439777 | N11: =AVERAGEIFS($F:$F,$B:$B,N$3,$C:$C,$I11) -> 28.176221 | O11: =AVERAGEIFS($F:$F,$B:$B,O$3,$C:$C,$I11) -> 26.265621 | P11: =AVERAGEIFS($F:$F,$B:$B,P$3,$C:$C,$I11) -> 26.398697
A12: 10 | B12: 2018 | C12: 1 | D12: 4KB | E12: 1.0295749e+10 | F12: 4.6712664 | G12: {"type":"MultiPoint","coordinates":[]} | I12: 9 | J12: =AVERAGEIFS($F:$F,$B:$B,J$3,$C:$C,$I12) -> 30.36277 | K12: =AVERAGEIFS($F:$F,$B:$B,K$3,$C:$C,$I12) -> 37.826673 | L12: =AVERAGEIFS($F:$F,$B:$B,L$3,$C:$C,$I12) -> 35.874735 | M12: =AVERAGEIFS($F:$F,$B:$B,M$3,$C:$C,$I12) -> 18.003652 | N12: =AVERAGEIFS($F:$F,$B:$B,N$3,$C:$C,$I12) -> 21.22887 | O12: =AVERAGEIFS($F:$F,$B:$B,O$3,$C:$C,$I12) -> 26.343731 | P12: =AVERAGEIFS($F:$F,$B:$B,P$3,$C:$C,$I12) -> 17.011603
A13: 11 | B13: 2018 | C13: 1 | D13: 4DD | E13: 4.5316791e+08 | F13: 10.084739 | G13: {"type":"MultiPoint","coordinates":[]} | I13: 10 | J13: =AVERAGEIFS($F:$F,$B:$B,J$3,$C:$C,$I13) -> 65.732633 | K13: =AVERAGEIFS($F:$F,$B:$B,K$3,$C:$C,$I13) -> 302.44466 | L13: =AVERAGEIFS($F:$F,$B:$B,L$3,$C:$C,$I13) -> 70.350674 | M13: =AVERAGEIFS($F:$F,$B:$B,M$3,$C:$C,$I13) -> 57.002652 | N13: =AVERAGEIFS($F:$F,$B:$B,N$3,$C:$C,$I13) -> 36.609786 | O13: =AVERAGEIFS($F:$F,$B:$B,O$3,$C:$C,$I13) -> 112.13397 | P13: =AVERAGEIFS($F:$F,$B:$B,P$3,$C:$C,$I13) -> 45.173401
A14: 12 | B14: 2018 | C14: 1 | D14: 4GE | E14: 1.1800845e+10 | F14: 6.555522 | G14: {"type":"MultiPoint","coordinates":[]} | I14: 11 | J14: =AVERAGEIFS($F:$F,$B:$B,J$3,$C:$C,$I14) -> 119.97796 | K14: =AVERAGEIFS($F:$F,$B:$B,K$3,$C:$C,$I14) -> 328.014 | L14: =AVERAGEIFS($F:$F,$B:$B,L$3,$C:$C,$I14) -> 150.07071 | M14: =AVERAGEIFS($F:$F,$B:$B,M$3,$C:$C,$I14) -> 102.07135 | N14: =AVERAGEIFS($F:$F,$B:$B,N$3,$C:$C,$I14) -> 205.08794 | O14: =AVERAGEIFS($F:$F,$B:$B,O$3,$C:$C,$I14) -> 373.932 | P14: =AVERAGEIFS($F:$F,$B:$B,P$3,$C:$C,$I14) -> 252.52525
A15: 13 | B15: 2018 | C15: 1 | D15: 4BF | E15: 3.765969e+08 | F15: 33.0171 | G15: {"type":"MultiPoint","coordinates":[]} | I15: 12 | J15: =AVERAGEIFS($F:$F,$B:$B,J$3,$C:$C,$I15) -> 160.58118 | K15: =AVERAGEIFS($F:$F,$B:$B,K$3,$C:$C,$I15) -> 195.78787 | L15: =AVERAGEIFS($F:$F,$B:$B,L$3,$C:$C,$I15) -> 59.844208 | M15: =AVERAGEIFS($F:$F,$B:$B,M$3,$C:$C,$I15) -> 168.98597 | N15: =AVERAGEIFS($F:$F,$B:$B,N$3,$C:$C,$I15) -> 47.892921 | O15: =AVERAGEIFS($F:$F,$B:$B,O$3,$C:$C,$I15) -> 79.21488 | P15: =AVERAGEIFS($F:$F,$B:$B,P$3,$C:$C,$I15) -> 61.941592
A16: 14 | B16: 2018 | C16: 1 | D16: 4BG | E16: 4.455162e+08 | F16: 25.242488 | G16: {"type":"MultiPoint","coordinates":[]}
A17: 15 | B17: 2018 | C17: 1 | D17: 4JB | E17: 3.6765904e+09 | F17: 2.9361985 | G17: {"type":"MultiPoint","coordinates":[]} | I17: TotalAnnual Rf from Monthly Avg | J17: =SUM(J4:J15) -> 1416.2429 | K17: =SUM(K4:K15) -> 1319.8234 | L17: =SUM(L4:L15) -> 1256.0921 | M17: =SUM(M4:M15) -> 822.48474 | N17: =SUM(N4:N15) -> 707.25963 | O17: =SUM(O4:O15) -> 1179.3082 | P17: =SUM(P4:P15) -> 1242.1687
A18: 16 | B18: 2018 | C18: 1 | D18: 4GF | E18: 1.5608902e+10 | F18: 7.0829241 | G18: {"type":"MultiPoint","coordinates":[]}
A19: 17 | B19: 2018 | C19: 1 | D19: 4HB | E19: 9.119548e+09 | F19: 6.1236031 | G19: {"type":"MultiPoint","coordinates":[]} | I19: WB_Area_sqkm | J19: ='Lakes Area'!$D$6/1000000 -> 424.39293 | K19: ='Lakes Area'!$D$6/1000000 -> 424.39293 | L19: ='Lakes Area'!$D$6/1000000 -> 424.39293 | M19: ='Lakes Area'!$D$6/1000000 -> 424.39293 | N19: ='Lakes Area'!$D$6/1000000 -> 424.39293 | O19: ='Lakes Area'!$D$6/1000000 -> 424.39293 | P19: ='Lakes Area'!$D$6/1000000 -> 424.39293
A20: 18 | B20: 2018 | C20: 1 | E20: 1.6150196e+08 | F20: 3.1129808 | G20: {"type":"MultiPoint","coordinates":[]} | I20: Basin_Area_sqkm | J20: 126208 | K20: 126208 | L20: 126208 | M20: 126208 | N20: 126208 | O20: 126208 | P20: 126208
A21: 19 | B21: 2018 | C21: 1 | E21: 65243578 | F21: 0 | G21: {"type":"MultiPoint","coordinates":[]} | I21: proportion(WB/BA)
A22: 20 | B22: 2018 | C22: 1 | E22: 50371439 | F22: 0 | G22: {"type":"MultiPoint","coordinates":[]} | I22: TotalRf_mm | J22: =J17 -> 1416.2429 | K22: =K17 -> 1319.8234 | L22: =L17 -> 1256.0921 | M22: =M17 -> 822.48474 | N22: =N17 -> 707.25963 | O22: =O17 -> 1179.3082 | P22: =P17 -> 1242.1687
A23: 21 | B23: 2018 | C23: 1 | D23: 4BE | E23: 5.5612612e+08 | F23: 39.656927 | G23: {"type":"MultiPoint","coordinates":[]} | I23: Rainfall_MCM_on_Lake | J23: =(J22*100*J19*10)/1000000 -> 601.04348 | K23: =(K22*100*K19*10)/1000000 -> 560.12371 | L23: =(L22*100*L19*10)/1000000 -> 533.0766 | M23: =(M22*100*M19*10)/1000000 -> 349.05671 | N23: =(N22*100*N19*10)/1000000 -> 300.15599 | O23: =(O22*100*O19*10)/1000000 -> 500.49007 | P23: =(P22*100*P19*10)/1000000 -> 527.16762
A24: 22 | B24: 2018 | C24: 1 | D24: 4CC | E24: 1.0243122e+09 | F24: 29.745633 | G24: {"type":"MultiPoint","coordinates":[]} | I24: BASIN_MAR | J24: =(J22*100*J20*10)/1000000 -> 178741.19 | K24: =(K22*100*K20*10)/1000000 -> 166572.27 | L24: =(L22*100*L20*10)/1000000 -> 158528.87 | M24: =(M22*100*M20*10)/1000000 -> 103804.15 | N24: =(N22*100*N20*10)/1000000 -> 89261.824 | O24: =(O22*100*O20*10)/1000000 -> 148838.13 | P24: =(P22*100*P20*10)/1000000 -> 156771.63
A25: 23 | B25: 2018 | C25: 1 | D25: 4DE | E25: 7.3999224e+08 | F25: 19.653881 | G25: {"type":"MultiPoint","coordinates":[]}
A26: 24 | B26: 2018 | C26: 1 | D26: 4HA | E26: 5.5127092e+09 | F26: 14.324562 | G26: {"type":"MultiPoint","coordinates":[]}
A27: 25 | B27: 2018 | C27: 1 | D27: 4GG | E27: 7.1644721e+09 | F27: 6.0188932 | G27: {"type":"MultiPoint","coordinates":[]}
A28: 26 | B28: 2018 | C28: 1 | D28: 4HC | E28: 6.6618128e+09 | F28: 2.170638 | G28: {"type":"MultiPoint","coordinates":[]}
A29: 27 | B29: 2018 | C29: 1 | D29: 3HD2 | E29: 4.0628645e+08 | F29: 5.7189246 | G29: {"type":"MultiPoint","coordinates":[]}
A30: 28 | B30: 2018 | C30: 1 | D30: 4GA | E30: 3.9327061e+09 | F30: 5.7482136 | G30: {"type":"MultiPoint","coordinates":[]}
A31: 29 | B31: 2018 | C31: 1 | D31: 4FB | E31: 3.9730883e+09 | F31: 6.7679747 | G31: {"type":"MultiPoint","coordinates":[]}
A32: 30 | B32: 2018 | C32: 1 | D32: 4GB | E32: 5.5351201e+09 | F32: 3.3543146 | G32: {"type":"MultiPoint","coordinates":[]}
A33: 31 | B33: 2018 | C33: 1 | D33: 4FA | E33: 2.192164e+09 | F33: 11.362784 | G33: {"type":"MultiPoint","coordinates":[]}
A34: 32 | B34: 2018 | C34: 1 | D34: 4JA | E34: 8.4070244e+09 | F34: 2.1570325 | G34: {"type":"MultiPoint","coordinates":[]}
A35: 33 | B35: 2018 | C35: 1 | D35: 4EB | E35: 1.1982913e+09 | F35: 12.156622 | G35: {"type":"MultiPoint","coordinates":[]}
A36: 34 | B36: 2018 | C36: 1 | D36: 4DC | E36: 3.56173e+08 | F36: 12.694003 | G36: {"type":"MultiPoint","coordinates":[]}
... A60: 58 | B60: 2018 | C60: 2 | D60: 4HB | E60: 9.119548e+09 | F60: 7.151751 | G60: {"type":"MultiPoint","coordinates":[]}
A61: 59 | B61: 2018 | C61: 2 | E61: 1.6150196e+08 | F61: 0 | G61: {"type":"MultiPoint","coordinates":[]}
A62: 60 | B62: 2018 | C62: 2 | E62: 65243578 | F62: 0 | G62: {"type":"MultiPoint","coordinates":[]}
A63: 61 | B63: 2018 | C63: 2 | E63: 50371439 | F63: 0 | G63: {"type":"MultiPoint","coordinates":[]}
...

Sheet LakeVictoriaSouth_Subbasin_Mont
A1: system:index | B1: Year | C1: Month | D1: Subbasin_ID | E1: area_m2 | F1: mean_rf_mm | G1: .geo
A2: 0 | B2: 2018 | C2: 1 | E2: 60992067 | F2: 29.05052 | G2: {"type":"MultiPoint","coordinates":[]} | J2: Year | K2: Year | L2: Year | M2: Year | N2: Year | O2: Year | P2: Year
A3: 1 | B3: 2018 | C3: 1 | D3: 1GE | E3: 3.9188315e+08 | F3: 25.531527 | G3: {"type":"MultiPoint","coordinates":[]} | I3: Month | J3: 2018 | K3: 2019 | L3: 2020 | M3: 2021 | N3: 2022 | O3: 2023 | P3: 2024
A4: 2 | B4: 2018 | C4: 1 | D4: 1GD | E4: 7.210051e+08 | F4: 24.271736 | G4: {"type":"MultiPoint","coordinates":[]} | I4: 1 | J4: =AVERAGEIFS($F:$F,$B:$B,J$3,$C:$C,$I4) -> 39.35118 | K4: =AVERAGEIFS($F:$F,$B:$B,K$3,$C:$C,$I4) -> 25.431682 | L4: =AVERAGEIFS($F:$F,$B:$B,L$3,$C:$C,$I4) -> 149.65933 | M4: =AVERAGEIFS($F:$F,$B:$B,M$3,$C:$C,$I4) -> 84.917832 | N4: =AVERAGEIFS($F:$F,$B:$B,N$3,$C:$C,$I4) -> 130.13121 | O4: =AVERAGEIFS($F:$F,$B:$B,O$3,$C:$C,$I4) -> 22.112507 | P4: =AVERAGEIFS($F:$F,$B:$B,P$3,$C:$C,$I4) -> 191.90627
A5: 3 | B5: 2018 | C5: 1 | D5: 1GB | E5: 5.179049e+08 | F5: 23.386028 | G5: {"type":"MultiPoint","coordinates":[]} | I5: 2 | J5: =AVERAGEIFS($F:$F,$B:$B,J$3,$C:$C,$I5) -> 50.325771 | K5: =AVERAGEIFS($F:$F,$B:$B,K$3,$C:$C,$I5) -> 50.999787 | L5: =AVERAGEIFS($F:$F,$B:$B,L$3,$C:$C,$I5) -> 89.497822 | M5: =AVERAGEIFS($F:$F,$B:$B,M$3,$C:$C,$I5) -> 107.64276 | N5: =AVERAGEIFS($F:$F,$B:$B,N$3,$C:$C,$I5) -> 223.75729 | O5: =AVERAGEIFS($F:$F,$B:$B,O$3,$C:$C,$I5) -> 16.793003 | P5: =AVERAGEIFS($F:$F,$B:$B,P$3,$C:$C,$I5) -> 117.89708
A6: 4 | B6: 2018 | C6: 1 | D6: 1GC | E6: 9.1360535e+08 | F6: 17.155477 | G6: {"type":"MultiPoint","coordinates":[]} | I6: 3 | J6: =AVERAGEIFS($F:$F,$B:$B,J$3,$C:$C,$I6) -> 239.98432 | K6: =AVERAGEIFS($F:$F,$B:$B,K$3,$C:$C,$I6) -> 76.271464 | L6: =AVERAGEIFS($F:$F,$B:$B,L$3,$C:$C,$I6) -> 284.6017 | M6: =AVERAGEIFS($F:$F,$B:$B,M$3,$C:$C,$I6) -> 106.46585 | N6: =AVERAGEIFS($F:$F,$B:$B,N$3,$C:$C,$I6) -> 118.03388 | O6: =AVERAGEIFS($F:$F,$B:$B,O$3,$C:$C,$I6) -> 239.25315 | P6: =AVERAGEIFS($F:$F,$B:$B,P$3,$C:$C,$I6) -> 132.20051
A7: 5 | B7: 2018 | C7: 1 | D7: 1GA | E7: 4.4259285e+08 | F7: 23.471674 | G7: {"type":"MultiPoint","coordinates":[]} | I7: 4 | J7: =AVERAGEIFS($F:$F,$B:$B,J$3,$C:$C,$I7) -> 340.49061 | K7: =AVERAGEIFS($F:$F,$B:$B,K$3,$C:$C,$I7) -> 179.74158 | L7: =AVERAGEIFS($F:$F,$B:$B,L$3,$C:$C,$I7) -> 289.06966 | M7: =AVERAGEIFS($F:$F,$B:$B,M$3,$C:$C,$I7) -> 285.89974 | N7: =AVERAGEIFS($F:$F,$B:$B,N$3,$C:$C,$I7) -> 198.07843 | O7: =AVERAGEIFS($F:$F,$B:$B,O$3,$C:$C,$I7) -> 264.46509 | P7: =AVERAGEIFS($F:$F,$B:$B,P$3,$C:$C,$I7) -> 271.16244
A8: 6 | B8: 2018 | C8: 1 | D8: 1GF | E8: 2.6889632e+08 | F8: 29.2862 | G8: {"type":"MultiPoint","coordinates":[]} | I8: 5 | J8: =AVERAGEIFS($F:$F,$B:$B,J$3,$C:$C,$I8) -> 253.28902 | K8: =AVERAGEIFS($F:$F,$B:$B,K$3,$C:$C,$I8) -> 185.77616 | L8: =AVERAGEIFS($F:$F,$B:$B,L$3,$C:$C,$I8) -> 169.11497 | M8: =AVERAGEIFS($F:$F,$B:$B,M$3,$C:$C,$I8) -> 227.17554 | N8: =AVERAGEIFS($F:$F,$B:$B,N$3,$C:$C,$I8) -> 218.22706 | O8: =AVERAGEIFS($F:$F,$B:$B,O$3,$C:$C,$I8) -> 173.31445 | P8: =AVERAGEIFS($F:$F,$B:$B,P$3,$C:$C,$I8) -> 194.27127
A9: 7 | B9: 2018 | C9: 1 | D9: 1GG | E9: 3.7443863e+08 | F9: 18.534629 | G9: {"type":"MultiPoint","coordinates":[]} | I9: 6 | J9: =AVERAGEIFS($F:$F,$B:$B,J$3,$C:$C,$I9) -> 166.43969 | K9: =AVERAGEIFS($F:$F,$B:$B,K$3,$C:$C,$I9) -> 165.11031 | L9: =AVERAGEIFS($F:$F,$B:$B,L$3,$C:$C,$I9) -> 140.68638 | M9: =AVERAGEIFS($F:$F,$B:$B,M$3,$C:$C,$I9) -> 85.150512 | N9: =AVERAGEIFS($F:$F,$B:$B,N$3,$C:$C,$I9) -> 97.240222 | O9: =AVERAGEIFS($F:$F,$B:$B,O$3,$C:$C,$I9) -> 146.82097 | P9: =AVERAGEIFS($F:$F,$B:$B,P$3,$C:$C,$I9) -> 71.00041
A10: 8 | B10: 2018 | C10: 1 | D10: 1HG | E10: 3.7321124e+08 | F10: 35.584976 | G10: {"type":"MultiPoint","coordinates":[]} | I10: 7 | J10: =AVERAGEIFS($F:$F,$B:$B,J$3,$C:$C,$I10) -> 84.358495 | K10: =AVERAGEIFS($F:$F,$B:$B,K$3,$C:$C,$I10) -> 106.91301 | L10: =AVERAGEIFS($F:$F,$B:$B,L$3,$C:$C,$I10) -> 131.73458 | M10: =AVERAGEIFS($F:$F,$B:$B,M$3,$C:$C,$I10) -> 78.650504 | N10: =AVERAGEIFS($F:$F,$B:$B,N$3,$C:$C,$I10) -> 73.836336 | O10: =AVERAGEIFS($F:$F,$B:$B,O$3,$C:$C,$I10) -> 60.318543 | P10: =AVERAGEIFS($F:$F,$B:$B,P$3,$C:$C,$I10) -> 127.46658
A11: 9 | B11: 2018 | C11: 1 | D11: 1HB | E11: 7.641634e+08 | F11: 30.033098 | G11: {"type":"MultiPoint","coordinates":[]} | I11: 8 | J11: =AVERAGEIFS($F:$F,$B:$B,J$3,$C:$C,$I11) -> 121.85281 | K11: =AVERAGEIFS($F:$F,$B:$B,K$3,$C:$C,$I11) -> 129.2058 | L11: =AVERAGEIFS($F:$F,$B:$B,L$3,$C:$C,$I11) -> 147.23925 | M11: =AVERAGEIFS($F:$F,$B:$B,M$3,$C:$C,$I11) -> 150.31397 | N11: =AVERAGEIFS($F:$F,$B:$B,N$3,$C:$C,$I11) -> 209.99247 | O11: =AVERAGEIFS($F:$F,$B:$B,O$3,$C:$C,$I11) -> 84.423045 | P11: =AVERAGEIFS($F:$F,$B:$B,P$3,$C:$C,$I11) -> 116.56345
A12: 10 | B12: 2018 | C12: 1 | D12: 1HA | E12: 8.5861782e+08 | F12: 31.197757 | G12: {"type":"MultiPoint","coordinates":[]} | I12: 9 | J12: =AVERAGEIFS($F:$F,$B:$B,J$3,$C:$C,$I12) -> 60.935926 | K12: =AVERAGEIFS($F:$F,$B:$B,K$3,$C:$C,$I12) -> 125.57144 | L12: =AVERAGEIFS($F:$F,$B:$B,L$3,$C:$C,$I12) -> 151.83335 | M12: =AVERAGEIFS($F:$F,$B:$B,M$3,$C:$C,$I12) -> 164.07086 | N12: =AVERAGEIFS($F:$F,$B:$B,N$3,$C:$C,$I12) -> 146.65812 | O12: =AVERAGEIFS($F:$F,$B:$B,O$3,$C:$C,$I12) -> 195.35032 | P12: =AVERAGEIFS($F:$F,$B:$B,P$3,$C:$C,$I12) -> 101.15678
A13: 11 | B13: 2018 | C13: 1 | D13: 1HF | E13: 8.7637017e+08 | F13: 33.915836 | G13: {"type":"MultiPoint","coordinates":[]} | I13: 10 | J13: =AVERAGEIFS($F:$F,$B:$B,J$3,$C:$C,$I13) -> 159.22859 | K13: =AVERAGEIFS($F:$F,$B:$B,K$3,$C:$C,$I13) -> 235.76735 | L13: =AVERAGEIFS($F:$F,$B:$B,L$3,$C:$C,$I13) -> 223.80097 | M13: =AVERAGEIFS($F:$F,$B:$B,M$3,$C:$C,$I13) -> 107.51711 | N13: =AVERAGEIFS($F:$F,$B:$B,N$3,$C:$C,$I13) -> 89.642314 | O13: =AVERAGEIFS($F:$F,$B:$B,O$3,$C:$C,$I13) -> 179.53513 | P13: =AVERAGEIFS($F:$F,$B:$B,P$3,$C:$C,$I13) -> 115.62494
A14: 12 | B14: 2018 | C14: 1 | D14: 1HE | E14: 8.047415e+08 | F14: 35.155488 | G14: {"type":"MultiPoint","coordinates":[]} | I14: 11 | J14: =AVERAGEIFS($F:$F,$B:$B,J$3,$C:$C,$I14) -> 92.856422 | K14: =AVERAGEIFS($F:$F,$B:$B,K$3,$C:$C,$I14) -> 208.94198 | L14: =AVERAGEIFS($F:$F,$B:$B,L$3,$C:$C,$I14) -> 335.95415 | M14: =AVERAGEIFS($F:$F,$B:$B,M$3,$C:$C,$I14) -> 104.10688 | N14: =AVERAGEIFS($F:$F,$B:$B,N$3,$C:$C,$I14) -> 206.175 | O14: =AVERAGEIFS($F:$F,$B:$B,O$3,$C:$C,$I14) -> 221.37019 | P14: =AVERAGEIFS($F:$F,$B:$B,P$3,$C:$C,$I14) -> 219.65466
A15: 13 | B15: 2018 | C15: 1 | D15: 1HC | E15: 6.1786161e+08 | F15: 29.427796 | G15: {"type":"MultiPoint","coordinates":[]} | I15: 12 | J15: =AVERAGEIFS($F:$F,$B:$B,J$3,$C:$C,$I15) -> 139.11977 | K15: =AVERAGEIFS($F:$F,$B:$B,K$3,$C:$C,$I15) -> 254.32632 | L15: =AVERAGEIFS($F:$F,$B:$B,L$3,$C:$C,$I15) -> 85.793689 | M15: =AVERAGEIFS($F:$F,$B:$B,M$3,$C:$C,$I15) -> 82.782837 | N15: =AVERAGEIFS($F:$F,$B:$B,N$3,$C:$C,$I15) -> 218.69032 | O15: =AVERAGEIFS($F:$F,$B:$B,O$3,$C:$C,$I15) -> 124.33878 | P15: =AVERAGEIFS($F:$F,$B:$B,P$3,$C:$C,$I15) -> 112.31998
A16: 14 | B16: 2018 | C16: 1 | D16: 1HD | E16: 7.8579194e+08 | F16: 33.808396 | G16: {"type":"MultiPoint","coordinates":[]}
A17: 15 | B17: 2018 | C17: 1 | D17: 1JA | E17: 7.5015032e+08 | F17: 25.953881 | G17: {"type":"MultiPoint","coordinates":[]} | I17: TotalAnnual Rf | J17: =SUM(J4:J15) -> 1748.2326 | K17: =SUM(K4:K15) -> 1744.0569 | L17: =SUM(L4:L15) -> 2198.9859 | M17: =SUM(M4:M15) -> 1584.6944 | N17: =SUM(N4:N15) -> 1930.4626 | O17: =SUM(O4:O15) -> 1728.0952 | P17: =SUM(P4:P15) -> 1771.2244
A18: 16 | B18: 2018 | C18: 1 | D18: 1JE | E18: 6.0134782e+08 | F18: 58.199129 | G18: {"type":"MultiPoint","coordinates":[]}
A19: 17 | B19: 2018 | C19: 1 | D19: 1JB | E19: 2.6183888e+08 | F19: 31.650935 | G19: {"type":"MultiPoint","coordinates":[]}
A20: 18 | B20: 2018 | C20: 1 | D20: 1JF | E20: 1.0098121e+09 | F20: 40.8202 | G20: {"type":"MultiPoint","coordinates":[]} | I20: WB_Area_sqkm | J20: ='Lakes Area'!$D$3/1000000 -> 22.750702 | K20: ='Lakes Area'!$D$3/1000000 -> 22.750702 | L20: ='Lakes Area'!$D$3/1000000 -> 22.750702 | M20: ='Lakes Area'!$D$3/1000000 -> 22.750702 | N20: ='Lakes Area'!$D$3/1000000 -> 22.750702 | O20: ='Lakes Area'!$D$3/1000000 -> 22.750702 | P20: ='Lakes Area'!$D$3/1000000 -> 22.750702
A21: 19 | B21: 2018 | C21: 1 | D21: 1JD | E21: 2.1350576e+08 | F21: 26.017339 | G21: {"type":"MultiPoint","coordinates":[]} | I21: Basin_Area_sqkm | J21: 22507 | K21: 22507 | L21: 22507 | M21: 22507 | N21: 22507 | O21: 22507 | P21: 22507
A22: 20 | B22: 2018 | C22: 1 | D22: 1JG | E22: 3.3065365e+08 | F22: 30.777678 | G22: {"type":"MultiPoint","coordinates":[]} | I22: proportion(WB/BA)
A23: 21 | B23: 2018 | C23: 1 | D23: 1JC | E23: 3.4031747e+08 | F23: 25.587328 | G23: {"type":"MultiPoint","coordinates":[]} | I23: TotalRf_mm | J23: =J17 -> 1748.2326 | K23: =K17 -> 1744.0569 | L23: =L17 -> 2198.9859 | M23: =M17 -> 1584.6944 | N23: =N17 -> 1930.4626 | O23: =O17 -> 1728.0952 | P23: =P17 -> 1771.2244
A24: 22 | B24: 2018 | C24: 1 | D24: 1KA | E24: 4.6290219e+08 | F24: 36.498057 | G24: {"type":"MultiPoint","coordinates":[]} | I24: Rainfall_MCM_on_Lake | J24: =(J23*100*J20*10)/1000000 -> 39.773518 | K24: =(K23*100*K20*10)/1000000 -> 39.678518 | L24: =(L23*100*L20*10)/1000000 -> 50.028472 | M24: =(M23*100*M20*10)/1000000 -> 36.05291 | N24: =(N23*100*N20*10)/1000000 -> 43.91938 | O24: =(O23*100*O20*10)/1000000 -> 39.315378 | P24: =(P23*100*P20*10)/1000000 -> 40.296597
A25: 23 | B25: 2018 | C25: 1 | D25: 1KC | E25: 2.8901703e+09 | F25: 66.925546 | G25: {"type":"MultiPoint","coordinates":[]} | I25: BASIN_MAR
A26: 24 | B26: 2018 | C26: 1 | D26: 1KB | E26: 3.5350283e+09 | F26: 45.175088 | G26: {"type":"MultiPoint","coordinates":[]}
A27: 25 | B27: 2018 | C27: 1 | D27: 1LA3 | E27: 2.8945988e+09 | F27: 117.31373 | G27: {"type":"MultiPoint","coordinates":[]}
A28: 26 | B28: 2018 | C28: 1 | D28: 1LB1 | E28: 1.4526325e+09 | F28: 56.477007 | G28: {"type":"MultiPoint","coordinates":[]}
A29: 27 | B29: 2018 | C29: 1 | D29: 1LB2 | E29: 2.7210238e+09 | F29: 88.316163 | G29: {"type":"MultiPoint","coordinates":[]}
A30: 28 | B30: 2018 | C30: 1 | D30: 1LA2 | E30: 1.004232e+09 | F30: 65.392878 | G30: {"type":"MultiPoint","coordinates":[]}
A31: 29 | B31: 2018 | C31: 1 | D31: 1LA1 | E31: 9.1374606e+08 | F31: 45.619318 | G31: {"type":"MultiPoint","coordinates":[]}
A32: 30 | B32: 2018 | C32: 2 | E32: 60992067 | F32: 56.834233 | G32: {"type":"MultiPoint","coordinates":[]}
A33: 31 | B33: 2018 | C33: 2 | D33: 1GE | E33: 3.9188315e+08 | F33: 52.791926 | G33: {"type":"MultiPoint","coordinates":[]}
A34: 32 | B34: 2018 | C34: 2 | D34: 1GD | E34: 7.210051e+08 | F34: 61.62308 | G34: {"type":"MultiPoint","coordinates":[]}
A35: 33 | B35: 2018 | C35: 2 | D35: 1GB | E35: 5.179049e+08 | F35: 56.975294 | G35: {"type":"MultiPoint","coordinates":[]}
A36: 34 | B36: 2018 | C36: 2 | D36: 1GC | E36: 9.1360535e+08 | F36: 33.369995 | G36: {"type":"MultiPoint","coordinates":[]}
A37: 35 | B37: 2018 | C37: 2 | D37: 1GA | E37: 4.4259285e+08 | F37: 37.856925 | G37: {"type":"MultiPoint","coordinates":[]}
A38: 36 | B38: 2018 | C38: 2 | D38: 1GF | E38: 2.6889632e+08 | F38: 44.160729 | G38: {"type":"MultiPoint","coordinates":[]}
A39: 37 | B39: 2018 | C39: 2 | D39: 1GG | E39: 3.7443863e+08 | F39: 34.65834 | G39: {"type":"MultiPoint","coordinates":[]}
A40: 38 | B40: 2018 | C40: 2 | D40: 1HG | E40: 3.7321124e+08 | F40: 74.912705 | G40: {"type":"MultiPoint","coordinates":[]}
...

Sheet AthiBasin_Subbasin_Monthly
A1: system:index | B1: Year | C1: Month | D1: Subbasin_ID | E1: area_m2 | F1: mean_rf_mm | G1: .geo | I1: Year | J1: Year | K1: Year | L1: Year | M1: Year | N1: Year | O1: Year
A2: 0 | B2: 2018 | C2: 1 | D2: 4CA | E2: 5.3882945e+08 | F2: 59.917438 | G2: {"type":"MultiPoint","coordinates":[]} | H2: Month | I2: 2018 | J2: 2019 | K2: 2020 | L2: 2021 | M2: 2022 | N2: 2023 | O2: 2024
A3: 1 | B3: 2018 | C3: 1 | D3: 3BD | E3: 3.2966944e+08 | F3: 40.589688 | G3: {"type":"MultiPoint","coordinates":[]} | H3: 1 | I3: =AVERAGEIFS($F:$F,$B:$B,I$2,$C:$C,$H3) -> 28.833024 | J3: =AVERAGEIFS($F:$F,$B:$B,J$2,$C:$C,$H3) -> 22.091912 | K3: =AVERAGEIFS($F:$F,$B:$B,K$2,$C:$C,$H3) -> 112.93936 | L3: =AVERAGEIFS($F:$F,$B:$B,L$2,$C:$C,$H3) -> 38.96405 | M3: =AVERAGEIFS($F:$F,$B:$B,M$2,$C:$C,$H3) -> 27.194327 | N3: =AVERAGEIFS($F:$F,$B:$B,N$2,$C:$C,$H3) -> 22.586906 | O3: =AVERAGEIFS($F:$F,$B:$B,O$2,$C:$C,$H3) -> 77.917308
A4: 2 | B4: 2018 | C4: 1 | D4: 3BC | E4: 4.7760072e+08 | F4: 45.579408 | G4: {"type":"MultiPoint","coordinates":[]} | H4: 2 | I4: =AVERAGEIFS(F:F,B:B,I$2,C:C,$H4) -> 17.551603 | J4: =AVERAGEIFS($F:$F,$B:$B,J$2,$C:$C,$H4) -> 19.148915 | K4: =AVERAGEIFS($F:$F,$B:$B,K$2,$C:$C,$H4) -> 47.093009 | L4: =AVERAGEIFS($F:$F,$B:$B,L$2,$C:$C,$H4) -> 42.094603 | M4: =AVERAGEIFS($F:$F,$B:$B,M$2,$C:$C,$H4) -> 34.745167 | N4: =AVERAGEIFS($F:$F,$B:$B,N$2,$C:$C,$H4) -> 5.1480191 | O4: =AVERAGEIFS($F:$F,$B:$B,O$2,$C:$C,$H4) -> 36.101971
A5: 3 | B5: 2018 | C5: 1 | D5: 3BB | E5: 2.5779628e+08 | F5: 37.80965 | G5: {"type":"MultiPoint","coordinates":[]} | H5: 3 | I5: =AVERAGEIFS(F:F,B:B,I$2,C:C,$H5) -> 220.72412 | J5: =AVERAGEIFS($F:$F,$B:$B,J$2,$C:$C,$H5) -> 19.231266 | K5: =AVERAGEIFS($F:$F,$B:$B,K$2,$C:$C,$H5) -> 171.26005 | L5: =AVERAGEIFS($F:$F,$B:$B,L$2,$C:$C,$H5) -> 38.781561 | M5: =AVERAGEIFS($F:$F,$B:$B,M$2,$C:$C,$H5) -> 35.112168 | N5: =AVERAGEIFS($F:$F,$B:$B,N$2,$C:$C,$H5) -> 82.759207 | O5: =AVERAGEIFS($F:$F,$B:$B,O$2,$C:$C,$H5) -> 119.8075
A6: 4 | B6: 2018 | C6: 1 | D6: 3BA | E6: 8.3312886e+08 | F6: 43.046625 | G6: {"type":"MultiPoint","coordinates":[]} | H6: 4 | I6: =AVERAGEIFS(F:F,B:B,I$2,C:C,$H6) -> 317.33685 | J6: =AVERAGEIFS($F:$F,$B:$B,J$2,$C:$C,$H6) -> 116.73907 | K6: =AVERAGEIFS($F:$F,$B:$B,K$2,$C:$C,$H6) -> 328.61394 | L6: =AVERAGEIFS($F:$F,$B:$B,L$2,$C:$C,$H6) -> 113.16848 | M6: =AVERAGEIFS($F:$F,$B:$B,M$2,$C:$C,$H6) -> 135.19466 | N6: =AVERAGEIFS($F:$F,$B:$B,N$2,$C:$C,$H6) -> 221.75919 | O6: =AVERAGEIFS($F:$F,$B:$B,O$2,$C:$C,$H6) -> 381.44392
A7: 5 | B7: 2018 | C7: 1 | D7: 3AA | E7: 7.0083537e+08 | F7: 56.098205 | G7: {"type":"MultiPoint","coordinates":[]} | H7: 5 | I7: =AVERAGEIFS(F:F,B:B,I$2,C:C,$H7) -> 222.64322 | J7: =AVERAGEIFS($F:$F,$B:$B,J$2,$C:$C,$H7) -> 144.46777 | K7: =AVERAGEIFS($F:$F,$B:$B,K$2,$C:$C,$H7) -> 102.74981 | L7: =AVERAGEIFS($F:$F,$B:$B,L$2,$C:$C,$H7) -> 141.72629 | M7: =AVERAGEIFS($F:$F,$B:$B,M$2,$C:$C,$H7) -> 77.231823 | N7: =AVERAGEIFS($F:$F,$B:$B,N$2,$C:$C,$H7) -> 77.718936 | O7: =AVERAGEIFS($F:$F,$B:$B,O$2,$C:$C,$H7) -> 168.2701
A8: 6 | B8: 2018 | C8: 1 | D8: 3AB | E8: 1.7950716e+09 | F8: 54.097295 | G8: {"type":"MultiPoint","coordinates":[]} | H8: 6 | I8: =AVERAGEIFS(F:F,B:B,I$2,C:C,$H8) -> 58.010996 | J8: =AVERAGEIFS($F:$F,$B:$B,J$2,$C:$C,$H8) -> 45.055504 | K8: =AVERAGEIFS($F:$F,$B:$B,K$2,$C:$C,$H8) -> 61.105278 | L8: =AVERAGEIFS($F:$F,$B:$B,L$2,$C:$C,$H8) -> 23.544116 | M8: =AVERAGEIFS($F:$F,$B:$B,M$2,$C:$C,$H8) -> 32.226872 | N8: =AVERAGEIFS($F:$F,$B:$B,N$2,$C:$C,$H8) -> 33.446173 | O8: =AVERAGEIFS($F:$F,$B:$B,O$2,$C:$C,$H8) -> 35.986997
A9: 7 | B9: 2018 | C9: 1 | D9: 3FA | E9: 1.0046151e+10 | F9: 52.208256 | G9: {"type":"MultiPoint","coordinates":[]} | H9: 7 | I9: =AVERAGEIFS(F:F,B:B,I$2,C:C,$H9) -> 50.281302 | J9: =AVERAGEIFS($F:$F,$B:$B,J$2,$C:$C,$H9) -> 42.633974 | K9: =AVERAGEIFS($F:$F,$B:$B,K$2,$C:$C,$H9) -> 42.238894 | L9: =AVERAGEIFS($F:$F,$B:$B,L$2,$C:$C,$H9) -> 43.836685 | M9: =AVERAGEIFS($F:$F,$B:$B,M$2,$C:$C,$H9) -> 47.875571 | N9: =AVERAGEIFS($F:$F,$B:$B,N$2,$C:$C,$H9) -> 37.273823 | O9: =AVERAGEIFS($F:$F,$B:$B,O$2,$C:$C,$H9) -> 29.550262
A10: 8 | B10: 2018 | C10: 1 | D10: 3N | E10: 3.1613646e+09 | F10: 70.972994 | G10: {"type":"MultiPoint","coordinates":[]} | H10: 8 | I10: =AVERAGEIFS(F:F,B:B,I$2,C:C,$H10) -> 37.112089 | J10: =AVERAGEIFS($F:$F,$B:$B,J$2,$C:$C,$H10) -> 36.29135 | K10: =AVERAGEIFS($F:$F,$B:$B,K$2,$C:$C,$H10) -> 22.582064 | L10: =AVERAGEIFS($F:$F,$B:$B,L$2,$C:$C,$H10) -> 28.948185 | M10: =AVERAGEIFS($F:$F,$B:$B,M$2,$C:$C,$H10) -> 23.798012 | N10: =AVERAGEIFS($F:$F,$B:$B,N$2,$C:$C,$H10) -> 22.852519 | O10: =AVERAGEIFS($F:$F,$B:$B,O$2,$C:$C,$H10) -> 24.570912
A11: 9 | B11: 2018 | C11: 1 | D11: 4CB | E11: 3.1458028e+08 | F11: 46.040887 | G11: {"type":"MultiPoint","coordinates":[]} | H11: 9 | I11: =AVERAGEIFS(F:F,B:B,I$2,C:C,$H11) -> 38.827793 | J11: =AVERAGEIFS($F:$F,$B:$B,J$2,$C:$C,$H11) -> 38.439134 | K11: =AVERAGEIFS($F:$F,$B:$B,K$2,$C:$C,$H11) -> 30.187649 | L11: =AVERAGEIFS($F:$F,$B:$B,L$2,$C:$C,$H11) -> 16.44859 | M11: =AVERAGEIFS($F:$F,$B:$B,M$2,$C:$C,$H11) -> 18.859395 | N11: =AVERAGEIFS($F:$F,$B:$B,N$2,$C:$C,$H11) -> 22.249367 | O11: =AVERAGEIFS($F:$F,$B:$B,O$2,$C:$C,$H11) -> 18.866178
A12: 10 | B12: 2018 | C12: 1 | D12: 3CB | E12: 3.9691378e+08 | F12: 40.206401 | G12: {"type":"MultiPoint","coordinates":[]} | H12: 10 | I12: =AVERAGEIFS(F:F,B:B,I$2,C:C,$H12) -> 101.59547 | J12: =AVERAGEIFS($F:$F,$B:$B,J$2,$C:$C,$H12) -> 269.13996 | K12: =AVERAGEIFS($F:$F,$B:$B,K$2,$C:$C,$H12) -> 45.865082 | L12: =AVERAGEIFS($F:$F,$B:$B,L$2,$C:$C,$H12) -> 42.404027 | M12: =AVERAGEIFS($F:$F,$B:$B,M$2,$C:$C,$H12) -> 30.939193 | N12: =AVERAGEIFS($F:$F,$B:$B,N$2,$C:$C,$H12) -> 80.217569 | O12: =AVERAGEIFS($F:$F,$B:$B,O$2,$C:$C,$H12) -> 35.898724
A13: 11 | B13: 2018 | C13: 1 | D13: 3DA | E13: 8.1128388e+08 | F13: 22.925402 | G13: {"type":"MultiPoint","coordinates":[]} | H13: 11 | I13: =AVERAGEIFS(F:F,B:B,I$2,C:C,$H13) -> 105.14459 | J13: =AVERAGEIFS($F:$F,$B:$B,J$2,$C:$C,$H13) -> 247.18867 | K13: =AVERAGEIFS($F:$F,$B:$B,K$2,$C:$C,$H13) -> 166.42394 | L13: =AVERAGEIFS($F:$F,$B:$B,L$2,$C:$C,$H13) -> 107.41769 | M13: =AVERAGEIFS($F:$F,$B:$B,M$2,$C:$C,$H13) -> 155.25259 | N13: =AVERAGEIFS($F:$F,$B:$B,N$2,$C:$C,$H13) -> 385.33144 | O13: =AVERAGEIFS($F:$F,$B:$B,O$2,$C:$C,$H13) -> 205.28757
A14: 12 | B14: 2018 | C14: 1 | D14: 3DB | E14: 8.2735656e+08 | F14: 19.426859 | G14: {"type":"MultiPoint","coordinates":[]} | H14: 12 | I14: =AVERAGEIFS(F:F,B:B,I$2,C:C,$H14) -> 171.0216 | J14: =AVERAGEIFS($F:$F,$B:$B,J$2,$C:$C,$H14) -> 234.13362 | K14: =AVERAGEIFS($F:$F,$B:$B,K$2,$C:$C,$H14) -> 76.141685 | L14: =AVERAGEIFS($F:$F,$B:$B,L$2,$C:$C,$H14) -> 147.61106 | M14: =AVERAGEIFS($F:$F,$B:$B,M$2,$C:$C,$H14) -> 50.233083 | N14: =AVERAGEIFS($F:$F,$B:$B,N$2,$C:$C,$H14) -> 102.78056 | O14: =AVERAGEIFS($F:$F,$B:$B,O$2,$C:$C,$H14) -> 110.35546
A15: 13 | B15: 2018 | C15: 1 | D15: 3FB | E15: 4.2209466e+09 | F15: 12.374153 | G15: {"type":"MultiPoint","coordinates":[]}
A16: 14 | B16: 2018 | C16: 1 | D16: 3HC | E16: 2.9596072e+09 | F16: 7.1383426 | G16: {"type":"MultiPoint","coordinates":[]} | H16: TotalAnnual Rf_mm | I16: =SUM(I3:I14) -> 1369.0826 | J16: =SUM(J3:J14) -> 1234.5611 | K16: =SUM(K3:K14) -> 1207.2008 | L16: =SUM(L3:L14) -> 784.94534 | M16: =SUM(M3:M14) -> 668.66287 | N16: =SUM(N3:N14) -> 1094.1237 | O16: =SUM(O3:O14) -> 1244.0569
A17: 15 | B17: 2018 | C17: 1 | D17: 3HB | E17: 2.5106039e+09 | F17: 4.3301614 | G17: {"type":"MultiPoint","coordinates":[]}
A18: 16 | B18: 2018 | C18: 1 | D18: 3HA | E18: 9.2608382e+08 | F18: 5.747263 | G18: {"type":"MultiPoint","coordinates":[]}
A19: 17 | B19: 2018 | C19: 1 | D19: 3HD1 | E19: 6.322851e+08 | F19: 6.5979339 | G19: {"type":"MultiPoint","coordinates":[]} | H19: WB_Area_sqkm | I19: ='Lakes Area'!$D$2/1000000 -> 170.39735 | J19: ='Lakes Area'!$D$2/1000000 -> 170.39735 | K19: ='Lakes Area'!$D$2/1000000 -> 170.39735 | L19: ='Lakes Area'!$D$2/1000000 -> 170.39735 | M19: ='Lakes Area'!$D$2/1000000 -> 170.39735 | N19: ='Lakes Area'!$D$2/1000000 -> 170.39735 | O19: ='Lakes Area'!$D$2/1000000 -> 170.39735
A20: 18 | B20: 2018 | C20: 1 | E20: 1.7039735e+08 | F20: 59.829734 | G20: {"type":"MultiPoint","coordinates":[]} | H20: Basin_Area_sqkm | I20: ='Lakes Area'!$G$2/1000000 -> 66559 | J20: ='Lakes Area'!$G$2/1000000 -> 66559 | K20: ='Lakes Area'!$G$2/1000000 -> 66559 | L20: ='Lakes Area'!$G$2/1000000 -> 66559 | M20: ='Lakes Area'!$G$2/1000000 -> 66559 | N20: ='Lakes Area'!$G$2/1000000 -> 66559 | O20: ='Lakes Area'!$G$2/1000000 -> 66559
A21: 19 | B21: 2018 | C21: 1 | D21: 3AC | E21: 8.9214077e+08 | F21: 30.82615 | G21: {"type":"MultiPoint","coordinates":[]} | H21: proportion(WB/BA) | I21: =I19/I20 -> 0.0025600948 | J21: =J19/J20 -> 0.0025600948 | K21: =K19/K20 -> 0.0025600948 | L21: =L19/L20 -> 0.0025600948 | M21: =M19/M20 -> 0.0025600948 | N21: =N19/N20 -> 0.0025600948 | O21: =O19/O20 -> 0.0025600948
A22: 20 | B22: 2018 | C22: 1 | D22: 3EA | E22: 8.798824e+08 | F22: 28.525278 | G22: {"type":"MultiPoint","coordinates":[]} | H22: TotalRf_mm | I22: =I16 -> 1369.0826 | J22: =J16 -> 1234.5611 | K22: =K16 -> 1207.2008 | L22: =L16 -> 784.94534 | M22: =M16 -> 668.66287 | N22: =N16 -> 1094.1237 | O22: =O16 -> 1244.0569
A23: 21 | B23: 2018 | C23: 1 | D23: 3EB | E23: 8.0789592e+08 | F23: 27.750843 | G23: {"type":"MultiPoint","coordinates":[]} | H23: Rainfall_MCM_on_Lake | I23: =(I22*100*I19*10)/1000000 -> 233.28806 | J23: =(J22*100*J19*10)/1000000 -> 210.36595 | K23: =(K22*100*K19*10)/1000000 -> 205.70381 | L23: =(L22*100*L19*10)/1000000 -> 133.75261 | M23: =(M22*100*M19*10)/1000000 -> 113.93838 | N23: =(N22*100*N19*10)/1000000 -> 186.43578 | O23: =(O22*100*O19*10)/1000000 -> 211.984
A24: 22 | B24: 2018 | C24: 1 | D24: 3ED | E24: 5.7289114e+08 | F24: 22.963661 | G24: {"type":"MultiPoint","coordinates":[]} | H24: BASIN_MAR | I24: =I22*100*I20*10/1000000 -> 91124.772 | J24: =J22*100*J20*10/1000000 -> 82171.155 | K24: =K22*100*K20*10/1000000 -> 80350.076 | L24: =L22*100*L20*10/1000000 -> 52245.177 | M24: =M22*100*M20*10/1000000 -> 44505.532 | N24: =N22*100*N20*10/1000000 -> 72823.78 | O24: =O22*100*O20*10/1000000 -> 82803.183
A25: 23 | B25: 2018 | C25: 1 | D25: 3EC | E25: 6.7420896e+08 | F25: 42.109814 | G25: {"type":"MultiPoint","coordinates":[]}
A26: 24 | B26: 2018 | C26: 1 | D26: 3G | E26: 6.3021441e+09 | F26: 27.577393 | G26: {"type":"MultiPoint","coordinates":[]}
A27: 25 | B27: 2018 | C27: 1 | D27: 3LA | E27: 7.349765e+09 | F27: 7.7344066 | G27: {"type":"MultiPoint","coordinates":[]} | J27: =(I19*52248)/66559 -> 133.75983
A28: 26 | B28: 2018 | C28: 1 | D28: 3J | E28: 2.8072957e+09 | F28: 30.083497 | G28: {"type":"MultiPoint","coordinates":[]} | L28: =L23/L24 -> 0.0025600948
A29: 27 | B29: 2018 | C29: 1 | D29: 3LB | E29: 7.8841806e+08 | F29: 5.2997499 | G29: {"type":"MultiPoint","coordinates":[]}
A30: 28 | B30: 2018 | C30: 1 | D30: 3MA | E30: 6.1570601e+09 | F30: 17.594793 | G30: {"type":"MultiPoint","coordinates":[]}
A31: 29 | B31: 2018 | C31: 1 | D31: 3MB | E31: 1.7125789e+09 | F31: 5.1365623 | G31: {"type":"MultiPoint","coordinates":[]}
A32: 30 | B32: 2018 | C32: 1 | D32: 3MD1 | E32: 1.3043892e+09 | F32: 7.8775298 | G32: {"type":"MultiPoint","coordinates":[]}
A33: 31 | B33: 2018 | C33: 1 | D33: 3MC | E33: 1.0504051e+09 | F33: 14.158991 | G33: {"type":"MultiPoint","coordinates":[]}
A34: 32 | B34: 2018 | C34: 1 | D34: 3K | E34: 4.1095886e+09 | F34: 18.470851 | G34: {"type":"MultiPoint","coordinates":[]}
A35: 33 | B35: 2018 | C35: 1 | D35: 3MD2 | E35: 1.8771208e+08 | F35: 9.2766178 | G35: {"type":"MultiPoint","coordinates":[]}
A36: 34 | B36: 2018 | C36: 2 | D36: 4CA | E36: 5.3882945e+08 | F36: 44.141407 | G36: {"type":"MultiPoint","coordinates":[]}
A37: 35 | B37: 2018 | C37: 2 | D37: 3BD | E37: 3.2966944e+08 | F37: 28.381948 | G37: {"type":"MultiPoint","coordinates":[]}
A38: 36 | B38: 2018 | C38: 2 | D38: 3BC | E38: 4.7760072e+08 | F38: 29.988661 | G38: {"type":"MultiPoint","coordinates":[]}
A39: 37 | B39: 2018 | C39: 2 | D39: 3BB | E39: 2.5779628e+08 | F39: 30.010848 | G39: {"type":"MultiPoint","coordinates":[]}
A40: 38 | B40: 2018 | C40: 2 | D40: 3BA | E40: 8.3312886e+08 | F40: 31.876564 | G40: {"type":"MultiPoint","coordinates":[]}
...

Sheet EwasoNgiro_Subbasin_Monthly
A1: system:index | B1: Year | C1: Month | D1: Subbasin_ID | E1: area_m2 | F1: mean_rf_mm | G1: .geo
A2: 0 | B2: 2018 | C2: 1 | D2: 5H | E2: 6.6565798e+09 | F2: 7.8063648e-05 | G2: {"type":"MultiPoint","coordinates":[]} | J2: Year | K2: Year | L2: Year | M2: Year | N2: Year | O2: Year | P2: Year
A3: 1 | B3: 2018 | C3: 1 | D3: 5GA | E3: 2.2453045e+10 | F3: 0 | G3: {"type":"MultiPoint","coordinates":[]} | I3: Month | J3: 2018 | K3: 2019 | L3: 2020 | M3: 2021 | N3: 2022 | O3: 2023 | P3: 2024
A4: 2 | B4: 2018 | C4: 1 | D4: 5GB | E4: 3.3554558e+09 | F4: 2.8911803e-06 | G4: {"type":"MultiPoint","coordinates":[]} | I4: 1 | J4: =AVERAGEIFS($F:$F,$B:$B,J$3,$C:$C,$I4) -> 7.6857345 | K4: =AVERAGEIFS($F:$F,$B:$B,K$3,$C:$C,$I4) -> 20.55772 | L4: =AVERAGEIFS($F:$F,$B:$B,L$3,$C:$C,$I4) -> 43.114808 | M4: =AVERAGEIFS($F:$F,$B:$B,M$3,$C:$C,$I4) -> 27.311927 | N4: =AVERAGEIFS($F:$F,$B:$B,N$3,$C:$C,$I4) -> 21.532777 | O4: =AVERAGEIFS($F:$F,$B:$B,O$3,$C:$C,$I4) -> 16.293503 | P4: =AVERAGEIFS($F:$F,$B:$B,P$3,$C:$C,$I4) -> 38.008196
A5: 3 | B5: 2018 | C5: 1 | D5: 5EB | E5: 2.7218095e+10 | F5: 0.03210697 | G5: {"type":"MultiPoint","coordinates":[]} | I5: 2 | J5: =AVERAGEIFS($F:$F,$B:$B,J$3,$C:$C,$I5) -> 8.8743927 | K5: =AVERAGEIFS($F:$F,$B:$B,K$3,$C:$C,$I5) -> 12.727334 | L5: =AVERAGEIFS($F:$F,$B:$B,L$3,$C:$C,$I5) -> 33.49477 | M5: =AVERAGEIFS($F:$F,$B:$B,M$3,$C:$C,$I5) -> 26.628894 | N5: =AVERAGEIFS($F:$F,$B:$B,N$3,$C:$C,$I5) -> 15.831148 | O5: =AVERAGEIFS($F:$F,$B:$B,O$3,$C:$C,$I5) -> 3.4237095 | P5: =AVERAGEIFS($F:$F,$B:$B,P$3,$C:$C,$I5) -> 46.86212
A6: 4 | B6: 2018 | C6: 1 | D6: 5EC | E6: 2.9429244e+10 | F6: 3.0949693 | G6: {"type":"MultiPoint","coordinates":[]} | I6: 3 | J6: =AVERAGEIFS($F:$F,$B:$B,J$3,$C:$C,$I6) -> 155.82657 | K6: =AVERAGEIFS($F:$F,$B:$B,K$3,$C:$C,$I6) -> 21.842966 | L6: =AVERAGEIFS($F:$F,$B:$B,L$3,$C:$C,$I6) -> 108.98857 | M6: =AVERAGEIFS($F:$F,$B:$B,M$3,$C:$C,$I6) -> 36.213602 | N6: =AVERAGEIFS($F:$F,$B:$B,N$3,$C:$C,$I6) -> 30.898874 | O6: =AVERAGEIFS($F:$F,$B:$B,O$3,$C:$C,$I6) -> 99.557303 | P6: =AVERAGEIFS($F:$F,$B:$B,P$3,$C:$C,$I6) -> 23.049137
A7: 5 | B7: 2018 | C7: 1 | D7: 5EA | E7: 2.5314563e+10 | F7: 0 | G7: {"type":"MultiPoint","coordinates":[]} | I7: 4 | J7: =AVERAGEIFS($F:$F,$B:$B,J$3,$C:$C,$I7) -> 242.91971 | K7: =AVERAGEIFS($F:$F,$B:$B,K$3,$C:$C,$I7) -> 88.951773 | L7: =AVERAGEIFS($F:$F,$B:$B,L$3,$C:$C,$I7) -> 256.3422 | M7: =AVERAGEIFS($F:$F,$B:$B,M$3,$C:$C,$I7) -> 74.156766 | N7: =AVERAGEIFS($F:$F,$B:$B,N$3,$C:$C,$I7) -> 96.968995 | O7: =AVERAGEIFS($F:$F,$B:$B,O$3,$C:$C,$I7) -> 203.17122 | P7: =AVERAGEIFS($F:$F,$B:$B,P$3,$C:$C,$I7) -> 223.34999
A8: 6 | B8: 2018 | C8: 1 | D8: 5CB | E8: 2.2694165e+09 | F8: 5.8096598 | G8: {"type":"MultiPoint","coordinates":[]} | I8: 5 | J8: =AVERAGEIFS($F:$F,$B:$B,J$3,$C:$C,$I8) -> 108.83625 | K8: =AVERAGEIFS($F:$F,$B:$B,K$3,$C:$C,$I8) -> 54.906291 | L8: =AVERAGEIFS($F:$F,$B:$B,L$3,$C:$C,$I8) -> 73.139617 | M8: =AVERAGEIFS($F:$F,$B:$B,M$3,$C:$C,$I8) -> 96.032303 | N8: =AVERAGEIFS($F:$F,$B:$B,N$3,$C:$C,$I8) -> 33.671765 | O8: =AVERAGEIFS($F:$F,$B:$B,O$3,$C:$C,$I8) -> 42.872745 | P8: =AVERAGEIFS($F:$F,$B:$B,P$3,$C:$C,$I8) -> 103.99033
A9: 7 | B9: 2018 | C9: 1 | D9: 5FB | E9: 8.2153523e+09 | F9: 0.030903916 | G9: {"type":"MultiPoint","coordinates":[]} | I9: 6 | J9: =AVERAGEIFS($F:$F,$B:$B,J$3,$C:$C,$I9) -> 97.03983 | K9: =AVERAGEIFS($F:$F,$B:$B,K$3,$C:$C,$I9) -> 53.561785 | L9: =AVERAGEIFS($F:$F,$B:$B,L$3,$C:$C,$I9) -> 52.060598 | M9: =AVERAGEIFS($F:$F,$B:$B,M$3,$C:$C,$I9) -> 10.324022 | N9: =AVERAGEIFS($F:$F,$B:$B,N$3,$C:$C,$I9) -> 13.190895 | O9: =AVERAGEIFS($F:$F,$B:$B,O$3,$C:$C,$I9) -> 32.007569 | P9: =AVERAGEIFS($F:$F,$B:$B,P$3,$C:$C,$I9) -> 11.707778
A10: 8 | B10: 2018 | C10: 1 | D10: 5DD | E10: 1.8916824e+09 | F10: 4.4611669 | G10: {"type":"MultiPoint","coordinates":[]} | I10: 7 | J10: =AVERAGEIFS($F:$F,$B:$B,J$3,$C:$C,$I10) -> 29.924425 | K10: =AVERAGEIFS($F:$F,$B:$B,K$3,$C:$C,$I10) -> 32.429488 | L10: =AVERAGEIFS($F:$F,$B:$B,L$3,$C:$C,$I10) -> 37.61657 | M10: =AVERAGEIFS($F:$F,$B:$B,M$3,$C:$C,$I10) -> 25.846181 | N10: =AVERAGEIFS($F:$F,$B:$B,N$3,$C:$C,$I10) -> 19.844823 | O10: =AVERAGEIFS($F:$F,$B:$B,O$3,$C:$C,$I10) -> 20.126628 | P10: =AVERAGEIFS($F:$F,$B:$B,P$3,$C:$C,$I10) -> 38.961447
A11: 9 | B11: 2018 | C11: 1 | D11: 5DC | E11: 1.274624e+09 | F11: 7.5054223 | G11: {"type":"MultiPoint","coordinates":[]} | I11: 8 | J11: =AVERAGEIFS($F:$F,$B:$B,J$3,$C:$C,$I11) -> 27.1474 | K11: =AVERAGEIFS($F:$F,$B:$B,K$3,$C:$C,$I11) -> 37.675389 | L11: =AVERAGEIFS($F:$F,$B:$B,L$3,$C:$C,$I11) -> 59.729476 | M11: =AVERAGEIFS($F:$F,$B:$B,M$3,$C:$C,$I11) -> 26.254575 | N11: =AVERAGEIFS($F:$F,$B:$B,N$3,$C:$C,$I11) -> 38.157077 | O11: =AVERAGEIFS($F:$F,$B:$B,O$3,$C:$C,$I11) -> 18.942843 | P11: =AVERAGEIFS($F:$F,$B:$B,P$3,$C:$C,$I11) -> 43.721023
A12: 10 | B12: 2018 | C12: 1 | D12: 5DB | E12: 1.292373e+09 | F12: 12.331483 | G12: {"type":"MultiPoint","coordinates":[]} | I12: 9 | J12: =AVERAGEIFS($F:$F,$B:$B,J$3,$C:$C,$I12) -> 18.698444 | K12: =AVERAGEIFS($F:$F,$B:$B,K$3,$C:$C,$I12) -> 24.268028 | L12: =AVERAGEIFS($F:$F,$B:$B,L$3,$C:$C,$I12) -> 24.732306 | M12: =AVERAGEIFS($F:$F,$B:$B,M$3,$C:$C,$I12) -> 19.269076 | N12: =AVERAGEIFS($F:$F,$B:$B,N$3,$C:$C,$I12) -> 27.043967 | O12: =AVERAGEIFS($F:$F,$B:$B,O$3,$C:$C,$I12) -> 19.479502 | P12: =AVERAGEIFS($F:$F,$B:$B,P$3,$C:$C,$I12) -> 10.434023
A13: 11 | B13: 2018 | C13: 1 | D13: 5AD | E13: 5.1993226e+08 | F13: 10.498103 | G13: {"type":"MultiPoint","coordinates":[]} | I13: 10 | J13: =AVERAGEIFS($F:$F,$B:$B,J$3,$C:$C,$I13) -> 51.682694 | K13: =AVERAGEIFS($F:$F,$B:$B,K$3,$C:$C,$I13) -> 156.117 | L13: =AVERAGEIFS($F:$F,$B:$B,L$3,$C:$C,$I13) -> 66.727722 | M13: =AVERAGEIFS($F:$F,$B:$B,M$3,$C:$C,$I13) -> 48.042658 | N13: =AVERAGEIFS($F:$F,$B:$B,N$3,$C:$C,$I13) -> 35.261166 | O13: =AVERAGEIFS($F:$F,$B:$B,O$3,$C:$C,$I13) -> 117.05309 | P13: =AVERAGEIFS($F:$F,$B:$B,P$3,$C:$C,$I13) -> 45.725117
A14: 12 | B14: 2018 | C14: 1 | D14: 5BD | E14: 6.769237e+08 | F14: 14.191052 | G14: {"type":"MultiPoint","coordinates":[]} | I14: 11 | J14: =AVERAGEIFS($F:$F,$B:$B,J$3,$C:$C,$I14) -> 62.536206 | K14: =AVERAGEIFS($F:$F,$B:$B,K$3,$C:$C,$I14) -> 195.49553 | L14: =AVERAGEIFS($F:$F,$B:$B,L$3,$C:$C,$I14) -> 65.85914 | M14: =AVERAGEIFS($F:$F,$B:$B,M$3,$C:$C,$I14) -> 56.472158 | N14: =AVERAGEIFS($F:$F,$B:$B,N$3,$C:$C,$I14) -> 90.960926 | O14: =AVERAGEIFS($F:$F,$B:$B,O$3,$C:$C,$I14) -> 214.07255 | P14: =AVERAGEIFS($F:$F,$B:$B,P$3,$C:$C,$I14) -> 110.09064
A15: 13 | B15: 2018 | C15: 1 | D15: 5ED | E15: 1.804048e+10 | F15: 1.1018667 | G15: {"type":"MultiPoint","coordinates":[]} | I15: 12 | J15: =AVERAGEIFS($F:$F,$B:$B,J$3,$C:$C,$I15) -> 115.12955 | K15: =AVERAGEIFS($F:$F,$B:$B,K$3,$C:$C,$I15) -> 111.2514 | L15: =AVERAGEIFS($F:$F,$B:$B,L$3,$C:$C,$I15) -> 32.061477 | M15: =AVERAGEIFS($F:$F,$B:$B,M$3,$C:$C,$I15) -> 68.565947 | N15: =AVERAGEIFS($F:$F,$B:$B,N$3,$C:$C,$I15) -> 41.914712 | O15: =AVERAGEIFS($F:$F,$B:$B,O$3,$C:$C,$I15) -> 30.891913 | P15: =AVERAGEIFS($F:$F,$B:$B,P$3,$C:$C,$I15) -> 19.967686
A16: 14 | B16: 2018 | C16: 1 | D16: 5FA | E16: 1.8521643e+10 | F16: 0.49120727 | G16: {"type":"MultiPoint","coordinates":[]}
A17: 15 | B17: 2018 | C17: 1 | D17: 5DA | E17: 2.2496159e+09 | F17: 9.9930818 | G17: {"type":"MultiPoint","coordinates":[]} | I17: TotalAnnual Rf | J17: =SUM(J4:J15) -> 926.30122 | K17: =SUM(K4:K15) -> 809.78471 | L17: =SUM(L4:L15) -> 853.86725 | M17: =SUM(M4:M15) -> 515.11811 | N17: =SUM(N4:N15) -> 465.27712 | O17: =SUM(O4:O15) -> 817.89257 | P17: =SUM(P4:P15) -> 715.86749
A18: 16 | B18: 2018 | C18: 1 | D18: 5BE | E18: 1.2433968e+09 | F18: 12.261721 | G18: {"type":"MultiPoint","coordinates":[]}
A19: 17 | B19: 2018 | C19: 1 | D19: 5BB | E19: 4.5181867e+08 | F19: 25.154459 | G19: {"type":"MultiPoint","coordinates":[]} | I19: WB_Area_sqkm | J19: 43 | K19: 43 | L19: 43 | M19: 43 | N19: 43 | O19: 43 | P19: 43
A20: 18 | B20: 2018 | C20: 1 | D20: 5BA | E20: 2.696955e+08 | F20: 23.607128 | G20: {"type":"MultiPoint","coordinates":[]} | I20: Basin_Area_sqkm | J20: 22507 | K20: 22507 | L20: 22507 | M20: 22507 | N20: 22507 | O20: 22507 | P20: 22507
A21: 19 | B21: 2018 | C21: 1 | D21: 5J | E21: 2.9390707e+10 | F21: 1.0522616 | G21: {"type":"MultiPoint","coordinates":[]} | I21: proportion(WB/BA)
A22: 20 | B22: 2018 | C22: 1 | D22: 5CC | E22: 3.0196649e+09 | F22: 5.2020704 | G22: {"type":"MultiPoint","coordinates":[]} | I22: TotalRf_mm | J22: =J17 -> 926.30122 | K22: =K17 -> 809.78471 | L22: =L17 -> 853.86725 | M22: =M17 -> 515.11811 | N22: =N17 -> 465.27712 | O22: =O17 -> 817.89257 | P22: =P17 -> 715.86749
A23: 21 | B23: 2018 | C23: 1 | D23: 5CA | E23: 2.3515078e+09 | F23: 7.9060294 | G23: {"type":"MultiPoint","coordinates":[]} | I23: Rainfall_MCM_on_Lake | J23: =(J22*100*J19*10)/1000000 -> 39.830952 | K23: =(K22*100*K19*10)/1000000 -> 34.820742 | L23: =(L22*100*L19*10)/1000000 -> 36.716292 | M23: =(M22*100*M19*10)/1000000 -> 22.150079 | N23: =(N22*100*N19*10)/1000000 -> 20.006916 | O23: =(O22*100*O19*10)/1000000 -> 35.169381 | P23: =(P22*100*P19*10)/1000000 -> 30.782302
A24: 22 | B24: 2018 | C24: 1 | D24: 5AC | E24: 1.0899844e+09 | F24: 9.0474237 | G24: {"type":"MultiPoint","coordinates":[]} | I24: BASIN_MAR
A25: 23 | B25: 2018 | C25: 1 | D25: 5AA | E25: 1.2516992e+09 | F25: 14.596663 | G25: {"type":"MultiPoint","coordinates":[]}
A26: 24 | B26: 2018 | C26: 1 | D26: 5AB | E26: 4.8411462e+08 | F26: 16.323228 | G26: {"type":"MultiPoint","coordinates":[]}
A27: 25 | B27: 2018 | C27: 1 | D27: 5BC | E27: 1.6448147e+09 | F27: 15.137008 | G27: {"type":"MultiPoint","coordinates":[]}
A28: 26 | B28: 2018 | C28: 2 | D28: 5H | E28: 6.6565798e+09 | F28: 11.777523 | G28: {"type":"MultiPoint","coordinates":[]}
A29: 27 | B29: 2018 | C29: 2 | D29: 5GA | E29: 2.2453045e+10 | F29: 9.9432017 | G29: {"type":"MultiPoint","coordinates":[]}
A30: 28 | B30: 2018 | C30: 2 | D30: 5GB | E30: 3.3554558e+09 | F30: 1.9582586 | G30: {"type":"MultiPoint","coordinates":[]}
A31: 29 | B31: 2018 | C31: 2 | D31: 5EB | E31: 2.7218095e+10 | F31: 14.242342 | G31: {"type":"MultiPoint","coordinates":[]}
A32: 30 | B32: 2018 | C32: 2 | D32: 5EC | E32: 2.9429244e+10 | F32: 8.3027825 | G32: {"type":"MultiPoint","coordinates":[]}
A33: 31 | B33: 2018 | C33: 2 | D33: 5EA | E33: 2.5314563e+10 | F33: 6.1159285 | G33: {"type":"MultiPoint","coordinates":[]}
A34: 32 | B34: 2018 | C34: 2 | D34: 5CB | E34: 2.2694165e+09 | F34: 6.5834628 | G34: {"type":"MultiPoint","coordinates":[]}
A35: 33 | B35: 2018 | C35: 2 | D35: 5FB | E35: 8.2153523e+09 | F35: 1.2159363 | G35: {"type":"MultiPoint","coordinates":[]}
A36: 34 | B36: 2018 | C36: 2 | D36: 5DD | E36: 1.8916824e+09 | F36: 5.6002371 | G36: {"type":"MultiPoint","coordinates":[]}
... A2185: 2183 | B2185: 2024 | C2185: 12 | D2185: 5BC | E2185: 1.6448147e+09 | F2185: 38.186941 | G2185: {"type":"MultiPoint","coordinates":[]}

Sheet Cover Page
F4: DRAFT Kenya Water Asset Accounts at Basin Level
J9: Version 1.3 | L9: 12-07-2025
J11: Prepared For:
J24: Prepared By:
J35: Contact People:
I37: Bernice Macquela b.macquela@primeafrica.net | L37: Jackie Crafford j.crafford@primeafrica.net

Sheet Colour Coding
B2: Data Cell Colour Codes within Water Accounts
B3: White | C3: Expected empty cells
B4: Grey | C4: Not applicable
B5: Green | C5: Official statistics from reputable data sources
B6: Light Green | C6: Data estimates by based on official statistics
B7: Orange | C7: Data derived from Green and Light Green statistics
B8: Red | C8: Literature estimates
B10: Data Text Colour Codes within Water Accounts
B11: Black Text | C11: Calculations
B12: Blue Text | C12: Data entered from data input sources
B13: Red Text | C13: Work in progress
B15: Tab Colour Codes within Water Accounts
B16: Yellow | C16: Work in progress
B17: Data Inputs | C17: Data entered from data input sources
B18: Output Tables | C18: Water Accounts

Sheet Notes to Water Accounts
B3: Notes for the Water Accounts
B4: General Framework
B5: 1 | C5: Data for the water accounts is drawn from multiple sources, including WRA reports, WASREB data, Chirp Data and basin-level hydrological assessments. While these sources vary in format, scope, and temporal resolution, efforts were made to ensure consistency through appropriate standardization and cross-referencing. In some cases, approximations were necessary to enable alignment across datasets.
B6: 2 | C6: The water accounts have been prepared for the years 2021 and 2023, consistent with the water Supply and Use Tables (SUTs).
B7: 3 | C7: All flows are reported in Million Cubic Metres per Annum (MCM/a).
B10: Methodology and Assumptions for Opening Stocks
B11: 4 | C11: Lakes and dams: Opening stocks are based on storage capacity, due to lack of observed level data.
B12: 5 | C12: Rivers: Represented by the Mean Annual Runoff (MAR) for each year.
B13: 6 | C13: Groundwater: Stocks reflect potential groundwater recharge. Additional recharge is based on abstrcated per year
B16: Data Inputs and Hydrological Components
B17: 7 | C17: The precipitation data was modelled using CHIRPs and was compared with basin level reports
