Workbook
Name DBDef1: #REF!
Name DBDef2: #REF!
Name DBDef2a: #REF!
Name DBDef3: #REF!
Name DBLinks: #REF!
Name dbsourcefiles: #REF!
Name FinalUse: #REF!
Name Input_A: #REF!
Name Output: #REF!
Name Prod_acc: #REF!
Name Supply: #REF!
Name TabDef1: #REF!
Name TabDef2: #REF!
Name TabDef3: #REF!
Name TabDef4: #REF!

Sheet Cover Page
F4: Kenya Water Accounts V2
J9: 20-06-2025
J11: Prepared For:
J24: Prepared By:
J35: Contact People:
I37: Bernice Macquela b.macquela@primeafrica.net | L37: Jackie Crafford j.crafford@primeafrica.net

Sheet Colour coding
B2: Data Cell Colour Codes within Water Accounts
B3: White | C3: Expected empty cells
B4: Green | C4: Official statistics from KNBS and other government departments
B5: Light Green | C5: Data estimates by KNBS and other government departments based on official statistics
B6: Orange | C6: Data derived from Green and Light Green statistics
B7: Red | C7: Literature estimates
B9: Data Text Colour Codes within Water Accounts
B10: Black Text | C10: Calculations
B11: Blue Text | C11: Data entered from data input sources
B12: Red Text | C12: Work in progress
B14: Tab Colour Codes within Water Accounts
B15: Yellow | C15: Work in progress
B16: Data Inputs | C16: Data entered from data input sources
B17: Output Tables | C17: Water IO tables and SUTs
B18: 2022 Output Tables | C18: Problematic Data, Recommend not to publish

Sheet Notes to Water Accounts
D3: Notes
C4: 1 | D4: This spreadsheet contains comments using the Excel comment function.The comments report on data problems identified, any key assumptions made, and other matters that need clarification.
C5: 2 | D5: These accounts were constructed using data reported for the Kenya government financial year which is from July to June. Key Data sources were from the Water Resources Authority (WRA) and WASREB. This data is available for 2021 and 2023. Some data is available for 2022 however, WRA data was reported on a calendar year basis, and in addition is not a full dataset as a result of a data loss that occured during a database migration in 2022.
C6: 3 | D6: For the reasons explained above the 2022 water SUT data is problematic and we recommend against it's publication.
C7: 4 | D7: The Irrigation data received from the WRA does not include all the irrigation schemes therefore this still needs to be reconciled with all the hectares of irrigated land within the country. This is still work in progress
C8: 5 | D8: Sewerage treatment data is problematic. The data is reported by WASREB. The 2021 WASREB data appears most comprehensive, and for this reason we used the 2021 WASREB sewerage volumes because for the 2023 SUT.
C9: 6 | D9: The 2023 WRA data reports an extremely high Household surface water value, and is likely erroneous. Needs verification from WRA.
C10: 7 | D10: Different datasets sourced from WRA reported vast differences in hydropower water requirements, varying by an order of magnitude. The values used, were the lower end values as reported officially on the WRA website.

Sheet Metadata and definitions 
B2: Data Sources
A3: 1 | B3: Water Resources Authority (WRA) Data for 2021-2023 - Database download received from WRA with data summarised by calendar year
A4: 2 | B4: Water Resources Authority (WRA) Data for 2021 & 2023 - data sourced from their performance reports
A5: 3 | B5: Water Services Regualtory Board (WASREB) Data for 2021-2023
A6: 4 | B6: National Irrigation Authority (NIA) Irrigation Data was received (not yet incorporated into the SUTs)
B10: Definitions
A11: 1 | B11: Non-Revenue Water | C11: Unbilled use by governmnet, water losses, water theft, water billed but not paid for

Sheet NIA Irrigation Data
A1: ANNUAL CROP PRODUCTION AND WATER USE DATA - PUBLIC IRRIGATION SCHEMES
E2: 2024 | K2: 2023 | N2: 2022 | Q2: 2021
B3: Irrigation Scheme | C3: County | D3: Crops | E3: Volume of Water Use (cubic meters) | F3: Area Cropped (acres) | G3: Area in Hectares | H3: Production (Tonnes) | I3: Volume of Use per Hectare | J3: Volume of Water use per production | K3: Volume of Water Use (cubic meters) | L3: Area Cropped (acres) | M3: Production (Tonnes) | N3: Volume of Water Use (cubic meters) | O3: Area Cropped (acres) | P3: Production (Tonnes) | Q3: Volume of Water Use (cubic meters) | R3: Area Cropped (acres) | S3: Production (Tonnes)
A4: 1 | B4: Mwea | C4: Kirinyaga | D4: Rice
B5: Main season 1 | E5: 143664192 | F5: 26485 | G5: =F5*$C$36 -> 10718.109 | H5: 66848 | I5: =E5/G5 -> 13403.875 | J5: =E5/H5 -> 2149.1173 | K5: 182492352 | L5: 26310 | M5: 66741 | N5: 133791264 | O5: 30600 | P5: 68268 | Q5: 152127496 | R5: 28100 | S5: 60282
B6: Crop season 2 | E6: 91971936 | F6: 26485 | G6: =F6*$C$36 -> 10718.109 | H6: 52239 | I6: =E6/G6 -> 8580.9856 | J6: =E6/H6 -> 1760.5991 | K6: 116829236 | L6: 26310 | M6: 18200 | N6: 78032160 | O6: 10000 | P6: 21492 | Q6: 86196960 | R6: 10492 | S6: 26200
B7: Ratoon | E7: 60419520 | F7: 26485 | G7: =F7*$C$36 -> 10718.109 | H7: 41120 | I7: =E7/G7 -> 5637.1438 | J7: =E7/H7 -> 1469.3463 | K7: 76749120 | L7: 26310 | M7: 33024 | N7: 45747072 | O7: 30600 | P7: 42000 | Q7: 47316096 | R7: 28100 | S7: 31000
A8: 2 | B8: Tana | C8: Tana River | D8: Rice, Maize
B9: Main season 1 | E9: 6158592 | F9: 3361 | G9: =F9*$C$36 -> 1360.1496 | H9: 6771 | I9: =E9/G9 -> 4527.8783 | J9: =E9/H9 -> 909.55428 | K9: 4800286 | L9: 2856 | M9: 4773 | N9: 2983168 | O9: 1084 | Q9: 476096 | R9: 173 | S9: 468
B10: Crop season 2 | E10: 3890240 | F10: 1989 | G10: =F10*$C$36 -> 804.92045 | H10: 3788 | J10: =E10/H10 -> 1026.9905 | K10: 2323443 | L10: 1268 | M10: 2155 | N10: 2064836 | O10: 987
B11: Ratoon
A12: 3 | B12: Bura | C12: Tana River | D12: Rice, Maize
B13: Main season 1 | E13: 29450328 | F13: 4200 | G13: =F13*$C$36 -> 1699.6812 | H13: 10940 | K13: 26763880 | L13: 4200 | M13: 11608 | N13: 5936866.4 | O13: 1987 | P13: 4967.5 | Q13: 5013619.4 | R13: 1678 | S13: 4195
B14: Crop season 2 | E14: 24465758 | F14: 2100 | G14: =F14*$C$36 -> 849.8406 | H14: 5764 | K14: 16095240 | L14: 2100 | M14: 4964 | N14: NIL | Q14: NIL
B15: Ratoon | N15: 5277214.6 | O15: 1987 | P15: 3170.2 | Q15: 4456550.6 | R15: 1678 | S15: 2684.8
A16: 4 | B16: Perkerra | C16: Baringo | D16: Maize
B17: Main season 1 | E17: 4950000 | F17: 1650 | G17: =F17*$C$36 -> 667.7319 | H17: 3600 | I17: =E17/G17 -> 7413.1549 | J17: =E17/H17 -> 1375 | K17: 4500000 | L17: 1500 | M17: 3200 | N17: 5000000 | O17: 2500 | P17: 4200 | Q17: 4400000 | R17: 2200
B18: Crop season 2 | E18: 1500000 | F18: 1250 | G18: =F18*$C$36 -> 505.8575 | H18: 550 | I18: =E18/G18 -> 2965.262 | J18: =E18/H18 -> 2727.2727 | K18: 1200000 | L18: 1000 | M18: 410 | N18: 900000 | O18: 750 | P18: 320 | Q18: 600000 | R18: 500
B19: Ratoon
A20: 5 | B20: Ahero | C20: Kisumu | D20: Rice
B21: Main season 1 | E21: 6870657 | F21: 2168 | G21: =F21*C36 -> 877.35925 | H21: 6829.2 | I21: =E21/G21 -> 7831.0647 | J21: =E21/H21 -> 1006.0705 | K21: 6621849 | L21: 2168 | M21: 7804.8 | N21: 6314083.2 | O21: 2168 | P21: 6070.4 | Q21: 6314083.2 | R21: 2168 | S21: 6937.6
B22: Crop season 2 | F22: 146 | H22: 275.94
B23: Ratoon
A24: 6 | B24: West Kano | C24: Kisumu | D24: Rice
B25: Main season 1 | E25: 5179300 | F25: 1550 | G25: =F25*$C$36 -> 627.2633 | H25: 4550.4 | I25: =E25/G25 -> 8256.9792 | J25: =E25/H25 -> 1138.2076 | K25: 5868320 | L25: 2055 | M25: 5797 | N25: 5899056 | O25: 2083 | P25: 6561.45 | Q25: 3738240 | R25: 1320 | S25: 3214
B26: Crop season 2 | N26: 801456 | O26: 283 | P26: 636750
B27: Ratoon
A28: 7 | B28: Bunyala | C28: Busia/Siaya | D28: Rice
B29: Main season 1 | E29: 4403442.4 | F29: 3126 | G29: =F29*$C$36 -> 1265.0484 | H29: 10467 | I29: =E29/G29 -> 3480.8489 | J29: =E29/H29 -> 420.69766 | K29: 4561768.8 | L29: 3126 | M29: 10324 | N29: =774882+900360+1092780+932580+692982+1003086 -> 5396670 | O29: 3226 | P29: 13024.9 | Q29: =908298+675684+689874+270270+499122+790668 -> 3833916 | R29: 2454 | S29: 7771.2
B30: Crop season 2 | E30: 5283863.4 | K30: 3993196.6 | N30: =1085562+512424+494134+536677.02+401098.5+652742.64 -> 3682638.2 | O30: 376 | Q30: =1113984+1381968+841068+906354+1026018+1178892 -> 6448284
B31: Ratoon
B32: Ratoon
B33: Total | E33: =SUM(E5:E32) -> 3.8820783e+08 | F33: =SUM(F5:F32) -> 100995 | N33: =SUM(N5:N30) -> 3.0182648e+08 | O33: =SUM(O5:O30) -> 88631 | Q33: =SUM(Q5:Q32) -> 3.2092134e+08 | R33: =SUM(R5:R32) -> 78863
B35: Acres | C35: Hectares | D35: Source
B36: 1 | C36: 0.404686 | D36: Google Calculator as at 20.06.2022

Sheet Irrigation Calculations
A1: Data Source | B1: Source: Economic Survey 2023 | I1: Source: Economic Survey 2023 | P1: Source: Economic Survey 2023
A2: Year | B2: 2021 | F2: Alternative estimate | I2: 2022 | M2: Alternative estimate | P2: 2023 | T2: Alternative estimate
A3: Crops Produced | B3: Volume Produced (in tonnes) | C3: In Kgs | D3: Average Water Use per ton (m3) | F3: Area under crop production (acres) | G3: Ave water use (m3/acre) | H3: Water Use m3 | I3: Volume Produced (in tonnes) | J3: In Kgs | K3: Average Water Use per Kg (litre per Kg) | M3: Area under crop production (acres) | N3: Ave water use (m3/acre) | O3: Water Use m3 | P3: Volume Produced (in tonnes) | Q3: In Kgs | R3: Average Water Use per Kg (litre per Kg) | T3: Area under crop production (acres) | U3: Ave water use (m3/acre) | V3: Water Use m3
A4: Rice - Irrigation | B4: ='[3]Table 7.15'!$F$24 -> 186000 | C4: =B4*[2]Notes!$B$68 -> 186000000 | D4: =AVERAGE('NIA Irrigation Data'!J5:J7,'NIA Irrigation Data'!J21,'NIA Irrigation Data'!J25,'NIA Irrigation Data'!J29) -> 1324.0064 | E4: =D4*C4 -> 2.4626519e+11 | H4: =E4/[2]Notes!$B$69 -> 2.4626519e+08 | I4: ='[3]Table 7.15'!$G$24 -> 192299 | J4: =I4*[2]Notes!$B$68 -> 192299000 | K4: =[2]Notes!I47 -> 0 | L4: =K4*J4 -> 0 | O4: =L4/[2]Notes!$B$69 -> 0 | P4: ='[3]Table 7.15'!$H$24 -> 229064 | Q4: =P4*[2]Notes!$B$68 -> 229064000 | R4: =[2]Notes!P47 -> 0 | S4: =R4*Q4 -> 0 | V4: =S4/[2]Notes!$B$69 -> 0
A5: Cut Flowers | B5: 210100 | C5: =B5*[2]Notes!$B$68 -> 210100000 | D5: =[2]Notes!B49 -> 2800 | E5: =D5*C5 -> 588280000000 | H5: =E5/[2]Notes!$B$69 -> 588280000 | I5: 202900 | J5: =I5*[2]Notes!$B$68 -> 202900000 | K5: =[2]Notes!I49 -> 0 | L5: =K5*J5 -> 0 | O5: =L5/[2]Notes!$B$69 -> 0 | P5: 221100 | Q5: =P5*[2]Notes!$B$68 -> 221100000 | R5: =[2]Notes!P49 -> 0 | S5: =R5*Q5 -> 0 | V5: =S5/[2]Notes!$B$69 -> 0
A6: Fruits | B6: 117300 | C6: =B6*[2]Notes!$B$68 -> 117300000 | D6: =[2]Notes!B51 -> 748 | E6: =D6*C6 -> 87740400000 | H6: =E6/[2]Notes!B69 -> 87740400 | I6: 113300 | J6: =I6*[2]Notes!$B$68 -> 113300000 | K6: =[2]Notes!I51 -> 0 | L6: =K6*J6 -> 0 | O6: =L6/[2]Notes!I69 -> #DIV/0! | P6: 131000 | Q6: =P6*[2]Notes!$B$68 -> 131000000 | R6: =[2]Notes!P51 -> 0 | S6: =R6*Q6 -> 0 | V6: =S6/[2]Notes!P69 -> #DIV/0!
A7: Vegetables | B7: 78100 | C7: =B7*[2]Notes!$B$68 -> 78100000 | D7: =[2]Notes!B50 -> 336 | E7: =D7*C7 -> 26241600000 | H7: =E7/[2]Notes!B69 -> 26241600 | I7: 75400 | J7: =I7*[2]Notes!$B$68 -> 75400000 | K7: =[2]Notes!I50 -> 0 | L7: =K7*J7 -> 0 | O7: =L7/[2]Notes!I69 -> #DIV/0! | P7: 78100 | Q7: =P7*[2]Notes!$B$68 -> 78100000 | R7: =[2]Notes!P50 -> 0 | S7: =R7*Q7 -> 0 | V7: =S7/[2]Notes!P69 -> #DIV/0!
A8: [Add new crop]
A9: [Add new crop]
A10: [Add new crop]
A11: [Add new crop]
A12: [Add new crop]
A13: [Add new crop]
A14: [Add new crop]
A15: [Add new crop]
B16: Total | H16: =SUM(H4:H7) -> 9.4852719e+08 | I16: Total | O16: =SUM(O4:O7) -> #DIV/0! | P16: Total | V16: =SUM(V4:V7) -> #DIV/0!

Sheet WRA Report Data
A1: Water use up to June 2023 (1000 m3/day)
A2: Basin | B2: Public_SW | C2: Public_GW | D2: Domestic_SW | E2: Domestic_GW | F2: Livestock_SW | G2: Livestock_GW | H2: Irrigation_SW | I2: Irrigation_GW | J2: Industrial_SW | K2: Industrial_GW | L2: Power_SW | M2: Power_GW | N2: Other_SW | O2: Other_GW | P2: Total
A3: LVN | B3: 134.62 | C3: 0.9325 | D3: 5526.04 | E3: 16.78 | F3: 2.03 | G3: 0.235 | H3: 11.4 | I3: 0.3 | J3: 224.45 | K3: 0.232 | L3: 411 | M3: 0 | N3: 12.466 | O3: 0.18 | P3: =SUM(B3:O3) -> 6340.6655
A4: LVS | B4: 104.84 | C4: 0.232 | D4: 7.192 | E4: 6.521 | F4: 0.102 | G4: 0.085 | H4: 17.546 | I4: 0.306 | J4: 24.63 | K4: 0.32 | L4: 2836.644 | M4: 0 | N4: 1.906 | O4: 0.09 | P4: =SUM(B4:O4) -> 3000.414
A5: RV | B5: 13.804 | C5: 65.111 | D5: 18.518 | E5: 26.464 | F5: 3.741 | G5: 2.479 | H5: 100.152 | I5: 268.269 | J5: 12.174 | K5: 3.334 | L5: 1658.509 | M5: 1.52 | N5: 13.06 | O5: 18.364 | P5: =SUM(B5:O5) -> 2205.499
A6: Athi | B6: 88.788 | C6: 60.364 | D6: 12.141 | E6: 111.543 | F6: 0.165 | G6: 2.819 | H6: 299.482 | I6: 33.984 | J6: 38.71 | K6: 33.91 | L6: 0.07 | M6: 1.48 | N6: 1.06 | O6: 1.854 | P6: =SUM(B6:O6) -> 686.37
A7: Tana | B7: 408.68 | C7: 107 | D7: 490.943 | E7: 108.184 | F7: 3.829 | G7: 1.82 | H7: 952.148 | I7: 2.2 | J7: 12.2 | K7: 0.16 | L7: 806.36 | M7: 0 | N7: 60.15 | O7: 1.1 | P7: =SUM(B7:O7) -> 2954.774
A8: ENN | B8: 31.233 | C8: 2.241 | D8: 61.898 | E8: 10.52 | F8: 8.32 | G8: 1.38 | H8: 116.92 | I8: 228.693 | J8: 1.068 | K8: 0.18 | L8: 0.07 | M8: 4.4 | N8: 5.715 | O8: 0 | P8: =SUM(B8:O8) -> 472.638
A9: Total | B9: =SUM(B3:B8) -> 781.965 | C9: =SUM(C3:C8) -> 235.8805 | D9: =SUM(D3:D8) -> 6116.732 | E9: =SUM(E3:E8) -> 280.012 | F9: =SUM(F3:F8) -> 18.187 | G9: =SUM(G3:G8) -> 8.818 | H9: =SUM(H3:H8) -> 1497.648 | I9: =SUM(I3:I8) -> 533.752 | ... P9: =SUM(P3:P8) -> 15660.361
A11: 2023 Water Use in Yearly Values (m3/year)
A12: Basin | B12: Public_SW | C12: Public_GW | D12: Domestic_SW | E12: Domestic_GW | F12: Livestock_SW | G12: Livestock_GW | H12: Irrigation_SW | I12: Irrigation_GW | J12: Industrial_SW | K12: Industrial_GW | L12: Power_SW | M12: Power_GW | N12: Other_SW | O12: Other_GW | P12: Total
A13: LVN | B13: =(B3*1000)*365 -> 49136300 | C13: =(C3*1000)*365 -> 340362.5 | D13: =(D3*1000)*365 -> 2017004600 | E13: =(E3*1000)*365 -> 6124700 | F13: =(F3*1000)*365 -> 740950 | G13: =(G3*1000)*365 -> 85775 | H13: =(H3*1000)*365 -> 4161000 | I13: =(I3*1000)*365 -> 109500 | ... O13: =(O3*1000)*365 -> 65700 | P13: =SUM(B13:O13) -> 2.3143429e+09
A14: LVS | B14: =(B4*1000)*365 -> 38266600 | C14: =(C4*1000)*365 -> 84680 | D14: =(D4*1000)*365 -> 2625080 | E14: =(E4*1000)*365 -> 2380165 | F14: =(F4*1000)*365 -> 37230 | G14: =(G4*1000)*365 -> 31025 | H14: =(H4*1000)*365 -> 6404290 | I14: =(I4*1000)*365 -> 111690 | ... O14: =(O4*1000)*365 -> 32850 | P14: =SUM(B14:O14) -> 1095151110
A15: RV | B15: =(B5*1000)*365 -> 5038460 | C15: =(C5*1000)*365 -> 23765515 | D15: =(D5*1000)*365 -> 6759070 | E15: =(E5*1000)*365 -> 9659360 | F15: =(F5*1000)*365 -> 1365465 | G15: =(G5*1000)*365 -> 904835 | H15: =(H5*1000)*365 -> 36555480 | I15: =(I5*1000)*365 -> 97918185 | ... O15: =(O5*1000)*365 -> 6702860 | P15: =SUM(B15:O15) -> 805007135
A16: Athi | B16: =(B6*1000)*365 -> 32407620 | C16: =(C6*1000)*365 -> 22032860 | D16: =(D6*1000)*365 -> 4431465 | E16: =(E6*1000)*365 -> 40713195 | F16: =(F6*1000)*365 -> 60225 | G16: =(G6*1000)*365 -> 1028935 | H16: =(H6*1000)*365 -> 109310930 | I16: =(I6*1000)*365 -> 12404160 | ... O16: =(O6*1000)*365 -> 676710 | P16: =SUM(B16:O16) -> 250525050
A17: Tana | B17: =(B7*1000)*365 -> 149168200 | C17: =(C7*1000)*365 -> 39055000 | D17: =(D7*1000)*365 -> 179194195 | E17: =(E7*1000)*365 -> 39487160 | F17: =(F7*1000)*365 -> 1397585 | G17: =(G7*1000)*365 -> 664300 | H17: =(H7*1000)*365 -> 347534020 | I17: =(I7*1000)*365 -> 803000 | ... O17: =(O7*1000)*365 -> 401500 | P17: =SUM(B17:O17) -> 1078492510
A18: ENN | B18: =(B8*1000)*365 -> 11400045 | C18: =(C8*1000)*365 -> 817965 | D18: =(D8*1000)*365 -> 22592770 | E18: =(E8*1000)*365 -> 3839800 | F18: =(F8*1000)*365 -> 3036800 | G18: =(G8*1000)*365 -> 503700 | H18: =(H8*1000)*365 -> 42675800 | I18: =(I8*1000)*365 -> 83472945 | ... O18: =(O8*1000)*365 -> 0 | P18: =SUM(B18:O18) -> 172512870
A19: Total | B19: =SUM(B13:B18) -> 285417225 | C19: =SUM(C13:C18) -> 86096382 | D19: =SUM(D13:D18) -> 2232607180 | E19: =SUM(E13:E18) -> 102204380 | F19: =SUM(F13:F18) -> 6638255 | G19: =SUM(G13:G18) -> 3218570 | H19: =SUM(H13:H18) -> 546641520 | I19: =SUM(I13:I18) -> 194819480 | ... P19: =SUM(P13:P18) -> 5.7160316e+09
A23: Calculations of Values for Industry, Domestic, Public and Other own supply values outside of WASREB supply
A24: Sector | B24: Surface Water | C24: % of total | D24: Derived Own Supply (% of Water left after WASREB deduction)
A25: Industrial | B25: =J19 -> 114329680 | C25: =B25/$B$29 -> 0.042871577 | D25: =($B$29-$B$31)*C25 -> 94886040
A26: Public | B26: =B19 -> 285417225 | C26: =B26/$B$29 -> 0.10702633 | D26: =($B$29-$B$31)*C26 -> 2.3687734e+08
A27: Domestic | B27: =D19 -> 2232607180 | C27: =B27/$B$29 -> 0.83718759 | D27: =($B$29-$B$31)*C27 -> 1.8529157e+09
A28: Other | B28: =N19 -> 34440305 | C28: =B28/$B$29 -> 0.012914496 | D28: =($B$29-$B$31)*C28 -> 28583165
A29: Total | B29: =SUM(B25:B28) -> 2666794390
A31: WASREB Total | B31: =SUM('Ph IO Table 2023'!H4) -> 4.5353219e+08
A32: Total | B32: =SUM(B19:E19,J19:K19,N19:O19) -> 2.8768944e+09
A35: Water Use Up to June 2021 (1000 m3/day)
A36: Basin | B36: Public_SW | C36: Public_GW | D36: Domestic_SW | E36: Domestic_GW | F36: Livestock_SW | G36: Livestock_GW | H36: Irrigation_SW | I36: Irrigation_GW | J36: Industrial_SW | K36: Industrial_GW | L36: Power_SW | M36: Power_GW | N36: Other_SW | O36: Other_GW | P36: Total
A37: LVN | B37: 88.15 | C37: 0.92 | D37: 10.04 | E37: 16.29 | F37: 2.03 | G37: 0.23 | H37: 11.1 | I37: 0.29 | J37: 123.3 | K37: 0.23 | L37: 411.5 | M37: 0 | N37: 12.4 | O37: 0.18 | P37: =SUM(B37:O37) -> 676.66
A38: LVS | B38: 104.75 | C38: 0.23 | D38: 6.64 | E38: 6.04 | F38: 0.012 | G38: 0.08 | H38: 17.14 | I38: 0.12 | J38: 24.12 | K38: 0.31 | L38: 2646.5 | M38: 0.01 | N38: 1.9 | O38: 0.09 | P38: =SUM(B38:O38) -> 2807.942
A39: RV | B39: 8.61 | C39: 64.5 | D39: 5.75 | E39: 22.8 | F39: 3.6 | G39: 1.9 | H39: 55.04 | I39: 202.24 | J39: 3.24 | K39: 0.47 | L39: 1657.9 | M39: 0.32 | N39: 6.18 | O39: 8 | P39: =SUM(B39:O39) -> 2040.55
A40: Athi | B40: 84.2 | C40: 60 | D40: 12 | E40: 102.33 | F40: 0.16 | G40: 2.44 | H40: 288.14 | I40: 31.16 | J40: 38.33 | K40: 31.4 | L40: 0.07 | M40: 1.48 | N40: 1.06 | O40: 1.75 | P40: =SUM(B40:O40) -> 654.52
A41: Tana | B41: 407.8 | C41: 10.7 | D41: 488.2 | E41: 10.7 | F41: 3.7 | G41: 1.8 | H41: 934.9 | I41: 1.9 | J41: 12.1 | K41: 0.14 | L41: 806.28 | M41: 0 | N41: 60.1 | O41: 1.1 | P41: =SUM(B41:O41) -> 2739.42
A42: ENN | B42: 30.6 | C42: 2.23 | D42: 45.3 | E42: 8.7 | F42: 6.5 | G42: 0.99 | H42: 101.9 | I42: 22 | J42: 4.4 | K42: 0.71 | L42: 0.07 | M42: 4.4 | N42: 0.165 | O42: 0 | P42: =SUM(B42:O42) -> 227.965
A43: Total | B43: =SUM(B37:B42) -> 724.11 | C43: =SUM(C37:C42) -> 138.58 | D43: =SUM(D37:D42) -> 567.93 | E43: =SUM(E37:E42) -> 166.86 | F43: =SUM(F37:F42) -> 16.002 | G43: =SUM(G37:G42) -> 7.44 | H43: =SUM(H37:H42) -> 1408.22 | I43: =SUM(I37:I42) -> 257.71 | ... P43: =SUM(P37:P42) -> 9147.057
A45: 2021 Water Use in Yearly Values (m3/year)
A46: Basin | B46: Public_SW | C46: Public_GW | D46: Domestic_SW | E46: Domestic_GW | F46: Livestock_SW | G46: Livestock_GW | H46: Irrigation_SW | I46: Irrigation_GW | J46: Industrial_SW | K46: Industrial_GW | L46: Power_SW | M46: Power_GW | N46: Other_SW | O46: Other_GW | P46: Total
A47: LVN | B47: =(B37*1000)*365 -> 32174750 | C47: =(C37*1000)*365 -> 335800 | D47: =(D37*1000)*365 -> 3664600 | E47: =(E37*1000)*365 -> 5945850 | F47: =(F37*1000)*365 -> 740950 | G47: =(G37*1000)*365 -> 83950 | H47: =(H37*1000)*365 -> 4051500 | I47: =(I37*1000)*365 -> 105850 | ... O47: =(O37*1000)*365 -> 65700 | P47: =SUM(B47:O47) -> 246980900
A48: LVS | B48: =(B38*1000)*365 -> 38233750 | C48: =(C38*1000)*365 -> 83950 | D48: =(D38*1000)*365 -> 2423600 | E48: =(E38*1000)*365 -> 2204600 | F48: =(F38*1000)*365 -> 4380 | G48: =(G38*1000)*365 -> 29200 | H48: =(H38*1000)*365 -> 6256100 | I48: =(I38*1000)*365 -> 43800 | ... O48: =(O38*1000)*365 -> 32850 | P48: =SUM(B48:O48) -> 1024898830
...

Sheet WASREB 20-21
A1: Data Source | B1: WASREB | C1: m3
A2: County | B2: Vihiga | C2: Bomet | D2: Busia | E2: Baringo | F2: Uasin Gishu | G2: Mandera | H2: Embu | I2: Embu | J2: Garissa | K2: Murang'a | L2: Murang'a | M2: Kiambu | N2: Kiambu | O2: Gusii | P2: Homabay | Q2: Meru | R2: Isiolo | S2: Murang'a | T2: Kakamega | U2: Kiambu | V2: Machakos | W2: Kericho | X2: Kitui | Y2: Kiambu | Z2: Makueni | AA2: Kiambu | AB2: Kilifi | AC2: Baringo | AD2: Kirinyaga | AE2: Kisumu | AF2: Kitui | AG2: Kwale | AH2: Embu | AI2: Kiambu | AJ2: Turkana | AK2: Machakos | AL2: Kilifi | AM2: Mandera | AN2: Nyeri | AO2: Machakos | AP2: Machakos | AQ2: Makueni | AR2: Meru | AS2: Migori | AT2: Mombasa | AU2: Murang'a | AV2: Murang'a | AW2: Tharaka-Nithi | AX2: Machakos | AY2: Nairobi | AZ2: Nakuru | BA2: Nakuru | BB2: Nakuru | BC2: Lakipia | BD2: Narok | BE2: Embu | BF2: Embu | BG2: Tharaka-Nithi | BH2: Kajiado | BI2: Laikipia | BJ2: Migori | BK2: Nyeri | BL2: Bungoma | BM2: Kajiado | BN2: Kajiado | BO2: Nyeri | BP2: Kiambu | BQ2: Kirinyaga | BR2: Siaya | BS2: Nandi | BT2: Taita-Taveta | BU2: Nyeri | BV2: Kiambu | BW2: Meru | BX2: Machakos | BY2: Elgeiyo Marakwet | BZ2: West Pokot | CA2: Nandi | CB2: Kiambu | CC2: Lamu | CD2: Tharaka-Nithi | CE2: Nyeri | CF2: Nyandarua | CG2: Nyandarua | CH2: Nairobi | CI2: Samburu | CJ2: Tana River | CK2: Kiambu | CL2: Wajir | CM2: Makueni | CO2: Totals
A3: INDICATORS | B3: Amatsi | C3: Bomet | D3: Busia | E3: Chemususu | F3: Eldoret | G3: Elwak | H3: Embe | I3: Embu | J3: Garissa | K3: Gatamathi | L3: Gatanga | M3: Gatundu | N3: Githunguri | O3: Gusii | P3: Homabay | Q3: Imetha | R3: Isiolo | S3: Kahuti | T3: Kakamega | U3: Karuri | V3: Kathiani | W3: Kericho | X3: Kiambere Mwingi | Y3: Kiamumbi | Z3: Kibwezi Makindu | AA3: Kikuyu | AB3: Kilifi Mariakani | AC3: Kirandich | AD3: Kirinyaga | AE3: Kisumu | AF3: Kitui | AG3: Kwale | AH3: Kyeni | AI3: Limuru | AJ3: Lodwar | AK3: Machakos | AL3: Malindi | AM3: Mandera | AN3: Mathira | AO3: Matungulu Kangundo | AP3: Mavoko | AQ3: Mbooni | AR3: Meru | AS3: Migori | AT3: Mombasa | AU3: Murang'a | AV3: Murang'a South | AW3: Murugi Mugumango | AX3: Mwala | AY3: Nairobi | AZ3: Naivasha | BA3: Nakuru | BB3: Nakuru Rural | BC3: Nanyuki | BD3: Narok | BE3: Ngagaka | BF3: Ngandori Nginda | BG3: Nithi | BH3: Nol Turesh Loitokitok | BI3: Nyahururu | BJ3: Nyasare | BK3: Nyeri | BL3: Nzoia | BM3: Olkejuado | BN3: Oloolaiser | BO3: Othaya Mukurweni | BP3: Ruiru-Juja | BQ3: Rukanga | BR3: Sibo | BS3: Tachasis | BT3: Tavevo | BU3: Tetu Aberdare | BV3: Thika | BW3: Tuuru | BX3: Yatta | BY3: Iten Tambach | BZ3: Kapenguria | CA3: Kapsabet Nandi | CB3: Kiambu | CC3: Lamu | CD3: Muthambi 4K | CE3: Naromoru | CF3: Nyandarua | CG3: Ol Kalou | CH3: Runda | CI3: Samburu | CJ3: Tana | CK3: Tatu City | CL3: Wajir | CM3: Wote
A4: Surface water abstracted | B4: 1573007 | C4: 4424004 | D4: 1207650 | E4: 850153 | F4: 15290495 | G4: 349920 | H4: 1034205 | I4: 7637891 | J4: 5961600 | K4: 2790003 | L4: 2273106 | M4: 7169376 | N4: 1183987 | O4: 3231652 | P4: 1018819 | Q4: 1184866 | R4: 2286780 | S4: 3335937 | T4: 5432762 | U4: 1410393 | V4: 100541 | W4: 4100926 | X4: 974979 | Y4: 523274 | Z4: 1298437 | AA4: 0 | AB4: 0 | AC4: 1036000 | AD4: 6722945 | AE4: 9915691 | AF4: 3626236 | AG4: 0 | AH4: 1039740 | AI4: 2148401 | AJ4: 2304940 | AK4: 1242862 | AL4: 0 | AM4: 582496 | AN4: 2281551 | AO4: =AO10 -> 153695 | AP4: 960832 | AQ4: 64972 | AR4: 3001251 | AS4: 481921 | AT4: 0 | AU4: 2742691 | AV4: 5690163 | AW4: 2214840 | AX4: 51337 | AY4: 193642797 | AZ4: 1899235 | BA4: 11537195 | BB4: 8242189 | BC4: 4551704 | BD4: 882905 | BE4: 1157580 | BF4: 2758450 | BG4: 3700773 | BH4: 2190000 | BI4: 3184387 | BJ4: 114293 | BK4: 7401710 | BL4: 8265495 | BM4: 0 | BN4: 1792633 | BO4: 5460800 | BP4: 10747235 | BQ4: 384030 | BR4: 3224003 | BS4: 350447 | BT4: 0 | BU4: 3028040 | BV4: 13172207 | BW4: 1885587 | BX4: 389392 | BY4: 1168859 | BZ4: 243026 | CA4: 1085366 | CB4: 2132758 | CC4: 600563 | CD4: 648456 | CE4: 269700 | CF4: 659793 | CG4: 621290 | CH4: 834833 | CI4: 648000 | CJ4: 1908000 | CK4: 136818 | CL4: =CL14 -> 571536 | CM4: 181233 | CO4: =SUM(B4:CM4) -> 424580645
A5: Groundwater abstracted | N5: 256968 | R5: 76160 | T5: 274551 | U5: 779729 | AA5: 2507323 | AK5: 21120 | AP5: 99230 | AX5: 32196 | AZ5: 1974833 | BC5: 109546 | BJ5: 25979 | BM5: 357800 | BN5: 654586 | BT5: 408110 | CB5: 215399 | CF5: 28928 | CM5: 278132 | CO5: =SUM(B5:CM5) -> 8100590
A6: Total volume of water treated | J6: 5166915 | K6: 2790003 | R6: 0 | Y6: 465132 | AA6: 2507323 | AK6: 1208832 | AL6: 0 | AO6: 0 | AU6: 2742691 | AX6: 115101 | AY6: 179341134 | BC6: 4661250 | BI6: 3180625 | BJ6: 0 | BK6: 7401710 | BM6: 0 | BN6: 1792633 | BS6: 0 | BU6: 1010520 | BX6: 389392 | BY6: 1168859 | CB6: 2132758 | CF6: 267731 | CM6: =SUM(CM4:CM5) -> 459365 | CO6: =SUM(B6:CM6) -> 216801974
A7: Imported treated water | J7: 0 | K7: 0 | R7: 0 | Y7: 0 | AA7: 0 | AB7: 11231993 | AG7: 4521589 | AK7: 0 | AL7: 6886695 | AO7: 0 | AT7: 12495475 | AU7: 0 | AX7: 0 | AY7: 0 | BC7: 0 | BI7: 0 | BJ7: 0 | BK7: 0 | BM7: 0 | BN7: 0 | BS7: 0 | BT7: 5357895 | BU7: 0 | BX7: 0 | BY7: 0 | CB7: 819034 | CF7: 50287 | CM7: 0 | CO7: =SUM(B7:CM7) -> 41362968
A8: Exported treated water | J8: 0 | K8: 0 | R8: 0 | Y8: 0 | AA8: 0 | AK8: 0 | AL8: 0 | AO8: 0 | AU8: 0 | AX8: 0 | AY8: 0 | BC8: 0 | BI8: 0 | BJ8: 0 | BK8: 0 | BM8: 0 | BN8: 0 | BS8: 0 | BU8: 0 | BX8: 0 | BY8: 0 | CB8: 0 | CF8: 0 | CM8: 0 | CO8: =SUM(B8:CM8) -> 0
A9: Metered volume produced | B9: 1573007 | C9: 4424004 | D9: 1207650 | E9: 850153 | F9: 15290495 | G9: 349920 | H9: 1034205 | I9: 7637891 | J9: 0 | K9: 2790003 | L9: 2273106 | M9: 7169376 | N9: 1183987 | O9: 3231652 | P9: 1018819 | Q9: 1184866 | R9: 2362940 | S9: 3335937 | T9: 5432762 | U9: 1410393 | V9: 100541 | W9: 4100926 | X9: 974979 | Y9: 465132 | Z9: 1298437 | AA9: 2507323 | AB9: 11231993 | AC9: 1036000 | AD9: 6722945 | AE9: 9915691 | AF9: 3626236 | AG9: 4521589 | AH9: 1039740 | AI9: 2148401 | AJ9: 2304940 | AK9: 1208832 | AL9: 6886695 | AM9: 582496 | AN9: 2281551 | AO9: 119125 | AP9: 960832 | AQ9: 64972 | AR9: 3001251 | AS9: 481921 | AT9: 12495475 | AU9: 2742691 | AV9: 5690163 | AW9: 2214840 | AX9: 115101 | AY9: 179341134 | AZ9: 1899235 | BA9: 11537195 | BB9: 8242189 | BC9: 4661250 | BD9: 882905 | BE9: 1157580 | BF9: 2758450 | BG9: 3700773 | BH9: 2190000 | BI9: 3180625 | BJ9: 0 | BK9: 7401710 | BL9: 8265495 | BM9: 357800 | BN9: 2447219 | BO9: 5460800 | BP9: 10747235 | BQ9: 384030 | BR9: 3224003 | BS9: 0 | BT9: 5357895 | BU9: 1990520 | BV9: 13172207 | BW9: 1885587 | BX9: 389392 | BY9: 1168859 | BZ9: 243026 | CA9: 1085366 | CB9: 3162191 | CC9: 600563 | CD9: 648456 | CE9: 269700 | CF9: 657679 | CG9: 621290 | CH9: 834833 | CI9: 648000 | CJ9: 1908000 | CK9: 136818 | CL9: n.d. | CM9: 459365 | CO9: =SUM(B9:CM9) -> 447681359
A10: Total Water Produced | B10: 1573007 | C10: 4424004 | D10: 1207650 | E10: 850153 | F10: 15290495 | G10: 349920 | H10: 1034205 | I10: 7637891 | J10: 5961600 | K10: 2790003 | L10: 2273106 | M10: 7169376 | N10: =SUM(N4:N5,N7) -> 1440955 | O10: 3231652 | P10: 1018819 | Q10: 1184866 | R10: 2362940 | S10: 3335937 | T10: =SUM(T4:T5,T7) -> 5707313 | U10: =SUM(U4:U5,U7) -> 2190122 | V10: 100541 | W10: 4100926 | X10: 974979 | Y10: =SUM(Y4:Y5,Y7) -> 523274 | Z10: 1298437 | AA10: 2507323 | AB10: 11231993 | AC10: 1036000 | AD10: 6722945 | AE10: 9915691 | AF10: 3626236 | AG10: 4521589 | AH10: 1039740 | AI10: 2148401 | AJ10: 2304940 | AK10: 1263982 | AL10: 6886695 | AM10: 582496 | AN10: 2281551 | AO10: 153695 | AP10: =SUM(AP4:AP5,AP7) -> 1060062 | AQ10: 64972 | AR10: 3001251 | AS10: 481921 | AT10: 12495475 | AU10: 2742691 | AV10: 5690163 | AW10: 2214840 | AX10: =SUM(AX4:AX5,AX7) -> 83533 | AY10: =SUM(AY4:AY5,AY7) -> 193642797 | AZ10: =SUM(AZ4:AZ5,AZ7) -> 3874068 | BA10: 11537195 | BB10: 8242189 | BC10: 4661250 | BD10: 882905 | BE10: 1157580 | BF10: 2758450 | BG10: 3700773 | BH10: 2190000 | BI10: 3184387 | BJ10: 140272 | BK10: 7401710 | BL10: 8265495 | BM10: =SUM(BM4:BM5,BM7) -> 357800 | BN10: 2447219 | BO10: 5460800 | BP10: 10747235 | BQ10: 384030 | BR10: 3224003 | BS10: 350447 | BT10: =SUM(BT4:BT5,BT7) -> 5766005 | BU10: 3028040 | BV10: 13172207 | BW10: 1885587 | BX10: 389392 | BY10: 1168859 | BZ10: 243026 | CA10: 1085366 | CB10: 3167191 | CC10: 600563 | CD10: 648456 | CE10: 269700 | CF10: 739008 | CG10: 621290 | CH10: 834833 | CI10: 648000 | CJ10: 1908000 | CK10: 136818 | CL10: =SUM(CL4:CL5,CL7) -> 571536 | CM10: 459365 | CO10: =SUM(B10:CM10) -> 474044203
B11: =SUM(B4:B5,B7)-B10 -> 0 | C11: =SUM(C4:C5,C7)-C10 -> 0 | D11: =SUM(D4:D5,D7)-D10 -> 0 | E11: =SUM(E4:E5,E7)-E10 -> 0 | F11: =SUM(F4:F5,F7)-F10 -> 0 | G11: =SUM(G4:G5,G7)-G10 -> 0 | H11: =SUM(H4:H5,H7)-H10 -> 0 | I11: =SUM(I4:I5,I7)-I10 -> 0 | ... CM11: =SUM(CM4:CM5,CM7)-CM10 -> 0
A12: Value of Water Abstracted/ Produced | B12: 73930703 | C12: 240039575 | D12: 79258129 | E12: 23063224 | F12: 7.1223858e+08 | G12: 79772794 | H12: 38597578 | I12: 3.6295737e+08 | J12: 4.6772077e+08 | K12: 60579777 | L12: 58531874 | M12: 136723929 | N12: 70805791 | O12: 1.7539918e+08 | P12: 97875348 | Q12: 56402541 | R12: 82307738 | S12: 76336089 | T12: 2.4503747e+08 | U12: 109157959 | V12: 14266064 | W12: 263530219 | X12: 135178025 | Y12: 22573822 | Z12: 86202402 | AA12: 139042955 | AB12: 5.6720057e+08 | AC12: 59753784 | AD12: 175178481 | AE12: 8.2584084e+08 | AF12: 278521048 | AG12: 208215827 | AH12: 16654271 | AI12: 141350626 | AJ12: 54230924 | AK12: 130523129 | AL12: 556219860 | AM12: 1.7856676e+08 | AN12: 148496925 | AO12: 16952185 | AP12: 208513398 | AQ12: 5071016 | AR12: 2.155529e+08 | AS12: 51740623 | AT12: 913363452 | AU12: 2.2835782e+08 | AV12: 228667569 | AW12: 21187941 | AX12: 18538604 | AY12: 6.7833619e+09 | AZ12: 93019470 | BA12: 8.2898502e+08 | BB12: 314924993 | BC12: 3.9550335e+08 | BD12: 110004557 | BE12: 38340240 | BF12: 69827129 | BG12: 110540087 | BH12: 69932275 | BI12: 2.219596e+08 | BJ12: 4239561 | BK12: 4.5253676e+08 | BL12: 3.3822517e+08 | BM12: 32142167 | BN12: 187075312 | BO12: 158301093 | BP12: 5.321785e+08 | BQ12: 8885446 | BR12: 136008536 | BS12: 2006154 | BT12: 415995123 | BU12: 66044176 | BV12: 497763520 | BW12: 20530487 | BX12: 46115044 | BY12: 35013579 | BZ12: 12673451 | CA12: 75328017 | CB12: 201580632 | CC12: 85334549 | CD12: 11512382 | CE12: 16540076 | CF12: 51195602 | CG12: 36236035 | CH12: 55328906 | CI12: 58365545 | CJ12: 86273989 | CK12: 52349712 | CL12: NO DATA | CM12: 42400663
A13: Value of Imported treated water | B13: 0 | C13: 0 | D13: 0 | E13: 0 | F13: 0 | G13: 0 | H13: 0 | I13: 0 | J13: 0 | K13: 0 | L13: 0 | M13: 0 | N13: 0 | O13: 0 | P13: 0 | Q13: 0 | R13: 0 | S13: 0 | T13: 0 | U13: 0 | V13: 0 | W13: 0 | X13: 0 | Y13: 0 | Z13: 0 | AA13: 0 | AB13: 5.6720057e+08 | AC13: 0 | AD13: 0 | AE13: 0 | AF13: 0 | AG13: 208215827 | AH13: 0 | AI13: 0 | AJ13: 0 | AK13: 0 | AL13: 556219860 | AM13: 0 | AN13: 0 | AO13: 0 | AP13: 0 | AQ13: 0 | AR13: 0 | AS13: 0 | AT13: 913363452 | AU13: 0 | AV13: 0 | AW13: 0 | AX13: 0 | AY13: 0 | AZ13: 0 | BA13: 0 | BB13: 0 | BC13: 0 | BD13: 0 | BE13: 0 | BF13: 0 | BG13: 0 | BH13: 0 | BI13: 0 | BJ13: 0 | BK13: 0 | BL13: 0 | BM13: 0 | BN13: 0 | BO13: 0 | BP13: 0 | BQ13: 0 | BR13: 0 | BS13: 0 | BT13: 415995123 | BU13: 0 | BV13: 0 | BW13: 0 | BX13: 0 | BY13: 0 | BZ13: 0 | CA13: 0 | CB13: 52128650 | CC13: 0 | CD13: 0 | CE13: 0 | CF13: 3483687.9 | CG13: 0 | CH13: 0 | CI13: 0 | CJ13: 0 | CK13: 0 | CL13: 0 | CM13: 0
A14: Total Billed Volume | B14: 1101104.9 | C14: 2005094 | D14: 620242 | E14: 272266 | F14: 8869969 | G14: 141426 | H14: 461783 | I14: 4739448 | J14: 3576960 | K14: 1020766 | L14: 1370875 | M14: 4742140 | N14: 690912 | O14: 1348246 | P14: 569227 | Q14: 716731 | R14: 1638248 | S14: 1214494 | T14: 3072689 | U14: 1005557 | V14: 70381 | W14: 1946176 | X14: 602643 | Y14: 354485 | Z14: 935944 | AA14: 1454089 | AB14: 5347542 | AC14: 440400 | AD14: 2701227 | AE14: 6696511 | AF14: 1653210 | AG14: 1835915 | AH14: 573552 | AI14: 1519934 | AJ14: 1273305 | AK14: 710419 | AL14: 5164287 | AM14: 344242 | AN14: 1214018 | AO14: 90678 | AP14: 604643 | AQ14: 42602 | AR14: 2421650 | AS14: 249630 | AT14: 5823200 | AU14: 2068366 | AV14: 2977634 | AW14: 1771192 | AX14: 42682 | AY14: 89727204 | AZ14: 1358834.9 | BA14: 7905899 | BB14: 3830215 | BC14: 2789074 | BD14: 785675 | BE14: 721694 | BF14: 1740204 | BG14: 1298768 | BH14: 1081545 | BI14: 1931100 | BJ14: 89065 | BK14: 6117001 | BL14: 4254899 | BM14: 219878 | BN14: 1428834 | BO14: 2986416 | BP14: 6915527 | BQ14: 156414 | BR14: 974798 | BS14: 262729 | BT14: 3350520 | BU14: 2149900 | BV14: 9214087 | BW14: 435051 | BX14: 274619 | BY14: 794825 | BZ14: 75766 | CA14: 681984 | CB14: 2072421 | CC14: 352197 | CD14: 486523 | CE14: 167689 | CF14: 394594 | CG14: 322268 | CH14: 618158 | CI14: 361390 | CJ14: 566988 | CK14: 125326 | CL14: 571536 | CM14: 298451
A15: Water Value | BR15: =BR12/BR10 -> 42.186231 | BS15: =BS12/BS10 -> 5.7245575 | CJ15: =CJ12/CJ10 -> 45.216975
A16: Total Water Produced | B16: 1573007 | C16: 4424004 | D16: 1207650 | E16: 850153 | F16: 15290495 | G16: 349920 | H16: 1034205 | I16: 7637891 | J16: 5961600 | K16: 2790003 | L16: 2273106 | M16: 7169376 | N16: 1183987 | O16: 3231652 | P16: 1018819 | Q16: 1184866 | R16: 2362940 | S16: 3335937 | T16: 5432762 | U16: 1410393 | V16: 100541 | W16: 4100926 | X16: 974979 | Y16: 465132 | Z16: 1298437 | AA16: 2507323 | AB16: 11231993 | AC16: 1036000 | AD16: 6722945 | AE16: 9915691 | AF16: 3626236 | AG16: 4521589 | AH16: 1039740 | AI16: 2148401 | AJ16: 2304940 | AK16: 1263982 | AL16: 6886695 | AM16: 582496 | AN16: 2281551 | AO16: 153695 | AP16: 960832 | AQ16: 64972 | AR16: 3001251 | AS16: 481921 | AT16: 12495475 | AU16: 2742691 | AV16: 5690163 | AW16: 2214840 | AX16: 58205 | AY16: 179341134 | AZ16: 1899235 | BA16: 11537195 | BB16: 8242189 | BC16: 4661250 | BD16: 882905 | BE16: 1157580 | BF16: 2758450 | BG16: 3700773 | BH16: 2190000 | BI16: 3184387 | BJ16: 140272 | BK16: 7401710 | BL16: 8265495 | BM16: 377280 | BN16: 2447219 | BO16: 5460800 | BP16: 10747235 | BQ16: 384030 | BR16: 3224003 | BS16: 350447 | BT16: 5357895 | BU16: 3028040 | BV16: 13172207 | BW16: 1885587 | BX16: 389392 | BY16: 1168859 | BZ16: 243026 | CA16: 1085366 | CB16: 3167191 | CC16: 600563 | CD16: 648456 | CE16: 269700 | CF16: 739008 | CG16: 621290 | CH16: 834833 | CI16: 648000 | CJ16: 1908000 | CK16: 136818 | CM16: 459365 | CO16: =SUM(B16:CM16) -> 455313593
A17: Total sewage treated | F17: 7850064 | I17: 1950734 | J17: 240000 | O17: 1816500 | P17: NO DATA | R17: 297423 | T17: 396060 | W17: 175140 | AE17: 4692420 | AF17: NO DATA | AK17: 72204 | AP17: 752000 | AT17: 6000 | AU17: 1261585.9 | AY17: 80525515 | AZ17: 993631 | BA17: 4393860 | BC17: 995579.1 | BI17: 1116976 | BK17: 3810236 | BL17: 1471640 | BP17: 1379820.5 | BV17: 4015000 | CB17: 2500 | CO17: =SUM(B17:CM17) -> 1.1821489e+08
A18: Total Expenditures | B18: 73930703 | C18: 240039575 | D18: 79258129 | E18: 23063224 | F18: 837927741 | G18: 79772794 | H18: 38597578 | I18: 427008665 | J18: 550259733 | K18: 60579777 | L18: 58531874 | M18: 136723929 | N18: 70805791 | O18: 206351982 | P18: 97875348 | Q18: 56402541 | R18: 96832633 | S18: 76336089 | T18: 350053531 | U18: 109157959 | V18: 14266064 | W18: 263530219 | X18: 135178025 | Y18: 22573822 | Z18: 86202402 | AA18: 139042955 | AB18: 667294785 | AC18: 59753784 | AD18: 175178481 | AE18: 943818099 | AF18: 278521048 | AG18: 208215827 | AH18: 16654271 | AI18: 141350626 | AJ18: 54230924 | AK18: 130523129 | AL18: 556219860 | AM18: 178566758 | AN18: 148496925 | AO18: 16952185 | AP18: 208513398 | AQ18: 5071016 | AR18: 215552899 | AS18: 51740623 | AT18: 913363452 | AU18: 235420437 | AV18: 228667569 | AW18: 21187941 | AX18: 18538604 | AY18: 10435941392 | AZ18: 186038940 | BA18: 975276497 | BB18: 314924993 | BC18: 416319319 | BD18: 110004557 | BE18: 38340240 | BF18: 69827129 | BG18: 110540087 | BH18: 69932275 | BI18: 261128942 | BJ18: 4239561 | BK18: 502818624 | BL18: 397911961 | BM18: 32142167 | BN18: 187075312 | BO18: 158301093 | BP18: 626092351 | BQ18: 8885446 | BR18: 136008536 | BS18: 2006154 | BT18: 415995123 | BU18: 66044176 | BV18: 654952000 | BW18: 20530487 | BX18: 46115044 | BY18: 35013579 | BZ18: 12673451 | CA18: 75328017 | CB18: 201580632 | CC18: 85334549 | CD18: 11512382 | CE18: 16540076 | CF18: 51195602 | CG18: 36236035 | CH18: 55328906 | CI18: 58365545 | CJ18: 86273989 | CK18: 52349712 | CL18: n.d. | CM18: 42400663
A19: Total Expenditures-water | B19: 73930703 | C19: 240039575 | D19: 79258129 | E19: 23063224 | F19: 7.1223858e+08 | G19: 79772794 | H19: 38597578 | I19: 3.6295737e+08 | J19: 4.6772077e+08 | K19: 60579777 | L19: 58531874 | M19: 136723929 | N19: 70805791 | O19: 1.7539918e+08 | P19: 97875348 | Q19: 56402541 | R19: 82307738 | S19: 76336089 | T19: 2.4503747e+08 | U19: 109157959 | V19: 14266064 | W19: 263530219 | X19: 135178025 | Y19: 22573822 | Z19: 86202402 | AA19: 139042955 | AB19: 5.6720057e+08 | AC19: 59753784 | AD19: 175178481 | AE19: 8.2584084e+08 | AF19: 278521048 | AG19: 208215827 | AH19: 16654271 | AI19: 141350626 | AJ19: 54230924 | AK19: 130523129 | AL19: 556219860 | AM19: 178566758 | AN19: 148496925 | AO19: 16952185 | AP19: 208513398 | AQ19: 5071016 | AR19: 215552899 | AS19: 51740623 | AT19: 913363452 | AU19: 2.2835782e+08 | AV19: 228667569 | AW19: 21187941 | AX19: 18538604 | AY19: 6.7833619e+09 | AZ19: 93019470 | BA19: 8.2898502e+08 | BB19: 314924993 | BC19: 3.9550335e+08 | BD19: 110004557 | BE19: 38340240 | BF19: 69827129 | BG19: 110540087 | BH19: 69932275 | BI19: 2.219596e+08 | BJ19: 4239561 | BK19: 4.5253676e+08 | BL19: 3.3822517e+08 | BM19: 32142167 | BN19: 187075312 | BO19: 158301093 | BP19: 5.321785e+08 | BQ19: 8885446 | BR19: 136008536 | BS19: 2006154 | BT19: 415995123 | BU19: 66044176 | BV19: 497763520 | BW19: 20530487 | BX19: 46115044 | BY19: 35013579 | BZ19: 12673451 | CA19: 75328017 | CB19: 201580632 | CC19: 85334549 | CD19: 11512382 | CE19: 16540076 | CF19: 51195602 | CG19: 36236035 | CH19: 55328906 | CI19: 58365545 | CJ19: 86273989 | CK19: 52349712 | CL19: n.d. | CM19: 42400663
A20: Total Expenditures-sewage | F20: 1.0683579e+08 | I20: 54443605 | J20: 70158116 | O20: 26309878 | P20: NO DATA | R20: 12346161 | T20: 73511242 | AE20: 1.032301e+08 | AF20: NO DATA | AK20: NO DATA | AP20: NO DATA | AT20: NO DATA | AU20: 6850734.7 | AY20: 3.6525795e+09 | AZ20: 79066550 | BA20: 1.2434775e+08 | BC20: 19775168 | BI20: 39169341 | BK20: 45253676 | BL20: 59686794 | BP20: 79826775 | BV20: 1.1946324e+08 | CB20: No Data
A21: Actual cost-water produced | B21: 46.999602 | C21: 54.258444 | D21: 65.630049 | E21: 27.128322 | F21: 46.580479 | G21: 227.97438 | H21: 37.321013 | I21: 47.520626 | J21: 78.455578 | K21: 21.713158 | L21: 25.749734 | M21: 19.070548 | N21: 59.802845 | O21: 54.275394 | P21: 96.067455 | Q21: 47.602464 | R21: 34.832767 | S21: 22.882953 | T21: 45.103664 | U21: 77.39542 | V21: 141.893 | W21: 64.26115 | X21: 138.64711 | Y21: 48.532077 | Z21: 66.38936 | AA21: 55.454744 | AB21: 50.498657 | AC21: 57.677398 | AD21: 26.056807 | AE21: 83.286262 | AF21: 76.807204 | AG21: 46.04926 | AH21: 16.017727 | AI21: 65.793409 | AJ21: 23.528128 | AK21: 103.26344 | AL21: 80.767314 | AM21: 306.55448 | AN21: 65.085955 | AO21: 110.29757 | AP21: 217.01338 | AQ21: 78.049252 | AR21: 71.821017 | AS21: 107.36329 | AT21: 73.095537 | AU21: 83.2605 | AV21: 40.186471 | AW21: 9.5663529 | AX21: 318.50535 | AY21: 37.823793 | AZ21: 48.977336 | BA21: 71.853256 | BB21: 38.208902 | BC21: 84.849204 | BD21: 124.59388 | BE21: 33.121028 | BF21: 25.313901 | BG21: 29.869459 | BH21: 31.932546 | BI21: 69.702458 | BJ21: 30.223858 | BK21: 61.139488 | BL21: 40.920134 | BM21: 85.194463 | BN21: 76.444042 | BO21: 28.988627 | BP21: 49.517713 | BQ21: 23.137375 | BR21: 42.186231 | BS21: 5.7245575 | BT21: 77.641522 | BU21: 21.810866 | BV21: 37.788923 | BW21: 10.888114 | BX21: 118.42833 | BY21: 29.955349 | BZ21: 52.14854 | CA21: 69.403332 | CB21: 63.646503 | CC21: 142.09092 | CD21: 17.753528 | CE21: 61.327683 | CF21: 69.276113 | CG21: 58.323866 | CH21: 66.275418 | CI21: 90.070285 | CJ21: 45.216975 | CK21: 382.62299 | CM21: =CM19/CM16 -> 92.302772
A22: Actual unit cost- sewage treated | F22: 13.609543 | I22: 27.909292 | J22: 292.32548 | O22: 14.48383 | P22: NO DATA | R22: 41.510444 | T22: 185.60633 | AE22: 21.999332 | AF22: NO DATA | AK22: NO DATA | AP22: NO DATA | AT22: NO DATA | AU22: 5.4302563 | AY22: 45.359281 | AZ22: 79.573352 | BA22: 28.300345 | BC22: 19.86298 | BI22: 35.067308 | BK22: 11.87687 | BL22: 40.558013 | BP22: 57.853015 | BV22: 29.754233 | CB22: No Data
A23: Value of Water sold (in Ksh.) per category
A24: Individual | B24: 17102919 | C24: 20777512 | D24: 36328002 | E24: 3545319 | F24: 3.2215111e+08 | G24: 0 | H24: 7786394.9 | I24: 1.6031273e+08 | J24: 1.0383424e+08 | K24: 15388491 | L24: 19767830 | M24: 86659010 | N24: 30353412 | O24: 28543890 | P24: 47893487 | Q24: 15353162 | R24: 50701249 | S24: 35563472 | T24: 47338910 | U24: 25838616 | V24: 1497955.3 | W24: 1.0455852e+08 | X24: 30070880 | Y24: 12042750 | Z24: 29805271 | AA24: 32738041 | AB24: 2.031948e+08 | AC24: 135194.5 | AD24: 57462831 | AE24: 2.6956399e+08 | AF24: 18344917 | AG24: 70917884 | AH24: 8414365.9 | AI24: 71373818 | AJ24: 0 | AK24: 12309951 | AL24: 3.0394807e+08 | AM24: 0 | AN24: 54209125 | AO24: 7022967.2 | AP24: 39279779 | AQ24: 0 | AR24: 1.3776964e+08 | AS24: 20011917 | AT24: 2.0080056e+08 | AU24: 1523830 | AV24: 86160436 | AW24: 13555082 | AX24: 2933434.3 | AY24: 4.0950422e+08 | AZ24: 37280976 | BA24: 2.9226675e+08 | BB24: 22681368 | BC24: 1.5101064e+08 | BD24: 56705041 | BE24: 20025061 | BF24: 16861229 | BG24: 19396775 | BH24: 22202016 | BI24: 73522410 | BJ24: 1894884.8 | BK24: 1.40106e+08 | BL24: 1.2646976e+08 | BM24: 3692515.3 | BN24: 29188372 | BO24: 74144825 | BP24: 2.2115818e+08 | BQ24: 3047196.8 | BR24: 22732432 | BS24: 1253844.1 | BT24: 2.0149155e+08 | BU24: 44366639 | BV24: 2.1494393e+08 | BW24: 3961054.7 | BX24: 7807824.4 | BY24: 10217606 | BZ24: 1503167.7 | CA24: 17126215 | CB24: 72299666 | CC24: 36876824 | CD24: 8466014.4 | CE24: 5092117.4 | CF24: 24314669 | CG24: 13326245 | CH24: 40450736 | CI24: 44440.05 | CJ24: 1356368 | CK24: 14186.35 | CL24: 18488.9 | CM24: 4610180.2
A25: Multi-dwelling units | B25: 0 | C25: 0 | D25: 0 | E25: 0 | F25: 1706298.6 | G25: 0 | H25: 3909376.1 | I25: 0 | J25: 19644354 | K25: 0 | L25: 0 | M25: 0 | N25: 1866088 | O25: 17248783 | P25: 0 | Q25: 5117703.5 | R25: 0 | S25: 2045000.1 | T25: 61544690 | U25: 35177999 | V25: 1597875.7 | W25: 0 | X25: 9854667.9 | Y25: 3440778.7 | Z25: 8845359.8 | AA25: 0 | AB25: 0 | AC25: 66592.15 | AD25: 0 | AE25: 0 | AF25: 7678624.5 | AG25: 0 | AH25: 0 | AI25: 0 | AJ25: 0 | AK25: 11111834 | AL25: 0 | AM25: 0 | AN25: 0 | AO25: 393192.61 | AP25: 23194413 | AQ25: 0 | AR25: 0 | AS25: 0 | AT25: 86057439 | AU25: 0 | AV25: 0 | AW25: 0 | AX25: 2682770.6 | AY25: 1.4628397e+08 | AZ25: 9568550.2 | BA25: 2.4991362e+08 | BB25: 26374560 | BC25: 0 | BD25: 3279310.8 | BE25: 0 | BF25: 0 | BG25: 0 | BH25: 0 | BI25: 0 | BJ25: 266876.67 | BK25: 1.2470144e+08 | BL25: 6813027.6 | BM25: 6857451.5 | BN25: 71322465 | BO25: 0 | BP25: 81980456 | BQ25: 0 | BR25: 83409.509 | BS25: 0 | BT25: 0 | BU25: 201227.05 | BV25: 7929790.5 | BW25: 0 | BX25: 14936879 | BY25: 2707124.6 | BZ25: 0 | CA25: 2753280.9 | CB25: 35955451 | CC25: 0 | CD25: 0 | CE25: 4403161.1 | CF25: 0 | CG25: 0 | CH25: 0 | CI25: 74067.7 | CJ25: 3390.55 | CK25: 8196.6 | CL25: 0 | CM25: 3504950.5
A26: Institutions | B26: 29588618 | C26: 35945785 | D26: 372229.84 | E26: 960234.07 | F26: 16646106 | G26: 0 | H26: 1562966.7 | I26: 9875403.2 | J26: 33675762 | K26: 1323559.9 | L26: 10589903 | M26: 2185471 | N26: 580924.84 | O26: 5234768.7 | P26: 2630372.4 | Q26: 3411836.9 | R26: 1688591.2 | S26: 3943954.6 | T26: 3377634.6 | U26: 311284.38 | V26: 3495269.5 | W26: 1165231.9 | X26: 4585285.8 | Y26: 1204275 | Z26: 2125946.7 | AA26: 0 | AB26: 13245608 | AC26: 7789.05 | AD26: 5403341.5 | AE26: 23590508 | AF26: 4639138.5 | AG26: 1476790.7 | AH26: 0 | AI26: 5775482.8 | AJ26: 0 | AK26: 13577122 | AL26: 12649946 | AM26: 0 | AN26: 11754660 | AO26: 584881.84 | AP26: 1252829.4 | AQ26: 0 | AR26: 6850291.8 | AS26: 3147823.2 | AT26: 8256502.7 | AU26: 0 | AV26: 1297138.9 | AW26: 1186065.1 | AX26: 1732669.1 | AY26: 21055236 | AZ26: 281029.63 | BA26: 791458.34 | BB26: 15593298 | BC26: 0 | BD26: 8547513.7 | BE26: 1544298.3 | BF26: 7945165.4 | BG26: 7758704.8 | BH26: 0 | BI26: 6628106 | BJ26: 133438.33 | BK26: 36237422 | BL26: 500202.34 | BM26: 3260925 | BN26: 392974 | BO26: 2425256.9 | BP26: 2231363.6 | BQ26: 18101.584 | BR26: 1973596.7 | BS26: 0 | BT26: 17888995 | BU26: 745168.25 | BV26: 4464327.2 | BW26: 402763.83 | BX26: 837178.62 | BY26: 4029602 | BZ26: 583632.86 | CA26: 9466406.5 | CB26: 1976746.2 | CC26: 0 | CD26: 7483.3654 | CE26: 208819.74 | CF26: 1737306.4 | CG26: 908219.25 | CH26: 0 | CI26: 85919.9 | CJ26: 113596.3 | CK26: 18442.35 | CL26: 0 | CM26: 7754379.3
A27: Schools | B27: 2929822.1 | C27: 3559299.7 | D27: 2258876.8 | E27: 590881.97 | F27: 2702905.3 | G27: 0 | H27: 2830686.9 | I27: 13665285 | J27: 50513643 | K27: 2727641 | L27: 0 | M27: 1280817.8 | N27: 3788988.7 | O27: 1877309.7 | P27: 1215686.1 | Q27: 3070642.9 | R27: 0 | S27: 2048788.8 | T27: 9907012.2 | U27: 233424.59 | V27: 1797595 | W27: 6269337.6 | X27: 3920850 | Y27: 516090.11 | Z27: 1471932.4 | AA27: 8869099 | AB27: 12705388 | AC27: 0 | AD27: 2673085.3 | AE27: 4095088.1 | AF27: 1988193.3 | AG27: 2215243.6 | AH27: 772633.22 | AI27: 4215554 | AJ27: 0 | AK27: 7977224.7 | AL27: 6474726.5 | AM27: 0 | AN27: 0 | AO27: 408853.5 | AP27: 498598.63 | AQ27: 0 | AR27: 2947328.8 | AS27: 1488623.8 | AT27: 5504388.5 | AU27: 70075.8 | AV27: 7022867.1 | AW27: 1694382.9 | AX27: 1748594.4 | AY27: 2031389.2 | AZ27: 1474026.8 | BA27: 809073.62 | BB27: 2846788.3 | BC27: 5606603.5 | BD27: 5379589.8 | BE27: 0 | BF27: 8193120.6 | BG27: 3879365.7 | BH27: 7048268.1 | BI27: 5952057.3 | BJ27: 53375.333 | BK27: 26490252 | BL27: 17156812 | BM27: 1468773.4 | BN27: 1442000.8 | BO27: 6230170 | BP27: 2514942.1 | BQ27: 97713.688 | BR27: 1695246.9 | BS27: 250163.16 | BT27: 8696394 | BU27: 748243.58 | BV27: 5764383.5 | BW27: 301828.22 | BX27: 2887072.1 | BY27: 3471327 | BZ27: 659920 | CA27: 2240297.2 | CB27: 557833.66 | CC27: 7790134.7 | CD27: 147538.71 | CE27: 147540.1 | CF27: 1203741.7 | CG27: 500418.77 | CH27: 400088.4 | CI27: 35551.85 | CJ27: 169546.5 | CK27: 22541.6 | CL27: 0 | CM27: 4281543.5
A28: Commercial customers | B28: 1893560.4 | C28: 2300395.3 | D28: 347300.77 | E28: 2215814.2 | F28: 49128097 | G28: 0 | H28: 877043.8 | I28: 39533920 | J28: 58933061 | K28: 2686955.3 | L28: 2823985 | M28: 150682.25 | N28: 406719.15 | O28: 4123544.5 | P28: 1939059.2 | Q28: 6823621.9 | R28: 4316444.5 | S28: 4289674.2 | T28: 4422118 | U28: 13775379 | V28: 1398156.4 | W28: 12474448 | X28: 2606377.4 | Y28: 0 | Z28: 4235807.2 | AA28: 36578005 | AB28: 7566299.3 | AC28: 52540.7 | AD28: 4831150.9 | AE28: 1.4358967e+08 | AF28: 2419728.7 | AG28: 2616545.4 | AH28: 0 | AI28: 11845285 | AJ28: 0 | AK28: 14427435 | AL28: 63200671 | AM28: 0 | AN28: 12950455 | AO28: 0 | AP28: 44608668 | AQ28: 0 | AR28: 23699029 | AS28: 1790456.5 | AT28: 41282513 | AU28: 1084050 | AV28: 24828367 | AW28: 491375.72 | AX28: 1661323.9 | AY28: 1.032914e+08 | AZ28: 13516937 | BA28: 23888769 | BB28: 19496335 | BC28: 79599887 | BD28: 15276954 | BE28: 2333888.6 | BF28: 5532888.2 | BG28: 7370752.3 | BH28: 0 | BI28: 23729291 | BJ28: 266876.67 | BK28: 45611036 | BL28: 19829485 | BM28: 2877239.2 | BN28: 5020171.9 | BO28: 3658573.1 | BP28: 0 | BQ28: 383619.93 | BR28: 897937.14 | BS28: 0 | BT28: 26278239 | BU28: 826522.78 | BV28: 85600892 | BW28: 0 | BX28: 0 | BY28: 3273981.1 | BZ28: 335305.64 | CA28: 14199539 | CB28: 4685638.9 | CC28: 8068917.1 | CD28: 4490.0192 | CE28: 427153.84 | CF28: 0 | CG28: 3360912.8 | CH28: 42738.125 | CI28: 50366.15 | CJ28: 50863.95 | CK28: 12294.9 | CL28: 0 | CM28: 5461665.4
A29: Industries | B29: 0 | C29: 0 | D29: 28341.411 | E29: 0 | F29: 0 | G29: 0 | H29: 0 | I29: 0 | J29: 14031408 | K29: 34005.944 | L29: 0 | M29: 0 | N29: 2722524.5 | O29: 3551.8416 | P29: 56442.197 | Q29: 0 | R29: 0 | S29: 2185994.2 | T29: 0 | U29: 0 | V29: 0 | W29: 0 | X29: 10814424 | Y29: 0 | Z29: 0 | AA29: 0 | AB29: 13979136 | AC29: 0 | AD29: 0 | AE29: 953250.7 | AF29: 0 | AG29: 1744382.8 | AH29: 0 | AI29: 0 | AJ29: 0 | AK29: 11808594 | AL29: 2384113.8 | AM29: 0 | AN29: 0 | AO29: 0 | AP29: 17533743 | AQ29: 0 | AR29: 0 | AS29: 0 | AT29: 27521702 | AU29: 0 | AV29: 0 | AW29: 0 | AX29: 0 | AY29: 6656737.9 | AZ29: 0 | BA29: 0 | BB29: 126897.63 | BC29: 0 | BD29: 0 | BE29: 0 | BF29: 5518947.9 | BG29: 0 | BH29: 0 | BI29: 7558959.4 | BJ29: 49718.246 | BK29: 0 | BL29: 0 | BM29: 0 | BN29: 0 | BO29: 0 | BP29: 31576691 | BQ29: 0 | BR29: 13106.16 | BS29: 0 | BT29: 2407120.1 | BU29: 0 | BV29: 29125841 | BW29: 0 | BX29: 0 | BY29: 0 | BZ29: 0 | CA29: 1159684.9 | CB29: 0 | CC29: 0 | CD29: 0 | CE29: 0 | CF29: 0 | CG29: 0 | CH29: 0 | CI29: 0 | CJ29: 0 | CK29: 0 | CL29: 0 | CM29: 0
A30: Kiosks | B30: 236577.81 | C30: 287406.98 | D30: 1371762.2 | E30: 73870.42 | F30: 20832883 | G30: 0 | H30: 267740.95 | I30: 1834195 | J30: 0 | K30: 3400.5944 | L30: 703357.89 | M30: 159227.62 | N30: 236580.05 | O30: 16144734 | P30: 945614.31 | Q30: 341194.08 | R30: 358425.88 | S30: 0 | T30: 11999168 | U30: 155564.79 | V30: 199719.27 | W30: 587711.96 | X30: 19192629 | Y30: 0 | Z30: 9385890 | AA30: 2450988.8 | AB30: 11083829 | AC30: 1102.95 | AD30: 14942.432 | AE30: 33834000 | AF30: 8357401.9 | AG30: 5571680.2 | AH30: 0 | AI30: 1128398.4 | AJ30: 0 | AK30: 2148148.9 | AL30: 28288423 | AM30: 0 | AN30: 0 | AO30: 1591667.9 | AP30: 4847589.6 | AQ30: 0 | AR30: 2659072.6 | AS30: 362277.44 | AT30: 48712142 | AU30: 2480.45 | AV30: 351792.37 | AW30: 16942.011 | AX30: 2835653.1 | AY30: 58388793 | AZ30: 4016223.5 | BA30: 394909.86 | BB30: 1203902.7 | BC30: 433576.45 | BD30: 3774197.7 | BE30: 0 | BF30: 0 | BG30: 387899.43 | BH30: 0 | BI30: 249758.95 | BJ30: 26717.89 | BK30: 844164.98 | BL30: 3019756.4 | BM30: 575483.78 | BN30: 1859862.7 | BO30: 113273.62 | BP30: 2979449.8 | BQ30: 72377.281 | BR30: 12917717 | BS30: 0 | BT30: 3098595.5 | BU30: 3380.6843 | BV30: 361262.89 | BW30: 71238.335 | BX30: 2534103.1 | BY30: 109619.21 | BZ30: 0 | CA30: 386538.11 | CB30: 680540.69 | CC30: 363326.48 | CD30: 11973.385 | CE30: 5185.5475 | CF30: 80221.739 | CG30: 645878.5 | CH30: 0 | CI30: 5925.15 | CJ30: 1694.8 | CK30: 3152.1 | CL30: 0 | CM30: 1935135.8
A31: Bulk | B31: 0 | C31: 0 | D31: 0 | E31: 0 | F31: 0 | G31: 0 | H31: 0 | I31: 0 | J31: 0 | K31: 0 | L31: 1414590.1 | M31: 0 | N31: 1363265.7 | O31: 0 | P31: 0 | Q31: 0 | R31: 0 | S31: 4701245.1 | T31: 0 | U31: 2334787.6 | V31: 0 | W31: 8259.0708 | X31: 0 | Y31: 0 | Z31: 0 | AA31: 0 | AB31: 8231531.3 | AC31: 0 | AD31: 0 | AE31: 56385511 | AF31: 1764740.2 | AG31: 0 | AH31: 0 | AI31: 5663101.5 | AJ31: 0 | AK31: 0 | AL31: 159643.87 | AM31: 0 | AN31: 101281.07 | AO31: 0 | AP31: 0 | AQ31: 0 | AR31: 0 | AS31: 0 | AT31: 7514684.1 | AU31: 0 | AV31: 0 | AW31: 0 | AX31: 0 | AY31: 1.1054998e+08 | AZ31: 414374.69 | BA31: 0 | BB31: 58025161 | BC31: 0 | BD31: 3403530.9 | BE31: 0 | BF31: 0 | BG31: 0 | BH31: 5286201.1 | BI31: 15523760 | BJ31: 0 | BK31: 0 | BL31: 321991.7 | BM31: 0 | BN31: 0 | BO31: 0 | BP31: 0 | BQ31: 0 | BR31: 809608.23 | BS31: 0 | BT31: 278577.78 | BU31: 0 | BV31: 0 | BW31: 0 | BX31: 3519612 | BY31: 0 | BZ31: 869060.08 | CA31: 0 | CB31: 15746473 | CC31: 0 | CD31: 0 | CE31: 0 | CF31: 0 | CG31: 54241.196 | CH31: 75117.372 | CI31: 0 | CJ31: 0 | CK31: 0 | CL31: 0 | CM31: 0
A32: Others | B32: 0 | C32: 0 | D32: 0 | E32: 0 | F32: 0 | G32: 0 | H32: 0 | I32: 0 | J32: 0 | K32: 0 | L32: 0 | M32: 0 | N32: 0 | O32: 0 | P32: 3527.6373 | Q32: 0 | R32: 0 | S32: 0 | T32: 0 | U32: 0 | V32: 0 | W32: 0 | X32: 2509598.7 | Y32: 0 | Z32: 6266516.9 | AA32: 0 | AB32: 37101.75 | AC32: 0 | AD32: 0 | AE32: 25715349 | AF32: 0 | AG32: 0 | AH32: 0 | AI32: 0 | AJ32: 0 | AK32: 0 | AL32: 0 | AM32: 0 | AN32: 0 | AO32: 0 | AP32: 0 | AQ32: 0 | AR32: 0 | AS32: 0 | AT32: 0 | AU32: 0 | AV32: 0 | AW32: 0 | AX32: 0 | AY32: 18818470 | AZ32: 0 | BA32: 0 | BB32: 0 | BC32: 0 | BD32: 1524156.9 | BE32: 0 | BF32: 0 | BG32: 0 | BH32: 0 | BI32: 1438072.5 | BJ32: 0 | BK32: 0 | BL32: 0 | BM32: 0 | BN32: 0 | BO32: 0 | BP32: 0 | BQ32: 0 | BR32: 0 | BS32: 0 | BT32: 0 | BU32: 0 | BV32: 0 | BW32: 0 | BX32: 3519612 | BY32: 0 | BZ32: 0 | CA32: 0 | CB32: 0 | CC32: 0 | CD32: 0 | CE32: 0 | CF32: 0 | CG32: 0 | CH32: 0 | CI32: 0 | CJ32: 0 | CK32: 0 | CL32: 0 | CM32: 0
A33: Total Value of water sold | B33: =SUM(B24:B32) -> 51751497 | C33: =SUM(C24:C32) -> 62870399 | D33: =SUM(D24:D32) -> 40706513 | E33: =SUM(E24:E32) -> 7386119.6 | F33: =SUM(F24:F32) -> 4.131674e+08 | G33: =SUM(G24:G32) -> 0 | H33: =SUM(H24:H32) -> 17234209 | I33: =SUM(I24:I32) -> 2.2522154e+08 | ... CM33: =SUM(CM24:CM32) -> 27547855
A37: Water Sold in cubic meters
A38: Individual | B38: =B24/$B$21 -> 363894.97 | C38: =C24/$C$21 -> 382936 | D38: =D24/$D$21 -> 553526.96 | E38: =E24/$E$21 -> 130687 | F38: =F24/$F$21 -> 6916011.2 | G38: =G24/$G$21 -> 0 | H38: =H24/$H$21 -> 208633 | I38: =I24/$I$21 -> 3373540 | J38: =J24/$J$21 -> 1323478.1 | K38: =K24/$K$21 -> 708717.3 | L38: =L24/$L$21 -> 767690.66 | M38: =M24/$M$21 -> 4544127.9 | N38: =N24/$N$21 -> 507558 | O38: =O24/$O$21 -> 525908.49 | P38: =P24/$P$21 -> 498540.19 | Q38: =Q24/$Q$21 -> 322528.73 | R38: =R24/$R$21 -> 1455561.9 | S38: =S24/$S$21 -> 1554147 | T38: =T24/$T$21 -> 1049558 | U38: =U24/$U$21 -> 333852 | V38: =V24/$V$21 -> 10556.936 | W38: =W24/$W$21 -> 1627087.6 | X38: =X24/$X$21 -> 216887.89 | Y38: =Y24/$Y$21 -> 248140 | Z38: =Z24/$Z$21 -> 448946.49 | AA38: =AA24/$AA$21 -> 590356 | AB38: =AB24/$AB$21 -> 4023766.4 | AC38: =AC24/$AC$21 -> 2343.9771 | AD38: =AD24/$AD$21 -> 2205290.6 | AE38: =AE24/$AE$21 -> 3236596.1 | AF38: =AF24/$AF$21 -> 238843.71 | AG38: =AG24/$AG$21 -> 1540044 | AH38: =AH24/$AH$21 -> 525315.86 | AI38: =AI24/$AI$21 -> 1084817.1 | AJ38: =AJ24/$AJ$21 -> 0 | AK38: =AK24/$AK$21 -> 119209.19 | AL38: =AL24/$AL$21 -> 3763255.8 | AM38: =AM24/$AM$21 -> 0 | AN38: =AN24/$AN$21 -> 832885.14 | AO38: =AO24/$AO$21 -> 63672.909 | AP38: =AP24/$AP$21 -> 181001.65 | AQ38: =AQ24/$AQ$21 -> 0 | AR38: =AR24/$AR$21 -> 1918235.8 | AS38: =AS24/$AS$21 -> 186394.41 | AT38: =AT24/$AT$21 -> 2747097.4 | AU38: =AU24/$AU$21 -> 18301.956 | AV38: =AV24/$AV$21 -> 2144016 | AW38: =AW24/$AW$21 -> 1416954 | AX38: =AX24/$AX$21 -> 9210 | AY38: =AY24/$AY$21 -> 10826630 | AZ38: =AZ24/$AZ$21 -> 761188.33 | BA38: =BA24/$BA$21 -> 4067550.5 | BB38: =BB24/$BB$21 -> 593614.74 | BC38: =BC24/$BC$21 -> 1779753.2 | BD38: =BD24/$BD$21 -> 455119 | BE38: =BE24/$BE$21 -> 604602.62 | BF38: =BF24/$BF$21 -> 666085.77 | BG38: =BG24/$BG$21 -> 649384.89 | BH38: =BH24/$BH$21 -> 695278.61 | BI38: =BI24/$BI$21 -> 1054803.7 | BJ38: =BJ24/$BJ$21 -> 62695 | BK38: =BK24/$BK$21 -> 2291579.5 | BL38: =BL24/$BL$21 -> 3090648.8 | BM38: =BM24/$BM$21 -> 43342.199 | BN38: =BN24/$BN$21 -> 381826.64 | BO38: =BO24/$BO$21 -> 2557721.2 | BP38: =BP24/$BP$21 -> 4466243.8 | BQ38: =BQ24/$BQ$21 -> 131700.2 | BR38: =BR24/$BR$21 -> 538859.04 | BS38: =BS24/$BS$21 -> 219029 | BT38: =BT24/$BT$21 -> 2595152 | BU38: =BU24/$BU$21 -> 2034153 | BV38: =BV24/$BV$21 -> 5688014.1 | BW38: =BW24/$BW$21 -> 363796.2 | BX38: =BX24/$BX$21 -> 65928.689 | BY38: =BY24/$BY$21 -> 341094.55 | BZ38: =BZ24/$BZ$21 -> 28824.732 | CA38: =CA24/$CA$21 -> 246763.59 | CB38: =CB24/$CB$21 -> 1135956.6 | CC38: =CC24/$CC$21 -> 259529.77 | CD38: =CD24/$CD$21 -> 476863.77 | CE38: =CE24/$CE$21 -> 83031.304 | CF38: =CF24/$CF$21 -> 350982 | CG38: =CG24/$CG$21 -> 228487 | CH38: =CH24/$CH$21 -> 610342.98 | CI38: =CI24/$CI$21 -> 493.39302 | CJ38: =CJ24/$CJ$21 -> 29996.876 | CK38: =CK24/$CK$21 -> 37.076575 | CM38: =CM24/$CM$21 -> 49946.281 | CO38: =SUM(B38:CM38) -> 1.0544718e+08
A39: Multi-dwelling units | B39: =B25/$B$21 -> 0 | C39: =C25/$C$21 -> 0 | D39: =D25/$D$21 -> 0 | E39: =E25/$E$21 -> 0 | F39: =F25/$F$21 -> 36631.195 | G39: =G25/$G$21 -> 0 | H39: =H25/$H$21 -> 104750 | I39: =I25/$I$21 -> 0 | J39: =J25/$J$21 -> 250388.24 | K39: =K25/$K$21 -> 0 | L39: =L25/$L$21 -> 0 | M39: =M25/$M$21 -> 0 | N39: =N25/$N$21 -> 31204 | O39: =O25/$O$21 -> 317801.16 | P39: =P25/$P$21 -> 0 | Q39: =Q25/$Q$21 -> 107509.21 | R39: =R25/$R$21 -> 0 | S39: =S25/$S$21 -> 89367.843 | T39: =T25/$T$21 -> 1364516.4 | U39: =U25/$U$21 -> 454523 | V39: =V25/$V$21 -> 11261.131 | W39: =W25/$W$21 -> 0 | X39: =X25/$X$21 -> 71077.338 | Y39: =Y25/$Y$21 -> 70897 | Z39: =Z25/$Z$21 -> 133234.6 | AA39: =AA25/$AA$21 -> 0 | AB39: =AB25/$AB$21 -> 0 | AC39: =AC25/$AC$21 -> 1154.5623 | AD39: =AD25/$AD$21 -> 0 | AE39: =AE25/$AE$21 -> 0 | AF39: =AF25/$AF$21 -> 99972.713 | AG39: =AG25/$AG$21 -> 0 | AH39: =AH25/$AH$21 -> 0 | AI39: =AI25/$AI$21 -> 0 | AJ39: =AJ25/$AJ$21 -> 0 | AK39: =AK25/$AK$21 -> 107606.66 | AL39: =AL25/$AL$21 -> 0 | AM39: =AM25/$AM$21 -> 0 | AN39: =AN25/$AN$21 -> 0 | AO39: =AO25/$AO$21 -> 3564.8348 | AP39: =AP25/$AP$21 -> 106880.11 | AQ39: =AQ25/$AQ$21 -> 0 | AR39: =AR25/$AR$21 -> 0 | AS39: =AS25/$AS$21 -> 0 | AT39: =AT25/$AT$21 -> 1177328.2 | AU39: =AU25/$AU$21 -> 0 | AV39: =AV25/$AV$21 -> 0 | AW39: =AW25/$AW$21 -> 0 | AX39: =AX25/$AX$21 -> 8423 | AY39: =AY25/$AY$21 -> 3867511.8 | AZ39: =AZ25/$AZ$21 -> 195366.9 | BA39: =BA25/$BA$21 -> 3478111.3 | BB39: =BB25/$BB$21 -> 690272.65 | BC39: =BC25/$BC$21 -> 0 | BD39: =BD25/$BD$21 -> 26320 | BE39: =BE25/$BE$21 -> 0 | BF39: =BF25/$BF$21 -> 0 | BG39: =BG25/$BG$21 -> 0 | BH39: =BH25/$BH$21 -> 0 | BI39: =BI25/$BI$21 -> 0 | BJ39: =BJ25/$BJ$21 -> 8830 | BK39: =BK25/$BK$21 -> 2039621.9 | BL39: =BL25/$BL$21 -> 166495.73 | BM39: =BM25/$BM$21 -> 80491.751 | BN39: =BN25/$BN$21 -> 933002.27 | BO39: =BO25/$BO$21 -> 0 | BP39: =BP25/$BP$21 -> 1655578.4 | BQ39: =BQ25/$BQ$21 -> 0 | BR39: =BR25/$BR$21 -> 1977.1737 | BS39: =BS25/$BS$21 -> 0 | BT39: =BT25/$BT$21 -> 0 | BU39: =BU25/$BU$21 -> 9226 | BV39: =BV25/$BV$21 -> 209844.31 | BW39: =BW25/$BW$21 -> 0 | BX39: =BX25/$BX$21 -> 126125.9 | BY39: =BY25/$BY$21 -> 90371.993 | BZ39: =BZ25/$BZ$21 -> 0 | CA39: =CA25/$CA$21 -> 39670.731 | CB39: =CB25/$CB$21 -> 564924.22 | CC39: =CC25/$CC$21 -> 0 | CD39: =CD25/$CD$21 -> 0 | CE39: =CE25/$CE$21 -> 71797.285 | CF39: =CF25/$CF$21 -> 0 | CG39: =CG25/$CG$21 -> 0 | CH39: =CH25/$CH$21 -> 0 | CI39: =CI25/$CI$21 -> 822.33224 | CJ39: =CJ25/$CJ$21 -> 74.984007 | CK39: =CK25/$CK$21 -> 21.422132 | CM39: =CM25/$CM$21 -> 37972.321 | CO39: =SUM(B39:CM39) -> 18842523
