Workbook

Sheet Sheet1
A1: Supply Table 2009/10, Uganda | N1: Flows to the Environment | O1: Overall total
A2: Description | B2: Agric. Production | C2: Forestry | D2: Fishings | E2: Mining & Quarrying | F2: H/hold | G2: Manufacturing | H2: Construction & Housing | I2: Wholesale & Retail trade | J2: Transport | K2: other services | L2: Education, health & social work | M2: Importations
A3: Natural inputs
A4: Sand (ha) | C4: =Sheet3!C4/10 -> 3.3 | O4: -
A5: Seed (kg) | C5: =Sheet3!C5/0.7 -> 792.85714 | O5: -
A6: Seedlings (No.) | C6: =Sheet3!C6*1000000/500 -> 2144000 | O6: -
A7: Wood biomass available for supply | O7: -
A8: Hard wood plantation (m3) | C8: 362964 | O8: 362964
A9: Soft wood plantation (m3) | C9: 744954 | O9: 744954
A10: Natural forest wood (m3) | C10: 27709169 | O10: 27709169
A11: NWFPs | O11: -
A12: Shea nut (tons) | B12: =1507035/1000 -> 1507.035 | O12: 1752
A13: Prunus Africana (trees>30 DBH) | B13: 22768 | O13: 22768
A14: Sandal wood | O14: -
A16: Products | O16: -
A17: Sawn wood ('000 tons) | B17: 5677 | C17: 1957 | D17: - | E17: - | F17: - | G17: - | K17: - | L17: - | O17: 7634
A18: Poles ('000 tons) | C18: 1056 | O18: 1056
A19: Firewood ('000 tons) | C19: 29013 | D19: - | E19: - | F19: - | G19: - | K19: - | L19: - | M19: - | O19: 29013
A20: Charcoal ('000 tons) | C20: 9134 | D20: - | E20: - | F20: - | G20: - | K20: - | L20: - | M20: - | O20: 9134
A21: Finished products
A22: Wood & articles of wood; wood charcoal (m3) | M22: 1937709 | O22: 1937709 | P22: =O57/O22 -> 2.1885082
A23: Cork & cork articles (kg) | M23: 1966 | O23: 1966 | P23: =O58/O23 -> 128.71974
A24: Manufacture of straw, esparata or other plaiting materials, basket ware or wicker work (kg) | M24: 278037 | O24: 278037 | P24: =O59/O24 -> 0.0025284405
A25: Pulp of wood or other fibrous cellulosic material, recovered (waste & scrap) paper or paperboard (kg) | M25: 482157 | O25: 482157 | P25: =O60/O25 -> 1.3676458
A26: Paper & paper board, article of paper or paper board (kg) | M26: 96989954 | O26: 96989954 | P26: =O61/O26 -> 0.071226583
A27: Non-wood forest products | O27: -
A28: Shea butter oil (tons) | F28: =B12*0.3 -> 452.1105 | O28: =F28 -> 452.1105
A29: Prunus Africana (Kg) | B29: 22768 | O29: =B29 -> 22768
A30: Sandalwood | O30: -
A31: Residues | O31: -
A32: Wood residues | O32: -
A35: Use Table 2009/10, Uganda | C35: - | D35: - | E35: - | K35: - | L35: -
A36: Description | B36: Agric. Production | C36: Forests | D36: Fisheries | E36: Mining & Quarrying | F36: household | G36: manufacturing | H36: construction & Housing | I36: Wholesale & Retail trade | J36: Transport | K36: other services | L36: Education, health & social work | M36: Exportations
A37: Natural inputs
A38: Forest soils/sand (ha)
A39: Seed
A40: Seedlings
A41: Wood biomass available for supply
A42: Hard wood plantation (m3)
A43: Soft wood plantation (m3)
...

Sheet Sheet2
A1: Supply Table 2016/17, Uganda
A2: Description | B2: Agric prod.n | C2: Forestry | D2: Fishing | E2: Mining & Oil&gas | F2: Households | G2: Manuf-acturing | H2: Construction & Housing | I2: Wholesale & Retail trade | J2: Transport | K2: other services | L2: Education, health, others | M2: Import-ations | N2: Flows to environ-ment | O2: Overall total
A3: Natural inputs
A4: Forest sand (ha) | C4: =Sheet4!C4/15 -> 15.866667 | O4: 4752
A5: Seed (kg) | C5: =Sheet4!C5/0.7 -> 505.71429 | O5: -
A6: Seedlings (No) | C6: =Sheet4!C6*1000000/500 -> 3640000 | O6: -
A7: Wood biomass supply | O7: -
A8: Hard wood plantation (m3) | C8: 1465196 | O8: 1465196
A9: Soft wood plantation (m3) | C9: 1491362 | O9: 1491362
A10: Natural forest wood (m3) | C10: 21426364 | O10: 21426364
A11: Non-wood forest products | O11: -
A12: Prunus Africana (kg) | C12: 88090 | O12: 88090
A13: Sandalwood (tons) | C13: 98 | O13: 98
A14: Shea nut (tons) | B14: 1752 | C14: 0 | O14: 1752
A15: Wood products | O15: -
A16: Timber ('000tons) | B16: 7818.581 | C16: 2453 | O16: =SUM(B16:N16) -> 10271.581
A17: Poles ('000tons) | C17: 1247 | O17: 1247
A18: Firewood ('000tons) | B18: =O58-P18 -> 9157.6 | C18: 33044 | O18: =O58 -> 42201.6 | P18: 33044
A19: Charcoal ('000tons) | C19: 11962 | O19: 11962
A21: Finished products
A22: Wood & articles of wood; wood charcoal (m3) | M22: 2624.201 | O22: =M22 -> 2624.201
A23: Cork & cork articles (kg) | M23: 12.046 | O23: =M23 -> 12.046
A24: Manufacture of straw, esparata or other plaiting materials, basket ware or wicker work (kg) | M24: 165.046 | O24: =M24 -> 165.046
A25: Pulp of wood or other fibrous cellulosic material, recovered (waste & scrap) paper or paperboard (kg) | M25: 3851.637 | O25: =M25 -> 3851.637
A26: Paper & paper board, article of paper or paper board (kg) | M26: 138631.73 | O26: =M26 -> 138631.73
A28: Non-wood forest products | O28: -
A29: Shea oil (tons) | B29: 526 | O29: 526
A30: Prunus Africana (kg) | C30: 252567 | O30: 252567
A31: Sandalwood (tons) | C31: =M70 -> 6400 | O31: -
A32: Residuals | O32: -
A33: Wood residues | B33: - | C33: 180000 | G33: 18000 | H33: - | I33: - | J33: - | K33: - | L33: - | O33: 198000
A38: Use Table 2016/17, Uganda
A39: Description | B39: Agric prod. | C39: Forestry | D39: Fishing | E39: Mining & Oil & gas | F39: House-holds | G39: Manuf-acturing | H39: Construction & Housing | I39: Wholesale & Retail trade | J39: Transport | K39: other services | L39: Education, health, others | M39: Export-ations | N39: Flows to environ-ment | O39: Overall total
A40: Natural inputs
A41: Forest soils/sand (ha) | O41: -
A42: Seed | O42: -
A43: Seedlings | O43: -
A44: Wood biomass available for supply | O44: -
A45: Hard wood plantation (m3) | O45: -
A46: Soft wood plantation (m3) | O46: -
...

Sheet Sheet3
A1: Supply Table 2009/10, Uganda
A2: Description | B2: Agric. Production | C2: Forestry | D2: Fisheries | E2: Mining & Quarrying | F2: House-hold | G2: Manufacturing | H2: Construction & Housing | I2: Wholesale & Retail trade | J2: Transport | K2: Other services | L2: Education, health & social work | M2: Import-ations | N2: Flows to environ-ment | O2: Overall total
A3: Natural inputs
A4: Forest sand (UGX mill) | C4: 33 | O4: 33
A5: Seed (UGX mill) | C5: 555 | O5: 555
A6: Seedlings (UGX mill) | C6: 1072 | O6: 1072
A7: Wood biomass available for supply | O7: -
A8: Hard wood plantation (UGX mill) | C8: 36296 | O8: 36296
A9: Soft wood plantation (UGX mill) | C9: 78220 | O9: 78220
A10: Natural forest wood (UGX mill) | C10: 2632371 | O10: 2632371
A11: NWFPs
A12: Shea Pods (number)
A13: Prunus Africana (trees>30 DBH)
A14: Sandal wood
A15: Bamboo
A16: Wood products
A17: Timber | C17: 132677 | D17: - | E17: - | F17: - | G17: - | K17: - | L17: - | M17: 1720 | O17: =SUM(B17:N17) -> 134397
A18: Poles | C18: 41438 | O18: =SUM(B18:N18) -> 41438
A19: Firewood | B19: 114234 | C19: =128916+25228+20130 -> 174274 | D19: - | E19: - | F19: - | G19: - | K19: - | L19: - | M19: - | O19: =SUM(B19:N19) -> 288508
A20: Charcoal | B20: 93123 | C20: 51210 | D20: - | E20: - | F20: - | G20: - | K20: - | L20: - | M20: - | O20: =SUM(B20:N20) -> 144333 | P20: =SUM(O17:O20) -> 608676
A21: Finished products | O21: =SUM(B21:N21) -> 0
A22: Wood & articles of wood; wood charcoal (m3) | M22: =14501778/1000 -> 14501.778 | O22: =SUM(B22:N22) -> 14501.778 | Q22: =O22-O59 -> 1789.993
A23: Cork & cork articles (kg) | M23: =15399/1000 -> 15.399 | O23: =SUM(B23:N23) -> 15.399
A24: Manufacture of straw, esparata or other plaiting materials, basket ware or wicker work (kg) | M24: =352961/1000 -> 352.961 | O24: =SUM(B24:N24) -> 352.961
A25: Pulp of wood or other fibrous cellulosic material, recovered (waste & scrap) paper or paperboard (kg) | M25: =476687/1000 -> 476.687 | O25: =SUM(B25:N25) -> 476.687
A26: Paper & paper board, article of paper or paper board (kg) | M26: =186423731/1000 -> 186423.73 | O26: =SUM(B26:N26) -> 186423.73 | P26: =SUM(O22:O26) -> 201770.56 | Q26: =P26/P63 -> 5.7506151
A27: Non-Wood Forest Products | O27: =SUM(B27:N27) -> 0
A28: Shea butter oil (tons) | F28: =Sheet1!F28*12*255/1000 -> 1383.4581 | O28: =SUM(B28:N28) -> 1383.4581
A29: Prunus Africana | B29: =M67 -> 68.304 | O29: =SUM(B29:N29) -> 68.304
A30: Sandalwood | O30: =SUM(B30:N30) -> 0 | P30: =SUM(O28:O30) -> 1451.7621
A31: Residues | O31: =SUM(B31:N31) -> 0
A32: Wood residuals | O32: =SUM(B32:N32) -> 0
O33: =SUM(B33:N33) -> 0
A34: Total (mill UGX) | B34: =SUM(B3:B33) -> 207425.3 | C34: =SUM(C16:C33) -> 399599 | D34: =SUM(D3:D33) -> 0 | E34: =SUM(E3:E33) -> 0 | F34: =SUM(F3:F33) -> 1383.4581 | G34: =SUM(G3:G33) -> 0 | H34: =SUM(H3:H33) -> 0 | I34: =SUM(I3:I33) -> 0 | J34: =SUM(J3:J33) -> 0 | K34: =SUM(K3:K33) -> 0 | ... N34: =SUM(N3:N33) -> 0 | O34: =SUM(B34:N34) -> 811898.32
O35: =SUM(B35:N35) -> 0 | P35: 811898.32 | R35: =Sheet4!O82/Sheet3!P35 -> 2.7195992
A36: Use Table 2009/10, Uganda | C36: - | D36: - | E36: - | K36: - | L36: - | O36: =SUM(B36:N36) -> 0
A37: Description | B37: Agric. Production | C37: Forests | D37: Fisheries | E37: Mining & Quarrying | F37: House-hold | G37: Manufa-cturing | H37: Construction & Housing | I37: Wholesale & Retail trade | J37: Transport | K37: other services | L37: Education, health & social work | M37: Exportations | N37: Flows to environ-ment | O37: =SUM(B37:N37) -> 0
A38: Natural Inputs | O38: =SUM(B38:N38) -> 0
A39: Forest soils/sand (UGX) | O39: =SUM(B39:N39) -> 0
A40: Seed (UGX) | O40: =SUM(B40:N40) -> 0
...

Sheet Sheet4
A1: Supply Table 2016/17, Uganda | N1: Flows to environment | O1: Overall total
A2: Description | B2: Agric production | C2: Forestry | D2: Fishing | E2: Mining & Oil&gas | F2: House-holds | G2: Manufa-cturing | H2: Construction & Housing | I2: Wholesale & Retail trade | J2: Transport | K2: Other services | L2: Education, health, others | M2: Import-ations
A3: Natural inputs
A4: Sand (UGX mill) | C4: 238 | O4: =SUM(B4:N4) -> 238
A5: Seed (UGX mill) | C5: 354 | O5: =SUM(B5:N5) -> 354
A6: Seedlings (UGX mill) | C6: 1820 | O6: =SUM(B6:N6) -> 1820 | P6: =SUM(O4:O6) -> 2412
A7: Wood biomass available for supply | O7: =SUM(B7:N7) -> 0
A8: Hard wood plantation (mill UGX) | C8: 146520 | O8: =SUM(B8:N8) -> 146520
A9: Soft wood plantation (mill UGX) | C9: 156593 | O9: =SUM(B9:N9) -> 156593
A10: Natural forest wood (million UGX) | C10: 2035505 | O10: =SUM(B10:N10) -> 2035505
A11: NWFPs | O11: =SUM(B11:N11) -> 0
A12: Prunus Africana (UGX mill) | C12: 758 | O12: =SUM(B12:N12) -> 758
A13: Sandal wood (UGX mill) | C13: 3561 | O13: =SUM(B13:N13) -> 3561
A14: Shea nuts (UGX mill) | C14: 3504 | O14: =SUM(B14:N14) -> 3504
O15: =SUM(B15:N15) -> 0
A16: Wood products | O16: =SUM(B16:N16) -> 0
A17: Timber (UGX million) | B17: - | C17: 361976 | D17: - | E17: - | F17: - | G17: - | H17: - | I17: - | J17: - | K17: - | L17: - | M17: - | O17: =SUM(B17:N17) -> 361976
A18: Poles (UGX million) | C18: 99291 | O18: =SUM(B18:N18) -> 99291
A19: Firewood (UGX million) | B19: 176277 | C19: 667755 | D19: - | E19: - | F19: - | G19: - | H19: - | I19: - | J19: - | K19: - | L19: - | M19: - | O19: =SUM(B19:N19) -> 844032
A20: Charcoal (UGX million) | B20: 430476 | C20: 27488 | D20: - | E20: - | F20: - | G20: - | H20: - | I20: - | J20: - | K20: - | L20: - | M20: - | O20: =SUM(B20:N20) -> 457964 | P20: =SUM(O17:O20) -> 1763263
O21: =SUM(B21:N21) -> 0
A22: Finished products | O22: =SUM(B22:N22) -> 0
A23: Wood & articles of wood; wood charcoal (m3) | M23: =18202503/1000 -> 18202.503 | O23: =SUM(B23:N23) -> 18202.503
A24: Cork & cork articles (kg) | M24: =212008/1000 -> 212.008 | O24: =SUM(B24:N24) -> 212.008
A25: Manufacture of straw, esparata or other plaiting materials, basket ware or wicker work (kg) | M25: =518636/1000 -> 518.636 | O25: =SUM(B25:N25) -> 518.636
A26: Pulp of wood or other fibrous cellulosic material, recovered (waste & scrap) paper or paperboard (kg) | M26: =2728314/1000 -> 2728.314 | O26: =SUM(B26:N26) -> 2728.314
A27: Paper & paper board, article of paper or paper board (kg) | M27: =417774026/1000 -> 417774.03 | O27: =SUM(B27:N27) -> 417774.03 | P27: =SUM(O23:O27) -> 439435.49 | Q27: =P27/P71 -> 2.5330621
O28: =SUM(B28:N28) -> 0
O29: =SUM(B29:N29) -> 0
A30: Non-wood forest products | O30: =SUM(B30:N30) -> 0
A31: Shea butter oil (litres) | B31: =F74+M74 -> 2630 | O31: =SUM(B31:N31) -> 2630
A32: Prunus Africana (UGX mill) | B32: =M75 -> 758 | O32: =SUM(B32:N32) -> 758
A33: Sandalwood | G33: =M77 -> 927.309 | O33: =SUM(B33:N33) -> 927.309
A34: Residuals | O34: =SUM(B34:N34) -> 0
A35: Wood residues (UGX mill) | C35: 1620 | G35: 162 | O35: =SUM(B35:N35) -> 1782 | P35: =SUM(O31:O35) -> 6097.309
O36: =SUM(B36:N36) -> 0
A37: Total (UGX Mill) | B37: =SUM(B15:B36) -> 610141 | C37: =SUM(C15:C36) -> 1158130 | D37: =SUM(D15:D36) -> 0 | E37: =SUM(E15:E36) -> 0 | F37: =SUM(F15:F36) -> 0 | G37: =SUM(G15:G36) -> 1089.309 | H37: =SUM(H15:H36) -> 0 | I37: =SUM(I15:I36) -> 0 | ... O37: =SUM(O15:O36) -> 2208795.8 | Q37: 2208037.8 | R37: =Q37/Sheet3!P35 -> 2.7195989
A42: Use Table 2016/17, Uganda Description | B42: Agric production | C42: Forestry | D42: Fishing | E42: Mining & Oil & gas | F42: Households | G42: Manuf-acturing | H42: Construction & Housing | I42: Wholesale & Retail trade | J42: Transport | K42: other services | L42: Education, health, others | M42: Export-ations | N42: Flows to environ-ment | O42: Overall total
A43: Natural inputs
A44: Forest soils/sand (UGX) | O44: -
...

Sheet PSUT 1990
A1: Supply Table 1990, Uganda | O1: Flows to the Environment | P1: Overall total
A2: Description | B2: Agric. Production | C2: Forestry | D2: Fishings | E2: Mining & Quarrying | F2: H/hold | G2: Manufacturing | H2: Construction & Housing | I2: Wholesale & Retail trade | J2: Transport | K2: Utilities (electricity) | L2: Education, health & social work | M2: Accumulation | N2: Importations | O2: Flows to the Environment | P2: Overall total
A3: Natural inputs | P3: =SUM(B3:O3) -> 0
A4: Seed (kg) | P4: =SUM(B4:O4) -> 0
A5: Seedlings (No.) | P5: =SUM(B5:O5) -> 0
A6: Wood biomass available for supply | P6: =SUM(B6:O6) -> 0
A7: Broad leaved plantations wood ('000 tons) | C7: =([1]Sheet3!$F$5/1000)/10 -> 34.5316 | P7: =SUM(B7:O7) -> 34.5316
A8: Coniferous plantations wood ('000 tons) | C8: =([2]Sheet2!$G$5/1000)/10 -> 63.0416 | P8: =SUM(B8:O8) -> 63.0416
A9: THF Well stocked wood ('000 tons) | C9: =([2]Sheet2!$I$5/1000)/30 -> 805.16807 | P9: =SUM(B9:O9) -> 805.16807
A10: THF Low stocked wood ('000 tons) | C10: =([2]Sheet2!$J$5/1000)/30 -> 122.96073 | P10: =SUM(B10:O10) -> 122.96073
A11: Woodlands wood ('000 tons) | C11: =([2]Sheet2!$K$5/1000)/30 -> 501.27357 | P11: =SUM(B11:O11) -> 501.27357
A12: Sub-total | C12: =SUM(C7:C11) -> 1526.9756
A13: Wood from other land covers ('000 tons) | C13: =[3]Sheet2!$P$7/1000 -> 57468.892
A14: Available wood inputs | C14: =SUM(C7:C13) -> 60522.843
A15: Wood not available for supply | C15: =P21-C14 -> -42271.643
A16: NWFPs | P16: =SUM(B16:O16) -> 0
A17: Shea nut (pods) | P17: =SUM(B17:O17) -> 0
A18: Prunus Africana (trees>30 DBH) | P18: =SUM(B18:O18) -> 0
A19: Sandal wood | P19: =SUM(B19:O19) -> 0
P20: =SUM(B20:O20) -> 0
A21: Wood Products ('000 tons) | C21: =SUM(C22:C27) -> 16592 | O21: =0.1*SUM(B21:N21) -> 1659.2 | P21: =SUM(B21:O21) -> 18251.2
A22: Sawn wood ('000 t) | C22: 324 | O22: =0.1*SUM(B22:N22) -> 32.4 | P22: =SUM(B22:O22) -> 356.4 | R22: =C22/$C$28 -> 0.019527483
A23: Poles ('000 t) | C23: 431 | O23: =0.1*SUM(B23:N23) -> 43.1 | P23: =SUM(B23:O23) -> 474.1 | R23: =C23/$C$28 -> 0.025976374
A24: Firewood Household ('000 ts) | C24: 11654 | O24: =0.1*SUM(B24:N24) -> 1165.4 | P24: =SUM(B24:O24) -> 12819.4 | R24: =C24/$C$28 -> 0.70238669 | S24: =R24+R25+R26 -> 0.8100892
A25: Firewood Commecial ('000 t) | C25: 1534 | O25: =0.1*SUM(B25:N25) -> 153.4 | P25: =SUM(B25:O25) -> 1687.4 | R25: =C25/$C$28 -> 0.092454195
A26: Firewood Industrial ('000 t) | C26: 253 | O26: =0.1*SUM(B26:N26) -> 25.3 | P26: =SUM(B26:O26) -> 278.3 | R26: =C26/$C$28 -> 0.015248312
A27: Charcoal ('000 t) | C27: =(2142+254) -> 2396 | O27: =0.1*SUM(B27:N27) -> 239.6 | P27: =SUM(B27:O27) -> 2635.6 | R27: =C27/$C$28 -> 0.14440694
A28: Sub-total | B28: =SUM(B22:B27) -> 0 | C28: =SUM(C22:C27) -> 16592 | E28: =SUM(E22:E27) -> 0 | F28: =SUM(F22:F27) -> 0 | G28: =SUM(G22:G27) -> 0 | H28: =SUM(H22:H27) -> 0 | I28: =SUM(I22:I27) -> 0 | J28: =SUM(J22:J27) -> 0 | K28: =SUM(K22:K27) -> 0 | L28: =SUM(L22:L27) -> 0 | N28: =SUM(N22:N27) -> 0 | O28: =SUM(O22:O27) -> 1659.2 | P28: =SUM(B28:O28) -> 18251.2 | R28: =C28/$C$28 -> 1
A29: Finished products | P29: =SUM(B29:O29) -> 0
A30: Wood & articles of wood; wood charcoal (m3) | P30: =SUM(B30:O30) -> 0
A31: Cork & cork articles (kg) | P31: =SUM(B31:O31) -> 0
A32: Manufacture of straw, esparata or other plaiting materials, basket ware or wicker work (kg) | P32: =SUM(B32:O32) -> 0
A33: Pulp of wood or other fibrous cellulosic material, recovered (waste & scrap) paper or paperboard (kg) | P33: =SUM(B33:O33) -> 0
A34: Paper & paper board, article of paper or paper board (kg) | P34: =SUM(B34:O34) -> 0
A35: Non-wood forest products | P35: =SUM(B35:O35) -> 0
A36: Shea butter oil (tons) | P36: =SUM(B36:O36) -> 0
A37: Prunus Africana (Kg) | P37: =SUM(B37:O37) -> 0
A38: Sandalwood | P38: =SUM(B38:O38) -> 0
A39: Residues | P39: =SUM(B39:O39) -> 0
A40: Wood residues | C40: =0.1*C28 -> 1659.2 | P40: =SUM(B40:O40) -> 1659.2
...

Sheet PSUT 2000
A1: Supply Table 2000, Uganda | N1: Flows to the Environment | O1: Overall total
A2: Description | B2: Agric. Production | C2: Forestry | D2: Fishings | E2: Mining & Quarrying | F2: H/hold | G2: Manufacturing | H2: Construction & Housing | I2: Wholesale & Retail trade | J2: Transport | K2: Utilities (electricity) | L2: Education, health & social work | M2: Importations | N2: Flows to the Environment | O2: Overall total
A3: Natural inputs | O3: =SUM(B3:N3) -> 0
A4: Seed (kg) | O4: =SUM(B4:N4) -> 0
A5: Seedlings (No.) | O5: =SUM(B5:N5) -> 0
A6: Wood biomass available for supply | C6: =SUM(C7:C11) -> 1494.4512 | O6: =SUM(B6:N6) -> 1494.4512
A7: Broad leaved plantations wood ('000tons) | C7: =([2]Sheet2!$F$5/1000)/15 -> 23.021067 | O7: =SUM(B7:N7) -> 23.021067
A8: Coniferous plantations wood ('000tons) | C8: =([2]Sheet2!$G$5/1000)/15 -> 42.027733 | O8: =SUM(B8:N8) -> 42.027733
A9: THF Well stocked wood ('000tons) | C9: =([2]Sheet2!$I$5/1000)/30 -> 805.16807 | O9: =SUM(B9:N9) -> 805.16807
A10: THF Low stocked wood ('000tons) | C10: =([2]Sheet2!$J$5/1000)/30 -> 122.96073 | O10: =SUM(B10:N10) -> 122.96073
A11: Woodlands wood ('000tons) | C11: =([2]Sheet2!$K$5/1000)/30 -> 501.27357 | O11: =SUM(B11:N11) -> 501.27357
A12: Forest wood available for supply | C12: =C6 -> 1494.4512
A13: Wood from other land covers | C13: =[3]Sheet2!$P$15/1000 -> 41813.499
A14: Wood available as natural inputs | C14: =C13+C12 -> 43307.951
A15: Wood not available for supply sources | C15: =O27-C14 -> -15577.451
A16: NWFPs | O16: =SUM(B16:N16) -> 0
A17: Shea nut (pods) | O17: =SUM(B17:N17) -> 0
A18: Prunus Africana (trees>30 DBH) | O18: =SUM(B18:N18) -> 0
A19: Sandal wood | O19: =SUM(B19:N19) -> 0
A20: Wood Products ('000 tons)
A21: Sawn wood ('000 tons) | C21: 652 | N21: =0.05*SUM(B21:M21) -> 32.6 | O21: =SUM(B21:N21) -> 684.6 | Q21: =C21/$C$27 -> 0.024687618
A22: Poles ('000 tons) | C22: 659 | N22: =0.05*SUM(B22:M22) -> 32.95 | O22: =SUM(B22:N22) -> 691.95 | Q22: =C22/$C$27 -> 0.024952669
A23: Firewood Household ('000 tons) | C23: 16100 | N23: =0.05*SUM(B23:M23) -> 805 | O23: =SUM(B23:N23) -> 16905 | Q23: =C23/$C$27 -> 0.60961757
A24: Firewood Commecial ('000 tons) | C24: 2550 | N24: =0.05*SUM(B24:M24) -> 127.5 | O24: =SUM(B24:N24) -> 2677.5 | Q24: =C24/$C$27 -> 0.096554335
A25: Firewood Industrial ('000 tons) | C25: 1569 | N25: =0.05*SUM(B25:M25) -> 78.45 | O25: =SUM(B25:N25) -> 1647.45 | Q25: =C25/$C$27 -> 0.059409315
A26: Charcoal ('000 tons) | C26: =(4332+548) -> 4880 | N26: =0.05*SUM(B26:M26) -> 244 | O26: =SUM(B26:N26) -> 5124 | Q26: =C26/$C$27 -> 0.18477849
A27: Sub-total ('000 tons) | B27: =SUM(B21:B26) -> 0 | C27: =SUM(C21:C26) -> 26410 | D27: =SUM(D21:D26) -> 0 | E27: =SUM(E21:E26) -> 0 | F27: =SUM(F21:F26) -> 0 | G27: =SUM(G21:G26) -> 0 | H27: =SUM(H21:H26) -> 0 | I27: =SUM(I21:I26) -> 0 | ... O27: =SUM(O21:O26) -> 27730.5 | Q27: =C27/$C$27 -> 1
A28: Finished products | N28: =0.05*SUM(B28:M28) -> 0 | O28: =SUM(B28:N28) -> 0
A29: Wood & articles of wood; wood charcoal ('000 tons) | M29: =([4]Sheet1!$G$21)*7/1000000 -> 74158.641 | N29: =0.05*SUM(B29:M29) -> 3707.9321 | O29: =SUM(B29:N29) -> 77866.573 | Q29: =M29-M74 -> 25037.296
A30: Cork & cork articles ('000tons) | M30: =[4]Sheet2!$G$21/1000000 -> 9976.9283 | N30: =0.05*SUM(B30:M30) -> 498.84642 | O30: =SUM(B30:N30) -> 10475.775 | Q30: =M30-M75 -> 9976.9283
A31: Manufacture of straw, esparata or other plaiting materials, basket ware or wicker work ('000tons) | M31: =[4]Sheet3!$G$21/1000000 -> 6135.8527 | N31: =0.05*SUM(B31:M31) -> 306.79264 | O31: =SUM(B31:N31) -> 6442.6453 | Q31: =M31-M76 -> 6133.8527
A32: Pulp of wood or other fibrous cellulosic material, recovered (waste & scrap) paper or paperboard ('000tons) | M32: =[4]Sheet4!$G$21/1000000 -> 191.52192 | N32: =0.05*SUM(B32:M32) -> 9.5760961 | O32: =SUM(B32:N32) -> 201.09802 | Q32: =M32-M77 -> 191.52192
A33: Paper & paper board, article of paper or paper board (tons) | M33: =[4]Sheet5!$G$21/1000000 -> 34303.549 | N33: =0.05*SUM(B33:M33) -> 1715.1775 | O33: =SUM(B33:N33) -> 36018.727 | Q33: =M79-M33 -> 15613.76
A34: Sub-total ('000 tons) | B34: =SUM(B29:B33) -> 0 | C34: =SUM(C29:C33) -> 0 | D34: =SUM(D29:D33) -> 0 | E34: =SUM(E29:E33) -> 0 | F34: =SUM(F29:F33) -> 0 | G34: =SUM(G29:G33) -> 0 | H34: =SUM(H29:H33) -> 0 | I34: =SUM(I29:I33) -> 0 | ... K34: =SUM(K29:K33) -> 0 | M34: =SUM(M29:M33) -> 124766.49 | N34: =SUM(N29:N33) -> 6238.3247 | O34: =SUM(O29:O33) -> 131004.82
A35: Non-wood forest products | N35: =0.05*SUM(B35:M35) -> 0 | O35: =SUM(B35:N35) -> 0
A36: Shea butter oil (tons) | N36: =0.05*SUM(B36:M36) -> 0 | O36: =SUM(B36:N36) -> 0
A37: Prunus Africana (Kg) | N37: =0.05*SUM(B37:M37) -> 0 | O37: =SUM(B37:N37) -> 0
A38: Sandalwood | N38: =0.05*SUM(B38:M38) -> 0 | O38: =SUM(B38:N38) -> 0
A39: Residues | O39: =SUM(B39:N39) -> 0
A40: Wood residues | C40: =N20 -> 0 | D40: =O20 -> 0 | E40: =P20 -> 0 | F40: =Q20 -> 0 | G40: =R20 -> 0 | H40: =S20 -> 0 | I40: =T20 -> 0 | J40: =U20 -> 0 | ... M40: =X20 -> 0 | N40: =N34+N27 -> 7558.8247 | O40: =SUM(B40:N40) -> 7558.8247
...

Sheet PSUT 2005
A1: Supply Table 2005, Uganda | N1: Flows to the Environment | O1: Overall total
A2: Description | B2: Agric. Production | C2: Forestry | D2: Fishings | E2: Mining & Quarrying | F2: H/hold | G2: Manufacturing | H2: Construction & Housing | I2: Wholesale & Retail trade | J2: Transport | K2: Utilities (electricity) | L2: Education, health & social work | M2: Importations | N2: Flows to the Environment | O2: Overall total
A3: Natural inputs
A4: Seed (kg) | O4: =SUM(B4:N4) -> 0
A5: Seedlings (No.) | O5: =SUM(B5:N5) -> 0
A6: Wood biomass available for supply | O6: =SUM(B6:N6) -> 0
A7: Broad leaved plantations wood ('000 tons) | C7: =([1]Sheet3!$F$17/1000)/15 -> 24.292533 | O7: =SUM(B7:N7) -> 24.292533
A8: Coniferous plantations wood ('000 tons) | C8: =([1]Sheet3!$G$17/1000)/15 -> 32.9068 | O8: =SUM(B8:N8) -> 32.9068
A9: THF Well stocked wood (('000 tons)tons) | C9: =([2]Sheet2!$I$17/1000)/30 -> 580.45623 | O9: =SUM(B9:N9) -> 580.45623
A10: THF Low stocked wood ('000 tons) | C10: =([2]Sheet2!$J$17/1000)/30 -> 68.7138 | O10: =SUM(B10:N10) -> 68.7138
A11: Woodlands wood ('000 tons) | C11: =([2]Sheet2!$K$17/1000)/30 -> 162.28957 | O11: =SUM(B11:N11) -> 162.28957
A12: Forest wood available for supply | C12: =SUM(C7:C11) -> 868.65893 | D12: =SUM(D7:D11) -> 0 | E12: =SUM(E7:E11) -> 0 | F12: =SUM(F7:F11) -> 0 | G12: =SUM(G7:G11) -> 0 | H12: =SUM(H7:H11) -> 0 | I12: =SUM(I7:I11) -> 0 | J12: =SUM(J7:J11) -> 0 | ... O12: =SUM(O7:O11) -> 868.65893 | P12: =O12/O27 -> 0.025709134
A13: Wood from other land covers | C13: =[3]Sheet2!$P$24/1000 -> 38895.619
A14: Wood available as natural inputs | C14: =C13+C12 -> 39764.278
A15: Wood not available for supply sources | C15: =O27-C14 -> -5976.3284
A16: NWFPs | O16: =SUM(B16:N16) -> 0
A17: Shea nut (pods) | O17: =SUM(B17:N17) -> 0
A18: Prunus Africana (trees>30 DBH) | O18: =SUM(B18:N18) -> 0
A19: Sandal wood | O19: =SUM(B19:N19) -> 0
A20: Wood Products ('000 tons) | C20: =SUM(C21:C26) -> 32179
A21: Sawn wood ('000 tons) | C21: 902 | N21: =0.05*SUM(B21:M21) -> 45.1 | O21: =SUM(B21:N21) -> 947.1 | Q21: =C21/$C$27 -> 0.028030703
A22: Poles ('000 tons) | C22: 808 | N22: =0.05*SUM(B22:M22) -> 40.4 | O22: =SUM(B22:N22) -> 848.4 | Q22: =C22/$C$27 -> 0.025109543
A23: Firewood Household ('000 tons) | C23: 19021 | N23: =0.05*SUM(B23:M23) -> 951.05 | O23: =SUM(B23:N23) -> 19972.05 | Q23: =C23/$C$27 -> 0.59109979
A24: Firewood Commecial ('000 tons) | C24: 2993 | N24: =0.05*SUM(B24:M24) -> 149.65 | O24: =SUM(B24:N24) -> 3142.65 | Q24: =C24/$C$27 -> 0.09301097
A25: Firewood Industrial ('000 tons) | C25: 1949 | N25: =0.05*SUM(B25:M25) -> 97.45 | O25: =SUM(B25:N25) -> 2046.45 | Q25: =C25/$C$27 -> 0.060567451
A26: Charcoal ('000 tons) | C26: =6506 -> 6506 | N26: =0.05*SUM(B26:M26) -> 325.3 | O26: =SUM(B26:N26) -> 6831.3 | Q26: =C26/$C$27 -> 0.20218155
A27: Sub-total ('000 tons) | C27: =SUM(C21:C26) -> 32179 | N27: =0.05*SUM(B27:M27) -> 1608.95 | O27: =SUM(B27:N27) -> 33787.95 | Q27: =C27/$C$27 -> 1
A28: Finished products | N28: =0.05*SUM(B28:M28) -> 0 | O28: =SUM(B28:N28) -> 0
A29: Wood & articles of wood; wood charcoal ('000tons) | M29: =[4]Sheet1!$I$16*0.7/1000 -> 1.2018655 | N29: =0.05*SUM(B29:M29) -> 0.060093274 | O29: =SUM(B29:N29) -> 1.2619588
A30: Cork & cork articles ('000tons) | M30: =[4]Sheet2!$I$16/1000 -> 0.049242251 | N30: =0.05*SUM(B30:M30) -> 0.0024621126 | O30: =SUM(B30:N30) -> 0.051704364
A31: Manufacture of straw, esparata or other plaiting materials, basket ware or wicker work ('000tons) | M31: =[4]Sheet3!$I$16/1000 -> 252.5912 | N31: =0.05*SUM(B31:M31) -> 12.62956 | O31: =SUM(B31:N31) -> 265.22076
A32: Pulp of wood or other fibrous cellulosic material, recovered (waste & scrap) paper or paperboard ('000tons) | M32: =[4]Sheet4!$I$16/1000 -> 0.33981352 | N32: =0.05*SUM(B32:M32) -> 0.016990676 | O32: =SUM(B32:N32) -> 0.3568042
A33: Paper & paper board, article of paper or paper board ('000tons) | M33: =[4]Sheet5!$I$16/1000 -> 18501.792 | N33: =0.05*SUM(B33:M33) -> 925.0896 | O33: =SUM(B33:N33) -> 19426.882
A34: Sub-total ('000 tons) | M34: =SUM(M29:M33) -> 18755.974 | N34: =0.05*SUM(B34:M34) -> 937.79871 | O34: =SUM(O29:O33) -> 19693.773
A35: Non-wood forest products | N35: =0.05*SUM(B35:M35) -> 0 | O35: =SUM(B35:N35) -> 0
A36: Shea butter oil (tons) | N36: =0.05*SUM(B36:M36) -> 0 | O36: =SUM(B36:N36) -> 0
A37: Prunus Africana (Kg) | N37: =0.05*SUM(B37:M37) -> 0 | O37: =SUM(B37:N37) -> 0
A38: Sandalwood | O38: =SUM(B38:N38) -> 0
A39: Residues | O39: =SUM(B39:N39) -> 0
A40: Wood residues | C40: =O20-C20 -> -32179 | O40: =SUM(B40:N40) -> -32179
...

Sheet PSUT 2010
A1: Supply Table 2010, Uganda | O1: Flows to the Environment | P1: Overall total
A2: Description | B2: Agric. Production | C2: Forestry | D2: Fishings | E2: Mining & Quarrying | F2: Manufacturing | G2: Utilities (electricity) | H2: Construction & Housing | I2: Wholesale & Retail trade | J2: Transport | K2: Education, health & social work | M2: H/hold | N2: Importations
A3: Natural inputs
A4: Seed (kg) | C4: =Sheet3!C5/0.7 -> 792.85714 | P4: =SUM(B4:O4) -> 792.85714
A5: Seedlings (No.) | C5: =Sheet3!C6*1000000/500 -> 2144000 | P5: =SUM(B5:O5) -> 2144000
A6: Wood biomass available for supply | P6: =SUM(B6:O6) -> 0
A7: Broad leaved plantations wood ('000 tons) | C7: =[2]Sheet2!$F$23/100015 -> 11.306934 | P7: =SUM(B7:O7) -> 11.306934
A8: Coniferous plantations wood ('000 tons) | C8: =[2]Sheet2!$G$23/1000/15 -> 174.301 | P8: =SUM(B8:O8) -> 174.301
A9: THF Well stocked wood ('000 tons) | C9: =([2]Sheet2!$I$23/1000)/30 -> 578.90283 | P9: =SUM(B9:O9) -> 578.90283
A10: THF Low stocked wood ('000 tons) | C10: =[2]Sheet2!$J$23/1000/30 -> 37.245133 | P10: =SUM(B10:O10) -> 37.245133
A11: Woodlands wood ('000 tons) | C11: =[2]Sheet2!$K$23/1000/30 -> 140.9923 | P11: =SUM(B11:O11) -> 140.9923
A12: Forest wood available for supply | C12: =SUM(C7:C11) -> 942.7482 | D12: =SUM(D7:D11) -> 0 | E12: =SUM(E7:E11) -> 0 | F12: =SUM(F7:F11) -> 0 | G12: =SUM(G7:G11) -> 0 | H12: =SUM(H7:H11) -> 0 | I12: =SUM(I7:I11) -> 0 | J12: =SUM(J7:J11) -> 0 | ... P12: =SUM(P7:P11) -> 942.7482 | R12: =C12/P28 -> 0.02274837
A13: Wood from other land covers | C13: =([3]Sheet2!$P$35)/1000 -> 45539.639
A14: Wood available as natural inputs | C14: =C13+C12 -> 46482.387
A15: Wood not available for supply sources | C15: =P28-C14 -> -5039.9374 | R15: =C15/P28 -> -0.12161292
A16: NWFPs | P16: =SUM(B16:O16) -> 0
A17: Shea nut (pods) | B17: 753518 | O17: =0.05*SUM(B17:N17) -> 37675.9 | P17: =SUM(B17:O17) -> 791193.9
A18: Prunus Africana (trees>30 DBH) | C18: =Sheet1!B29 -> 22768 | O18: =0.05*SUM(B18:N18) -> 1138.4 | P18: =SUM(B18:O18) -> 23906.4
A19: Sandal wood | O19: =0.05*SUM(B19:N19) -> 0 | P19: =SUM(B19:O19) -> 0
P20: =SUM(B20:O20) -> 0
A21: Wood Products ('000 tons) | C21: =SUM(C22:C27) -> 39469
A22: Sawn wood ('000 tons) | C22: 1847 | O22: =0.05*SUM(B22:N22) -> 92.35 | P22: =SUM(B22:O22) -> 1939.35 | R22: =C22/$C$21 -> 0.04679622 | S22: 132677 | T22: =S22*1000000/(C22*1000) -> 71833.785
A23: Poles ('000 tons) | C23: 1013 | O23: =0.05*SUM(B23:N23) -> 50.65 | P23: =SUM(B23:O23) -> 1063.65 | R23: =C23/$C$21 -> 0.025665712 | S23: 41438 | T23: =S23*1000000/(C23*1000) -> 40906.219
A24: Firewood Household ('000 tons) | C24: 22692 | O24: =0.05*SUM(B24:N24) -> 1134.6 | P24: =SUM(B24:O24) -> 23826.6 | R24: =C24/$C$21 -> 0.57493223 | S24: 128916 | T24: =S24*1000000/(C24*1000) -> 5681.1211
A25: Firewood Commecial ('000 tons) | C25: 3256 | O25: =0.05*SUM(B25:N25) -> 162.8 | P25: =SUM(B25:O25) -> 3418.8 | R25: =C25/$C$21 -> 0.082495123 | S25: 25225 | T25: =S25*1000000/(C25*1000) -> 7747.2359
A26: Firewood Industrial ('000 tons) | C26: 2126 | O26: =0.05*SUM(B26:N26) -> 106.3 | P26: =SUM(B26:O26) -> 2232.3 | R26: =C26/$C$21 -> 0.053865059 | S26: 20130 | T26: =S26*1000000/(C26*1000) -> 9468.4854
A27: Charcoal ('000 tons) | C27: =8535 -> 8535 | O27: =0.05*SUM(B27:N27) -> 426.75 | P27: =SUM(B27:O27) -> 8961.75 | R27: =C27/$C$21 -> 0.21624566 | S27: 51210 | T27: =S27*1000000/(C27*1000) -> 6000
A28: Sub-total ('000 tons) | B28: =SUM(B22:B27) -> 0 | C28: =SUM(C22:C27) -> 39469 | D28: =SUM(D22:D27) -> 0 | E28: =SUM(E22:E27) -> 0 | F28: =SUM(F22:F27) -> 0 | G28: =SUM(G22:G27) -> 0 | H28: =SUM(H22:H27) -> 0 | I28: =SUM(I22:I27) -> 0 | ... P28: =SUM(P22:P27) -> 41442.45 | R28: =C28/$C$21 -> 1 | S28: 399599 | T28: =S28*1000000/(C28*1000) -> 10124.376
A29: Finished products | B29: =SUM(B22:B28) -> 0 | O29: =0.05*SUM(B29:N29) -> 0 | P29: =SUM(B29:O29) -> 0
A30: Wood & articles of wood; wood charcoal ('000tons) | N30: =3341716*0.7/1000 -> 2339.2012 | O30: =0.05*SUM(B30:N30) -> 116.96006 | P30: =SUM(B30:O30) -> 2456.1613
A31: Cork & cork articles ('000tons) | N31: =2081/1000000 -> 0.002081 | O31: =0.05*SUM(B31:N31) -> 0.00010405 | P31: =SUM(B31:O31) -> 0.00218505
A32: Manufacture of straw, esparata or other plaiting materials, basket ware or wicker work ('000tons) | N32: =345524/1000000 -> 0.345524 | O32: =0.05*SUM(B32:N32) -> 0.0172762 | P32: =SUM(B32:O32) -> 0.3628002
A33: Pulp of wood or other fibrous cellulosic material, recovered (waste & scrap) paper or paperboard ('000tons) | N33: =911851/1000000 -> 0.911851 | O33: =0.05*SUM(B33:N33) -> 0.04559255 | P33: =SUM(B33:O33) -> 0.95744355
A34: Paper & paper board, article of paper or paper board ('000tons) | N34: =95852047/1000000 -> 95.852047 | O34: =0.05*SUM(B34:N34) -> 4.7926024 | P34: =SUM(B34:O34) -> 100.64465
A35: Sub-total ('000 tons) | N35: =SUM(N30:N34) -> 2436.3127 | O35: =SUM(O30:O34) -> 121.81564 | P35: =SUM(P30:P34) -> 2558.1283
A36: Non-wood forest products | O36: =0.05*SUM(B36:N36) -> 0 | P36: =SUM(B36:O36) -> 0
A37: Shea butter oil (tons) | F37: =[6]Sheet1!$Y$12/1000 -> 1507.035 | O37: =0.05*SUM(B37:N37) -> 75.35175 | P37: =SUM(C37:O37) -> 1582.3868
A38: Prunus Africana (Kg) | P38: =SUM(C38:O38) -> 0
A39: Sandalwood | O39: =0.05*SUM(B39:N39) -> 0 | P39: =SUM(B39:O39) -> 0
A40: Residues | O40: =0.05*SUM(B40:N40) -> 0 | P40: =SUM(B40:O40) -> 0
...

Sheet PSUT 2015
A1: Supply Table 2015 Uganda | N1: Flows to the Environment | O1: Overall total
A2: Description | B2: Agric. Production | C2: Forestry | D2: Fishings | E2: Mining & Quarrying | F2: H/hold | G2: Manufacturing | H2: Construction & Housing | I2: Wholesale & Retail trade | J2: Transport | K2: Utilities (electricity) | L2: Education, health & social work | M2: Importations | N2: Flows to the Environment | O2: Overall total
A3: Natural inputs | O3: =SUM(B3:N3) -> 0
A4: Seed (kg) | O4: =SUM(B4:N4) -> 0
A5: Seedlings (No.) | O5: =SUM(B5:N5) -> 0
A6: Wood biomass available for supply | O6: =SUM(B6:N6) -> 0 | P6: =O6/O28 -> 0
A7: Broad leaved plantations wood ('000 tons) | C7: =[2]Sheet2!$F$28/1000/15 -> 97.679733 | O7: =SUM(B7:N7) -> 97.679733
A8: Coniferous plantations wood ('000 tons) | C8: =[2]Sheet2!$G$28/1000/15 -> 99.424067 | O8: =SUM(B8:N8) -> 99.424067
A9: THF Well stocked wood ('000 tons) | C9: =[2]Sheet2!$I$28/1000/30 -> 525.22857 | O9: =SUM(B9:N9) -> 525.22857
A10: THF Low stocked wood ('000 tons) | C10: =[2]Sheet2!$J$28/1000/30 -> 71.2422 | O10: =SUM(B10:N10) -> 71.2422
A11: Woodlands wood ('000 tons) | C11: =[2]Sheet2!$K$28/1000/30 -> 154.44267 | O11: =SUM(B11:N11) -> 154.44267
A12: Forest wood available for supply | C12: =SUM(C7:C11) -> 948.01723
A13: Wood from other land covers | C13: =[3]Sheet2!$P$42/1000 -> 45805.061
A14: Wood available as natural inputs | C14: =C13+C12 -> 46753.078
A15: Wood not available for supply sources | C15: =O28-C14 -> 4388.2216 | P15: =C15/O28 -> 0.085805829
A16: NWFPs | O16: =SUM(B16:N16) -> 0
A17: Shea nut (pods) | O17: =SUM(B17:N17) -> 0
A18: Prunus Africana (trees>30 DBH) | O18: =SUM(B18:N18) -> 0
A19: Sandal wood | O19: =SUM(B19:N19) -> 0
O20: =SUM(B20:N20) -> 0
A21: Wood Products ('000 tons) | C21: =SUM(C22:C27) -> 48706 | O21: =SUM(O22:O27) -> 51141.3
A22: Sawn wood ('000 tons) | C22: 2453 | N22: =0.05*SUM(B22:M22) -> 122.65 | O22: =SUM(B22:N22) -> 2575.65 | R22: 361976 | S22: =R22*1000000/(C22*1000) -> 147564.61
A23: Poles ('000 tons) | C23: 1247 | N23: =0.05*SUM(B23:M23) -> 62.35 | O23: =SUM(B23:N23) -> 1309.35 | Q23: =C22/$C$28 -> 0.050363405 | R23: 251793 | S23: =R23*1000000/(C23*1000) -> 201919.01
A24: Firewood Household ('000 tons) | C24: 27024 | N24: =0.05*SUM(B24:M24) -> 1351.2 | O24: =SUM(B24:N24) -> 28375.2 | Q24: =C23/$C$28 -> 0.025602595 | R24: 146752 | S24: =R24*1000000/(C24*1000) -> 5430.4322
A25: Firewood Commecial ('000 tons) | C25: 3656 | N25: =0.05*SUM(B25:M25) -> 182.8 | O25: =SUM(B25:N25) -> 3838.8 | Q25: =C24/$C$28 -> 0.55483924 | R25: 27523 | S25: =R25*1000000/(C25*1000) -> 7528.1729
A26: Firewood Industrial ('000 tons) | C26: 2364 | N26: =0.05*SUM(B26:M26) -> 118.2 | O26: =SUM(B26:N26) -> 2482.2 | Q26: =C25/$C$28 -> 0.075062621 | R26: 21867 | S26: =R26*1000000/(C26*1000) -> 9250
A27: Charcoal ('000 tons) | C27: =11962 -> 11962 | N27: =0.05*SUM(B27:M27) -> 598.1 | O27: =SUM(B27:N27) -> 12560.1 | Q27: =C26/$C$28 -> 0.048536115 | R27: 66894 | S27: =R27*1000000/(C27*1000) -> 5592.2087
A28: Sub-total ('000 tons) | B28: =SUM(B22:B27) -> 0 | C28: =SUM(C22:C27) -> 48706 | D28: =SUM(D22:D27) -> 0 | E28: =SUM(E22:E27) -> 0 | F28: =SUM(F22:F27) -> 0 | G28: =SUM(G22:G27) -> 0 | H28: =SUM(H22:H27) -> 0 | I28: =SUM(I22:I27) -> 0 | ... O28: =SUM(O22:O27) -> 51141.3 | Q28: =C27/$C$28 -> 0.24559603 | R28: 876805
A29: Finished products | N29: =0.05*SUM(B29:M29) -> 0 | O29: =SUM(B29:N29) -> 0 | Q29: =C28/$C$28 -> 1
A30: Wood & articles of wood; wood charcoal ('000tons) | M30: =[4]Sheet1!$I$6*0.7 -> 136.5 | N30: =0.05*SUM(B30:M30) -> 6.825 | O30: =SUM(B30:N30) -> 143.325
A31: Cork & cork articles ('000tons) | M31: =[4]Sheet2!$I$6/1000 -> 0.337 | N31: =0.05*SUM(B31:M31) -> 0.01685 | O31: =SUM(B31:N31) -> 0.35385
A32: Manufacture of straw, esparata or other plaiting materials, basket ware or wicker work (tons) | M32: =[4]Sheet3!$I$6/1000000 -> 0.083032 | N32: =0.05*SUM(B32:M32) -> 0.0041516 | O32: =SUM(B32:N32) -> 0.0871836
A33: Pulp of wood or other fibrous cellulosic material, recovered (waste & scrap) paper or paperboard (tons) | M33: =[4]Sheet4!$I$6/1000000 -> 1.266913 | N33: =0.05*SUM(B33:M33) -> 0.06334565 | O33: =SUM(B33:N33) -> 1.3302586
A34: Paper & paper board, article of paper or paper board (tons) | M34: =[4]Sheet5!$I$6/1000000 -> 34.487876 | N34: =0.05*SUM(B34:M34) -> 1.7243938 | O34: =SUM(B34:N34) -> 36.21227
A35: Sub-total ('000 tons) | B35: =SUM(B30:B34) -> 0 | C35: =SUM(C30:C34) -> 0 | D35: =SUM(D30:D34) -> 0 | E35: =SUM(E30:E34) -> 0 | F35: =SUM(F30:F34) -> 0 | G35: =SUM(G30:G34) -> 0 | H35: =SUM(H30:H34) -> 0 | I35: =SUM(I30:I34) -> 0 | ... O35: =SUM(O30:O34) -> 181.30856
A36: Non-wood forest products | N36: =0.05*SUM(B36:M36) -> 0 | O36: =SUM(B36:N36) -> 0
A37: Shea butter oil (tons) | N37: =0.05*SUM(B37:M37) -> 0 | O37: =SUM(B37:N37) -> 0
A38: Prunus Africana (Kg) | N38: =0.05*SUM(B38:M38) -> 0 | O38: =SUM(B38:N38) -> 0
A39: Sandalwood | N39: =0.05*SUM(B39:M39) -> 0 | O39: =SUM(B39:N39) -> 0
A40: Residues | N40: =0.05*SUM(B40:M40) -> 0 | O40: =SUM(B40:N40) -> 0
...

Sheet MSUT 1990
A1: Supply Table 1990, Uganda
A2: Description | B2: Agric. Production | C2: Forestry | D2: Fisheries | E2: Mining & Quarrying | F2: House-hold | G2: Manufacturing | H2: Construction & Housing | I2: Wholesale & Retail trade | J2: Transport | K2: Education, health & social work | L2: Utilities (electricity) | M2: Accumulations | N2: Import-ations | O2: Flows to environ-ment | P2: Overall total
A3: Natural inputs | P3: =SUM(B3:O3) -> 0
A4: Forest sand (UGX mill) | P4: =SUM(B4:O4) -> 0
A5: Seed (UGX mill) | P5: =SUM(B5:O5) -> 0
A6: Seedlings (UGX mill) | P6: =SUM(B6:O6) -> 0
A7: Wood biomass available for supply | P7: =SUM(B7:O7) -> 0
A8: Broad leaved plantations wood (UGX mill) | C8: =[2]Sheet2!$U$5 -> 7063.0582 | P8: =SUM(B8:O8) -> 7063.0582
A9: Coniferous plantations wood (UGX mill) | C9: =[2]Sheet2!$V$5 -> 13539.188 | P9: =SUM(B9:O9) -> 13539.188
A10: THF Well stocked wood (UGX mill) | C10: =[2]Sheet2!$X$5 -> 295944.79 | P10: =SUM(B10:O10) -> 295944.79
A11: THF Low stocked wood (UGX mill) | C11: =[2]Sheet2!$Y$5 -> 45195.022 | P11: =SUM(B11:O11) -> 45195.022
A12: Woodlands wood (UGX mill) | C12: =[2]Sheet2!$Z$5 -> 563406.75 | P12: =SUM(B12:O12) -> 563406.75
A13: Sub-total (UGX mill) | B13: =SUM(B8:B12) -> 0 | C13: =SUM(C8:C12) -> 925148.82 | D13: =SUM(D8:D12) -> 0 | E13: =SUM(E8:E12) -> 0 | F13: =SUM(F8:F12) -> 0 | G13: =SUM(G8:G12) -> 0 | H13: =SUM(H8:H12) -> 0 | I13: =SUM(I8:I12) -> 0 | ... P13: =SUM(P8:P12) -> 925148.82
A14: NWFPs
A15: Shea Pods (number) | P15: =SUM(B15:O15) -> 0
A16: Prunus Africana (trees>30 DBH) | P16: =SUM(B16:O16) -> 0
A17: Sandal wood | P17: =SUM(B17:O17) -> 0
A18: Bamboo | P18: =SUM(B18:O18) -> 0
P19: =SUM(B19:O19) -> 0
A20: Wood products(UGX Mill)
A21: Sawn wood (Timber) (UGX mill) | C21: 5530 | O21: =0.1*SUM(B21:N21) -> 553 | P21: =SUM(B21:O21) -> 6083
A22: Poles (UGX mill) | C22: 3136 | O22: =0.1*SUM(B22:N22) -> 313.6 | P22: =SUM(B22:O22) -> 3449.6
A23: Firewood Household (UGX mill) | C23: 16125 | O23: =0.1*SUM(B23:N23) -> 1612.5 | P23: =SUM(B23:O23) -> 17737.5
A24: Firewood Commecial (UGX mill) | C24: 4380 | O24: =0.1*SUM(B24:N24) -> 438 | P24: =SUM(B24:O24) -> 4818
A25: Firewood Industrial (UGX mill) | C25: 2051 | O25: =0.1*SUM(B25:N25) -> 205.1 | P25: =SUM(B25:O25) -> 2256.1
A26: Charcoal (UGX mill) | C26: 8526 | O26: =0.1*SUM(B26:N26) -> 852.6 | P26: =SUM(B26:O26) -> 9378.6
A27: Sub-total (UGX mill) | C27: =SUM(C21:C26) -> 39748 | O27: =SUM(O21:O26) -> 3974.8 | P27: =SUM(P21:P26) -> 43722.8
A28: Finished products | P28: =SUM(B28:O28) -> 0
A29: Wood & articles of wood; wood charcoal (m3) | P29: =SUM(B29:O29) -> 0
A30: Cork & cork articles (kg) | P30: =SUM(B30:O30) -> 0
A31: Manufacture of straw, esparata or other plaiting materials, basket ware or wicker work (kg) | P31: =SUM(B31:O31) -> 0
A32: Pulp of wood or other fibrous cellulosic material, recovered (waste & scrap) paper or paperboard (kg) | P32: =SUM(B32:O32) -> 0
A33: Paper & paper board, article of paper or paper board (kg) | P33: =SUM(B33:O33) -> 0
A34: Non-Wood Forest Products | P34: =SUM(B34:O34) -> 0
A35: Shea butter oil (UGX mill) | P35: =SUM(B35:O35) -> 0
A36: Prunus Africana | P36: =SUM(B36:O36) -> 0
A37: Sandalwood | P37: =SUM(B37:O37) -> 0
A38: Residues | P38: =SUM(B38:O38) -> 0
A39: Wood residuals | P39: =SUM(B39:O39) -> 0
P40: =SUM(B40:O40) -> 0
...

Sheet MSUT 2000
A1: Supply Table 2000, Uganda
A2: Description | B2: Agric. Production | C2: Forestry | D2: Fisheries | E2: Mining & Quarrying | F2: House-hold | G2: Manufacturing | H2: Construction & Housing | I2: Wholesale & Retail trade | J2: Transport | K2: Education, health & social work | L2: other sevices | M2: Accumulation | N2: Import-ations | O2: Flows to environ-ment | P2: Overall total
A3: Natural inputs | P3: =SUM(B3:O3) -> 0
A4: Forest sand (UGX mill) | P4: =SUM(B4:O4) -> 0
A5: Seed (UGX mill) | P5: =SUM(B5:O5) -> 0
A6: Seedlings (UGX mill) | P6: =SUM(B6:O6) -> 0
A7: Wood biomass available for supply | P7: =SUM(B7:O7) -> 0
A8: Broad leaved plantations wood (UGX mill) | C8: =[2]Sheet2!$U$11 -> 22754.999 | P8: =SUM(B8:O8) -> 22754.999
A9: Coniferous plantations wood (UGX mill) | C9: =[2]Sheet2!$V$11 -> 40821.626 | P9: =SUM(B9:O9) -> 40821.626
A10: THF Well stocked wood (UGX mill) | C10: =[2]Sheet2!$X$11 -> 1204008 | P10: =SUM(B10:O10) -> 1204008
A11: THF Low stocked wood (UGX mill) | C11: =[2]Sheet2!$Y$11 -> 158011.16 | P11: =SUM(B11:O11) -> 158011.16
A12: Woodlands wood (UGX mill) | C12: =[2]Sheet2!$Z$11 -> 404908.38 | P12: =SUM(B12:O12) -> 404908.38
A13: NWFPs | P13: =SUM(B13:O13) -> 0
A14: Shea Pods (number) | P14: =SUM(B14:O14) -> 0
A15: Prunus Africana (trees>30 DBH) | P15: =SUM(B15:O15) -> 0
A16: Sandal wood | P16: =SUM(B16:O16) -> 0
A17: Wood products(UGX Mill)
A18: Sawn wood (Timber) (UGX mill) | C18: 23180 | O18: =0.05*SUM(B18:N18) -> 1159 | P18: =SUM(B18:O18) -> 24339
A19: Poles (UGX mill) | C19: 11564 | O19: =0.05*SUM(B19:N19) -> 578.2 | P19: =SUM(B19:O19) -> 12142.2
A20: Firewood Household (UGX mill) | C20: 55383 | O20: =0.05*SUM(B20:N20) -> 2769.15 | P20: =SUM(B20:O20) -> 58152.15
A21: Firewood Commecial (UGX mill) | C21: 15822 | O21: =0.05*SUM(B21:N21) -> 791.1 | P21: =SUM(B21:O21) -> 16613.1
A22: Firewood Industrial (UGX mill) | C22: 10902 | O22: =0.05*SUM(B22:N22) -> 545.1 | P22: =SUM(B22:O22) -> 11447.1
A23: Charcoal (UGX mill) | C23: =34070 -> 34070 | O23: =0.05*SUM(B23:N23) -> 1703.5 | P23: =SUM(B23:O23) -> 35773.5
A24: Sub-total (UGX milliona) | B24: =SUM(B18:B23) -> 0 | C24: =SUM(C18:C23) -> 150921 | D24: =SUM(D18:D23) -> 0 | E24: =SUM(E18:E23) -> 0 | F24: =SUM(F18:F23) -> 0 | H24: =SUM(H18:H23) -> 0 | I24: =SUM(I18:I23) -> 0 | J24: =SUM(J18:J23) -> 0 | K24: =SUM(K18:K23) -> 0 | L24: =SUM(L18:L23) -> 0 | M24: =SUM(M18:M23) -> 0 | N24: =SUM(N18:N23) -> 0 | O24: =SUM(O18:O23) -> 7546.05 | P24: =SUM(P18:P23) -> 158467.05
A25: Finished products | O25: =0.05*SUM(B25:N25) -> 0 | P25: =SUM(B25:O25) -> 0 | R25: 208668.6
A26: Wood & articles of wood; wood charcoal (m3) | N26: =[4]Sheet1!$G$21/1000000 -> 10594.092 | O26: =0.05*SUM(B26:N26) -> 529.70458 | P26: =SUM(B26:O26) -> 11123.796 | R26: 150925
A27: Cork & cork articles (kg) | N27: =[4]Sheet2!$G$21/1000000 -> 9976.9283 | O27: =0.05*SUM(B27:N27) -> 498.84642 | P27: =SUM(B27:O27) -> 10475.775
A28: Manufacture of straw, esparata or other plaiting materials, basket ware or wicker work (kg) | N28: =[4]Sheet3!$G$21/1000000 -> 6135.8527 | O28: =0.05*SUM(B28:N28) -> 306.79264 | P28: =SUM(B28:O28) -> 6442.6453 | R28: =R25-R26 -> 57743.6
A29: Pulp of wood or other fibrous cellulosic material, recovered (waste & scrap) paper or paperboard (kg) | N29: =[4]Sheet4!$G$21/1000000 -> 191.52192 | O29: =0.05*SUM(B29:N29) -> 9.5760961 | P29: =SUM(B29:O29) -> 201.09802
A30: Paper & paper board, article of paper or paper board (kg) | N30: =[4]Sheet5!$G$21/1000000 -> 34303.549 | O30: =0.05*SUM(B30:N30) -> 1715.1775 | P30: =SUM(B30:O30) -> 36018.727 | R30: 866137.01
A31: Sub-total | B31: =SUM(B26:B30) -> 0 | C31: =SUM(C26:C30) -> 0 | D31: =SUM(D26:D30) -> 0 | E31: =SUM(E26:E30) -> 0 | F31: =SUM(F26:F30) -> 0 | G31: =SUM(G26:G30) -> 0 | H31: =SUM(H26:H30) -> 0 | I31: =SUM(I26:I30) -> 0 | ... L31: =SUM(L26:L30) -> 0 | N31: =SUM(N26:N30) -> 61201.944 | O31: =SUM(O26:O30) -> 3060.0972 | P31: =SUM(B31:O31) -> 64262.041
A32: Non-Wood Forest Products | O32: =0.05*SUM(B32:N32) -> 0 | P32: =SUM(B32:O32) -> 0 | R32: 61201.944
A33: Shea butter oil (UGX mill) | O33: =0.05*SUM(B33:N33) -> 0 | P33: =SUM(B33:O33) -> 0
A34: Prunus Africana | O34: =0.05*SUM(B34:N34) -> 0 | P34: =SUM(B34:O34) -> 0 | R34: =R30-R32 -> 804935.07
A35: Sandalwood | O35: =0.05*SUM(B35:N35) -> 0 | P35: =SUM(B35:O35) -> 0
A36: Sub-total | B36: =SUM(B33:B35) -> 0 | C36: =SUM(C33:C35) -> 0 | D36: =SUM(D33:D35) -> 0 | E36: =SUM(E33:E35) -> 0 | F36: =SUM(F33:F35) -> 0 | G36: =SUM(G33:G35) -> 0 | H36: =SUM(H33:H35) -> 0 | I36: =SUM(I33:I35) -> 0 | ... P36: =SUM(P33:P35) -> 0
A37: Residues | P37: =SUM(B37:O37) -> 0 | R37: 1118768.2
A38: Wood residuals | P38: =SUM(B38:O38) -> 0 | R38: 1077865.7
P39: =SUM(B39:O39) -> 0
A40: Total (mill UGX) | B40: =SUM(B17:B39) -> 0 | C40: =SUM(C17:C39) -> 301842 | D40: =SUM(D17:D39) -> 0 | E40: =SUM(E17:E39) -> 0 | F40: =SUM(F17:F39) -> 0 | G40: =SUM(G17:G39) -> 0 | H40: =SUM(H17:H39) -> 0 | I40: =SUM(I17:I39) -> 0 | ... L40: =SUM(L17:L39) -> 0 | O40: =SUM(O17:O39) -> 21212.294 | P40: =P38+P36+P31+P24 -> 222729.09
...

Sheet MSUT 2005
A1: Supply Table 2005, Uganda
A2: Description | B2: Agric. Production | C2: Forestry | D2: Fisheries | E2: Mining & Quarrying | F2: House-hold | G2: Manufacturing | H2: Construction & Housing | I2: Wholesale & Retail trade | J2: Transport | K2: Education, health & social work | L2: Other services | M2: Accumulations | N2: Import-ations | O2: Flows to environ-ment | P2: Overall total
A3: Natural inputs | P3: =SUM(B3:O3) -> 0
A4: Forest sand (UGX mill) | P4: =SUM(B4:O4) -> 0
A5: Seed (UGX mill) | P5: =SUM(B5:O5) -> 0
A6: Seedlings (UGX mill) | P6: =SUM(B6:O6) -> 0
A7: Wood biomass available for supply | P7: =SUM(B7:O7) -> 0
A8: Broad leaved plantations wood (UGX mill) | C8: =[2]Sheet2!$U$17 -> 42463.877 | P8: =SUM(B8:O8) -> 42463.877
A9: Coniferous plantations wood (UGX mill) | C9: =[2]Sheet2!$V$17 -> 60397.893 | P9: =SUM(B9:O9) -> 60397.893
A10: THF Well stocked wood (UGX mill) | C10: =[2]Sheet2!$X$17 -> 1215550.9 | P10: =SUM(B10:O10) -> 1215550.9
A11: THF Low stocked wood (UGX mill) | C11: =[2]Sheet2!$Y$17 -> 143895.64
A12: Woodlands wood (UGX mill) | C12: =[2]Sheet2!$Z$17 -> 229785.42
A13: Sub-total (UGX mill) | C13: =SUM(C8:C12) -> 1692093.7
A14: Wood not available for supply & other (UGX mill) | C14: ='PSUT 2005'!C15*[2]Sheet2!$AH$11/1000 -> 0
A15: NWFPs | C15: =C14+C13 -> 1692093.7 | P15: =SUM(B15:O15) -> 1692093.7
A16: Shea Pods (number) | P16: =SUM(B16:O16) -> 0
A17: Prunus Africana (trees>30 DBH) | P17: =SUM(B17:O17) -> 0
A18: Sandal wood | P18: =SUM(B18:O18) -> 0
A19: Bamboo | P19: =SUM(B19:O19) -> 0
P20: =SUM(B20:O20) -> 0
A21: Wood products(UGX Mill) | C21: 235202 | O21: =0.05*SUM(B21:N21) -> 11760.1 | P21: =SUM(B21:O21) -> 246962.1
A22: Sawn wood (Timber) (UGX mill) | C22: 37648 | O22: =0.05*SUM(B22:N22) -> 1882.4 | P22: =SUM(B22:O22) -> 39530.4
A23: Poles (UGX mill) | C23: 15177 | O23: =0.05*SUM(B23:N23) -> 758.85 | P23: =SUM(B23:O23) -> 15935.85
A24: Firewood Household (UGX mill) | C24: 111117 | O24: =0.05*SUM(B24:N24) -> 5555.85 | P24: =SUM(B24:O24) -> 116672.85
A25: Firewood Commecial (UGX mill) | C25: 20926 | O25: =0.05*SUM(B25:N25) -> 1046.3 | P25: =SUM(B25:O25) -> 21972.3
A26: Firewood Industrial (UGX mill) | C26: 13789 | O26: =0.05*SUM(B26:N26) -> 689.45 | P26: =SUM(B26:O26) -> 14478.45
A27: Charcoal (UGX mill) | C27: 36545 | O27: =0.05*SUM(B27:N27) -> 1827.25 | P27: =SUM(B27:O27) -> 38372.25
A28: Sub-total | B28: =SUM(B22:B27) -> 0 | C28: =SUM(C22:C27) -> 235202 | D28: =SUM(D22:D27) -> 0 | E28: =SUM(E22:E27) -> 0 | F28: =SUM(F22:F27) -> 0 | G28: =SUM(G22:G27) -> 0 | H28: =SUM(H22:H27) -> 0 | I28: =SUM(I22:I27) -> 0 | ... N28: =SUM(N22:N27) -> 0 | O28: =0.05*SUM(B28:N28) -> 11760.1 | P28: =SUM(P22:P27) -> 246962.1
A29: Finished products | O29: =0.05*SUM(B29:N29) -> 0 | P29: =SUM(B29:O29) -> 0
A30: Wood & articles of wood; wood charcoal (m3) | N30: =[4]Sheet1!$G$16/1000000 -> 1918.649 | O30: =0.05*SUM(B30:N30) -> 95.932451 | P30: =SUM(B30:O30) -> 2014.5815
A31: Cork & cork articles (kg) | N31: =[4]Sheet2!$G$16/1000000 -> 1872.6829 | O31: =0.05*SUM(B31:N31) -> 93.634144 | P31: =SUM(B31:O31) -> 1966.317
A32: Manufacture of straw, esparata or other plaiting materials, basket ware or wicker work (kg) | N32: =[4]Sheet3!$G$16/1000000 -> 1578.9148 | O32: =0.05*SUM(B32:N32) -> 78.94574 | P32: =SUM(B32:O32) -> 1657.8605
A33: Pulp of wood or other fibrous cellulosic material, recovered (waste & scrap) paper or paperboard (kg) | N33: =[4]Sheet4!$G$16/1000000 -> 136.98336 | O33: =0.05*SUM(B33:N33) -> 6.8491682 | P33: =SUM(B33:O33) -> 143.83253
A34: Paper & paper board, article of paper or paper board (kg) | N34: =[4]Sheet5!$G$16/1000000 -> 296519.33 | O34: =0.05*SUM(B34:N34) -> 14825.966 | P34: =SUM(B34:O34) -> 311345.29
A35: Sub-total | B35: =SUM(B30:B34) -> 0 | C35: =SUM(C30:C34) -> 0 | D35: =SUM(D30:D34) -> 0 | E35: =SUM(E30:E34) -> 0 | F35: =SUM(F30:F34) -> 0 | G35: =SUM(G30:G34) -> 0 | H35: =SUM(H30:H34) -> 0 | I35: =SUM(I30:I34) -> 0 | ... P35: =SUM(P30:P34) -> 317127.88
A36: Non-Wood Forest Products | P36: =SUM(B36:O36) -> 0
A37: Shea butter oil (UGX mill) | P37: =SUM(B37:O37) -> 0
A38: Prunus Africana | P38: =SUM(B38:O38) -> 0
A39: Sandalwood | P39: =SUM(B39:O39) -> 0
A40: Sub-total | B40: =SUM(B37:B39) -> 0 | C40: =SUM(C37:C39) -> 0 | D40: =SUM(D37:D39) -> 0 | E40: =SUM(E37:E39) -> 0 | F40: =SUM(F37:F39) -> 0 | G40: =SUM(G37:G39) -> 0 | H40: =SUM(H37:H39) -> 0 | I40: =SUM(I37:I39) -> 0 | ... P40: =SUM(P37:P39) -> 0
...

Sheet MSUT2010
A1: Supply Table 2010, Uganda
A2: Description | B2: Agric. Production | C2: Forestry | D2: Fisheries | E2: Mining & Quarrying | F2: House-hold | G2: Manufacturing | H2: Construction & Housing | I2: Wholesale & Retail trade | J2: Transport | K2: Education, health & social work | L2: Other services | M2: Accumulation | N2: Import-ations | O2: Flows to environ-ment | P2: Overall total
A3: Natural inputs | P3: =SUM(B3:O3) -> 0
A4: Seed (UGX mill) | C4: =Sheet2!C5 -> 505.71429 | P4: =SUM(B4:O4) -> 505.71429
A5: Seedlings (UGX mill) | C5: =Sheet2!C6 -> 3640000 | P5: =SUM(B5:O5) -> 3640000
A6: Wood biomass available for supply | P6: =SUM(B6:O6) -> 0
A7: Broad leaved plantations wood (UGX mill) | C7: =[2]Sheet2!$U$23 -> 168002.98 | P7: =SUM(B7:O7) -> 168002.98
A8: Coniferous plantations wood (UGX mill) | C8: =[2]Sheet2!$V$23 -> 407837.77 | P8: =SUM(B8:O8) -> 407837.77
A9: THF Well stocked wood (UGX mill) | C9: =[2]Sheet2!$X$23 -> 1545470.6 | P9: =SUM(B9:O9) -> 1545470.6
A10: THF Low stocked wood (UGX mill) | C10: =[2]Sheet2!$Y$23 -> 99431.642
A11: Woodlands wood (UGX mill) | C11: =[2]Sheet2!$Z$23 -> 254494.66
A12: Sub-total (UGX mill) | C12: =SUM(C7:C11) -> 2475237.7
A13: Wood not available for supply & other (UGX mill) | C13: ='PSUT 2010'!C15*[2]Sheet2!$AH$11/1000 -> 0
A14: NWFPs | C14: =C13+C12 -> 2475237.7 | P14: =SUM(B14:O14) -> 2475237.7
A15: Shea Pods (number) | P15: =SUM(B15:O15) -> 0
A16: Prunus Africana (trees>30 DBH) | P16: =SUM(B16:O16) -> 0
A17: Sandal wood | P17: =SUM(B17:O17) -> 0
A18: Bamboo | P18: =SUM(B18:O18) -> 0
A19: Sub-total | B19: =SUM(B4:B18) -> 0 | C19: =SUM(C4:C18) -> 11066219 | D19: =SUM(D4:D18) -> 0 | E19: =SUM(E4:E18) -> 0 | F19: =SUM(F4:F18) -> 0 | G19: =SUM(G4:G18) -> 0 | H19: =SUM(H4:H18) -> 0 | I19: =SUM(I4:I18) -> 0 | ... P19: =SUM(P4:P18) -> 8237054.8
A20: Wood products(UGX Mill)
A21: Sawn wood (Timber) (UGX mill) | C21: 132677 | O21: =0.05*SUM(B21:N21) -> 6633.85 | P21: =SUM(B21:O21) -> 139310.85
A22: Poles (UGX mill) | C22: 41438 | O22: =0.05*SUM(B22:N22) -> 2071.9 | P22: =SUM(B22:O22) -> 43509.9
A23: Firewood Household (UGX mill) | C23: 128916 | O23: =0.05*SUM(B23:N23) -> 6445.8 | P23: =SUM(B23:O23) -> 135361.8
A24: Firewood Commecial (UGX mill) | C24: 25228 | O24: =0.05*SUM(B24:N24) -> 1261.4 | P24: =SUM(B24:O24) -> 26489.4
A25: Firewood Industrial (UGX mill) | C25: 20130 | O25: =0.05*SUM(B25:N25) -> 1006.5 | P25: =SUM(B25:O25) -> 21136.5
A26: Charcoal (UGX mill) | C26: 51210 | O26: =0.05*SUM(B26:N26) -> 2560.5 | P26: =SUM(B26:O26) -> 53770.5
A27: Sub-total | B27: =SUM(B20:B26) -> 0 | C27: =SUM(C20:C26) -> 399599 | D27: =SUM(D20:D26) -> 0 | E27: =SUM(E20:E26) -> 0 | F27: =SUM(F20:F26) -> 0 | G27: =SUM(G20:G26) -> 0 | H27: =SUM(H20:H26) -> 0 | I27: =SUM(I20:I26) -> 0 | ... P27: =SUM(P20:P26) -> 419578.95
A28: Finished products | O28: =0.05*SUM(B28:N28) -> 0 | P28: =SUM(B28:O28) -> 0
A29: Wood & articles of wood; wood charcoal (m3) | N29: =5129245/1000 -> 5129.245 | O29: =0.05*SUM(B29:N29) -> 256.46225 | P29: =SUM(B29:O29) -> 5385.7072
A30: Cork & cork articles (kg) | N30: =61472392/1000 -> 61472.392 | O30: =0.05*SUM(B30:N30) -> 3073.6196 | P30: =SUM(B30:O30) -> 64546.012
A31: Manufacture of straw, esparata or other plaiting materials, basket ware or wicker work (kg) | N31: =28958069/1000 -> 28958.069 | O31: =0.05*SUM(B31:N31) -> 1447.9035 | P31: =SUM(B31:O31) -> 30405.972
A32: Pulp of wood or other fibrous cellulosic material, recovered (waste & scrap) paper or paperboard (kg) | N32: =38806461/1000 -> 38806.461 | O32: =0.05*SUM(B32:N32) -> 1940.3231 | P32: =SUM(B32:O32) -> 40746.784
A33: Paper & paper board, article of paper or paper board (kg) | N33: =192766264/1000 -> 192766.26 | O33: =0.05*SUM(B33:N33) -> 9638.3132 | P33: =SUM(B33:O33) -> 202404.58
A34: Sub-total | B34: =SUM(B29:B33) -> 0 | C34: =SUM(C29:C33) -> 0 | D34: =SUM(D29:D33) -> 0 | E34: =SUM(E29:E33) -> 0 | F34: =SUM(F29:F33) -> 0 | G34: =SUM(G29:G33) -> 0 | H34: =SUM(H29:H33) -> 0 | I34: =SUM(I29:I33) -> 0 | ... P34: =SUM(P29:P33) -> 343489.05
A35: Non-Wood Forest Products | O35: =0.05*SUM(B35:N35) -> 0 | P35: =SUM(B35:O35) -> 0
A36: Shea butter oil (UGX mill) | B36: =[6]Sheet1!$Y$14*3700/1000000 -> 14553.437 | O36: =0.05*SUM(B36:N36) -> 727.67185 | P36: =SUM(B36:O36) -> 15281.109
A37: Prunus Africana | B37: =Sheet2!C30/1000000 -> 0.252567 | O37: =0.05*SUM(B37:N37) -> 0.01262835 | P37: =SUM(B37:O37) -> 0.26519535
A38: Sandalwood | O38: =0.05*SUM(B38:N38) -> 0 | P38: =SUM(B38:O38) -> 0
A39: Sub-total | B39: =SUM(B36:B38) -> 14553.69 | C39: =SUM(C36:C38) -> 0 | D39: =SUM(D36:D38) -> 0 | E39: =SUM(E36:E38) -> 0 | F39: =SUM(F36:F38) -> 0 | G39: =SUM(G36:G38) -> 0 | H39: =SUM(H36:H38) -> 0 | I39: =SUM(I36:I38) -> 0 | ... P39: =SUM(P36:P38) -> 15281.374
A40: Residues | O40: =0.05*SUM(B40:N40) -> 0 | P40: =SUM(B40:O40) -> 0
...

Sheet MSUT 2015
A1: Supply Table 2015, Uganda
A2: Description | B2: Agric. Production | C2: Forestry | D2: Fisheries | E2: Mining & Quarrying | F2: House-hold | G2: Manufacturing | H2: Construction & Housing | I2: Wholesale & Retail trade | J2: Transport | K2: Education, health & social work | L2: Other services | M2: Accumulations | N2: Import-ations | O2: Flows to environ-ment | P2: Overall total
A3: Natural inputs
A4: Seed (UGX mill)
A5: Seedlings (UGX mill)
A6: Wood biomass available for supply | P6: =SUM(B6:O6) -> 0
A7: Broad leaved plantations wood (UGX mill) | C7: =[2]Sheet2!$U$28 -> 219779.4 | P7: =SUM(B7:O7) -> 219779.4
A8: Coniferous plantations wood (UGX mill) | C8: =[2]Sheet2!$V$28 -> 223704.15 | P8: =SUM(B8:O8) -> 223704.15
A9: THF Well stocked wood (UGX mill) | C9: =[2]Sheet2!$X$28 -> 1348336.8 | P9: =SUM(B9:O9) -> 1348336.8
A10: THF Low stocked wood (UGX mill) | C10: =[2]Sheet2!$Y$28 -> 182888.9 | P10: =SUM(B10:O10) -> 182888.9
A11: Woodlands wood (UGX mill) | C11: =[2]Sheet2!$Z$28 -> 268068.34 | P11: =SUM(B11:O11) -> 268068.34
A12: Sub-total (UGX mill) | C12: =SUM(C7:C11) -> 2242777.6
A13: Wood not available for supply & other (UGX mill) | C13: ='PSUT 2015'!C15*[2]Sheet2!$AH$11/1000 -> 0
A14: NWFPs | P14: =SUM(B14:O14) -> 0
A15: Shea Pods (number) | P15: =SUM(B15:O15) -> 0
A16: Prunus Africana (trees>30 DBH) | P16: =SUM(B16:O16) -> 0
A17: Sandal wood | P17: =SUM(B17:O17) -> 0
A18: Bamboo | P18: =SUM(B18:O18) -> 0
P19: =SUM(B19:O19) -> 0
A20: Wood products(UGX Mill) | P20: =SUM(B20:O20) -> 0
A21: Sawn wood (Timber) (UGX mill) | C21: 361976 | O21: =0.05*SUM(B21:N21) -> 18098.8 | P21: =SUM(B21:O21) -> 380074.8
A22: Poles (UGX mill) | C22: =F69+H69 -> 251793 | O22: =0.05*SUM(B22:N22) -> 12589.65 | P22: =SUM(B22:O22) -> 264382.65
A23: Firewood Household (UGX mill) | C23: =F70 -> 146752 | O23: =0.05*SUM(B23:N23) -> 7337.6 | P23: =SUM(B23:O23) -> 154089.6
A24: Firewood Commecial (UGX mill) | C24: =K71 -> 27523 | O24: =0.05*SUM(B24:N24) -> 1376.15 | P24: =SUM(B24:O24) -> 28899.15
A25: Firewood Industrial (UGX mill) | C25: =G72 -> 21867 | O25: =0.05*SUM(B25:N25) -> 1093.35 | P25: =SUM(B25:O25) -> 22960.35
A26: Charcoal (UGX mill) | C26: 66894 | O26: =0.05*SUM(B26:N26) -> 3344.7 | P26: =SUM(B26:O26) -> 70238.7
A27: Sub-total (UGX mill) | B27: =SUM(B21:B26) -> 0 | C27: =SUM(C21:C26) -> 876805 | D27: =SUM(D21:D26) -> 0 | E27: =SUM(E21:E26) -> 0 | F27: =SUM(F21:F26) -> 0 | G27: =SUM(G21:G26) -> 0 | H27: =SUM(H21:H26) -> 0 | I27: =SUM(I21:I26) -> 0 | ... P27: =SUM(P21:P26) -> 920645.25
A28: Finished products | O28: =0.05*SUM(B28:N28) -> 0 | P28: =SUM(B28:O28) -> 0
A29: Wood & articles of wood; wood charcoal (UGX mill) | N29: =[4]Sheet1!$G$6/1000000 -> 1815.2833 | O29: =0.05*SUM(B29:N29) -> 90.764164 | P29: =SUM(B29:O29) -> 1906.0474
A30: Cork & cork articles (UGX mill) | N30: =[4]Sheet2!$G$6/1000000 -> 55.173963 | O30: =0.05*SUM(B30:N30) -> 2.7586982 | P30: =SUM(B30:O30) -> 57.932661
A31: Manufacture of straw, esparata or other plaiting materials, basket ware or wicker work (UGX mill) | N31: =[4]Sheet3!$G$6/1000000 -> 140.25602 | O31: =0.05*SUM(B31:N31) -> 7.0128009 | P31: =SUM(B31:O31) -> 147.26882
A32: Pulp of wood or other fibrous cellulosic material, recovered (waste & scrap) paper or paperboard (UGX mill) | N32: =[4]Sheet4!$G$6/1000000 -> 87817.386 | O32: =0.05*SUM(B32:N32) -> 4390.8693 | P32: =SUM(B32:O32) -> 92208.256
A33: Paper & paper board, article of paper or paper board (UGX mill) | N33: =[4]Sheet5!$G$6/1000000 -> 57008.649 | O33: =0.05*SUM(B33:N33) -> 2850.4325 | P33: =SUM(B33:O33) -> 59859.082
A34: Sub-total (UGX mill) | B34: =SUM(B29:B33) -> 0 | C34: =SUM(C29:C33) -> 0 | D34: =SUM(D29:D33) -> 0 | E34: =SUM(E29:E33) -> 0 | F34: =SUM(F29:F33) -> 0 | G34: =SUM(G29:G33) -> 0 | H34: =SUM(H29:H33) -> 0 | I34: =SUM(I29:I33) -> 0 | ... L34: =SUM(L29:L33) -> 0 | M34: 33982.437 | N34: =SUM(N29:N33) -> 146836.75 | O34: =SUM(O29:O33) -> 7341.8374 | P34: =SUM(B34:O34) -> 188161.02
A35: Non-wood forest products | O35: =0.05*SUM(B35:N35) -> 0 | P35: =SUM(B35:O35) -> 0
A36: Shea butter oil (litres) | B36: =F84+N83 -> 0 | O36: =0.05*SUM(B36:N36) -> 0 | P36: =SUM(B36:O36) -> 0
A37: Prunus Africana (UGX mill) | B37: =N85 -> 0 | O37: =0.05*SUM(B37:N37) -> 0 | P37: =SUM(B37:O37) -> 0
A38: Sandalwood | G38: =N87 -> 927.309 | O38: =0.05*SUM(B38:N38) -> 46.36545 | P38: =SUM(B38:O38) -> 973.67445
A39: Sub-total (UGX mill) | B39: =SUM(B36:B38) -> 0 | C39: =SUM(C36:C38) -> 0 | D39: =SUM(D36:D38) -> 0 | E39: =SUM(E36:E38) -> 0 | F39: =SUM(F36:F38) -> 0 | G39: =SUM(G36:G38) -> 927.309 | H39: =SUM(H36:H38) -> 0 | I39: =SUM(I36:I38) -> 0 | ... O39: =SUM(O36:O38) -> 46.36545 | P39: =SUM(B39:O39) -> 973.67445
A40: Residuals | P40: =SUM(B40:O40) -> 0
...

Sheet Sheet6
C2: Wood supply | K2: Wood supply | X2: Wood supply
D3: 1990 | E3: 2000 | F3: 2005 | G3: 2010 | H3: 2015 | L3: 1990 | M3: 2000 | N3: 2005 | O3: 2010 | P3: 2015 | R3: 1990 | S3: 2000 | T3: 2005 | U3: 2010 | V3: 2015 | Y3: 1990 | Z3: 2000 | AA3: 2005 | AB3: 2010 | AC3: 2015
