Workbook

Sheet Readme
A1: The following worksheets contain SLEEK land cover data by county, in hectares, for the whole SLEEK data series. I used the QGIS Zonal Histograms function to generate the data in pixel counts then converted in hectares (cell *0.09)
A3: Check de la superficie totale | C3: =Baringo!C12+Bomet!C12+Bungoma!C12+Busia!C12+'Elgeyo-Marakwet'!C12+Embu!C12+Garissa!C12+'Homa Bay'!C12+Isiolo!C12+Kajiado!C12+Kakamega!C12+Kericho!C12+Kiambu!C12+Kilifi!C12+Kirinyaga!C12+Kisii!C12+Kisumu!C12+Kitui!C12+Kwale!C12+Laikipia!C12+Lamu!C12+Machakos!C12+Makueni!C12+Mandera!C12+Marsabit!C12+Meru!C12+Migori!C12+Mombasa!C12+'Murang''a'!C12+Nairobi!C12+Nakuru!C12+Nandi!C12+Narok!C12+Nyamira!C12+Nyandarua!C12+Nyeri!C12+Samburu!C12+Samburu!C12+Siaya!C12+'Taita Taveta'!C12+'Tana River'!C12+'Tharaka-Nithi'!C12+'Trans Nzoia'!C12+Turkana!C12+'Uasin Gishu'!C12+Vihiga!C12+Wajir!C12+'West Pokot'!C12 -> 61277341
A5: Results are analysed in "Asset account additions and reductions v2.xls".

Sheet Totals
A1: Results of the 1990-2000 / 2015-2018 reconciliation accounts: Net Change
A3: Absolute values
C4: Baringo | D4: Bomet | E4: Bungoma | F4: Busia | G4: Elgeyo-Marakwet | H4: Embu | I4: Garissa | J4: Homa Bay | K4: Isiolo | L4: Kajiado | M4: Kakamega | N4: Kericho | O4: Kiambu | P4: Kilifi | Q4: Kirinyaga | R4: Kisii | S4: Kisumu | T4: Kitui | U4: Kwale | V4: Laikipia | W4: Lamu | X4: Machakos | Y4: Makueni | Z4: Mandera | AA4: Marsabit | AB4: Meru | AC4: Migori | AD4: Mombasa | AE4: Murang'a | AF4: Nairobi | AG4: Nakuru | AH4: Nandi | AI4: Narok | AJ4: Nyamira | AK4: Nyandarua | AL4: Nyeri | AM4: Samburu | AN4: Siaya | AO4: Taita Taveta | AP4: Tana River | AQ4: Tharaka-Nithi | AR4: Trans Nzoia | AS4: Turkana | AT4: Uasin Gishu | AU4: Vihiga | AV4: Wajir | AW4: West Pokot
A5: Sleek Class | B5: Land Cover
A6: 1 | B6: Dense Forest | C6: =Baringo!E17 -> -4742.475 | D6: =Bomet!E17 -> -2296.8 | E6: =Bungoma!E17 -> -2279.445 | F6: =Busia!E17 -> -339.765 | G6: ='Elgeyo-Marakwet'!E17 -> -3666.15 | H6: =Embu!E17 -> -3491.985 | I6: =Garissa!E17 -> -32236.335 | J6: ='Homa Bay'!E17 -> -1778.13 | K6: =Isiolo!E17 -> 33352.305 | L6: =Kajiado!E17 -> -3048.72 | M6: =Kakamega!E17 -> 794.805 | N6: =Kericho!E17 -> -6495.645 | O6: =Kiambu!E17 -> 7089.69 | P6: =Kilifi!E17 -> -6087.315 | Q6: =Kirinyaga!E17 -> 1241.625 | R6: =Kisii!E17 -> 1436.925 | S6: =Kisumu!E17 -> -60.03 | T6: =Kitui!E17 -> 173.355 | U6: =Kwale!E17 -> -5966.61 | V6: =Laikipia!E17 -> -6616.605 | W6: =Lamu!E17 -> 29100.03 | X6: =Machakos!E17 -> 4828.02 | Y6: =Makueni!E17 -> -24375.12 | Z6: =Mandera!E17 -> -11649.27 | AA6: =Marsabit!E17 -> 11775.045 | AB6: =Meru!E17 -> -10017.555 | AC6: =Migori!E17 -> -1833.27 | AD6: =Mombasa!E17 -> -765 | AE6: ='Murang''a'!E17 -> 5248.065 | AF6: =Nairobi!E17 -> -214.71 | AG6: =Nakuru!E17 -> -37619.085 | AH6: =Nandi!E17 -> 3426.51 | AI6: =Narok!E17 -> -78904.905 | AJ6: =Nyamira!E17 -> 2434.44 | AK6: =Nyandarua!E17 -> 6385.905 | AL6: =Nyeri!E17 -> 2438.085 | AM6: =Samburu!E17 -> 80834.235 | AN6: =Siaya!E17 -> -137.4 | AO6: ='Taita Taveta'!E17 -> -10344.975 | AP6: ='Tana River'!E17 -> 21531.99 | AQ6: ='Tharaka-Nithi'!E17 -> -9808.095 | AR6: ='Trans Nzoia'!E17 -> -1715.205 | AS6: =Turkana!E17 -> -5953.095 | AT6: ='Uasin Gishu'!E17 -> -7691.34 | AU6: =Vihiga!E17 -> 1308.105 | AV6: =Wajir!E17 -> 1668.045 | AW6: ='West Pokot'!E17 -> -6221.04
A7: 2 | B7: Moderate Forest | C7: =Baringo!E18 -> 1204.395 | D7: =Bomet!E18 -> 8638.23 | E7: =Bungoma!E18 -> 1447.395 | F7: =Busia!E18 -> 268.71 | G7: ='Elgeyo-Marakwet'!E18 -> -19120.305 | H7: =Embu!E18 -> -1347.3 | I7: =Garissa!E18 -> -44837.82 | J7: ='Homa Bay'!E18 -> 1594.02 | K7: =Isiolo!E18 -> 18358.785 | L7: =Kajiado!E18 -> 362.46 | M7: =Kakamega!E18 -> -211.485 | N7: =Kericho!E18 -> 2135.52 | O7: =Kiambu!E18 -> -5301.24 | P7: =Kilifi!E18 -> -46466.805 | Q7: =Kirinyaga!E18 -> 398.88 | R7: =Kisii!E18 -> 382.215 | S7: =Kisumu!E18 -> 292.695 | T7: =Kitui!E18 -> -3373.665 | U7: =Kwale!E18 -> -10252.23 | V7: =Laikipia!E18 -> 9724.83 | W7: =Lamu!E18 -> -41172.15 | X7: =Machakos!E18 -> -562.155 | Y7: =Makueni!E18 -> 10694.475 | Z7: =Mandera!E18 -> 4554.48 | AA7: =Marsabit!E18 -> 1902.915 | AB7: =Meru!E18 -> 6745.2 | AC7: =Migori!E18 -> 269.25 | AD7: =Mombasa!E18 -> 122.295 | AE7: ='Murang''a'!E18 -> -4346.37 | AF7: =Nairobi!E18 -> -512.235 | AG7: =Nakuru!E18 -> 932.115 | AH7: =Nandi!E18 -> 26.61 | AI7: =Narok!E18 -> -27404.79 | AJ7: =Nyamira!E18 -> 893.055 | AK7: =Nyandarua!E18 -> -735.195 | AL7: =Nyeri!E18 -> 2106 | AM7: =Samburu!E18 -> 5568.99 | AN7: =Siaya!E18 -> -142.08 | AO7: ='Taita Taveta'!E18 -> 10172.925 | AP7: ='Tana River'!E18 -> -26852.04 | AQ7: ='Tharaka-Nithi'!E18 -> -502.74 | AR7: ='Trans Nzoia'!E18 -> 1455.945 | AS7: =Turkana!E18 -> 38.76 | AT7: ='Uasin Gishu'!E18 -> -986.82 | AU7: =Vihiga!E18 -> -501.42 | AV7: =Wajir!E18 -> 2172.48 | AW7: ='West Pokot'!E18 -> -8750.4
A8: 3 | B8: Open Forest | C8: =Baringo!E19 -> -6255.525 | D8: =Bomet!E19 -> 975.735 | E8: =Bungoma!E19 -> -881.355 | F8: =Busia!E19 -> 263.595 | G8: ='Elgeyo-Marakwet'!E19 -> -441.525 | H8: =Embu!E19 -> -519.075 | I8: =Garissa!E19 -> -14001.765 | J8: ='Homa Bay'!E19 -> 25.26 | K8: =Isiolo!E19 -> -2076.42 | L8: =Kajiado!E19 -> -8071.2 | M8: =Kakamega!E19 -> 1395.6 | N8: =Kericho!E19 -> 110.295 | O8: =Kiambu!E19 -> -2389.605 | P8: =Kilifi!E19 -> 8398.935 | Q8: =Kirinyaga!E19 -> -388.56 | R8: =Kisii!E19 -> -216.195 | S8: =Kisumu!E19 -> 102.795 | T8: =Kitui!E19 -> 29381.94 | U8: =Kwale!E19 -> -5959.815 | V8: =Laikipia!E19 -> -647.97 | W8: =Lamu!E19 -> -721.095 | X8: =Machakos!E19 -> -1279.74 | Y8: =Makueni!E19 -> 2573.55 | Z8: =Mandera!E19 -> 3528.855 | AA8: =Marsabit!E19 -> -1890.375 | AB8: =Meru!E19 -> -3888.645 | AC8: =Migori!E19 -> 1416.825 | AD8: =Mombasa!E19 -> -62.505 | AE8: ='Murang''a'!E19 -> -1947.87 | AF8: =Nairobi!E19 -> -474.435 | AG8: =Nakuru!E19 -> -652.065 | AH8: =Nandi!E19 -> 1918.77 | AI8: =Narok!E19 -> -20122.995 | AJ8: =Nyamira!E19 -> -428.145 | AK8: =Nyandarua!E19 -> -665.565 | AL8: =Nyeri!E19 -> -1500.975 | AM8: =Samburu!E19 -> 4806.915 | AN8: =Siaya!E19 -> 236.07 | AO8: ='Taita Taveta'!E19 -> -1904.67 | AP8: ='Tana River'!E19 -> 5908.59 | AQ8: ='Tharaka-Nithi'!E19 -> -284.34 | AR8: ='Trans Nzoia'!E19 -> -4410.825 | AS8: =Turkana!E19 -> 18582.21 | AT8: ='Uasin Gishu'!E19 -> 629.55 | AU8: =Vihiga!E19 -> 1070.475 | AV8: =Wajir!E19 -> -19030.56 | AW8: ='West Pokot'!E19 -> -10236.015
A9: 4 | B9: Wooded Grassland | C9: =Baringo!E20 -> -14174.85 | D9: =Bomet!E20 -> -441.63 | E9: =Bungoma!E20 -> -38010.21 | F9: =Busia!E20 -> -33703.545 | G9: ='Elgeyo-Marakwet'!E20 -> -25727.67 | H9: =Embu!E20 -> -49686.09 | I9: =Garissa!E20 -> -160754.35 | J9: ='Homa Bay'!E20 -> -29474.805 | K9: =Isiolo!E20 -> -124284.04 | L9: =Kajiado!E20 -> -47215.02 | M9: =Kakamega!E20 -> -30529.05 | N9: =Kericho!E20 -> -34202.355 | O9: =Kiambu!E20 -> -7359.765 | P9: =Kilifi!E20 -> -36213.48 | Q9: =Kirinyaga!E20 -> -17487.585 | R9: =Kisii!E20 -> 3474.36 | S9: =Kisumu!E20 -> -26188.11 | T9: =Kitui!E20 -> -401765.37 | U9: =Kwale!E20 -> -105859.82 | V9: =Laikipia!E20 -> -26311.665 | W9: =Lamu!E20 -> 1850.43 | X9: =Machakos!E20 -> -89403.18 | Y9: =Makueni!E20 -> -142112.52 | Z9: =Mandera!E20 -> -114468.98 | AA9: =Marsabit!E20 -> -88146.885 | AB9: =Meru!E20 -> -59308.98 | AC9: =Migori!E20 -> -38644.59 | AD9: =Mombasa!E20 -> -5819.85 | AE9: ='Murang''a'!E20 -> -23068.65 | AF9: =Nairobi!E20 -> 562.845 | AG9: =Nakuru!E20 -> -1986.63 | AH9: =Nandi!E20 -> -30068.07 | AI9: =Narok!E20 -> 51207.825 | AJ9: =Nyamira!E20 -> 946.41 | AK9: =Nyandarua!E20 -> -14636.76 | AL9: =Nyeri!E20 -> -7077.045 | AM9: =Samburu!E20 -> -144162.25 | AN9: =Siaya!E20 -> -46007.595 | AO9: ='Taita Taveta'!E20 -> -53841.375 | AP9: ='Tana River'!E20 -> 15296.25 | AQ9: ='Tharaka-Nithi'!E20 -> -28510.095 | AR9: ='Trans Nzoia'!E20 -> -56006.175 | AS9: =Turkana!E20 -> -281791.08 | AT9: ='Uasin Gishu'!E20 -> -48633.12 | AU9: =Vihiga!E20 -> -8456.07 | AV9: =Wajir!E20 -> -207343.62 | AW9: ='West Pokot'!E20 -> 11914.725
A10: 5 | B10: Open Grassland | C10: =Baringo!E21 -> -7593.315 | D10: =Bomet!E21 -> -77761.68 | E10: =Bungoma!E21 -> -25958.88 | F10: =Busia!E21 -> -1421.1 | G10: ='Elgeyo-Marakwet'!E21 -> -25356.405 | H10: =Embu!E21 -> -3403.335 | I10: =Garissa!E21 -> 265310.35 | J10: ='Homa Bay'!E21 -> -32805.465 | K10: =Isiolo!E21 -> 171973.41 | L10: =Kajiado!E21 -> 35938.29 | M10: =Kakamega!E21 -> -26513.28 | N10: =Kericho!E21 -> -42596.925 | O10: =Kiambu!E21 -> -14781.57 | P10: =Kilifi!E21 -> -574.695 | Q10: =Kirinyaga!E21 -> -2858.745 | R10: =Kisii!E21 -> -13547.205 | S10: =Kisumu!E21 -> -19094.46 | T10: =Kitui!E21 -> -10428.285 | U10: =Kwale!E21 -> 26415.225 | V10: =Laikipia!E21 -> -35900.595 | W10: =Lamu!E21 -> -1169.64 | X10: =Machakos!E21 -> -32208.765 | Y10: =Makueni!E21 -> -1670.34 | Z10: =Mandera!E21 -> 127775.19 | AA10: =Marsabit!E21 -> 190635.81 | AB10: =Meru!E21 -> -25624.92 | AC10: =Migori!E21 -> -39489.33 | AD10: =Mombasa!E21 -> 1758.3 | AE10: ='Murang''a'!E21 -> -13379.445 | AF10: =Nairobi!E21 -> -9368.94 | AG10: =Nakuru!E21 -> -94366.65 | AH10: =Nandi!E21 -> -40678.62 | AI10: =Narok!E21 -> -131201.85 | AJ10: =Nyamira!E21 -> -14484.255 | AK10: =Nyandarua!E21 -> -64025.61 | AL10: =Nyeri!E21 -> -39292.335 | AM10: =Samburu!E21 -> 74526.765 | AN10: =Siaya!E21 -> -23427.045 | AO10: ='Taita Taveta'!E21 -> 25809.015 | AP10: ='Tana River'!E21 -> -35516.685 | AQ10: ='Tharaka-Nithi'!E21 -> -231.255 | AR10: ='Trans Nzoia'!E21 -> -30123.675 | AS10: =Turkana!E21 -> 302545.78 | AT10: ='Uasin Gishu'!E21 -> -55631.7 | AU10: =Vihiga!E21 -> -456.045 | AV10: =Wajir!E21 -> 234473.11 | AW10: ='West Pokot'!E21 -> -33925.785
A11: 6 | B11: Perennial Cropland | C11: =Baringo!E22 -> 1012.905 | D11: =Bomet!E22 -> 5249.28 | E11: =Bungoma!E22 -> -3022.68 | F11: =Busia!E22 -> 467.58 | G11: ='Elgeyo-Marakwet'!E22 -> 629.385 | H11: =Embu!E22 -> 6524.61 | I11: =Garissa!E22 -> 0 | J11: ='Homa Bay'!E22 -> 92.43 | K11: =Isiolo!E22 -> 0.73166667 | L11: =Kajiado!E22 -> 535.425 | M11: =Kakamega!E22 -> -9163.77 | N11: =Kericho!E22 -> 6672.075 | O11: =Kiambu!E22 -> -10570.215 | P11: =Kilifi!E22 -> 1947.03 | Q11: =Kirinyaga!E22 -> 3735.015 | R11: =Kisii!E22 -> 2256.225 | S11: =Kisumu!E22 -> -273.69 | T11: =Kitui!E22 -> 82.605 | U11: =Kwale!E22 -> 748.68 | V11: =Laikipia!E22 -> 60.855 | W11: =Lamu!E22 -> 4.0166667 | X11: =Machakos!E22 -> 270.51 | Y11: =Makueni!E22 -> 1205.43 | Z11: =Mandera!E22 -> 0 | AA11: =Marsabit!E22 -> 0 | AB11: =Meru!E22 -> 9344.61 | AC11: =Migori!E22 -> 8205.765 | AD11: =Mombasa!E22 -> 0.435 | AE11: ='Murang''a'!E22 -> 6079.98 | AF11: =Nairobi!E22 -> -733.635 | AG11: =Nakuru!E22 -> -1800.255 | AH11: =Nandi!E22 -> 6139.62 | AI11: =Narok!E22 -> 6052.59 | AJ11: =Nyamira!E22 -> 2548.38 | AK11: =Nyandarua!E22 -> 205.875 | AL11: =Nyeri!E22 -> 12985.77 | AM11: =Samburu!E22 -> 0 | AN11: =Siaya!E22 -> -280.38 | AO11: ='Taita Taveta'!E22 -> 3389.115 | AP11: ='Tana River'!E22 -> 9.9566667 | AQ11: ='Tharaka-Nithi'!E22 -> 3071.37 | AR11: ='Trans Nzoia'!E22 -> 406.125 | AS11: =Turkana!E22 -> 0 | AT11: ='Uasin Gishu'!E22 -> 180.135 | AU11: =Vihiga!E22 -> -70.71 | AV11: =Wajir!E22 -> 0 | AW11: ='West Pokot'!E22 -> 946.23
A12: 7 | B12: Annual Cropland | C12: =Baringo!E23 -> 36084.03 | D12: =Bomet!E23 -> 65497.155 | E12: =Bungoma!E23 -> 65344.59 | F12: =Busia!E23 -> 31393.545 | G12: ='Elgeyo-Marakwet'!E23 -> 72966.945 | H12: =Embu!E23 -> 52849.74 | I12: =Garissa!E23 -> 709.185 | J12: ='Homa Bay'!E23 -> 59349.9 | K12: =Isiolo!E23 -> 1286.37 | L12: =Kajiado!E23 -> 34751.115 | M12: =Kakamega!E23 -> 63080.52 | N12: =Kericho!E23 -> 73257.3 | O12: =Kiambu!E23 -> 32953.545 | P12: =Kilifi!E23 -> 69534.465 | Q12: =Kirinyaga!E23 -> 14828.88 | R12: =Kisii!E23 -> 5193.015 | S12: =Kisumu!E23 -> 41251.11 | T12: =Kitui!E23 -> 379650.06 | U12: =Kwale!E23 -> 98631.525 | V12: =Laikipia!E23 -> 58156.14 | W12: =Lamu!E23 -> 10838.835 | X12: =Machakos!E23 -> 117917.25 | Y12: =Makueni!E23 -> 151878.64 | Z12: =Mandera!E23 -> 2403.9 | AA12: =Marsabit!E23 -> 3124.995 | AB12: =Meru!E23 -> 79896.225 | AC12: =Migori!E23 -> 69361.185 | AD12: =Mombasa!E23 -> 2359.77 | AE12: ='Murang''a'!E23 -> 31241.37 | AF12: =Nairobi!E23 -> 6491.28 | AG12: =Nakuru!E23 -> 127108.78 | AH12: =Nandi!E23 -> 58834.275 | AI12: =Narok!E23 -> 198571.65 | AJ12: =Nyamira!E23 -> 7799.085 | AK12: =Nyandarua!E23 -> 71082.105 | AL12: =Nyeri!E23 -> 29379.255 | AM12: =Samburu!E23 -> 1122.765 | AN12: =Siaya!E23 -> 65980.185 | AO12: ='Taita Taveta'!E23 -> 25232.415 | AP12: ='Tana River'!E23 -> 16285.47 | AQ12: ='Tharaka-Nithi'!E23 -> 35644.8 | AR12: ='Trans Nzoia'!E23 -> 88679.79 | AS12: =Turkana!E23 -> 1226.01 | AT12: ='Uasin Gishu'!E23 -> 109861.38 | AU12: =Vihiga!E23 -> 7072.515 | AV12: =Wajir!E23 -> 0 | AW12: ='West Pokot'!E23 -> 48374.1
A13: 8 | B13: Vegetated Wetland | C13: =Baringo!E24 -> 185.475 | D13: =Bomet!E24 -> -16.83 | E13: =Bungoma!E24 -> 9.99 | F13: =Busia!E24 -> 2357.76 | G13: ='Elgeyo-Marakwet'!E24 -> -105.33 | H13: =Embu!E24 -> 10.14 | I13: =Garissa!E24 -> -18.12 | J13: ='Homa Bay'!E24 -> 2410.05 | K13: =Isiolo!E24 -> 130.785 | L13: =Kajiado!E24 -> -1290.735 | M13: =Kakamega!E24 -> 66.27 | N13: =Kericho!E24 -> -23.1 | O13: =Kiambu!E24 -> -103.53 | P13: =Kilifi!E24 -> 1267.83 | Q13: =Kirinyaga!E24 -> 17.055 | R13: =Kisii!E24 -> 14.715 | S13: =Kisumu!E24 -> 2466.99 | T13: =Kitui!E24 -> 168.44667 | U13: =Kwale!E24 -> 0.585 | V13: =Laikipia!E24 -> -400.89 | W13: =Lamu!E24 -> 293.205 | X13: =Machakos!E24 -> -20.4 | Y13: =Makueni!E24 -> -10.74 | Z13: =Mandera!E24 -> 0 | AA13: =Marsabit!E24 -> 691.41 | AB13: =Meru!E24 -> 182.97 | AC13: =Migori!E24 -> -214.41 | AD13: =Mombasa!E24 -> 0 | AE13: ='Murang''a'!E24 -> -61.38 | AF13: =Nairobi!E24 -> 6.72 | AG13: =Nakuru!E24 -> -30.855 | AH13: =Nandi!E24 -> 21.45 | AI13: =Narok!E24 -> 148.59 | AJ13: =Nyamira!E24 -> -3.72 | AK13: =Nyandarua!E24 -> 413.55 | AL13: =Nyeri!E24 -> -17.52 | AM13: =Samburu!E24 -> 5.835 | AN13: =Siaya!E24 -> 2437.8 | AO13: ='Taita Taveta'!E24 -> 764.565 | AP13: ='Tana River'!E24 -> 951.15 | AQ13: ='Tharaka-Nithi'!E24 -> 5.925 | AR13: ='Trans Nzoia'!E24 -> -7.5 | AS13: =Turkana!E24 -> 7180.77 | AT13: ='Uasin Gishu'!E24 -> -391.965 | AU13: =Vihiga!E24 -> -36.135 | AV13: =Wajir!E24 -> 0 | AW13: ='West Pokot'!E24 -> 49.106667
A14: 9 | B14: Open Water | C14: =Baringo!E25 -> 6528.93 | D14: =Bomet!E25 -> 77.73 | E14: =Bungoma!E25 -> 77.76 | F14: =Busia!E25 -> -47.055 | G14: ='Elgeyo-Marakwet'!E25 -> 146.535 | H14: =Embu!E25 -> -1377.09 | I14: =Garissa!E25 -> 367.485 | J14: ='Homa Bay'!E25 -> -564.84 | K14: =Isiolo!E25 -> -171.285 | L14: =Kajiado!E25 -> -1453.395 | M14: =Kakamega!E25 -> 250.245 | N14: =Kericho!E25 -> 126.03 | O14: =Kiambu!E25 -> -248.64 | P14: =Kilifi!E25 -> 1008.465 | Q14: =Kirinyaga!E25 -> -164.835 | R14: =Kisii!E25 -> -25.725 | S14: =Kisumu!E25 -> -1499.385 | T14: =Kitui!E25 -> 425.91 | U14: =Kwale!E25 -> 193.245 | V14: =Laikipia!E25 -> 138.795 | W14: =Lamu!E25 -> -419.985 | X14: =Machakos!E25 -> -1768.41 | Y14: =Makueni!E25 -> 421.2 | Z14: =Mandera!E25 -> 988.005 | AA14: =Marsabit!E25 -> 5076.18 | AB14: =Meru!E25 -> 56.52 | AC14: =Migori!E25 -> -344.265 | AD14: =Mombasa!E25 -> 210.18 | AE14: ='Murang''a'!E25 -> -166.8 | AF14: =Nairobi!E25 -> -52.26 | AG14: =Nakuru!E25 -> 4083.6 | AH14: =Nandi!E25 -> 31.5 | AI14: =Narok!E25 -> 929.34 | AJ14: =Nyamira!E25 -> 3.345 | AK14: =Nyandarua!E25 -> 1055.85 | AL14: =Nyeri!E25 -> 43.74 | AM14: =Samburu!E25 -> -9.075 | AN14: =Siaya!E25 -> -25.14 | AO14: ='Taita Taveta'!E25 -> 685.275 | AP14: ='Tana River'!E25 -> -3595.275 | AQ14: ='Tharaka-Nithi'!E25 -> 176.985 | AR14: ='Trans Nzoia'!E25 -> 73.155 | AS14: =Turkana!E25 -> 3446.535 | AT14: ='Uasin Gishu'!E25 -> 49.125 | AU14: =Vihiga!E25 -> 13.095 | AV14: =Wajir!E25 -> 235.935 | AW14: ='West Pokot'!E25 -> 1565.595
A15: 10 | B15: Other land | C15: =Baringo!E26 -> -12249.57 | D15: =Bomet!E26 -> 78.81 | E15: =Bungoma!E26 -> 3272.835 | F15: =Busia!E26 -> 760.275 | G15: ='Elgeyo-Marakwet'!E26 -> 674.52 | H15: =Embu!E26 -> 440.385 | I15: =Garissa!E26 -> -14538.63 | J15: ='Homa Bay'!E26 -> 1151.58 | K15: =Isiolo!E26 -> -98570.67 | L15: =Kajiado!E26 -> -10508.22 | M15: =Kakamega!E26 -> 830.145 | N15: =Kericho!E26 -> 1016.805 | O15: =Kiambu!E26 -> 711.33 | P15: =Kilifi!E26 -> 7185.57 | Q15: =Kirinyaga!E26 -> 678.27 | R15: =Kisii!E26 -> 1031.67 | S15: =Kisumu!E26 -> 3002.085 | T15: =Kitui!E26 -> 5684.97 | U15: =Kwale!E26 -> 2049.21 | V15: =Laikipia!E26 -> 1797.105 | W15: =Lamu!E26 -> 1396.32 | X15: =Machakos!E26 -> 2226.87 | Y15: =Makueni!E26 -> 1395.42 | Z15: =Mandera!E26 -> -13132.185 | AA15: =Marsabit!E26 -> -123169.1 | AB15: =Meru!E26 -> 2614.575 | AC15: =Migori!E26 -> 1272.84 | AD15: =Mombasa!E26 -> 2196.375 | AE15: ='Murang''a'!E26 -> 401.1 | AF15: =Nairobi!E26 -> 4295.37 | AG15: =Nakuru!E26 -> 4331.04 | AH15: =Nandi!E26 -> 347.955 | AI15: =Narok!E26 -> 724.545 | AJ15: =Nyamira!E26 -> 291.405 | AK15: =Nyandarua!E26 -> 919.845 | AL15: =Nyeri!E26 -> 935.025 | AM15: =Samburu!E26 -> -22694.175 | AN15: =Siaya!E26 -> 1365.585 | AO15: ='Taita Taveta'!E26 -> 37.71 | AP15: ='Tana River'!E26 -> 5980.56 | AQ15: ='Tharaka-Nithi'!E26 -> 437.445 | AR15: ='Trans Nzoia'!E26 -> 1648.365 | AS15: =Turkana!E26 -> -45275.895 | AT15: ='Uasin Gishu'!E26 -> 2614.755 | AU15: =Vihiga!E26 -> 56.19 | AV15: =Wajir!E26 -> -12175.395 | AW15: ='West Pokot'!E26 -> -3716.55
C16: =SUM(C6:C15) -> 0 | D16: =SUM(D6:D15) -> 8.8107299e-13 | E16: =SUM(E6:E15) -> 8.1854523e-12 | F16: =SUM(F6:F15) -> -1.0459189e-11 | G16: =SUM(G6:G15) -> 2.3305802e-11 | H16: =SUM(H6:H15) -> 9.3223207e-12 | I16: =SUM(I6:I15) -> -4.0017767e-11 | J16: =SUM(J6:J15) -> -5.0022209e-12 | ... AW16: =SUM(AW6:AW15) -> -0.033333333
A18: As % of opening area
A19: Sleek Class | B19: Land Cover
A20: 1 | B20: Dense Forest | C20: =Baringo!E31 -> -7.7857044 | D20: =Bomet!E31 -> -4.9474047 | E20: =Bungoma!E31 -> -8.5527286 | F20: =Busia!E31 -> -76.148054 | G20: ='Elgeyo-Marakwet'!E31 -> -5.498503 | H20: =Embu!E31 -> -12.139047 | I20: =Garissa!E31 -> -21.217611 | J20: ='Homa Bay'!E31 -> -28.318952 | K20: =Isiolo!E31 -> 97.899734 | L20: =Kajiado!E31 -> -18.772779 | M20: =Kakamega!E31 -> 4.2121304 | N20: =Kericho!E31 -> -15.757194 | O20: =Kiambu!E31 -> 20.237587 | P20: =Kilifi!E31 -> -10.951394 | Q20: =Kirinyaga!E31 -> 3.8834847 | R20: =Kisii!E31 -> 38.324439 | S20: =Kisumu!E31 -> -22.503374 | T20: =Kitui!E31 -> 0.054436748 | U20: =Kwale!E31 -> -25.671948 | V20: =Laikipia!E31 -> -17.62957 | W20: =Lamu!E31 -> 27.734529 | X20: =Machakos!E31 -> 232.97095 | Y20: =Makueni!E31 -> -42.31946 | Z20: =Mandera!E31 -> -22.333231 | AA20: =Marsabit!E31 -> 36.917864 | AB20: =Meru!E31 -> -8.5898395 | AC20: =Migori!E31 -> -79.183404 | AD20: =Mombasa!E31 -> -77.597225 | AE20: ='Murang''a'!E31 -> 14.291217 | AF20: =Nairobi!E31 -> -8.8036312 | AG20: =Nakuru!E31 -> -47.519563 | AH20: =Nandi!E31 -> 8.2060991 | AI20: =Narok!E31 -> -40.685898 | AJ20: =Nyamira!E31 -> 45.100513 | AK20: =Nyandarua!E31 -> 12.203636 | AL20: =Nyeri!E31 -> 2.0174159 | AM20: =Samburu!E31 -> 74.925415 | AN20: =Siaya!E31 -> -40.530973 | AO20: ='Taita Taveta'!E31 -> -32.246142 | AP20: ='Tana River'!E31 -> 21.871675 | AQ20: ='Tharaka-Nithi'!E31 -> -17.959942 | AR20: ='Trans Nzoia'!E31 -> -7.8931964 | AS20: =Turkana!E31 -> -25.699849 | AT20: ='Uasin Gishu'!E31 -> -30.477832 | AU20: =Vihiga!E31 -> 44.206028 | AV20: =Wajir!E31 -> 44.363017 | AW20: ='West Pokot'!E31 -> -25.151185
A21: 2 | B21: Moderate Forest | C21: =Baringo!E32 -> 10.282321 | D21: =Bomet!E32 -> 121.8308 | E21: =Bungoma!E32 -> 185.69916 | F21: =Busia!E32 -> 153.8739 | G21: ='Elgeyo-Marakwet'!E32 -> -84.119988 | H21: =Embu!E32 -> -33.686627 | I21: =Garissa!E32 -> -25.408478 | J21: ='Homa Bay'!E32 -> 565.37561 | K21: =Isiolo!E32 -> 667.82288 | L21: =Kajiado!E32 -> 1.4111403 | M21: =Kakamega!E32 -> -6.1092816 | N21: =Kericho!E32 -> 55.862134 | O21: =Kiambu!E32 -> -61.117145 | P21: =Kilifi!E32 -> -34.313294 | Q21: =Kirinyaga!E32 -> 182.31181 | R21: =Kisii!E32 -> 537.12057 | S21: =Kisumu!E32 -> 194.58516 | T21: =Kitui!E32 -> -4.2023086 | U21: =Kwale!E32 -> -34.507407 | V21: =Laikipia!E32 -> 262.5572 | W21: =Lamu!E32 -> -44.483401 | X21: =Machakos!E32 -> -13.204961 | Y21: =Makueni!E32 -> 79.076523 | Z21: =Mandera!E32 -> 416.31064 | AA21: =Marsabit!E32 -> 9.5472792 | AB21: =Meru!E32 -> 251.14211 | AC21: =Migori!E32 -> 533.90839 | AD21: =Mombasa!E32 -> 19.774436 | AE21: ='Murang''a'!E32 -> -67.958965 | AF21: =Nairobi!E32 -> -23.876746 | AG21: =Nakuru!E32 -> 8.1202892 | AH21: =Nandi!E32 -> 1.23419 | AI21: =Narok!E32 -> -32.935378 | AJ21: =Nyamira!E32 -> 1380.7282 | AK21: =Nyandarua!E32 -> -45.298521 | AL21: =Nyeri!E32 -> 72.175442 | AM21: =Samburu!E32 -> 6.5450039 | AN21: =Siaya!E32 -> -16.988306 | AO21: ='Taita Taveta'!E32 -> 105.98652 | AP21: ='Tana River'!E32 -> -32.834001 | AQ21: ='Tharaka-Nithi'!E32 -> -17.234358 | AR21: ='Trans Nzoia'!E32 -> 59.375918 | AS21: =Turkana!E32 -> 0.10728464 | AT21: ='Uasin Gishu'!E32 -> -47.431867 | AU21: =Vihiga!E32 -> -48.085388 | AV21: =Wajir!E32 -> 30.290583 | AW21: ='West Pokot'!E32 -> -25.162854
A22: 3 | B22: Open Forest | C22: =Baringo!E33 -> -63.399606 | D22: =Bomet!E33 -> 19.17967 | E22: =Bungoma!E33 -> -6.1590018 | F22: =Busia!E33 -> 5668.7097 | G22: ='Elgeyo-Marakwet'!E33 -> -22.900555 | H22: =Embu!E33 -> -99.611399 | I22: =Garissa!E33 -> -80.323946 | J22: ='Homa Bay'!E33 -> 93.45172 | K22: =Isiolo!E33 -> -31.195464 | L22: =Kajiado!E33 -> -32.051924 | M22: =Kakamega!E33 -> 454.29688 | N22: =Kericho!E33 -> 24.114522 | O22: =Kiambu!E33 -> -95.279306 | P22: =Kilifi!E33 -> 70.486114 | Q22: =Kirinyaga!E33 -> -99.815043 | R22: =Kisii!E33 -> -60.788697 | S22: =Kisumu!E33 -> 4031.1765 | T22: =Kitui!E33 -> 410.71105 | U22: =Kwale!E33 -> -46.080094 | V22: =Laikipia!E33 -> -28.726659 | W22: =Lamu!E33 -> -31.27106 | X22: =Machakos!E33 -> -31.17295 | Y22: =Makueni!E33 -> 29.546089 | Z22: =Mandera!E33 -> 251.9405 | AA22: =Marsabit!E33 -> -7.5550842 | AB22: =Meru!E33 -> -83.471678 | AC22: =Migori!E33 -> 234.01962 | AD22: =Mombasa!E33 -> -34.707646 | AE22: ='Murang''a'!E33 -> -99.581301 | AF22: =Nairobi!E33 -> -91.186646 | AG22: =Nakuru!E33 -> -23.560241 | AH22: =Nandi!E33 -> 251.69808 | AI22: =Narok!E33 -> -22.318324 | AJ22: =Nyamira!E33 -> -52.765556 | AK22: =Nyandarua!E33 -> -75.233138 | AL22: =Nyeri!E33 -> -75.273064 | AM22: =Samburu!E33 -> 25.179302 | AN22: =Siaya!E33 -> 262300 | AO22: ='Taita Taveta'!E33 -> -10.581976 | AP22: ='Tana River'!E33 -> 51.193456 | AQ22: ='Tharaka-Nithi'!E33 -> -78.897861 | AR22: ='Trans Nzoia'!E33 -> -42.105301 | AS22: =Turkana!E33 -> 13.316543 | AT22: ='Uasin Gishu'!E33 -> 115.77292 | AU22: =Vihiga!E33 -> 35682.5 | AV22: =Wajir!E33 -> -77.234447 | AW22: ='West Pokot'!E33 -> -19.388331
A23: 4 | B23: Wooded Grassland | C23: =Baringo!E34 -> -1.7163393 | D23: =Bomet!E34 -> -2.5835154 | E23: =Bungoma!E34 -> -70.993233 | F23: =Busia!E34 -> -57.2192 | G23: ='Elgeyo-Marakwet'!E34 -> -18.621626 | H23: =Embu!E34 -> -38.797032 | I23: =Garissa!E34 -> -4.4649948 | J23: ='Homa Bay'!E34 -> -33.718053 | K23: =Isiolo!E34 -> -8.6262412 | L23: =Kajiado!E34 -> -3.396916 | M23: =Kakamega!E34 -> -56.714243 | N23: =Kericho!E34 -> -66.931389 | O23: =Kiambu!E34 -> -15.352005 | P23: =Kilifi!E34 -> -3.7258109 | Q23: =Kirinyaga!E34 -> -54.230871 | R23: =Kisii!E34 -> 37.400453 | S23: =Kisumu!E34 -> -48.226592 | T23: =Kitui!E34 -> -18.131389 | U23: =Kwale!E34 -> -15.440557 | V23: =Laikipia!E34 -> -5.2685752 | W23: =Lamu!E34 -> 0.50089531 | X23: =Machakos!E34 -> -30.859526 | Y23: =Makueni!E34 -> -27.318157 | Z23: =Mandera!E34 -> -4.8166716 | AA23: =Marsabit!E34 -> -3.528494 | AB23: =Meru!E34 -> -23.072874 | AC23: =Migori!E34 -> -55.383182 | AD23: =Mombasa!E34 -> -40.272908 | AE23: ='Murang''a'!E34 -> -50.153437 | AF23: =Nairobi!E34 -> 2.7704355 | AG23: =Nakuru!E34 -> -1.0244462 | AH23: =Nandi!E34 -> -57.937337 | AI23: =Narok!E34 -> 8.8319446 | AJ23: =Nyamira!E34 -> 15.709953 | AK23: =Nyandarua!E34 -> -20.765091 | AL23: =Nyeri!E34 -> -12.779499 | AM23: =Samburu!E34 -> -9.9374379 | AN23: =Siaya!E34 -> -57.31039 | AO23: ='Taita Taveta'!E34 -> -3.7616616 | AP23: ='Tana River'!E34 -> 0.46665589 | AQ23: ='Tharaka-Nithi'!E34 -> -26.593224 | AR23: ='Trans Nzoia'!E34 -> -71.623812 | AS23: =Turkana!E34 -> -9.2236226 | AT23: ='Uasin Gishu'!E34 -> -61.438967 | AU23: =Vihiga!E34 -> -66.229708 | AV23: =Wajir!E34 -> -5.0237619 | AW23: ='West Pokot'!E34 -> 1.7716348
A24: 5 | B24: Open Grassland | C24: =Baringo!E35 -> -8.966167 | D24: =Bomet!E35 -> -81.540375 | E24: =Bungoma!E35 -> -46.830827 | F24: =Busia!E35 -> -11.370756 | G24: ='Elgeyo-Marakwet'!E35 -> -48.542402 | H24: =Embu!E35 -> -27.31391 | I24: =Garissa!E35 -> 73.54663 | J24: ='Homa Bay'!E35 -> -43.909743 | K24: =Isiolo!E35 -> 20.806107 | L24: =Kajiado!E35 -> 5.454033 | M24: =Kakamega!E35 -> -59.398578 | N24: =Kericho!E35 -> -76.353148 | O24: =Kiambu!E35 -> -32.002949 | P24: =Kilifi!E35 -> -1.358565 | Q24: =Kirinyaga!E35 -> -42.810516 | R24: =Kisii!E35 -> -76.21648 | S24: =Kisumu!E35 -> -54.620239 | T24: =Kitui!E35 -> -15.632496 | U24: =Kwale!E35 -> 74.980776 | V24: =Laikipia!E35 -> -10.02647 | W24: =Lamu!E35 -> -7.4432563 | X24: =Machakos!E35 -> -28.410104 | Y24: =Makueni!E35 -> -4.4970919 | Z24: =Mandera!E35 -> 104.89571 | AA24: =Marsabit!E35 -> 15.642251 | AB24: =Meru!E35 -> -19.674838 | AC24: =Migori!E35 -> -55.28795 | AD24: =Mombasa!E35 -> 388.60894 | AE24: ='Murang''a'!E35 -> -77.229845 | AF24: =Nairobi!E35 -> -35.295168 | AG24: =Nakuru!E35 -> -42.020499 | AH24: =Nandi!E35 -> -68.962897 | AI24: =Narok!E35 -> -18.496401 | AJ24: =Nyamira!E35 -> -82.536164 | AK24: =Nyandarua!E35 -> -59.785184 | AL24: =Nyeri!E35 -> -55.14384 | AM24: =Samburu!E35 -> 23.804612 | AN24: =Siaya!E35 -> -52.986948 | AO24: ='Taita Taveta'!E35 -> 13.429546 | AP24: ='Tana River'!E35 -> -8.89306 | AQ24: ='Tharaka-Nithi'!E35 -> -2.7713962 | AR24: ='Trans Nzoia'!E35 -> -55.747511 | AS24: =Turkana!E35 -> 24.720375 | AT24: ='Uasin Gishu'!E35 -> -53.202037 | AU24: =Vihiga!E35 -> -14.499299 | AV24: =Wajir!E35 -> 17.261122 | AW24: ='West Pokot'!E35 -> -26.542284
A25: 6 | B25: Perennial Cropland | C25: =Baringo!E36 -> 112.23075 | D25: =Bomet!E36 -> 53.437087 | E25: =Bungoma!E36 -> -41.818401 | F25: =Busia!E36 -> 39.799801 | G25: ='Elgeyo-Marakwet'!E36 -> 249.99404 | H25: =Embu!E36 -> 66.424876 | I25: =Garissa!E36 -> 0 | J25: ='Homa Bay'!E36 -> 5.1056426 | K25: =Isiolo!E36 -> 2195 | L25: =Kajiado!E36 -> 200.1514 | M25: =Kakamega!E36 -> -62.932578 | N25: =Kericho!E36 -> 60.378529 | O25: =Kiambu!E36 -> -23.734576 | P25: =Kilifi!E36 -> 49.119049 | Q25: =Kirinyaga!E36 -> 34.113745 | R25: =Kisii!E36 -> 271.47782 | S25: =Kisumu!E36 -> -1.2969732 | T25: =Kitui!E36 -> 19667.857 | U25: =Kwale!E36 -> 29.884204 | V25: =Laikipia!E36 -> 114.34611 | W25: =Lamu!E36 -> 12050 | X25: =Machakos!E36 -> 16.985646 | Y25: =Makueni!E36 -> 23.633102 | Z25: =Mandera!E36 -> 0 | AA25: =Marsabit!E36 -> 0 | AB25: =Meru!E36 -> 32.453459 | AC25: =Migori!E36 -> 198.24423 | AD25: =Mombasa!E36 -> 38.157895 | AE25: ='Murang''a'!E36 -> 18.062408 | AF25: =Nairobi!E36 -> -48.837697 | AG25: =Nakuru!E36 -> -24.617862 | AH25: =Nandi!E36 -> 49.452326 | AI25: =Narok!E36 -> 758.18489 | AJ25: =Nyamira!E36 -> 94.704335 | AK25: =Nyandarua!E36 -> 50.810751 | AL25: =Nyeri!E36 -> 102.93031 | AM25: =Samburu!E36 -> 0 | AN25: =Siaya!E36 -> -29.934021 | AO25: ='Taita Taveta'!E36 -> 39.471055 | AP25: ='Tana River'!E36 -> 29870 | AQ25: ='Tharaka-Nithi'!E36 -> 61.07439 | AR25: ='Trans Nzoia'!E36 -> 131.29182 | AS25: =Turkana!E36 -> 0 | AT25: ='Uasin Gishu'!E36 -> 95.811393 | AU25: =Vihiga!E36 -> -29.286779 | AV25: =Wajir!E36 -> 0 | AW25: ='West Pokot'!E36 -> 2366.1665
A26: 7 | B26: Annual Cropland | C26: =Baringo!E37 -> 65.312861 | D26: =Bomet!E37 -> 102.79346 | E26: =Bungoma!E37 -> 45.349136 | F26: =Busia!E37 -> 33.735801 | G26: ='Elgeyo-Marakwet'!E37 -> 376.18614 | H26: =Embu!E37 -> 56.842567 | I26: =Garissa!E37 -> 2569.5109 | J26: ='Homa Bay'!E37 -> 42.27088 | K26: =Isiolo!E37 -> 669.46136 | L26: =Kajiado!E37 -> 238.31106 | M26: =Kakamega!E37 -> 38.188479 | N26: =Kericho!E37 -> 82.891197 | O26: =Kiambu!E37 -> 49.093616 | P26: =Kilifi!E37 -> 315.16081 | Q26: =Kirinyaga!E37 -> 23.280533 | R26: =Kisii!E37 -> 5.2003668 | S26: =Kisumu!E37 -> 44.221826 | T26: =Kitui!E37 -> 109.85951 | U26: =Kwale!E37 -> 322.75464 | V26: =Laikipia!E37 -> 114.44344 | W26: =Lamu!E37 -> 159.6409 | X26: =Machakos!E37 -> 65.988151 | Y26: =Makueni!E37 -> 88.225925 | Z26: =Mandera!E37 -> 363.05559 | AA26: =Marsabit!E37 -> 157.80412 | AB26: =Meru!E37 -> 55.321409 | AC26: =Migori!E37 -> 62.756917 | AD26: =Mombasa!E37 -> 157.38725 | AE26: ='Murang''a'!E37 -> 28.552334 | AF26: =Nairobi!E37 -> 62.321174 | AG26: =Nakuru!E37 -> 61.553778 | AH26: =Nandi!E37 -> 50.545574 | AI26: =Narok!E37 -> 148.26094 | AJ26: =Nyamira!E37 -> 13.563242 | AK26: =Nyandarua!E37 -> 77.115289 | AL26: =Nyeri!E37 -> 43.761641 | AM26: =Samburu!E37 -> 5278.6319 | AN26: =Siaya!E37 -> 53.959048 | AO26: ='Taita Taveta'!E37 -> 200.12527 | AP26: ='Tana River'!E37 -> 257.49774 | AQ26: ='Tharaka-Nithi'!E37 -> 45.557479 | AR26: ='Trans Nzoia'!E37 -> 108.57702 | AS26: =Turkana!E37 -> 519.60585 | AT26: ='Uasin Gishu'!E37 -> 86.10681 | AU26: =Vihiga!E37 -> 19.674452 | AV26: =Wajir!E37 -> 0 | AW26: ='West Pokot'!E37 -> 473.95617
A27: 8 | B27: Vegetated Wetland | C27: =Baringo!E38 -> 22.714748 | D27: =Bomet!E38 -> -100 | E27: =Bungoma!E38 -> 60.326087 | F27: =Busia!E38 -> 161.15816 | G27: ='Elgeyo-Marakwet'!E38 -> -100 | H27: =Embu!E38 -> 528.125 | I27: =Garissa!E38 -> -100 | J27: ='Homa Bay'!E38 -> 359.0712 | K27: =Isiolo!E38 -> 119.27497 | L27: =Kajiado!E38 -> -47.12638 | M27: =Kakamega!E38 -> 82.302534 | N27: =Kericho!E38 -> -100 | O27: =Kiambu!E38 -> -77.97108 | P27: =Kilifi!E38 -> 2412.1575 | Q27: =Kirinyaga!E38 -> 42.2049 | R27: =Kisii!E38 -> 908.33333 | S27: =Kisumu!E38 -> 52.99884 | T27: =Kitui!E38 -> 505340 | U27: =Kwale!E38 -> 0 | V27: =Laikipia!E38 -> -45.581062 | W27: =Lamu!E38 -> 221.37033 | X27: =Machakos!E38 -> -76.404494 | Y27: =Makueni!E38 -> -98.351648 | Z27: =Mandera!E38 -> 0 | AA27: =Marsabit!E38 -> 74.465267 | AB27: =Meru!E38 -> 185.4927 | AC27: =Migori!E38 -> -24.830629 | AD27: =Mombasa!E38 -> 0 | AE27: ='Murang''a'!E38 -> -76.116071 | AF27: =Nairobi!E38 -> 22.4 | AG27: =Nakuru!E38 -> -2.8575795 | AH27: =Nandi!E38 -> 12.211785 | AI27: =Narok!E38 -> 644.92187 | AJ27: =Nyamira!E38 -> -67.391304 | AK27: =Nyandarua!E38 -> 63.997214 | AL27: =Nyeri!E38 -> -61.668427 | AM27: =Samburu!E38 -> 55.09915 | AN27: =Siaya!E38 -> 92.265419 | AO27: ='Taita Taveta'!E38 -> 22.649349 | AP27: ='Tana River'!E38 -> 58.920275 | AQ27: ='Tharaka-Nithi'!E38 -> 184.57944 | AR27: ='Trans Nzoia'!E38 -> -98.814229 | AS27: =Turkana!E38 -> 256.69076 | AT27: ='Uasin Gishu'!E38 -> -96.488443 | AU27: =Vihiga!E38 -> -60.558069 | AV27: =Wajir!E38 -> 0 | AW27: ='West Pokot'!E38 -> 147320
A28: 9 | B28: Open Water | C28: =Baringo!E39 -> 40.19255 | D28: =Bomet!E39 -> 3159.7561 | E28: =Bungoma!E39 -> 138.01917 | F28: =Busia!E39 -> -0.32952581 | G28: ='Elgeyo-Marakwet'!E39 -> 449.35603 | H28: =Embu!E39 -> -27.752888 | I28: =Garissa!E39 -> 159.29129 | J28: ='Homa Bay'!E39 -> -0.34438482 | K28: =Isiolo!E39 -> -15.071404 | L28: =Kajiado!E39 -> -14.528429 | M28: =Kakamega!E39 -> 56.399594 | N28: =Kericho!E39 -> 204.22946 | O28: =Kiambu!E39 -> -41.652427 | P28: =Kilifi!E39 -> 26.669232 | Q28: =Kirinyaga!E39 -> -51.78117 | R28: =Kisii!E39 -> -82.53128 | S28: =Kisumu!E39 -> -2.5858813 | T28: =Kitui!E39 -> 11.271038 | U28: =Kwale!E39 -> 90.508641 | V28: =Laikipia!E39 -> 29.712286 | W28: =Lamu!E39 -> -25.590897 | X28: =Machakos!E39 -> -21.422575 | Y28: =Makueni!E39 -> 43.960173 | Z28: =Mandera!E39 -> 6962.685 | AA28: =Marsabit!E39 -> 1.0321231 | AB28: =Meru!E39 -> 39.974539 | AC28: =Migori!E39 -> -0.62182093 | AD28: =Mombasa!E39 -> 50.075048 | AE28: ='Murang''a'!E39 -> -18.043746 | AF28: =Nairobi!E39 -> -14.939966 | AG28: =Nakuru!E39 -> 21.804179 | AH28: =Nandi!E39 -> 127.73723 | AI28: =Narok!E39 -> 1905.1661 | AJ28: =Nyamira!E39 -> 9.0798046 | AK28: =Nyandarua!E39 -> 99.418096 | AL28: =Nyeri!E39 -> 44.262295 | AM28: =Samburu!E39 -> -2.4120884 | AN28: =Siaya!E39 -> -0.024708059 | AO28: ='Taita Taveta'!E39 -> 69.833384 | AP28: ='Tana River'!E39 -> -23.895761 | AQ28: ='Tharaka-Nithi'!E39 -> 68.710692 | AR28: ='Trans Nzoia'!E39 -> 309.45431 | AS28: =Turkana!E39 -> 1.5005456 | AT28: ='Uasin Gishu'!E39 -> 14.105435 | AU28: =Vihiga!E39 -> 74.615385 | AV28: =Wajir!E39 -> 2340.625 | AW28: ='West Pokot'!E39 -> 134.0487
A29: 10 | B29: Other land | C29: =Baringo!E40 -> -49.184808 | D29: =Bomet!E40 -> 255.79357 | E29: =Bungoma!E40 -> 316.6657 | F29: =Busia!E40 -> 256.45112 | G29: ='Elgeyo-Marakwet'!E40 -> 350.65502 | H29: =Embu!E40 -> 60.088007 | I29: =Garissa!E40 -> -28.326428 | J29: ='Homa Bay'!E40 -> 333.32754 | K29: =Isiolo!E40 -> -43.612274 | L29: =Kajiado!E40 -> -22.716934 | M29: =Kakamega!E40 -> 95.835354 | N29: =Kericho!E40 -> 392.46758 | O29: =Kiambu!E40 -> 40.893726 | P29: =Kilifi!E40 -> 200.95899 | Q29: =Kirinyaga!E40 -> 66.040602 | R29: =Kisii!E40 -> 3685.8521 | S29: =Kisumu!E40 -> 297.29501 | T29: =Kitui!E40 -> 97.26926 | U29: =Kwale!E40 -> 131.70407 | V29: =Laikipia!E40 -> 147.26989 | W29: =Lamu!E40 -> 40.603327 | X29: =Machakos!E40 -> 95.699091 | Y29: =Makueni!E40 -> 76.845809 | Z29: =Mandera!E40 -> -29.416336 | AA29: =Marsabit!E40 -> -3.7161246 | AB29: =Meru!E40 -> 18.252635 | AC29: =Migori!E40 -> 106.62981 | AD29: =Mombasa!E40 -> 80.355281 | AE29: ='Murang''a'!E40 -> 238.92066 | AF29: =Nairobi!E40 -> 65.717328 | AG29: =Nakuru!E40 -> 95.03209 | AH29: =Nandi!E40 -> 323.70918 | AI29: =Narok!E40 -> 28.835202 | AJ29: =Nyamira!E40 -> 2728.5112 | AK29: =Nyandarua!E40 -> 269.59905 | AL29: =Nyeri!E40 -> 69.551683 | AM29: =Samburu!E40 -> -18.006903 | AN29: =Siaya!E40 -> 145.4576 | AO29: ='Taita Taveta'!E40 -> 1.155161 | AP29: ='Tana River'!E40 -> 28.577818 | AQ29: ='Tharaka-Nithi'!E40 -> 42.688389 | AR29: ='Trans Nzoia'!E40 -> 266.5058 | AS29: =Turkana!E40 -> -1.9474793 | AT29: ='Uasin Gishu'!E40 -> 367.21508 | AU29: =Vihiga!E40 -> 42.860412 | AV29: =Wajir!E40 -> -8.4940452 | AW29: ='West Pokot'!E40 -> -38.064819

Sheet Baringo
A1: Sleek Class | B1: Land Cover | C1: 1990 | D1: 1995 | E1: 2000 | F1: 2002 | G1: 2003 | H1: 2004 | I1: 2005 | J1: 2006 | K1: 2007 | L1: 2008 | M1: 2009 | N1: 2010 | O1: 2011 | P1: 2012 | Q1: 2013 | R1: 2014 | S1: 2015 | T1: 2018
A2: 1 | B2: Dense Forest | C2: 65660.31 | D2: 66940.47 | E2: 50137.02 | F2: 49188.78 | G2: 62064.09 | H2: 66620.79 | I2: 58543.65 | J2: 55769.04 | K2: 63667.8 | L2: 65757.78 | M2: 60063.21 | N2: 61879.05 | O2: 53605.53 | P2: 58184.64 | Q2: 56399.94 | R2: 68647.41 | S2: 63722.52 | T2: 48617.73 | U2: =SUM(C2:T2) -> 1075469.8
A3: 2 | B3: Moderate Forest | C3: 12114.72 | D3: 11229.12 | E3: 11795.94 | F3: 12447.45 | G3: 14127.03 | H3: 8632.17 | I3: 10312.02 | J3: 11868.66 | K3: 19274.4 | L3: 21374.1 | M3: 11033.19 | N3: 15051.24 | O3: 27774.72 | P3: 30769.74 | Q3: 19000.26 | R3: 14753.16 | S3: 13753.35 | T3: 12081.96
A4: 3 | B4: Open Forest | C4: 5605.65 | D4: 12717.72 | E4: 11277.09 | F4: 17709.21 | G4: 12828.87 | H4: 22040.64 | I4: 18591.75 | J4: 16196.31 | K4: 14130.18 | L4: 16161.75 | M4: 11590.92 | N4: 15183.99 | O4: 8276.04 | P4: 13404.78 | Q4: 11655 | R4: 7324.65 | S4: 4596.66 | T4: 2625.93
A5: 4 | B5: Wooded Grassland | C5: 861771.15 | D5: 800888.04 | E5: 814971.6 | F5: 807094.71 | G5: 785359.17 | H5: 794836.71 | I5: 835436.61 | J5: 784490.13 | K5: 746630.91 | L5: 756973.89 | M5: 799511.67 | N5: 767950.2 | O5: 761107.86 | P5: 751866.3 | Q5: 791339.49 | R5: 805477.68 | S5: 814131.63 | T5: 809272.53
A6: 5 | B6: Open Grassland | C6: 75004.11 | D6: 90503.1 | E6: 88558.38 | F6: 84540.33 | G6: 86058.54 | H6: 86171.85 | I6: 56996.82 | J6: 92604.78 | K6: 108265.95 | L6: 95103.9 | M6: 85311.81 | N6: 100941.21 | O6: 105241.05 | P6: 110429.37 | Q6: 93768.03 | R6: 74674.98 | S6: 72522.36 | T6: 81668.07
A7: 6 | B7: Perennial Cropland | C7: 516.42 | D7: 1167.48 | E7: 1023.66 | F7: 2313.36 | G7: 1240.92 | H7: 2125.26 | I7: 3555.63 | J7: 1279.98 | K7: 186.84 | L7: 2554.38 | M7: 8182.17 | N7: 2634.93 | O7: 1430.82 | P7: 1989.36 | Q7: 2496.42 | R7: 3585.24 | S7: 2651.67 | T7: 1179.18
A8: 7 | B8: Annual Cropland | C8: 36639.18 | D8: 60773.13 | E8: 68331.6 | F8: 72384.66 | G8: 65922.12 | H8: 72889.38 | I8: 76331.07 | J8: 85949.46 | K8: 57360.51 | L8: 84051.72 | M8: 68963.58 | N8: 89517.06 | O8: 73397.7 | P8: 84984.3 | Q8: 78109.65 | R8: 71752.5 | S8: 85141.89 | T8: 97522.11
A9: 8 | B9: Vegetated Wetland | C9: 1450.35 | D9: 845.82 | E9: 153.45 | F9: 1067.13 | G9: 1385.1 | H9: 311.85 | I9: 881.64 | J9: 1892.7 | K9: 2792.34 | L9: 445.86 | M9: 28.08 | N9: 1.26 | O9: 926.01 | P9: 1265.58 | Q9: 639.99 | R9: 1891.53 | S9: 268.02 | T9: 1736.01
A10: 9 | B10: Open Water | C10: 17124.66 | D10: 15336.63 | E10: 16271.1 | F10: 15550.47 | G10: 15051.78 | H10: 16206.48 | I10: 17521.56 | J10: 16195.86 | K10: 17181.63 | L10: 19002.78 | M10: 17555.49 | N10: 17573.76 | O10: 18126.27 | P10: 18396.9 | Q10: 20764.53 | R10: 24003.9 | S10: 23033.34 | T10: 22512.78
A11: 10 | B11: Other land | C11: 15287.94 | D11: 30772.98 | E11: 28654.65 | F11: 28878.39 | G11: 47136.87 | H11: 21339.36 | I11: 13003.74 | J11: 24927.57 | K11: 61683.93 | L11: 29748.33 | M11: 28934.37 | N11: 20441.79 | O11: 41288.49 | P11: 19883.52 | Q11: 17001.18 | R11: 19063.44 | S11: 11353.05 | T11: 13958.19
C12: =SUM(C2:C11) -> 1091174.5
C14: Closing | D14: Opening
C15: moyenne 2015-2018 | D15: moyenne 1990-2000
A16: Sleek Class | B16: Land Cover
A17: 1 | B17: Dense Forest | C17: =AVERAGE(S2:T2) -> 56170.125 | D17: =AVERAGE(C2:E2) -> 60912.6 | E17: =C17-D17 -> -4742.475
A18: 2 | B18: Moderate Forest | C18: =AVERAGE(S3:T3) -> 12917.655 | D18: =AVERAGE(C3:E3) -> 11713.26 | E18: =C18-D18 -> 1204.395
A19: 3 | B19: Open Forest | C19: =AVERAGE(S4:T4) -> 3611.295 | D19: =AVERAGE(C4:E4) -> 9866.82 | E19: =C19-D19 -> -6255.525
A20: 4 | B20: Wooded Grassland | C20: =AVERAGE(S5:T5) -> 811702.08 | D20: =AVERAGE(C5:E5) -> 825876.93 | E20: =C20-D20 -> -14174.85
A21: 5 | B21: Open Grassland | C21: =AVERAGE(S6:T6) -> 77095.215 | D21: =AVERAGE(C6:E6) -> 84688.53 | E21: =C21-D21 -> -7593.315
A22: 6 | B22: Perennial Cropland | C22: =AVERAGE(S7:T7) -> 1915.425 | D22: =AVERAGE(C7:E7) -> 902.52 | E22: =C22-D22 -> 1012.905
A23: 7 | B23: Annual Cropland | C23: =AVERAGE(S8:T8) -> 91332 | D23: =AVERAGE(C8:E8) -> 55247.97 | E23: =C23-D23 -> 36084.03
A24: 8 | B24: Vegetated Wetland | C24: =AVERAGE(S9:T9) -> 1002.015 | D24: =AVERAGE(C9:E9) -> 816.54 | E24: =C24-D24 -> 185.475
A25: 9 | B25: Open Water | C25: =AVERAGE(S10:T10) -> 22773.06 | D25: =AVERAGE(C10:E10) -> 16244.13 | E25: =C25-D25 -> 6528.93
A26: 10 | B26: Other land | C26: =AVERAGE(S11:T11) -> 12655.62 | D26: =AVERAGE(C11:E11) -> 24905.19 | E26: =C26-D26 -> -12249.57
E27: =SUM(E17:E26) -> 0
C28: =SUM(C17:C27) -> 1091174.5 | D28: =SUM(D17:D27) -> 1091174.5 | E28: =SUM(E17:E27) -> 1.0913936e-11
A30: As % of opening area
B31: Dense Forest | E31: =(E17/D17)*100 -> -7.7857044
B32: Moderate Forest | E32: =(E18/D18)*100 -> 10.282321
B33: Open Forest | E33: =(E19/D19)*100 -> -63.399606
B34: Wooded Grassland | E34: =(E20/D20)*100 -> -1.7163393
B35: Open Grassland | E35: =(E21/D21)*100 -> -8.966167
B36: Perennial Cropland | E36: =(E22/D22)*100 -> 112.23075
B37: Annual Cropland | E37: =(E23/D23)*100 -> 65.312861
B38: Vegetated Wetland | E38: =(E24/D24)*100 -> 22.714748
B39: Open Water | E39: =(E25/D25)*100 -> 40.19255
B40: Other land | E40: =(E26/D26)*100 -> -49.184808

Sheet Bomet
A1: Sleek Class | B1: Land Cover | C1: 1990 | D1: 1995 | E1: 2000 | F1: 2002 | G1: 2003 | H1: 2004 | I1: 2005 | J1: 2006 | K1: 2007 | L1: 2008 | M1: 2009 | N1: 2010 | O1: 2011 | P1: 2012 | Q1: 2013 | R1: 2014 | S1: 2015 | T1: 2018
A2: 1 | B2: Dense Forest | C2: 43678.89 | D2: 60883.56 | E2: 34710.57 | F2: 48329.91 | G2: 33489.54 | H2: 47836.8 | I2: 46014.3 | J2: 36918.54 | K2: 34316.1 | L2: 37413.27 | M2: 37213.74 | N2: 38184.03 | O2: 39122.82 | P2: 35405.46 | Q2: 46830.15 | R2: 46380.51 | S2: 42571.26 | T2: 45683.82
A3: 2 | B3: Moderate Forest | C3: 8937.9 | D3: 276.03 | E3: 12057.12 | F3: 4130.01 | G3: 14799.78 | H3: 4051.35 | I3: 15087.33 | J3: 9618.57 | K3: 12088.62 | L3: 11363.04 | M3: 10740.69 | N3: 12306.87 | O3: 17016.66 | P3: 14594.76 | Q3: 18093.96 | R3: 16446.78 | S3: 14656.41 | T3: 16800.75
A4: 3 | B4: Open Forest | C4: 1602.09 | D4: 2078.37 | E4: 11581.56 | F4: 2469.33 | G4: 16191.36 | H4: 4591.53 | I4: 13665.69 | J4: 5448.06 | K4: 4230 | L4: 5537.88 | M4: 9326.25 | N4: 9740.79 | O4: 5144.04 | P4: 4784.31 | Q4: 3849.39 | R4: 9582.21 | S4: 5792.85 | T4: 6333.3
A5: 4 | B5: Wooded Grassland | C5: 15090.03 | D5: 10859.4 | E5: 25333.02 | F5: 18545.85 | G5: 41459.13 | H5: 41980.59 | I5: 13861.26 | J5: 25943.4 | K5: 19043.28 | L5: 49391.64 | M5: 29038.59 | N5: 38956.5 | O5: 4279.23 | P5: 38454.57 | Q5: 26989.2 | R5: 33105.42 | S5: 16027.65 | T5: 17277.39
A6: 5 | B6: Open Grassland | C6: 120441.87 | D6: 89968.41 | E6: 75687.3 | F6: 56433.78 | G6: 62067.96 | H6: 42049.71 | I6: 38476.44 | J6: 36039.24 | K6: 28606.77 | L6: 35299.71 | M6: 33148.98 | N6: 37316.07 | O6: 20153.43 | P6: 30712.14 | Q6: 32574.78 | R6: 33808.41 | S6: 20854.35 | T6: 14354.01
A7: 6 | B7: Perennial Cropland | C7: 8872.92 | D7: 8813.88 | E7: 11783.07 | F7: 10899.36 | G7: 10219.59 | H7: 12977.73 | I7: 15229.35 | J7: 13129.65 | K7: 11137.23 | L7: 11084.13 | M7: 10731.51 | N7: 12632.4 | O7: 14784.12 | P7: 12492.45 | Q7: 14084.1 | R7: 11841.48 | S7: 17149.41 | T7: 12995.73
A8: 7 | B8: Annual Cropland | C8: 46019.16 | D8: 71680.59 | E8: 73451.97 | F8: 103659.57 | G8: 66417.93 | H8: 90993.24 | I8: 101825.73 | J8: 117335.34 | K8: 134818.2 | L8: 94380.21 | M8: 113401.8 | N8: 95130.18 | O8: 144140.58 | P8: 108066.96 | Q8: 102002.85 | R8: 93329.91 | S8: 127480.68 | T8: 130948.11
A9: 8 | B9: Vegetated Wetland | C9: 1.44 | D9: 30.69 | E9: 18.36 | F9: 33.48 | G9: 3.96 | H9: 0 | I9: 8.19 | J9: 0.27 | K9: 340.11 | L9: 101.25 | M9: 913.5 | N9: 234.45 | O9: 0 | P9: 0 | Q9: 62.64 | R9: 15.12 | S9: 0 | T9: 0
A10: 9 | B10: Open Water | C10: 1.71 | D10: 2.79 | E10: 2.88 | F10: 75.06 | G10: 0.27 | H10: 38.52 | I10: 186.39 | J10: 35.19 | K10: 8.91 | L10: 38.43 | M10: 30.33 | N10: 28.8 | O10: 1.62 | P10: 1.53 | Q10: 40.23 | R10: 68.13 | S10: 55.71 | T10: 104.67
A11: 10 | B11: Other land | C11: 6.66 | D11: 58.95 | E11: 26.82 | F11: 76.32 | G11: 3.15 | H11: 133.2 | I11: 297.99 | J11: 184.41 | K11: 63.45 | L11: 43.11 | M11: 107.28 | N11: 122.58 | O11: 10.17 | P11: 140.49 | Q11: 125.37 | R11: 74.7 | S11: 64.35 | T11: 154.89
C12: =SUM(C2:C11) -> 244652.67
C15: moyenne 2015-2018 | D15: moyenne 1990-2000
A16: Sleek Class | B16: Land Cover
A17: 1 | B17: Dense Forest | C17: =AVERAGE(S2:T2) -> 44127.54 | D17: =AVERAGE(C2:E2) -> 46424.34 | E17: =C17-D17 -> -2296.8
A18: 2 | B18: Moderate Forest | C18: =AVERAGE(S3:T3) -> 15728.58 | D18: =AVERAGE(C3:E3) -> 7090.35 | E18: =C18-D18 -> 8638.23
A19: 3 | B19: Open Forest | C19: =AVERAGE(S4:T4) -> 6063.075 | D19: =AVERAGE(C4:E4) -> 5087.34 | E19: =C19-D19 -> 975.735
A20: 4 | B20: Wooded Grassland | C20: =AVERAGE(S5:T5) -> 16652.52 | D20: =AVERAGE(C5:E5) -> 17094.15 | E20: =C20-D20 -> -441.63
A21: 5 | B21: Open Grassland | C21: =AVERAGE(S6:T6) -> 17604.18 | D21: =AVERAGE(C6:E6) -> 95365.86 | E21: =C21-D21 -> -77761.68
A22: 6 | B22: Perennial Cropland | C22: =AVERAGE(S7:T7) -> 15072.57 | D22: =AVERAGE(C7:E7) -> 9823.29 | E22: =C22-D22 -> 5249.28
A23: 7 | B23: Annual Cropland | C23: =AVERAGE(S8:T8) -> 129214.39 | D23: =AVERAGE(C8:E8) -> 63717.24 | E23: =C23-D23 -> 65497.155
A24: 8 | B24: Vegetated Wetland | C24: =AVERAGE(S9:T9) -> 0 | D24: =AVERAGE(C9:E9) -> 16.83 | E24: =C24-D24 -> -16.83
A25: 9 | B25: Open Water | C25: =AVERAGE(S10:T10) -> 80.19 | D25: =AVERAGE(C10:E10) -> 2.46 | E25: =C25-D25 -> 77.73
A26: 10 | B26: Other land | C26: =AVERAGE(S11:T11) -> 109.62 | D26: =AVERAGE(C11:E11) -> 30.81 | E26: =C26-D26 -> 78.81
A30: As % of opening area
B31: Dense Forest | E31: =(E17/D17)*100 -> -4.9474047
B32: Moderate Forest | E32: =(E18/D18)*100 -> 121.8308
B33: Open Forest | E33: =(E19/D19)*100 -> 19.17967
B34: Wooded Grassland | E34: =(E20/D20)*100 -> -2.5835154
B35: Open Grassland | E35: =(E21/D21)*100 -> -81.540375
B36: Perennial Cropland | E36: =(E22/D22)*100 -> 53.437087
B37: Annual Cropland | E37: =(E23/D23)*100 -> 102.79346
B38: Vegetated Wetland | E38: =(E24/D24)*100 -> -100
B39: Open Water | E39: =(E25/D25)*100 -> 3159.7561
B40: Other land | E40: =(E26/D26)*100 -> 255.79357

Sheet Bungoma
A1: Sleek Class | B1: Land Cover | C1: 1990 | D1: 1995 | E1: 2000 | F1: 2002 | G1: 2003 | H1: 2004 | I1: 2005 | J1: 2006 | K1: 2007 | L1: 2008 | M1: 2009 | N1: 2010 | O1: 2011 | P1: 2012 | Q1: 2013 | R1: 2014 | S1: 2015 | T1: 2018
A2: 1 | B2: Dense Forest | C2: 28160.19 | D2: 26943.39 | E2: 24851.43 | F2: 29209.32 | G2: 24967.44 | H2: 37734.21 | I2: 23467.59 | J2: 23691.06 | K2: 27090.9 | L2: 29739.96 | M2: 25004.52 | N2: 27009.45 | O2: 27684 | P2: 28063.53 | Q2: 22875.93 | R2: 31058.46 | S2: 24553.26 | T2: 24191.19
A3: 2 | B3: Moderate Forest | C3: 512.64 | D3: 1660.95 | E3: 164.7 | F3: 26.91 | G3: 4.23 | H3: 0.27 | I3: 27.36 | J3: 23.49 | K3: 497.25 | L3: 1.17 | M3: 62.73 | N3: 1.35 | O3: 1169.46 | P3: 93.69 | Q3: 328.59 | R3: 280.53 | S3: 2328.39 | T3: 2125.26
A4: 3 | B4: Open Forest | C4: 13222.8 | D4: 17807.22 | E4: 11900.07 | F4: 13970.43 | G4: 10495.62 | H4: 10028.43 | I4: 9652.5 | J4: 13852.17 | K4: 19528.56 | L4: 7874.64 | M4: 11543.31 | N4: 8984.16 | O4: 6526.44 | P4: 8609.22 | Q4: 8548.02 | R4: 6662.97 | S4: 12366.81 | T4: 14490.54
A5: 4 | B5: Wooded Grassland | C5: 61023.87 | D5: 55128.33 | E5: 44469.63 | F5: 30042 | G5: 45841.23 | H5: 45206.73 | I5: 43505.82 | J5: 29898.54 | K5: 19386.9 | L5: 30557.34 | M5: 18000 | N5: 20403.63 | O5: 36925.47 | P5: 32730.84 | Q5: 13289.67 | R5: 15518.34 | S5: 17604.45 | T5: 13456.35
A6: 5 | B6: Open Grassland | C6: 54019.62 | D6: 43208.64 | E6: 69065.28 | F6: 64621.89 | G6: 64251 | H6: 53990.19 | I6: 44041.86 | J6: 40987.62 | K6: 25841.16 | L6: 45235.8 | M6: 44025.48 | N6: 37864.44 | O6: 35978.76 | P6: 39412.35 | Q6: 38708.1 | R6: 30036.42 | S6: 33498.54 | T6: 25446.06
A7: 6 | B7: Perennial Cropland | C7: 4779.81 | D7: 6681.42 | E7: 10223.1 | F7: 8330.04 | G7: 5603.4 | H7: 18850.77 | I7: 17520.48 | J7: 18803.88 | K7: 14554.71 | L7: 6360.48 | M7: 22353.84 | N7: 13729.41 | O7: 11964.24 | P7: 14782.05 | Q7: 7883.28 | R7: 11994.57 | S7: 6354.99 | T7: 2055.87
A8: 7 | B8: Annual Cropland | C8: 139822.11 | D8: 150452.37 | E8: 142002.27 | F8: 151704.09 | G8: 150056.55 | H8: 135201.24 | I8: 156652.83 | J8: 171810.72 | K8: 193460.49 | L8: 177368.04 | M8: 175877.01 | N8: 189207.18 | O8: 167724.9 | P8: 172887.21 | Q8: 202905.36 | R8: 199438.47 | S8: 201826.62 | T8: 217047.06
A9: 8 | B9: Vegetated Wetland | C9: 11.07 | D9: 2.97 | E9: 35.64 | F9: 125.73 | G9: 534.42 | H9: 138.15 | I9: 2408.49 | J9: 195.93 | K9: 190.8 | L9: 334.62 | M9: 459.45 | N9: 688.59 | O9: 435.78 | P9: 0 | Q9: 0 | R9: 62.55 | S9: 50.94 | T9: 2.16
A10: 9 | B10: Open Water | C10: 51.3 | D10: 66.6 | E10: 51.12 | F10: 81 | G10: 90.81 | H10: 78.03 | I10: 166.86 | J10: 88.02 | K10: 125.91 | L10: 188.1 | M10: 191.88 | N10: 144.36 | O10: 251.73 | P10: 192.42 | Q10: 137.25 | R10: 98.91 | S10: 105.3 | T10: 162.9
A11: 10 | B11: Other land | C11: 1536.3 | D11: 1187.82 | E11: 376.47 | F11: 5028.3 | G11: 1295.01 | H11: 1911.69 | I11: 5695.92 | J11: 3788.28 | K11: 2463.03 | L11: 5479.56 | M11: 5621.49 | N11: 5107.14 | O11: 14478.93 | P11: 6368.4 | Q11: 8463.51 | R11: 7988.49 | S11: 4450.41 | T11: 4162.32
C12: =SUM(C2:C11) -> 303139.71
C15: moyenne 2015-2018 | D15: moyenne 1990-2000
A16: Sleek Class | B16: Land Cover
A17: 1 | B17: Dense Forest | C17: =AVERAGE(S2:T2) -> 24372.225 | D17: =AVERAGE(C2:E2) -> 26651.67 | E17: =C17-D17 -> -2279.445
A18: 2 | B18: Moderate Forest | C18: =AVERAGE(S3:T3) -> 2226.825 | D18: =AVERAGE(C3:E3) -> 779.43 | E18: =C18-D18 -> 1447.395
A19: 3 | B19: Open Forest | C19: =AVERAGE(S4:T4) -> 13428.675 | D19: =AVERAGE(C4:E4) -> 14310.03 | E19: =C19-D19 -> -881.355
A20: 4 | B20: Wooded Grassland | C20: =AVERAGE(S5:T5) -> 15530.4 | D20: =AVERAGE(C5:E5) -> 53540.61 | E20: =C20-D20 -> -38010.21
A21: 5 | B21: Open Grassland | C21: =AVERAGE(S6:T6) -> 29472.3 | D21: =AVERAGE(C6:E6) -> 55431.18 | E21: =C21-D21 -> -25958.88
A22: 6 | B22: Perennial Cropland | C22: =AVERAGE(S7:T7) -> 4205.43 | D22: =AVERAGE(C7:E7) -> 7228.11 | E22: =C22-D22 -> -3022.68
A23: 7 | B23: Annual Cropland | C23: =AVERAGE(S8:T8) -> 209436.84 | D23: =AVERAGE(C8:E8) -> 144092.25 | E23: =C23-D23 -> 65344.59
A24: 8 | B24: Vegetated Wetland | C24: =AVERAGE(S9:T9) -> 26.55 | D24: =AVERAGE(C9:E9) -> 16.56 | E24: =C24-D24 -> 9.99
A25: 9 | B25: Open Water | C25: =AVERAGE(S10:T10) -> 134.1 | D25: =AVERAGE(C10:E10) -> 56.34 | E25: =C25-D25 -> 77.76
A26: 10 | B26: Other land | C26: =AVERAGE(S11:T11) -> 4306.365 | D26: =AVERAGE(C11:E11) -> 1033.53 | E26: =C26-D26 -> 3272.835
A30: As % of opening area
B31: Dense Forest | E31: =(E17/D17)*100 -> -8.5527286
B32: Moderate Forest | E32: =(E18/D18)*100 -> 185.69916
B33: Open Forest | E33: =(E19/D19)*100 -> -6.1590018
B34: Wooded Grassland | E34: =(E20/D20)*100 -> -70.993233
B35: Open Grassland | E35: =(E21/D21)*100 -> -46.830827
B36: Perennial Cropland | E36: =(E22/D22)*100 -> -41.818401
B37: Annual Cropland | E37: =(E23/D23)*100 -> 45.349136
B38: Vegetated Wetland | E38: =(E24/D24)*100 -> 60.326087
B39: Open Water | E39: =(E25/D25)*100 -> 138.01917
B40: Other land | E40: =(E26/D26)*100 -> 316.6657

Sheet Busia
A1: Sleek Class | B1: Land Cover | C1: 1990 | D1: 1995 | E1: 2000 | F1: 2002 | G1: 2003 | H1: 2004 | I1: 2005 | J1: 2006 | K1: 2007 | L1: 2008 | M1: 2009 | N1: 2010 | O1: 2011 | P1: 2012 | Q1: 2013 | R1: 2014 | S1: 2015 | T1: 2018
A2: 1 | B2: Dense Forest | C2: 1261.8 | D2: 74.79 | E2: 1.98 | F2: 141.93 | G2: 7.74 | H2: 562.5 | I2: 46.44 | J2: 54.09 | K2: 15.84 | L2: 98.46 | M2: 18.27 | N2: 95.22 | O2: 71.64 | P2: 175.95 | Q2: 28.71 | R2: 816.93 | S2: 46.71 | T2: 166.14
A3: 2 | B3: Moderate Forest | C3: 225.9 | D3: 293.76 | E3: 4.23 | F3: 18.45 | G3: 0.99 | H3: 1.44 | I3: 3.24 | J3: 2.07 | K3: 5.58 | L3: 2.34 | M3: 0.81 | N3: 0 | O3: 698.4 | P3: 46.26 | Q3: 269.82 | R3: 30.87 | S3: 276.21 | T3: 610.47
A4: 3 | B4: Open Forest | C4: 4.86 | D4: 0 | E4: 9.09 | F4: 5.49 | G4: 13.05 | H4: 1.35 | I4: 11.43 | J4: 4.5 | K4: 78.75 | L4: 9.09 | M4: 0.09 | N4: 19.17 | O4: 35.73 | P4: 15.3 | Q4: 12.06 | R4: 0 | S4: 357.03 | T4: 179.46
A5: 4 | B5: Wooded Grassland | C5: 64739.16 | D5: 59156.28 | E5: 52812.09 | F5: 34289.73 | G5: 38564.82 | H5: 40976.01 | I5: 25092.72 | J5: 19683.36 | K5: 18932.22 | L5: 33415.2 | M5: 23161.5 | N5: 23937.21 | O5: 29050.56 | P5: 19940.76 | Q5: 9576.45 | R5: 22226.85 | S5: 27956.25 | T5: 22441.68
A6: 5 | B6: Open Grassland | C6: 8900.82 | D6: 15012.36 | E6: 13580.37 | F6: 20267.64 | G6: 17873.28 | H6: 13481.91 | I6: 15590.97 | J6: 1360.89 | K6: 2211.84 | L6: 3215.7 | M6: 4347.09 | N6: 2988.09 | O6: 13842.45 | P6: 13431.87 | Q6: 9639.9 | R6: 9605.79 | S6: 6779.79 | T6: 15373.71
A7: 6 | B7: Perennial Cropland | C7: 398.7 | D7: 568.8 | E7: 2556.99 | F7: 5382.36 | G7: 4019.22 | H7: 15285.96 | I7: 4508.82 | J7: 10800.27 | K7: 8891.37 | L7: 781.2 | M7: 2099.34 | N7: 2972.25 | O7: 5088.06 | P7: 7214.13 | Q7: 3823.11 | R7: 3081.24 | S7: 2665.26 | T7: 619.56
A8: 7 | B8: Annual Cropland | C8: 91357.02 | D8: 91621.35 | E8: 96192.81 | F8: 104738.22 | G8: 104217.3 | H8: 94991.04 | I8: 117004.32 | J8: 132488.1 | K8: 135314.91 | L8: 124110.72 | M8: 130686.48 | N8: 128795.67 | O8: 114077.25 | P8: 120749.58 | Q8: 138417.84 | R8: 128060.37 | S8: 123949.8 | T8: 124951.41
A9: 8 | B9: Vegetated Wetland | C9: 876.06 | D9: 1223.19 | E9: 2289.78 | F9: 1923.03 | G9: 2764.08 | H9: 1820.07 | I9: 4894.29 | J9: 3992.4 | K9: 2604.06 | L9: 5240.16 | M9: 6636.6 | N9: 8681.31 | O9: 4749.84 | P9: 4721.22 | Q9: 6223.59 | R9: 3889.44 | S9: 5559.84 | T9: 2081.7
A10: 9 | B10: Open Water | C10: 14413.68 | D10: 13857.3 | E10: 14567.85 | F10: 14737.23 | G10: 14567.76 | H10: 14412.51 | I10: 13929.39 | J10: 13883.85 | K10: 14037.48 | L10: 13844.7 | M10: 14321.88 | N10: 14195.34 | O10: 14194.8 | P10: 15562.53 | Q10: 14112.18 | R10: 14051.88 | S10: 14042.88 | T10: 14422.23
A11: 10 | B11: Other land | C11: 118.8 | D11: 488.97 | E11: 281.61 | F11: 792.72 | G11: 268.56 | H11: 764.01 | I11: 1215.18 | J11: 27.27 | K11: 204.75 | L11: 1579.23 | M11: 1024.74 | N11: 612.54 | O11: 488.07 | P11: 439.2 | Q11: 193.14 | R11: 533.43 | S11: 663.03 | T11: 1450.44
C12: =SUM(C2:C11) -> 182296.8
C15: moyenne 2015-2018 | D15: moyenne 1990-2000
A16: Sleek Class | B16: Land Cover
A17: 1 | B17: Dense Forest | C17: =AVERAGE(S2:T2) -> 106.425 | D17: =AVERAGE(C2:E2) -> 446.19 | E17: =C17-D17 -> -339.765
A18: 2 | B18: Moderate Forest | C18: =AVERAGE(S3:T3) -> 443.34 | D18: =AVERAGE(C3:E3) -> 174.63 | E18: =C18-D18 -> 268.71
A19: 3 | B19: Open Forest | C19: =AVERAGE(S4:T4) -> 268.245 | D19: =AVERAGE(C4:E4) -> 4.65 | E19: =C19-D19 -> 263.595
A20: 4 | B20: Wooded Grassland | C20: =AVERAGE(S5:T5) -> 25198.965 | D20: =AVERAGE(C5:E5) -> 58902.51 | E20: =C20-D20 -> -33703.545
A21: 5 | B21: Open Grassland | C21: =AVERAGE(S6:T6) -> 11076.75 | D21: =AVERAGE(C6:E6) -> 12497.85 | E21: =C21-D21 -> -1421.1
A22: 6 | B22: Perennial Cropland | C22: =AVERAGE(S7:T7) -> 1642.41 | D22: =AVERAGE(C7:E7) -> 1174.83 | E22: =C22-D22 -> 467.58
A23: 7 | B23: Annual Cropland | C23: =AVERAGE(S8:T8) -> 124450.6 | D23: =AVERAGE(C8:E8) -> 93057.06 | E23: =C23-D23 -> 31393.545
A24: 8 | B24: Vegetated Wetland | C24: =AVERAGE(S9:T9) -> 3820.77 | D24: =AVERAGE(C9:E9) -> 1463.01 | E24: =C24-D24 -> 2357.76
A25: 9 | B25: Open Water | C25: =AVERAGE(S10:T10) -> 14232.555 | D25: =AVERAGE(C10:E10) -> 14279.61 | E25: =C25-D25 -> -47.055
A26: 10 | B26: Other land | C26: =AVERAGE(S11:T11) -> 1056.735 | D26: =AVERAGE(C11:E11) -> 296.46 | E26: =C26-D26 -> 760.275
A30: As % of opening area
B31: Dense Forest | E31: =(E17/D17)*100 -> -76.148054
B32: Moderate Forest | E32: =(E18/D18)*100 -> 153.8739
B33: Open Forest | E33: =(E19/D19)*100 -> 5668.7097
B34: Wooded Grassland | E34: =(E20/D20)*100 -> -57.2192
B35: Open Grassland | E35: =(E21/D21)*100 -> -11.370756
B36: Perennial Cropland | E36: =(E22/D22)*100 -> 39.799801
B37: Annual Cropland | E37: =(E23/D23)*100 -> 33.735801
B38: Vegetated Wetland | E38: =(E24/D24)*100 -> 161.15816
B39: Open Water | E39: =(E25/D25)*100 -> -0.32952581
B40: Other land | E40: =(E26/D26)*100 -> 256.45112

Sheet Elgeyo-Marakwet
A1: Sleek Class | B1: Land Cover | C1: 1990 | D1: 1995 | E1: 2000 | F1: 2002 | G1: 2003 | H1: 2004 | I1: 2005 | J1: 2006 | K1: 2007 | L1: 2008 | M1: 2009 | N1: 2010 | O1: 2011 | P1: 2012 | Q1: 2013 | R1: 2014 | S1: 2015 | T1: 2018
A2: 1 | B2: Dense Forest | C2: 69822.09 | D2: 61745.58 | E2: 68458.59 | F2: 72280.89 | G2: 70411.5 | H2: 62026.38 | I2: 69168.6 | J2: 67988.34 | K2: 61152.57 | L2: 59402.7 | M2: 66240.09 | N2: 73211.76 | O2: 62045.19 | P2: 65237.13 | Q2: 56861.46 | R2: 68483.61 | S2: 64450.8 | T2: 61567.74
A3: 2 | B3: Moderate Forest | C3: 21809.79 | D3: 39234.15 | E3: 7145.46 | F3: 7707.33 | G3: 6425.46 | H3: 9459.54 | I3: 6593.13 | J3: 9156.78 | K3: 21434.4 | L3: 12484.53 | M3: 7803.63 | N3: 9361.62 | O3: 17672.22 | P3: 16190.1 | Q3: 15568.2 | R3: 6877.62 | S3: 4901.58 | T3: 2317.41
A4: 3 | B4: Open Forest | C4: 1464.93 | D4: 3097.62 | E4: 1221.48 | F4: 3568.14 | G4: 1390.32 | H4: 4504.95 | I4: 2372.31 | J4: 2396.25 | K4: 9092.79 | L4: 1949.22 | M4: 2775.69 | N4: 566.19 | O4: 2858.13 | P4: 1523.7 | Q4: 2109.33 | R4: 1257.66 | S4: 1479.51 | T4: 1493.46
A5: 4 | B5: Wooded Grassland | C5: 143162.46 | D5: 136140.75 | E5: 135177.3 | F5: 108267.66 | G5: 134869.86 | H5: 112864.5 | I5: 120763.35 | J5: 113760.54 | K5: 110570.58 | L5: 122025.96 | M5: 124833.06 | N5: 122238.18 | O5: 110697.84 | P5: 117159.03 | Q5: 101788.11 | R5: 120943.62 | S5: 115790.22 | T5: 109074.78
A6: 5 | B6: Open Grassland | C6: 54985.86 | D6: 47356.2 | E6: 54364.68 | F6: 50222.34 | G6: 66399.57 | H6: 52001.73 | I6: 36400.23 | J6: 40221.9 | K6: 23793.39 | L6: 28936.44 | M6: 23513.67 | N6: 35198.19 | O6: 39713.04 | P6: 32529.15 | Q6: 39478.68 | R6: 32560.29 | S6: 24448.86 | T6: 29309.49
A7: 6 | B7: Perennial Cropland | C7: 57.6 | D7: 434.7 | E7: 262.98 | F7: 650.43 | G7: 256.86 | H7: 1341.27 | I7: 358.65 | J7: 1673.37 | K7: 1492.02 | L7: 520.29 | M7: 1019.43 | N7: 938.43 | O7: 410.13 | P7: 1070.01 | Q7: 676.71 | R7: 1233.99 | S7: 979.83 | T7: 782.46
A8: 7 | B8: Annual Cropland | C8: 10273.77 | D8: 12985.11 | E8: 34930.62 | F8: 58041.9 | G8: 21705.3 | H8: 58729.41 | I8: 65627.73 | J8: 65605.41 | K8: 73824.48 | L8: 75588.75 | M8: 75074.31 | N8: 59477.49 | O8: 67686.48 | P8: 67603.86 | Q8: 84661.2 | R8: 69640.47 | S8: 88785.99 | T8: 95940.9
A9: 8 | B9: Vegetated Wetland | C9: 6.84 | D9: 286.29 | E9: 22.86 | F9: 301.86 | G9: 23.4 | H9: 305.19 | I9: 93.15 | J9: 311.94 | K9: 97.74 | L9: 0 | M9: 178.92 | N9: 99.09 | O9: 170.64 | P9: 72.27 | Q9: 137.43 | R9: 136.89 | S9: 0 | T9: 0
A10: 9 | B10: Open Water | C10: 37.35 | D10: 27.36 | E10: 33.12 | F10: 164.43 | G10: 130.41 | H10: 82.35 | I10: 175.41 | J10: 76.23 | K10: 117.99 | L10: 198.54 | M10: 78.39 | N10: 154.44 | O10: 94.14 | P10: 80.46 | Q10: 118.89 | R10: 141.48 | S10: 137.16 | T10: 221.13
A11: 10 | B11: Other land | C11: 86.85 | D11: 399.78 | E11: 90.45 | F11: 502.56 | G11: 94.86 | H11: 392.22 | I11: 154.98 | J11: 516.78 | K11: 131.58 | L11: 601.11 | M11: 190.35 | N11: 462.15 | O11: 359.73 | P11: 241.83 | Q11: 307.53 | R11: 431.91 | S11: 733.59 | T11: 1000.17
C12: =SUM(C2:C11) -> 301707.54
C15: moyenne 2015-2018 | D15: moyenne 1990-2000
A16: Sleek Class | B16: Land Cover
A17: 1 | B17: Dense Forest | C17: =AVERAGE(S2:T2) -> 63009.27 | D17: =AVERAGE(C2:E2) -> 66675.42 | E17: =C17-D17 -> -3666.15
A18: 2 | B18: Moderate Forest | C18: =AVERAGE(S3:T3) -> 3609.495 | D18: =AVERAGE(C3:E3) -> 22729.8 | E18: =C18-D18 -> -19120.305
A19: 3 | B19: Open Forest | C19: =AVERAGE(S4:T4) -> 1486.485 | D19: =AVERAGE(C4:E4) -> 1928.01 | E19: =C19-D19 -> -441.525
A20: 4 | B20: Wooded Grassland | C20: =AVERAGE(S5:T5) -> 112432.5 | D20: =AVERAGE(C5:E5) -> 138160.17 | E20: =C20-D20 -> -25727.67
A21: 5 | B21: Open Grassland | C21: =AVERAGE(S6:T6) -> 26879.175 | D21: =AVERAGE(C6:E6) -> 52235.58 | E21: =C21-D21 -> -25356.405
A22: 6 | B22: Perennial Cropland | C22: =AVERAGE(S7:T7) -> 881.145 | D22: =AVERAGE(C7:E7) -> 251.76 | E22: =C22-D22 -> 629.385
A23: 7 | B23: Annual Cropland | C23: =AVERAGE(S8:T8) -> 92363.445 | D23: =AVERAGE(C8:E8) -> 19396.5 | E23: =C23-D23 -> 72966.945
A24: 8 | B24: Vegetated Wetland | C24: =AVERAGE(S9:T9) -> 0 | D24: =AVERAGE(C9:E9) -> 105.33 | E24: =C24-D24 -> -105.33
A25: 9 | B25: Open Water | C25: =AVERAGE(S10:T10) -> 179.145 | D25: =AVERAGE(C10:E10) -> 32.61 | E25: =C25-D25 -> 146.535
A26: 10 | B26: Other land | C26: =AVERAGE(S11:T11) -> 866.88 | D26: =AVERAGE(C11:E11) -> 192.36 | E26: =C26-D26 -> 674.52
A30: As % of opening area
B31: Dense Forest | E31: =(E17/D17)*100 -> -5.498503
B32: Moderate Forest | E32: =(E18/D18)*100 -> -84.119988
B33: Open Forest | E33: =(E19/D19)*100 -> -22.900555
B34: Wooded Grassland | E34: =(E20/D20)*100 -> -18.621626
B35: Open Grassland | E35: =(E21/D21)*100 -> -48.542402
B36: Perennial Cropland | E36: =(E22/D22)*100 -> 249.99404
B37: Annual Cropland | E37: =(E23/D23)*100 -> 376.18614
B38: Vegetated Wetland | E38: =(E24/D24)*100 -> -100
B39: Open Water | E39: =(E25/D25)*100 -> 449.35603
B40: Other land | E40: =(E26/D26)*100 -> 350.65502

Sheet Embu
A1: Sleek Class | B1: Land Cover | C1: 1990 | D1: 1995 | E1: 2000 | F1: 2002 | G1: 2003 | H1: 2004 | I1: 2005 | J1: 2006 | K1: 2007 | L1: 2008 | M1: 2009 | N1: 2010 | O1: 2011 | P1: 2012 | Q1: 2013 | R1: 2014 | S1: 2015 | T1: 2018
A2: 1 | B2: Dense Forest | C2: 31489.29 | D2: 25915.23 | E2: 28895.13 | F2: 28483.47 | G2: 22853.16 | H2: 24003 | I2: 28755.63 | J2: 25171.83 | K2: 25241.31 | L2: 27346.05 | M2: 26835.66 | N2: 23246.82 | O2: 36902.16 | P2: 27445.14 | Q2: 27986.58 | R2: 30097.62 | S2: 24934.05 | T2: 25615.08
