Workbook

Sheet Introduction
B2: Uganda Bureau of Statistics
B3: Draft Water Accounts Framework
B4: 27/9/2017
B5: For comment
B6: Drafted by Jackie Crafford, j.crafford@primeafrica.net
B8: This draft structure of Water Accounts for Uganda was constructed based on the UN SEEA Central Framwork recommendations, as well as the structure of the Uganda Supply and Use Tables.
B9: The structure of the water accounts need to be revised an updated during the development of the first draft set of water accounts, and is subject to data availability and the strcuture of the Uganda water economy.
B10: It is proposed that Water Asset Accounts are premature at this stage, and should follow at a later stage.
B11: The following steps to completion of Water Accounts are proposed:
B12: 1. Redesign Water Accounts Architechture | C12: Completed
A13: Iterative approach | B13: 2. Note to confirm classification (nomenclature) of Tables 1, 2 and 3 as we start populating data - it is possible that classification of T1 may be different to T2 and T3.
B14: 3. Populate Table 1 using physical flow data from various sources
B15: 4. Populate Table 3 using monetary data principally from UBOS
B16: 5. Complete Water Price Table 4 in order to bridge Tables 1 and 3
B17: 6. Complete Table 2 (we may have independent data sets for Table 2)
B18: 7. Develop Meta-data description & data quality assessment
B19: 8. Develop back-working tables, links and do balancing of all tables
B20: 9. Fill in Tables 5 & 6
B21: 10. Develop key indicators
B24: Notes:
B25: Classification of hydrological (water) assets
B27: Rivers | F27: Surface water (Rivers, wetlands, dams, estuaries)
B28: Wetlands and swamps | F28: Groundwater (springs, fountains, wells, soil water)
B29: Dams | F29: Rainwater (harvested)
B30: Lakes
B31: Springs, fountains, wells
B32: Rainwater (harvested)

Sheet Meta data
A1: Impotant notes/assumptions for estimations and reconciliation | H1: National % of hh abstracting by source type, 2014 census
A2: 1. Rural/urban domestic and rural/urban supply purposes has been used as a proxy for Rural Water Supply, i.e, all abstraction for ss/distn purposes that is not NWSC, is assumed RWS. | D2: 2015 License daily amount- Gabba plant | E2: 250000 | I2: 2002 | M2: 2014
A3: 1.1 Assumed that 80% of this RWS is for domestic consumption, 5% for Public Admin, 5% for Health, 3% for Accomodation, 4% for Other and 3% for Education.
A4: 2. NWSC paid a license for only Gabba plant for 2015 of 25000 cubic metres per day, equivalent to 91,250,000 cubic metres.- Ignored | E4: 365 | H4: Water source | I4: Urban | J4: Rural | K4: Total | M4: Urban | N4: Rural | O4: Total
A5: 3. From NAS, NWSC provided data indicating that it produced 103,523,325 cubic metres of water for 2015- Used to compile acs | D5: 2015 License amount- Gabba plant | E5: =E4*E2 -> 91250000 | H5: Safe Sources | I5: 93 | J5: 55.6 | K5: 60.9 | M5: 84.7 | N5: 65.9 | O5: 71.2 | P5: =100-O5 -> 28.8
A6: 4. From prevoius records, Kampala water pdn by NWSC accounts for about 65% of total water pdn by NWSC | D6: NAS data records for 2015 water pdn | E6: 1.0352333e+08 | H6: Piped Water | I6: 58.5 | J6: 3.9 | K6: 11.5 | M6: 51.9 | N6: 7.2 | O6: 19.7
A7: 5. Therefore, 36,233,164 cubic metres were producde by NWSC for other areas. | D7: Assummed pdn for other areas- A1 | E7: =E6-E5 -> 12273326 | H7: Borehole | I7: 12.4 | J7: 26 | K7: 24.1 | M7: 16.6 | N7: 40.2 | O7: 33.6
A8: 6. Therefore, total abstraction as lincensed by DWRM have been adjusted to add the difference between data in 3. and 2. above | E8: =E6-E10 -> 36233164 | H8: Protected String/Well | I8: 20.7 | J8: 22.7 | K8: 22.5 | M8: 14.9 | N8: 17 | O8: 16.4
A9: 7. Breakdwon for bills by of NWSC for supplies by industry/ institutionsl unit were used to estimate amount supplied. Assumed that amount supplied includes thefts by hh. Phsyical losses not recognised as supplies bse no ss is made. | D9: Kampala pdn to toal pdn-% | E9: 0.65 | H9: GFS | I9: 1.4 | J9: 3 | K9: 2.8 | M9: 0.8 | N9: 1.4 | O9: 1.2
A10: 8. Use IC water % by industry for SUT 2009/10 to breakdwon the NWSC supplies to industries. | D10: Estimated Kampala pdn to toal pdn-Volume | E10: =E6*0.65 -> 67290162 | H10: Bottled Water | I10: - | J10: - | M10: 0.5 | N10: 0.1 | O10: 0.2
A11: 9. Control total for water use/IC in water balance table for NWSC column is water sold by NWSC. | D11: Assummed pdn for other areas- A2 | E11: =E6-E10 -> 36233164 | H11: Unsafe sources | I11: 6.8 | J11: 44.4 | K11: 39.1 | M11: 15.3 | N11: 34 | O11: 28.8
A12: 10. Control total for water distribution for NWSC row is water supply for NWSC.
A13: 11. Distribution ratios for 9 above are from USE table of 2009/10 SUT. | D13: From SUT 2009/10 | E13: million shillings | F13: % share | G13: NWSC | H13: RWS
A14: 12. Distribution ratios for 10 above are from USE table of 2009/10 SUT and NWSC annual reports. | D14: Intermediate consumption for water- Industries | E14: ='[1]Final SUT'!$FQ$274 -> 45344.837 | F14: =E14/$E$34*100 -> 5.3050843 | I14: Estimation for Vol of water supplied from community schemes, M3
A15: 13. Assumed that 42.68% of the water consumed by hh is from commuity schemes (boreholes, protected wells/springs and gravitational flow), 28% is from own supply . Impying that 28.42% of the water consumed by HH is from NWSC and RWS. Seems realistic since 78.6% of the population is rural. | D15: Agriculture (Rainfed crops) | E15: 0 | F15: =E15/$E$34*100 -> 0 | I15: Community Schemes | J15: National % hh abstracting by source type, 2014 census
A16: 14. 90 % of the water abstracted via community schemes is for hh consumption and 100% abtsracted via own supply is for hh consumption. | D16: Agriculture (Livestock) | E16: =SUM('[1]Final SUT'!$AS$274:$BD$274) -> 16003.038 | F16: =E16/$E$34*100 -> 1.8722631 | I16: =H7 -> Borehole | J16: =0.75*O7 -> 25.2 | L16: Assumed that 0.25 of the boreholes are under RWS
A17: 15. Assumed that all water in valley tanks and earth dams is for livestock, despite the neglieable vol used for hh consumption, aquaculture and irrigation. | D17: Forestry | E17: 0 | F17: =E17/$E$34*100 -> 0 | I17: =H8 -> Protected String/Well | J17: =O8 -> 16.4
A18: 16. All water licenses in the database are permanently active from the year of first permit on wards. | D18: Fishing | E18: 0 | F18: =E18/$E$34*100 -> 0 | I18: =H9 -> GFS | J18: =O9*0.9 -> 1.08 | L18: Assumed that 0.10 of the GFS are under RWS and NWSC
A19: 17. Annual maintainence fee formotorised borhole is between 2 million shs to 15 million shs. | D19: Crude oil and Mining | E19: =SUM('[1]Final SUT'!$BM$274:$BO$274) -> 753.57475 | F19: =E19/$E$34*100 -> 0.088163899 | J19: =SUM(J16:J18) -> 42.68
A20: 18. For RWS and Community schemes, there is a charge per institutional unit of about 1,000 UGX per month. | B20: Monthly charge | C20: 1000 | D20: Manufacturing (Food and beverages) | E20: =SUM('[1]Final SUT'!$BP$274:$CD$274) -> 6933.5085 | F20: =E20/$E$34*100 -> 0.8111805
B21: months | C21: 12 | D21: Manufacturing (Non-food) | E21: =SUM('[1]Final SUT'!$CE$274:$DF$274) -> 3502.1025 | F21: =E21/$E$34*100 -> 0.40972579 | I21: 42.68 % of hh water consumption is from Community schemes. Seems justified since 78.6 % of the popn is rural.
B22: % of hh served | C22: =J19 -> 42.68 | D22: Electricity, Gas, Steam & Air Conditioning Supply | E22: ='[1]Final SUT'!$DG$274 -> 126.34762 | F22: =E22/$E$34*100 -> 0.014781943 | I22: =H11 -> Unsafe sources | J22: =O11 -> 28.8 | K22: Assumed % of hh that have own supply. | X22: Revised estimate | AA22: By source type
B23: Number of hh | C23: 7306000 | D23: Construction | E23: =SUM('[1]Final SUT'!$DI$274:$DL$274) -> 1057.9593 | F23: =E23/$E$34*100 -> 0.12377513 | P23: % | Q23: 000M3 | U23: By source type | AA23: Surface water | AB23: Ground water
B24: No.of households served | C24: =C23*C22/100 -> 3118200.8 | D24: Accommodation | E24: =SUM('[1]Final SUT'!$DW$274:$DX$274) -> 1577.648 | F24: =E24/$E$34*100 -> 0.18457571 | I24: HH consumption of water , '000m3 | O24: NWSC | P24: =Q24/Q29*100 -> 26.832303 | Q24: ='Table 1 Water Input table'!J47 -> 2.3485589e+08 | R24: =Q24/R26*100 -> 94.082409 | U24: Surface water | V24: Ground water | X24: =Q24 -> 2.3485589e+08 | Y24: =X24/$X$29 -> 0.37652422
B25: % of hh which pay | C25: 0.4 | D25: Public Administration | E25: ='[1]Final SUT'!$EZ$274 -> 7647.9418 | F25: =E25/$E$34*100 -> 0.89476507 | I25: NWSC | J25: ='Table 1 Water Input table'!J77 -> 6905559.4 | O25: RWS, Other urban | P25: =Q25/Q29*100 -> 1.6876971 | Q25: ='Table 1 Water Input table'!L47+'Table 1 Water Input table'!K47 -> 14771956 | R25: =Q25/R26*100 -> 5.9175914 | X25: =Q25 -> 14771956 | Y25: =X25/$X$29 -> 0.023682605
C26: =C24*C25 -> 1247280.3 | D26: Education | E26: =SUM('[1]Final SUT'!$FB$274:$FE$274) -> 907.26537 | F26: =E26/$E$34*100 -> 0.10614482 | I26: RWS | J26: ='Table 1 Water Input table'!AE58 -> 2814289.4 | O26: Comm.schemes | P26: =J19 -> 42.68 | Q26: =P26*S27 -> 3.7356649e+08 | R26: =Q24+Q25 -> 2.4962784e+08 | S26: =100-P26-P27 -> 28.52 | U26: =Q26*Q32 -> 3.7350825e+08 | V26: =Q26-U26 -> 58236.065 | X26: =Q26 -> 3.7356649e+08 | Y26: =X26/$X$29 -> 0.59890699 | AA26: =X26*Q32 -> 3.7350825e+08 | AB26: =Q26-AA26 -> 58236.065
C27: =C26*C21*C20 -> 14967363840 | D27: Health | E27: =SUM('[1]Final SUT'!$FF$274:$FG$274) -> 1795.1517 | F27: =E27/$E$34*100 -> 0.21002239 | J27: =SUM(J25:J26) -> 9719848.9 | K27: =100-J19 -> 57.32 | O27: Own supply | P27: =O11 -> 28.8 | Q27: =P27*S27 -> 2.5207861e+08 | S27: =R26/S26 -> 8752729.4 | U27: =Q27*Q32 -> 2.5203931e+08 | V27: =Q27-U27 -> 39297.063 | X27: 552754.03 | Y27: =X27/$X$29 -> 0.00088618294 | AA27: =X27*Q32 -> 552667.86 | AB27: 0
C28: ='Table 1 Water Input table'!M42+'Table 1 Water Input table'!M43 -> 0 | D28: Other | E28: ='[1]Final SUT'!$DH$274+SUM('[1]Final SUT'!$DM$274:$DV$274)+SUM('[1]Final SUT'!$DY$274:$EY$274)+'[1]Final SUT'!$FA$274+SUM('[1]Final SUT'!$FH$274:$FP$274) -> 5040.299 | F28: =E28/$E$34*100 -> 0.58968591 | I28: Community schemes | J28: =J27/K27*J19 -> 7237319.4 | K28: =J28/J29 -> 0.4268 | O28: Precipitation | P28: =5.5/12 -> 0.45833333 | Q28: =Q27*P28 -> 1.1553603e+08 | X28: =Q28 -> 1.1553603e+08
C29: =C27/C28 -> #DIV/0! | D29: Final Consumption | E29: =E30+E33 -> 809398.16 | F29: =E29/$E$34*100 -> 94.694916 | J29: =J28+J27 -> 16957168 | O29: Total water | Q29: =SUM(Q24:Q27) -> 8.7527294e+08 | X29: =SUM(X24:X27) -> 6.2374709e+08
D30: Households | E30: ='[1]Final SUT'!$FT$274 -> 809398.16 | F30: =E30/$E$34*100 -> 94.694916 | S30: =Q27-Q28 -> 1.3654258e+08
B31: Daily water usage/ hh, Litres | C31: =5*20 -> 100 | D31: Market | E31: 183281.46 | F31: =E31/$E$34*100 -> 21.442874 | O31: Ratios for source type
B32: Monthly water used, litres | C32: =30*C31 -> 3000 | D32: Non Market | E32: 626116.7 | F32: =E32/$E$34*100 -> 73.252042 | O32: Surface | P32: ='Table 1 Water Input table'!I42 -> 1.1058278e+11 | Q32: =P32/P34 -> 0.99984411
B33: Annual water used, litres | C33: =C32*12 -> 36000 | D33: Exports | E33: 0 | F33: =E33/$E$34*100 -> 0 | O33: Ground | P33: ='Table 1 Water Input table'!I43 -> 17241670 | Q33: =P33/P34 -> 0.0001558921
B34: Annual water used, m3 | C34: =C33*0.001 -> 36 | D34: Total Economy | E34: =E30+E14 -> 854743 | P34: =SUM(P32:P33) -> 1.1060002e+11
B35: Annual charge | C35: =C20*12 -> 12000 | I35: Assumed ratios for distribution
B36: Charge/ m3 | C36: =C35/C34 -> 333.33333 | J36: Comm. scheme | K36: Own ss
I37: Mining | J37: 0.05 | K37: 0.05
D38: Suggested breakdown for water ss from RWS | I38: Construction | J38: 0.25 | K38: 0.3
D39: Construction | E39: 0.01 | I39: Other | J39: 0.1 | K39: 0.05
D40: Manufacturing | E40: 0 | I40: Household | J40: 0.6 | K40: 0.6
...

Sheet Table 2 Ph IO Table
A1: Table 2. Physical Accounts (million m3) | B1: Note | C1: =A3 -> From the Environment | J1: Distribution (Water, Sewerage) | O1: Use of Water (IC) | AD1: Final consumption | AF1: Return flows
C2: Rivers | D2: Wetlands and swamps | E2: Dams | F2: Lakes | G2: Springs, fountains, wells | H2: Rainwater (harvested) | I2: =B9 -> Soil water | J2: DWRM | K2: NWSC | L2: RWS | M2: Community Schemes | N2: Own Supply | O2: Agriculture (Irrigation) | P2: Agriculture (Rainfed crops) | Q2: Agriculture (Livestock) | R2: Forestry | S2: Fishing | T2: Crude oil and Mining | U2: Manufacturing (Food and beverages) | V2: Manufacturing (Non-food) | W2: Electricity, Gas, Steam & Air Conditioning Supply | X2: Construction | Y2: Accommodation | Z2: Public Administration | AA2: Education | AB2: Health | AC2: Other | AD2: Households | AE2: Exports | AF2: Surface Water | AG2: Other
A3: From the Environment | B3: Rivers | J3: XXX | M3: XXX | N3: XXX | Q3: XXX | S3: XXX | AD3: XXX
B4: Wetlands and swamps | M4: XXX | N4: XXX | Q4: XXX | AD4: XXX
B5: Dams | M5: XXX | N5: XXX | Q5: XXX | S5: XXX | AD5: XXX
B6: Lakes | J6: XXX | N6: XXX | Q6: XXX | AD6: XXX
B7: Springs, fountains, wells | J7: XXX | M7: XXX | N7: XXX | Q7: XXX | S7: XXX | AD7: XXX
B8: Rainwater (harvested & precipitation) | N8: XXX | Q8: XXX | AD8: XXX
B9: Soil water | P9: XXX | R9: XXX
A10: Distribution | B10: DWRM | K10: XXX | L10: XXX | O10: XXX | T10: XXX | U10: XXX | V10: XXX | W10: XXX | X10: XXX | Z10: XXX | AA10: XXX | AB10: XXX | AC10: XXX | AE10: 0
A11: (Water, Sewerage) | B11: NWSC | T11: XXX? | U11: XXX | V11: XXX | W11: XXX | X11: XXX | Y11: XXX | Z11: XXX | AA11: XXX | AB11: XXX | AC11: XXX | AF11: XXX
B12: RWS | T12: XXX? | U12: XXX | V12: XXX | W12: XXX? | X12: XXX | Y12: XXX | Z12: XXX | AA12: XXX | AB12: XXX | AC12: XXX
B13: Community Schemes | T13: XXX | X13: XXX | AC13: XXX | AF13: XXX
B14: Own Supply | T14: XXX | X14: XXX | AC14: XXX
A15: Use of Water (IC) | B15: Agriculture (Irrigation) | AF15: XXX
B16: Agriculture (Rainfed crops)
B17: Agriculture (Livestock)
B18: Forestry
B19: Fishing
B20: Crude oil and Mining | AG20: XXX
B21: Manufacturing (Food and beverages) | K21: XXX | AF21: XXX
B22: Manufacturing (Non-food) | K22: XXX | AF22: XXX
B23: Electricity, Gas, Steam & Air Conditioning Supply | K23: XXX | AF23: XXX
B24: Construction | K24: XXX
B25: Accommodation | K25: XXX
B26: Public Administration | K26: XXX
B27: Education | K27: XXX
B28: Health | K28: XXX
B29: Other | K29: XXX
A30: Final consumption | B30: Households | K30: XXX
B31: Exports
A32: Return flows | B32: Surface Water
B33: Other

Sheet Table 3 Mon IO Table
A2: T3. Monetary values (Million UGX) | C2: =A5 -> From the Environment | J2: Distribution (Water, Sewerage) | O2: Use of Water (IC) | AD2: Final consumption | AH2: Return flows | AJ2: Total
C3: Rivers | D3: Wetlands and swamps | E3: Dams | F3: Lakes | G3: Springs, fountains, wells | H3: Rainwater (harvested) | I3: =B11 -> Soil water | J3: DWRM | K3: NWSC | L3: RWS | M3: Community Schemes | N3: Own Supply | O3: Agriculture (Irrigation) | P3: Agriculture (Rainfed crops) | Q3: Agriculture (Livestock) | R3: Forestry | S3: Fishing | T3: Crude oil and Mining | U3: Manufacturing (Food and beverages) | V3: Manufacturing (Non-food) | W3: Electricity, Gas, Steam & Air Conditioning Supply | X3: Construction | Y3: Accommodation | Z3: Public Administration | AA3: Education | AB3: Health | AC3: Other | AD3: Households | AG3: Exports | AH3: Surface Water | AI3: Other
AD4: Marketed | AE4: Own Acct. | AF4: Gift/Received
A5: From the Environment | B5: Rivers
B6: Wetlands and swamps
B7: Dams
B8: Lakes
B9: Springs, fountains, wells
B10: Rainwater (harvested & precipitation)
B11: Soil water
A12: Distribution | B12: DWRM | K12: ='Table 4 Water Prices'!K11 -> 26494000 | L12: ='Table 4 Water Prices'!L11 -> 32434000 | M12: ='Table 4 Water Prices'!M11 -> 13140000 | O12: ='Table 4 Water Prices'!P11 -> 4059000 | T12: ='Table 4 Water Prices'!U11 -> 48282000 | U12: ='Table 4 Water Prices'!V11 -> 95326000 | V12: ='Table 4 Water Prices'!W11 -> 20367000 | W12: ='Table 4 Water Prices'!X11 -> 49931000 | X12: ='Table 4 Water Prices'!Y11 -> 86615000 | Y12: ='Table 4 Water Prices'!Z11 -> 11142000 | AA12: ='Table 4 Water Prices'!AB11 -> 5694000 | AB12: ='Table 4 Water Prices'!AC11 -> 2628000 | AC12: ='Table 4 Water Prices'!AD11 -> 8322000 | AG12: 0
A13: (Water, Sewerage) | B13: NWSC | T13: ='Table 4 Water Prices'!U12*'Table 1 Water Input table'!T56*1000 -> 6.3514134e+12 | U13: ='Table 4 Water Prices'!V12*'Table 1 Water Input table'!U56*1000 -> 4.6563574e+13 | V13: ='Table 4 Water Prices'!W12*'Table 1 Water Input table'!V56*1000 -> 2.9442198e+13 | W13: ='Table 4 Water Prices'!X12*'Table 1 Water Input table'!W56*1000 -> 1.0649056e+12 | X13: ='Table 4 Water Prices'!Y12*'Table 1 Water Input table'!Y56*1000 -> 8.8942704e+12 | Y13: ='Table 4 Water Prices'!Z12*'Table 1 Water Input table'!Z56*1000 -> 1.3297015e+13 | Z13: ='Table 4 Water Prices'!AA12*'Table 1 Water Input table'!AA56*1000 -> 8.7488772e+13 | AA13: ='Table 4 Water Prices'!AB12*'Table 1 Water Input table'!AB56*1000 -> 5.4206564e+12 | AB13: ='Table 4 Water Prices'!AC12*'Table 1 Water Input table'!AC56*1000 -> 1.2348121e+13 | AC13: ='Table 4 Water Prices'!AD12*'Table 1 Water Input table'!AD56*1000 -> 3.4670174e+13 | AD13: ='Table 4 Water Prices'!AE12*'Table 1 Water Input table'!AE56*1000 -> 2.2719906e+14
B14: Other Urban/DWD | T14: ='Table 4 Water Prices'!U13*'Table 1 Water Input table'!T57*1000 -> 0 | U14: ='Table 4 Water Prices'!V13*'Table 1 Water Input table'!U57*1000 -> 5.4092109e+10 | V14: ='Table 4 Water Prices'!W13*'Table 1 Water Input table'!V57*1000 -> 2.7321826e+10 | W14: ='Table 4 Water Prices'!X13*'Table 1 Water Input table'!W57*1000 -> 9.8570724e+08 | X14: ='Table 4 Water Prices'!Y13*'Table 1 Water Input table'!Y57*1000 -> 8.2537216e+09 | Y14: ='Table 4 Water Prices'!Z13*'Table 1 Water Input table'!Z57*1000 -> 1.2308099e+10 | Z14: ='Table 4 Water Prices'!AA13*'Table 1 Water Input table'!AA57*1000 -> 0 | AA14: ='Table 4 Water Prices'!AB13*'Table 1 Water Input table'!AB57*1000 -> 7.0780757e+09 | AB14: ='Table 4 Water Prices'!AC13*'Table 1 Water Input table'!AC57*1000 -> 1.4004965e+10 | AC14: ='Table 4 Water Prices'!AD13*'Table 1 Water Input table'!AD57*1000 -> 3.9322142e+10 | AD14: ='Table 4 Water Prices'!AE13*'Table 1 Water Input table'!AE57*1000 -> 6.4779264e+12
B15: RWS | Y15: ='Table 4 Water Prices'!Z14*'Table 1 Water Input table'!Z58*1000 -> 3.5178618e+10 | Z15: ='Table 4 Water Prices'!AA14*'Table 1 Water Input table'!AA58*1000 -> 23452412000 | AA15: ='Table 4 Water Prices'!AB14*'Table 1 Water Input table'!AB58*1000 -> 5.863103e+10 | AB15: ='Table 4 Water Prices'!AC14*'Table 1 Water Input table'!AC58*1000 -> 5.863103e+10 | AC15: ='Table 4 Water Prices'!AD14*'Table 1 Water Input table'!AD58*1000 -> 46904824000 | AD15: ='Table 4 Water Prices'!AE14*'Table 1 Water Input table'!AE58*1000 -> 9.3809648e+11 | AE15: ='Table 4 Water Prices'!AF13*'Table 1 Water Input table'!AG57*1000 -> 0 | AF15: ='Table 4 Water Prices'!AG13*'Table 1 Water Input table'!AI57*1000 -> 0
B16: Community Schemes | T16: ='Table 4 Water Prices'!U15*'Table 1 Water Input table'!T59*1000 -> 0 | X16: ='Table 4 Water Prices'!Y15*'Table 1 Water Input table'!Y59*1000 -> 0 | AC16: ='Table 4 Water Prices'!AD15*'Table 1 Water Input table'!AD59*1000 -> 0 | AD16: ='Table 4 Water Prices'!AE15*'Table 1 Water Input table'!AE59*1000 -> 0 | AF16: XXX
B17: Own Supply | T17: ='Table 4 Water Prices'!U16*'Table 1 Water Input table'!T60*1000 -> 4.2840933e+13 | X17: ='Table 4 Water Prices'!Y16*'Table 1 Water Input table'!Y60*1000 -> 7.4756678e+13 | AC17: ='Table 4 Water Prices'!AD16*'Table 1 Water Input table'!AD60*1000 -> 1.0990818e+12 | AE17: ='Table 4 Water Prices'!AE16*'Table 1 Water Input table'!AE60*1000 -> 2.2074346e+13
A18: Water users | B18: Agriculture (Irrigation)
B19: Agriculture (Rainfed crops)
B20: Agriculture (Livestock)
B21: Forestry
B22: Fishing
B23: Crude oil and Mining
B24: Manufacturing (Food and beverages)
B25: Manufacturing (Non-food)
B26: Electricity, Gas, Steam & Air Conditioning Supply
B27: Construction
B28: Accommodation
B29: Public Administration
B30: Education
... B32: Other
A33: Final consumption | B33: Households
B34: Exports
A35: Return flows | B35: Surface Water
B36: Other
A37: Total

Sheet Table 1  Water Input table
G1: =A3 -> From the Environment | M1: Distribution (Water, Sewerage) | S1: Use of Water (IC) | AK1: Final consumption | AM1: Return flows
G2: Rivers | H2: Dams | I2: Lakes | J2: Springs, fountains, wells | K2: Rainwater (harvested) | L2: =E9 -> 0 | M2: DWRM | N2: NWSC | P2: RWS | Q2: Community Schemes | R2: Own Supply | S2: Agriculture (Irrigation) | T2: Agriculture (Rainfed crops) | U2: Agriculture (Livestock) | V2: Forestry | W2: Fishing | Y2: Crude oil and Mining | Z2: Manufacturing (Food and beverages) | AA2: Manufacturing (Non-food) | AB2: Electricity, Gas, Steam & Air Conditioning Supply | AC2: Construction | AD2: Accommodation | AE2: Public Administration | AG2: Education | AH2: Health | AJ2: Other | AK2: Households | AL2: Exports | AM2: Surface Water
A3: From the Environment | B3: Rivers | M3: XXX | Q3: XXX | R3: XXX | U3: XXX | W3: XXX | AK3: XXX
B4: Wetlands and swamps | Q4: XXX | R4: XXX | U4: XXX | AK4: XXX
B5: Valley Dams | Q5: XXX | R5: XXX | U5: XXX | W5: XXX | AK5: XXX
B6: Lakes | M6: XXX | R6: XXX | U6: XXX | AK6: XXX
B7: Springs, fountains, wells | M7: XXX | Q7: XXX | R7: XXX | U7: XXX | W7: XXX | AK7: XXX
B8: Rainwater (harvested & precipitation) | R8: XXX | U8: XXX | AK8: XXX
B9: Soil water | T9: XXX | V9: XXX
A10: Distribution | B10: DWRM | N10: XXX | P10: XXX | S10: XXX | Y10: XXX | Z10: XXX | AA10: XXX | AB10: XXX | AC10: XXX | AE10: XXX | AG10: XXX | AH10: XXX | AJ10: XXX | AL10: 0
A11: (Water, Sewerage) | B11: NWSC | Y11: XXX? | Z11: XXX | AA11: XXX | AB11: XXX | AC11: XXX | AD11: XXX | AE11: XXX | AG11: XXX | AH11: XXX | AJ11: XXX | AM11: XXX
B12: RWS | Y12: XXX? | Z12: XXX | AA12: XXX | AB12: XXX? | AC12: XXX | AD12: XXX | AE12: XXX | AG12: XXX | AH12: XXX | AJ12: XXX
B13: Community Schemes | Y13: XXX | AC13: XXX | AJ13: XXX | AK13: XXX | AM13: XXX
B14: Own Supply | Y14: XXX | AC14: XXX | AJ14: XXX
A15: Use of Water (IC) | B15: Agriculture (Irrigation) | AM15: XXX
B16: Agriculture (Rainfed crops)
B17: Agriculture (Livestock)
B18: Forestry
B19: Fishing
B20: Crude oil and Mining
B21: Manufacturing (Food and beverages) | N21: XXX | AM21: XXX
B22: Manufacturing (Non-food) | N22: XXX | AM22: XXX
B23: Electricity, Gas, Steam & Air Conditioning Supply | N23: XXX | AM23: XXX
B24: Construction | N24: XXX
B25: Accommodation | N25: XXX
B26: Public Administration | N26: XXX
B27: Education | N27: XXX
B28: Health | N28: XXX
B29: Other | N29: XXX
A30: Final consumption | B30: Households | N30: XXX
B31: Exports
A32: Return flows | B32: Surface Water
B33: Other
A37: Water volume M3 | I37: =4312+0.0447 -> 4312.0447 | J37: 4312.0447 | N37: =N42+N43+N44 -> 1.0530948e+08 | X37: 110494558834 | AG37: -1 | AK37: =AK48+AK51-AK42 -> 0
AK38: Total use | AL38: Total ss
C39: =A42 -> From the Environment | I39: Distribution (Water, Sewerage) | O39: Use of Water (IC) | AE39: Final consumption | AH39: Return flows | AK39: Total- ROW | AL39: Total- Column | AM39: Diff/Residual
C40: Precipitation | D40: Surface water | E40: Ground water | F40: Valley Dams | G40: Springs, fountains, wells | H40: Soil water | I40: DWRM | J40: NWSC | K40: Other Urban | L40: RWS | M40: Own Supply-HEP | N40: Own Supply-Other | O40: Agriculture (Irrigation) | P40: Agriculture (Rainfed crops) | Q40: Agriculture (Livestock) | R40: Forestry | S40: Fishing | T40: Crude oil and Mining | U40: Manufacturing (Food and beverages) | V40: Manufacturing (Non-food) | W40: Electricity, Gas, Steam & Air Conditioning Supply | X40: Water Supply; Sewerage and Waste Management Activities | Y40: Construction | Z40: Accommodation | AA40: Public Administration | AB40: Education | AC40: Health | AD40: Other | AE40: Households | AF40: Embedded water/Evapotranspiration | AG40: Exports | AH40: Surface Water | AI40: Ground water | AJ40: Other | AN40: Notes
B41: Precipitation | C41: =SUM(I41:N41) -> 2.5536634e+14 | N41: =SUM(O55:AG55) -> 2.5536634e+14 | AE41: ='[2]OWN SS'!$H$90 -> 484461.34 | AK41: =SUM(J41,N41) -> 2.5536634e+14 | AN41: No balancing required
A42: From the Environment | B42: Surface Water | D42: =SUM(I42:AJ42) -> 1.1066811e+11 | I42: =SUM(O48:AE48) -> 1.1058278e+11 | N42: ='[3]OWN SS'!$I$91+O51 -> 85330860 | AK42: =SUM(I42:AJ42) -> 1.1066811e+11 | AL42: =D83 -> 1.1066811e+11 | AM42: =AK42-AL42 -> 0
B43: Ground water | E43: =SUM(I43:AJ43) -> 36196661 | I43: =SUM(O49:AE49) -> 17241670 | N43: ='[3]OWN SS'!$I$92 -> 18954991 | AK43: =SUM(I43:AJ43) -> 36196661 | AL43: =E84 -> 36196661 | AM43: =AK43-AL43 -> 0
...

Sheet Table 4 Water Prices
A1: T4. Water Charge Table | C1: =A4 -> From the Environment | J1: Distribution (Water, Sewerage) | P1: Use of Water (IC) | AE1: Final consumption | AI1: Return flows | AK1: Total
C2: Rivers | D2: Wetlands and swamps | E2: Dams | F2: Lakes | G2: Springs, fountains, wells | H2: Rainwater (harvested) | I2: =B10 -> Soil water | J2: DWRM | K2: NWSC | L2: Other Urban/DWD | M2: RWS | N2: Community Schemes | O2: Own Supply | P2: Agriculture (Irrigation) | Q2: Agriculture (Rainfed crops) | R2: Agriculture (Livestock) | S2: Forestry | T2: Fishing | U2: Crude oil and Mining | V2: Manufacturing (Food and beverages) | W2: Manufacturing (Non-food) | X2: Electricity, Gas, Steam & Air Conditioning Supply | Y2: Construction | Z2: Accommodation | AA2: Public Administration | AB2: Education | AC2: Health | AD2: Other | AE2: Households | AH2: Exports | AI2: Surface Water | AJ2: Other
AE3: Marketed | AF3: Own Acct. | AG3: Gift/Received
A4: From the Environment | B4: Rivers
B5: Wetlands and swamps
B6: Dams
B7: Lakes
B8: Springs, fountains, wells
B9: Rainwater (harvested & precipitation)
B10: Soil water
A11: Distribution | B11: DWRM= Total annual charge | K11: ='[11]Fees and charges'!$K$209 -> 26494000 | L11: ='[11]Fees and charges'!$K$214+'[11]Fees and charges'!$K$215 -> 32434000 | M11: =+'[11]Fees and charges'!$K$217+'[11]Fees and charges'!$K$218 -> 13140000 | P11: ='[11]Fees and charges'!$K$194 -> 4059000 | U11: ='[11]Fees and charges'!$K$199 -> 48282000 | V11: ='[11]Fees and charges'!$K$200 -> 95326000 | W11: ='[11]Fees and charges'!$K$201 -> 20367000 | X11: ='[11]Fees and charges'!$K$202 -> 49931000 | Y11: ='[11]Fees and charges'!$K$203 -> 86615000 | Z11: ='[11]Fees and charges'!$K$204 -> 11142000 | AA11: Licence fee | AB11: ='[11]Fees and charges'!$K$206 -> 5694000 | AC11: ='[11]Fees and charges'!$K$207 -> 2628000 | AD11: ='[11]Fees and charges'!$K$208 -> 8322000 | AH11: 0
A12: (Water, Sewerage) | B12: NWSC- per m3 | U12: =GEOMEAN('[12]Annual reports'!$G$65:$H$65) -> 4657.8114 | V12: =GEOMEAN('[12]Annual reports'!$G$67:$H$67) -> 3711.3431 | W12: =GEOMEAN('[12]Annual reports'!$G$66:$H$66) -> 4646.0003 | X12: =GEOMEAN('[12]Annual reports'!$G$65:$H$65) -> 4657.8114 | Y12: =GEOMEAN('[12]Annual reports'!$G$66:$H$66) -> 4646.0003 | Z12: =GEOMEAN('[12]Annual reports'!$G$65:$H$65) -> 4657.8114 | AA12: =GEOMEAN('[12]Annual reports'!$G$64:$H$64) -> 3801.3476 | AB12: =GEOMEAN('[12]Annual reports'!$F$64:$G$64) -> 3301.8353 | AC12: =GEOMEAN('[12]Annual reports'!$G$64:$H$64) -> 3801.3476 | AD12: =GEOMEAN('[12]Annual reports'!$G$64:$H$64) -> 3801.3476 | AE12: =GEOMEAN('[12]Annual reports'!$G$63:$H$63) -> 3290.0891
B13: Other Urban/DWD per m3 | U13: =GEOMEAN('[12]Annual reports'!$G$86:$H$86) -> 2605.7628 | V13: =GEOMEAN('[12]Annual reports'!$G$86:$H$86) -> 2605.7628 | W13: =GEOMEAN('[12]Annual reports'!$G$86:$H$86) -> 2605.7628 | X13: =GEOMEAN('[12]Annual reports'!$G$86:$H$86) -> 2605.7628 | Y13: =GEOMEAN('[12]Annual reports'!$G$86:$H$86) -> 2605.7628 | Z13: =GEOMEAN('[12]Annual reports'!$G$86:$H$86) -> 2605.7628 | AA13: =GEOMEAN('[12]Annual reports'!$G$86:$H$86) -> 2605.7628 | AB13: =GEOMEAN('[12]Annual reports'!$G$86:$H$86) -> 2605.7628 | ... AE13: =GEOMEAN('[12]Annual reports'!$G$86:$H$86) -> 2605.7628
B14: RWS- per m3 | Z14: ='Meta data'!$C$36 -> 333.33333 | AA14: ='Meta data'!$C$36 -> 333.33333 | AB14: ='Meta data'!$C$36 -> 333.33333 | AC14: ='Meta data'!$C$36 -> 333.33333 | AD14: ='Meta data'!$C$36 -> 333.33333 | AE14: 333.33333 | AG14: Subsidy
B15: Community Schemes-m3 | U15: ='Meta data'!$C$36 -> 333.33333 | Y15: ='Meta data'!$C$36 -> 333.33333 | Z15: ='Meta data'!$C$36 -> 333.33333 | AB15: ='Meta data'!$C$36 -> 333.33333 | AC15: ='Meta data'!$C$36 -> 333.33333 | AD15: ='Meta data'!$C$36 -> 333.33333 | AE15: ='Meta data'!$C$36 -> 333.33333 | AG15: Subsidy
B16: Own Supply | U16: ='Meta data'!$C$36 -> 333.33333 | Y16: ='Meta data'!$C$36 -> 333.33333 | Z16: ='Meta data'!$C$36 -> 333.33333 | AD16: ='Meta data'!$C$36 -> 333.33333 | AE16: ='Meta data'!$C$36 -> 333.33333 | AF16: 0?
A17: Water users | B17: Agriculture (Irrigation)
B18: Agriculture (Rainfed crops)
B19: Agriculture (Livestock)
B20: Forestry
B21: Fishing
B22: Crude oil and Mining | K22: =GEOMEAN('[12]Annual reports'!$G$110:$H$110) -> 3777.7254
B23: Manufacturing (Food and beverages) | K23: =GEOMEAN('[12]Annual reports'!$G$112:$H$112) -> 4634.1892
B24: Manufacturing (Non-food) | K24: =GEOMEAN('[12]Annual reports'!$G$111:$H$111) -> 4634.1892
B25: Electricity, Gas, Steam & Air Conditioning Supply | K25: =GEOMEAN('[12]Annual reports'!$G$110:$H$110) -> 3777.7254
B26: Construction | K26: =GEOMEAN('[12]Annual reports'!$G$112:$H$112) -> 4634.1892
B27: Accommodation | K27: =GEOMEAN('[12]Annual reports'!$G$111:$H$111) -> 4634.1892
B28: Public Administration | K28: =GEOMEAN('[12]Annual reports'!$G$110:$H$110) -> 3777.7254
B29: Education | K29: =GEOMEAN('[12]Annual reports'!$G$110:$H$110) -> 3777.7254
B30: Health | K30: =GEOMEAN('[12]Annual reports'!$G$110:$H$110) -> 3777.7254
B31: Other | K31: =GEOMEAN('[12]Annual reports'!$G$111:$H$111) -> 4634.1892
A32: Final consumption | B32: Households | K32: =GEOMEAN('[12]Annual reports'!$G$109:$H$109) -> 2301.7914
B33: Exports
A34: Return flows | B34: Surface Water
B35: Other
A36: Total

Sheet Aggregates
C1: 2018
A2: Gross Water Input | C2: =C3+C4 -> 2.5547719e+14
A3: Total abstracted water | C3: ='Table 5& 6 PSUT '!V12 -> 2.5547719e+14
A4: Imports | C4: 0
A8: Net Domestic Water | C8: =C15+C9 -> 2.5283902e+14
A9: All return flows to envt | C9: ='Table 5& 6 PSUT '!U73 -> 2.2324079e+14 | N9: =22*10 -> 220
A10: Evaporation
A11: Transpiration
A12: Water incorporated in pdts
N13: =N9/5 -> 44
A15: Final Water Use | C15: ='Table 5& 6 PSUT '!V33 -> 2.9598226e+13
A16: Evaporation
A17: Transpiration
A18: Water incorporated in pdts
A21: Population | C21: 38335300
A22: Households, 2014 census report | C22: =C21/4.7 -> 8156446.8
A24: Annual Water consumption per capita, cubic metres | C24: =L53/C21*1000 -> 840912.31
A25: Annual Water consumption per household, cubic metres | C25: =L52/C22*1000 -> 10.679844
A26: Average Daily Water Use per hh, litres, UNHS 2016/17-unweighted | C26: 58.65329
G27: 1000
A29: Water profile and water productivity , 2018
M30: 1000
A31: Industry | B31: Industry Value Added- mill. shs | C31: ='Table 5& 6 PSUT '!A81 -> Total abstraction | D31: ='Table 5& 6 PSUT '!A82 -> Total supply | E31: Water use '000 cubic metres | F31: Percentage of water use | G31: Water use, excluding precipitation '000 cubic metres | H31: Water Use Efficiency, shs per cubic metre | I31: Water productivity- Shs ( VA/M3) | J31: Water Use Efficiency- Shs (Shs/M3) | K31: Water Efficiency-Ltrs (Ltr/VA) | L31: Water consumption '000 cubic metres | M31: Percentage of water consumption | N31: Water productivity- Shs ( VA/CM3) | V31: Proportion
A32: Agriculture | B32: =SUM(B33:B38) -> 33260864 | C32: =SUM(C33:C38) -> 2.5383689e+11 | D32: =SUM(D33:D38) -> 2.2162637e+11 | E32: =SUM(E33:E38) -> 2.5383692e+11 | F32: =SUM(F33:F38) -> 99.357869 | G32: =SUM(G33:G38) -> 463327.68 | H32: =B32/G32*1000 -> 71786.913 | I32: =(B32/E32)*1000 -> 0.13103241 | J32: =(B32/E32*F32)*1000 -> 13.019101 | L32: =SUM(L33:L38) -> 3.2210547e+10 | M32: =SUM(M33:M38) -> 99.919102 | N32: =(B32/L32)*1000 -> 1.0326079
A33: Agriculture (Irrigation) | B33: =0.05*([13]AGDP_CP_CY!$O$6+[13]AGDP_CP_CY!$O$7)*1000 -> 959176.76 | C33: =('Table 5& 6 PSUT '!B81)/1000 -> 262585.43 | D33: =('Table 5& 6 PSUT '!B82)/1000 -> 131292.72 | E33: =('Table 5& 6 PSUT '!B83)/1000 -> 262585.43 | F33: =(E33/$E$53)*100 -> 0.00010278225 | G33: =E33 -> 262585.43 | H33: =B33/G33*1000 -> 3652.8178 | I33: =(B33/E33)*1000 -> 3652.8178 | J33: =(B33/E33*F33)*1000 -> 0.37544483 | K33: =E33/B33*1000 -> 273.76126 | L33: =('Table 5& 6 PSUT '!B84)/1000 -> 131292.72 | M33: =L33/L$53*100 -> 0.0004072781 | N33: =(B33/L33)*1000 -> 7305.6357 | O33: 95265.754 | P33: =L33-O33 -> 36026.963 | V33: =E33/$E$54 -> #DIV/0! | W33: =J33*V33 -> #DIV/0!
A34: Agriculture (Rainfed crop) | B34: =0.95*([13]AGDP_CP_CY!$O$6+[13]AGDP_CP_CY!$O$7)*1000 -> 18224358 | C34: =('Table 5& 6 PSUT '!C81)/1000 -> 1.6976821e+11 | D34: =('Table 5& 6 PSUT '!C82)/1000 -> 1.5279139e+11 | E34: =('Table 5& 6 PSUT '!C83)/1000 -> 1.6976821e+11 | F34: =(E34/E$53*100) -> 66.451356 | I34: =(B34/E34)*1000 -> 0.10734847 | J34: =(B34/E34*F34)*1000 -> 7.1334517 | K34: =E34/B34*1000 -> 9315456.1 | L34: =('Table 5& 6 PSUT '!C84)/1000 -> 1.6976821e+10 | M34: =L34/L$53*100 -> 52.663145 | N34: =(B34/L34)*1000 -> 1.0734847 | O34: 12014738 | P34: =L34-O34 -> 1.6964806e+10 | V34: =E34/$E$54 -> #DIV/0! | W34: =J34*F34 -> 474.02754
A35: Agriculture (Livestock) | B35: =[13]AGDP_CP_CY!$O$8*1000 -> 5095936.6 | C35: =('Table 5& 6 PSUT '!D81)/1000 -> 5.2592103e+10 | D35: =('Table 5& 6 PSUT '!D82)/1000 -> 4.3651444e+10 | E35: =('Table 5& 6 PSUT '!D83)/1000 -> 5.2592132e+10 | F35: =(E35/E$53*100) -> 20.585824 | G35: ='Table 5& 6 PSUT '!D92/1000 -> 30285.344 | H35: =B35/G35*1000 -> 168264.11 | I35: =(B35/E35)*1000 -> 0.096895419 | J35: =(B35/E35*F35)*1000 -> 1.994672 | K35: =E35/B35*1000 -> 10320405 | L35: =('Table 5& 6 PSUT '!D84)/1000 -> 8.9406876e+09 | M35: =L35/L$53*100 -> 27.734564 | N35: =(B35/L35)*1000 -> 0.56997145 | O35: 11685191 | P35: =L35-O35 -> 8.9290024e+09 | V35: =E35/$E$54 -> #DIV/0! | W35: =J35*F35 -> 41.061967
A36: Agriculture Support Services | B36: =[13]AGDP_CP_CY!$O$9*1000 -> 19590.434
A37: Agriculture (Forestry) | B37: =[13]AGDP_CP_CY!$O$10*1000 -> 5526992.3 | C37: =('Table 5& 6 PSUT '!E81)/1000 -> 3.1462908e+10 | D37: =('Table 5& 6 PSUT '!E82)/1000 -> 2.5170325e+10 | E37: =('Table 5& 6 PSUT '!E83)/1000 -> 3.1462908e+10 | F37: =(E37/E$53*100) -> 12.315338 | I37: =(B37/E37)*1000 -> 0.17566693 | J37: =(B37/E37*F37)*1000 -> 2.1633976 | K37: =E37/B37*1000 -> 5692591.2 | L37: =('Table 5& 6 PSUT '!E84)/1000 -> 6.2925834e+09 | M37: =L37/L$53*100 -> 19.519981 | N37: =(B37/L37)*1000 -> 0.87833438 | O37: 4460548.1 | P37: =L37-O37 -> 6.2881228e+09 | V37: =E37/$E$54 -> #DIV/0! | W37: =J37*F37 -> 26.642973
A38: Agriculture (Fishing) | B38: =[13]AGDP_CP_CY!$O$11*1000 -> 3434809.6 | C38: =('Table 5& 6 PSUT '!F81)/1000 -> 13407533 | D38: =('Table 5& 6 PSUT '!F82)/1000 -> 13083901 | E38: =('Table 5& 6 PSUT '!F83)/1000 -> 13407533 | F38: =(E38/E$53*100) -> 0.0052480307 | G38: ='Table 5& 6 PSUT '!F92/1000 -> 170456.91 | H38: =B38/G38*1000 -> 20150.604 | I38: =(B38/E38)*1000 -> 256.18505 | J38: =(B38/E38*F38)*1000 -> 1.344467 | K38: =E38/B38*1000 -> 3903.4284 | L38: ='Table 5& 6 PSUT '!F84/1000 -> 323631.94 | M38: =L38/L$53*100 -> 0.0010039262 | N38: =(B38/L38)*1000 -> 10613.321 | O38: 0 | P38: =L38-O38 -> 323631.94 | V38: =E38/$E$54 -> #DIV/0! | W38: =J38*F38 -> 0.007055804
A39: Industry | B39: =SUM(B40:B45) -> 36178737 | C39: =SUM(C40:C45) -> 1.6402907e+09 | D39: =SUM(D40:D45) -> 1.6143587e+09 | E39: =SUM(E40:E45) -> 1.6403131e+09 | F39: =SUM(F40:F45) -> 0.64205797 | G39: =SUM(G40:G45) -> 703460.3 | H39: =B39/G39*1000 -> 51429.678 | I39: =(B39/E39)*1000 -> 22.055994 | J39: =(B39/E39*F39)*1000 -> 14.161227 | L39: =SUM(L40:L45) -> 25954391 | M39: =SUM(M40:M45) -> 0.080512119 | N39: =(B39/L39)*1000 -> 1393.9351
A40: Crude oil and Mining | B40: =[13]AGDP_CP_CY!$O$13*1000 -> 1742856.7 | C40: =('Table 5& 6 PSUT '!G81)/1000 -> 128522.8 | D40: =('Table 5& 6 PSUT '!G82)/1000 -> 89965.959 | E40: =('Table 5& 6 PSUT '!G83)/1000 -> 129886.4 | F40: =(E40/E$53*100) -> 5.0840659e-05 | G40: =E40 -> 129886.4 | H40: =B40/G40*1000 -> 13418.316 | I40: =(B40/E40)*1000 -> 13418.316 | J40: =(B40/E40*F40)*1000 -> 0.682196 | K40: =E40/B40*1000 -> 74.525002 | L40: =('Table 5& 6 PSUT '!G84)/1000 -> 39920.444 | M40: =L40/L$53*100 -> 0.00012383568 | N40: =(B40/L40)*1000 -> 43658.25 | O40: 1238.1266 | P40: =L40-O40 -> 38682.318 | V40: =E40/$E$54 -> #DIV/0! | W40: =J40*F40 -> 3.4683294e-05
A41: Manufacturing (Food and Beverages) | B41: =0.47*[13]AGDP_CP_CY!$O$14*1000 -> 10183004 | C41: =('Table 5& 6 PSUT '!H81)/1000 -> 10916.48 | D41: =('Table 5& 6 PSUT '!H82)/1000 -> 11114.448 | E41: =('Table 5& 6 PSUT '!H83)/1000 -> 23483.525 | F41: =(E41/E$53*100) -> 9.1920158e-06 | G41: =E41 -> 23483.525 | H41: =B41/G41*1000 -> 433623.3 | I41: =(B41/E41)*1000 -> 433623.3 | J41: =(B41/E41*F41)*1000 -> 3.9858723 | K41: =E41/B41*1000 -> 2.3061491 | L41: =('Table 5& 6 PSUT '!H84)/1000 -> 12369.077 | M41: =L41/L$53*100 -> 3.8369639e-05 | N41: =(B41/L41)*1000 -> 823263.03 | O41: 10464.271 | P41: =L41-O41 -> 1904.806 | V41: =E41/$E$54 -> #DIV/0! | W41: =J41*F41 -> 3.6638201e-05
A42: Manufacturing (Other) | B42: =((1-0.47)*[13]AGDP_CP_CY!$O$14)*1000 -> 11482962 | C42: =('Table 5& 6 PSUT '!I81)/1000 -> 6902.369 | D42: =('Table 5& 6 PSUT '!I82)/1000 -> 7569.7499 | E42: =('Table 5& 6 PSUT '!I83)/1000 -> 13249.961 | F42: =(E42/E$53*100) -> 5.1863529e-06 | G42: =E42 -> 13249.961 | H42: =B42/G42*1000 -> 866641.19 | I42: =(B42/E42)*1000 -> 866641.19 | J42: =(B42/E42*F42)*1000 -> 4.494707 | K42: =E42/B42*1000 -> 1.1538801 | L42: =('Table 5& 6 PSUT '!I84)/1000 -> 5680.2106 | M42: =L42/L$53*100 -> 1.7620363e-05 | N42: =(B42/L42)*1000 -> 2021573.2 | O42: 6535.0206 | P42: =L42-O42 -> -854.81001 | V42: =E42/$E$54 -> #DIV/0! | W42: =J42*F42 -> 2.3311137e-05
A43: Electricity | B43: =[13]AGDP_CP_CY!$O$15*1000 -> 1816972.2 | C43: =('Table 5& 6 PSUT '!J81)/1000 -> 1.0985893e+08 | D43: =('Table 5& 6 PSUT '!J82)/1000 -> 1.0974928e+08 | E43: =('Table 5& 6 PSUT '!J83)/1000 -> 1.0985916e+08 | F43: =(E43/E$53*100) -> 0.043001514 | G43: ='Table 5& 6 PSUT '!J34/1000 -> 157687.12 | H43: =B43/G43*1000 -> 11522.642 | I43: =(B43/E43)*1000 -> 16.539105 | J43: =(B43/E43*F43)*1000 -> 0.71120656 | K43: =E43/B43*1000 -> 60462.763 | L43: =('Table 5& 6 PSUT '!J84)/1000 -> 109882 | M43: =L43/L$53*100 -> 0.00034086073 | N43: =(B43/L43)*1000 -> 16535.668 | O43: 87474.183 | P43: =L43-O43 -> 22407.815 | V43: =E43/$E$54 -> #DIV/0! | W43: =J43*F43 -> 0.030582959
A44: Water Supply; Sewerage and Waste Management Activities | B44: =[13]AGDP_CP_CY!$O$16*1000 -> 3114374.4 | C44: =('Table 5& 6 PSUT '!K81)/1000 -> 1.5300611e+09 | D44: =('Table 5& 6 PSUT '!K82)/1000 -> 1.5044556e+09 | E44: =('Table 5& 6 PSUT '!K83)/1000 -> 1.5300611e+09 | F44: =(E44/E$53*100) -> 0.59890268 | G44: =('Table 5& 6 PSUT '!K58+'Table 5& 6 PSUT '!K66-'Table 5& 6 PSUT '!K51+'Table 5& 6 PSUT '!K49)/1000 -> 152930.52 | H44: =B44/G44*1000 -> 20364.636 | I44: =(B44/E44)*1000 -> 2.0354575 | J44: =(B44/E44*F44)*1000 -> 1.219041 | K44: =E44/B44*1000 -> 491290.04 | L44: =('Table 5& 6 PSUT '!K84)/1000 -> 25605522 | M44: =L44/L$53*100 -> 0.079429908 | N44: =(B44/L44)*1000 -> 121.62901 | O44: 9940.0162 | P44: =L44-O44 -> 25595582 | V44: =E44/$E$54 -> #DIV/0! | W44: =J44*F44 -> 0.73008691
A45: Construction | B45: =[13]AGDP_CP_CY!$O$17*1000 -> 7838568.3 | C45: =('Table 5& 6 PSUT '!L81)/1000 -> 224270.03 | D45: =('Table 5& 6 PSUT '!L82)/1000 -> 45206.267 | E45: =('Table 5& 6 PSUT '!L83)/1000 -> 226222.77 | F45: =(E45/E$53*100) -> 8.8549028e-05 | G45: =E45 -> 226222.77 | H45: =B45/G45*1000 -> 34649.776 | I45: =(B45/E45)*1000 -> 34649.776 | J45: =(B45/E45*F45)*1000 -> 3.068204 | K45: =E45/B45*1000 -> 28.860216 | L45: =('Table 5& 6 PSUT '!L84)/1000 -> 181016.51 | M45: =L45/L$53*100 -> 0.00056152436 | N45: =(B45/L45)*1000 -> 43303.058 | O45: 12418.925 | P45: =L45-O45 -> 168597.58 | V45: =E45/$E$54 -> #DIV/0! | W45: =J45*F45 -> 0.00027168648
A46: Services | B46: =SUM(B47:B52) -> 69785700 | C46: =SUM(C47:C52) -> 5077.8541 | D46: =SUM(D47:D52) -> 61802.671 | E46: =SUM(E47:E52) -> 186233.61 | F46: =SUM(F47:F52) -> 7.2896309e-05 | G46: =SUM(G47:G52) -> 120010.57 | H46: =B46/G46*1000 -> 581496.26 | I46: =(B46/E46)*1000 -> 374721.3 | J46: =(B46/E46*F46)*1000 -> 27.315799 | L46: =SUM(L47:L52) -> 124430.94 | M46: =SUM(M47:M52) -> 0.00038599244 | N46: =(B46/L46)*1000 -> 560838.81
A47: Accommodation | B47: =[13]AGDP_CP_CY!$O$21*1000 -> 3759369.9 | C47: =('Table 5& 6 PSUT '!M81)/1000 -> 367.2078 | D47: =('Table 5& 6 PSUT '!M82)/1000 -> 609.35334 | E47: =('Table 5& 6 PSUT '!M83)/1000 -> 3332.2445 | F47: =(E47/E$53*100) -> 1.3043205e-06 | G47: =E47 -> 3332.2445 | H47: =B47/G47*1000 -> 1128179.5 | I47: =(B47/E47)*1000 -> 1128179.5 | J47: =(B47/E47*F47)*1000 -> 1.4715077 | K47: =E47/B47*1000 -> 0.88638376 | L47: =('Table 5& 6 PSUT '!M84)/1000 -> 2722.8911 | M47: =L47/L$53*100 -> 8.4465761e-06 | N47: =(B47/L47)*1000 -> 1380653.8 | O47: 2303.3725 | P47: =L47-O47 -> 419.51865 | V47: =E47/$E$54 -> #DIV/0! | W47: =J47*F47 -> 1.9193177e-06
A48: Public Administration | B48: =[13]AGDP_CP_CY!$O$27*1000 -> 3658485.7 | C48: =('Table 5& 6 PSUT '!N81)/1000 -> 78.315 | D48: =('Table 5& 6 PSUT '!N82)/1000 -> 4172.4703 | E48: =('Table 5& 6 PSUT '!N83)/1000 -> 23163.871 | F48: =(E48/E$53*100) -> 9.0668957e-06 | G48: =E48 -> 23163.871 | H48: =B48/G48*1000 -> 157939.3 | I48: =(B48/E48)*1000 -> 157939.3 | J48: =(B48/E48*F48)*1000 -> 1.4320192 | K48: =E48/B48*1000 -> 6.3315462 | L48: =('Table 5& 6 PSUT '!N84)/1000 -> 18991.401 | M48: =L48/L$53*100 -> 5.8912496e-05 | N48: =(B48/L48)*1000 -> 192639.06 | O48: 17236.585 | P48: =L48-O48 -> 1754.8157 | Q48: Sch children | S48: 8655924 | V48: =E48/$E$54 -> #DIV/0! | W48: =J48*F48 -> 1.2983969e-05
...

Sheet Table 5& 6 PSUT 
A1: A. Physical Supply Table
A2: Industries by SIC | B2: Agriculture (Irrigation) | C2: Agriculture (Rainfed crop) | D2: Agriculture (Livestock) | E2: Agriculture (Forestry) | F2: Agriculture (Fishing) | G2: Crude oil and Mining | H2: Manufacturing (Food and Beverages) | I2: Manufacturing (Other) | J2: Electricity | K2: Water Supply; Sewerage and Waste Management Activities | L2: Construction | M2: Accommodation | N2: Public Administration | O2: Education | P2: Health | Q2: Other | R2: Households | S2: Accumulation | T2: Rest of the World | U2: Flows from the environment | V2: Total Supply
A3: (I) Sources of Abstracted Water
A4: Inland Water Resources
A5: Surface Water | U5: ='Table 1 Water Input table'!$AK$42 -> 1.1066811e+11 | V5: =U5 -> 1.1066811e+11 | X5: =V5-V46 -> 0
A6: Groundwater | U6: ='Table 1 Water Input table'!$AK$43+'Table 1 Water Input table'!$AK$44+'Table 1 Water Input table'!$AK$45 -> 1.8183291e+08 | V6: =U6 -> 1.8183291e+08 | X6: =V6-V47 -> 0
A7: Soil Water | U7: ='Table 1 Water Input table'!$AK$46 -> 0 | V7: =U7 -> 0 | X7: =V7-V48 -> 0
A8: Total | U8: =SUM(U5:U7) -> 1.1084995e+11 | V8: =U8 -> 1.1084995e+11 | X8: =V8-V49 -> 0
A9: Other water sources | X9: =V9-V50 -> 0
A10: Precipitation | U10: ='Table 1 Water Input table'!$AK$41 -> 2.5536634e+14 | V10: =U10 -> 2.5536634e+14 | X10: =V10-V51 -> 0
A11: Total | U11: =U10 -> 2.5536634e+14 | V11: =U11 -> 2.5536634e+14 | X11: =V11-V52 -> 0
A12: Total Supply Abstracted Water | U12: =U11+U8 -> 2.5547719e+14 | V12: =U12 -> 2.5547719e+14 | X12: =V12-V53 -> 0
A13: (II) Abstracted water | X13: =V13-V54 -> 0
A14: For distribution-NWSC | K14: =V55 -> 1.6028388e+08 | T14: 0 | V14: =SUM(T14,K14) -> 1.6028388e+08 | X14: =V14-V55 -> 0
A15: For distribution- Other distributors | K15: =V56 -> 6066556.2 | V15: =SUM(T15,K15) -> 6066556.2 | X15: =V15-V56 -> 0
A16: For own use | B16: =B57 -> 2.6258543e+08 | C16: =C57 -> 1.6976821e+14 | D16: =D57 -> 5.2592103e+13 | E16: =E57 -> 3.1462908e+13 | F16: =F57 -> 1.3407533e+10 | G16: =G57 -> 1.285228e+08 | H16: =H57 -> 10916480 | I16: =I57 -> 6902369 | J16: =J57 -> 1.0985893e+11 | K16: =K57+R57 -> 1.5299069e+12 | L16: =L57 -> 2.2427003e+08 | M16: =M57 -> 367207.8 | N16: =N57 -> 78315 | O16: =O57 -> 269575 | P16: =P57 -> 1065511 | Q16: =Q57 -> 3297245.3 | V16: =SUM(B16:R16) -> 2.5547703e+14 | X16: =V16-V57 -> 0
A17: Total | B17: =B16 -> 2.6258543e+08 | C17: =C16 -> 1.6976821e+14 | D17: =D16 -> 5.2592103e+13 | E17: =E16 -> 3.1462908e+13 | F17: =F16 -> 1.3407533e+10 | G17: =G16 -> 1.285228e+08 | H17: =H16 -> 10916480 | I17: =I16 -> 6902369 | J17: =J16 -> 1.0985893e+11 | K17: =K16+K14+K15 -> 1.5300733e+12 | L17: =L16 -> 2.2427003e+08 | M17: =M16 -> 367207.8 | N17: =N16 -> 78315 | O17: =O16 -> 269575 | P17: =P16 -> 1065511 | Q17: =Q16 -> 3297245.3 | T17: =T14 -> 0 | V17: =SUM(V14:V16) -> 2.554772e+14 | X17: =V17-V58 -> 0
A18: (III) Supply of water to other economic unitsof which: | X18: =V18-V59 -> 0
A19: Wastewater
A20: Wastewater to treatment | B20: ='Table 1 Water Input table'!$J$61 -> 0 | C20: ='Table 1 Water Input table'!$J$62 -> 0 | D20: ='Table 1 Water Input table'!$J$63 -> 2895773.4 | E20: ='Table 1 Water Input table'!$J$64 -> 0 | F20: ='Table 1 Water Input table'!$J$65 -> 0 | G20: ='Table 1 Water Input table'!$J$66 -> 0 | H20: ='Table 1 Water Input table'!$J$67 -> 1254628.6 | I20: ='Table 1 Water Input table'!$J$68 -> 633710.64 | J20: ='Table 1 Water Input table'!$J$69 -> 22862.79 | K20: ='Table 1 Water Input table'!$J$70 -> 0 | L20: ='Table 1 Water Input table'!$J$71 -> 191439.3 | M20: ='Table 1 Water Input table'!$J$72 -> 285477.74 | N20: ='Table 1 Water Input table'!$J$73 -> 2301519.9 | O20: ='Table 1 Water Input table'!$J$74 -> 164171.01 | P20: ='Table 1 Water Input table'!$J$75 -> 324835.36 | Q20: ='Table 1 Water Input table'!$J$76 -> 912049.56 | R20: ='Table 1 Water Input table'!$J$77 -> 6905559.4 | V20: =SUM(B20:R20) -> 15892028 | X20: =V20-V61 -> 0
A21: Own treatment | V21: =SUM(B21:R21) -> 0 | X21: =V21-V62 -> 0
A22: Reused water | X22: =V22-V63 -> 0
A23: For distribution | V23: =SUM(B23:R23) -> 0 | X23: =V23-V64 -> 0
A24: For own use | V24: =SUM(B24:R24) -> 0 | X24: =V24-V65 -> 0
A25: Total | V25: =SUM(V20:V21,V23:V24) -> 15892028 | X25: =V25-V66 -> 0
A26: (IV) Return flows of water | X26: =V26-V67 -> 0
A27: To inland water resources | X27: =V27-V68 -> 0
A28: Surface Water | B28: ='Table 1 Water Input table'!AH61 -> 0 | C28: ='Table 1 Water Input table'!AH62 -> 5.0930463e+13 | D28: ='Table 1 Water Input table'!AH63 -> 1.3148025e+13 | E28: ='Table 1 Water Input table'!AH64 -> 3.1462906e+12 | F28: ='Table 1 Water Input table'!S80 -> 1.3083901e+10 | G28: ='Table 1 Water Input table'!AH66 -> 0 | H28: ='Table 1 Water Input table'!AH67 -> 6668668.9 | I28: ='Table 1 Water Input table'!AH68 -> 3784875 | J28: ='Table 1 Water Input table'!AH69 -> 1.0974928e+11 | K28: =SUM('Table 1 Water Input table'!AH56:AH60)+'Table 1 Water Input table'!AH70 -> 1.4992569e+12 | L28: ='Table 1 Water Input table'!AH71 -> 0 | M28: ='Table 1 Water Input table'!AH72 -> 0 | N28: ='Table 1 Water Input table'!AH73 -> 0 | O28: ='Table 1 Water Input table'!AH74 -> 0 | P28: ='Table 1 Water Input table'!AH75 -> 0 | Q28: ='Table 1 Water Input table'!AH76 -> 0 | R28: ='Table 1 Water Input table'!AH77 -> 0 | V28: =SUM(B28:R28) -> 6.884688e+13 | X28: =V28-V70 -> 0
A29: Groundwater | B29: ='Table 1 Water Input table'!AI61 -> 1.3129272e+08 | C29: ='Table 1 Water Input table'!AI62 -> 3.3953642e+13 | D29: ='Table 1 Water Input table'!AI63 -> 7.8888152e+12 | E29: ='Table 1 Water Input table'!AI64 -> 6.2925811e+12 | G29: ='Table 1 Water Input table'!AI66 -> 0 | H29: ='Table 1 Water Input table'!AI67 -> 2222889.6 | I29: ='Table 1 Water Input table'!AI68 -> 0 | J29: ='Table 1 Water Input table'!AI69 -> 0 | K29: =SUM('Table 1 Water Input table'!AI56:AI60)+'Table 1 Water Input table'!AI70 -> 5.198701e+09 | L29: ='Table 1 Water Input table'!AI71 -> 0 | M29: ='Table 1 Water Input table'!AI72 -> 0 | N29: ='Table 1 Water Input table'!AI73 -> 0 | O29: ='Table 1 Water Input table'!AI74 -> 0 | P29: ='Table 1 Water Input table'!AI75 -> 0 | Q29: ='Table 1 Water Input table'!AI76 -> 0 | R29: ='Table 1 Water Input table'!AI77 -> 0 | V29: =SUM(B29:R29) -> 4.8140371e+13 | X29: =V29-V71 -> 0
A30: Other sources | B30: ='Table 1 Water Input table'!AJ61 -> 0 | C30: ='Table 1 Water Input table'!AJ62 -> 6.7907284e+13 | D30: ='Table 1 Water Input table'!AJ63 -> 2.2614604e+13 | E30: ='Table 1 Water Input table'!AJ64 -> 1.5731453e+13 | G30: ='Table 1 Water Input table'!AJ66 -> 89965959 | H30: ='Table 1 Water Input table'!AJ67 -> 2222889.6 | I30: ='Table 1 Water Input table'!AJ68 -> 3784875 | J30: ='Table 1 Water Input table'!AJ69 -> 0 | L30: ='Table 1 Water Input table'!AJ71 -> 45206267 | M30: ='Table 1 Water Input table'!AJ72 -> 609353.34 | N30: ='Table 1 Water Input table'!AJ73 -> 4172470.3 | O30: ='Table 1 Water Input table'!AJ74 -> 385144.7 | P30: ='Table 1 Water Input table'!AJ75 -> 834059.39 | Q30: ='Table 1 Water Input table'!AJ76 -> 2332299.3 | R30: ='Table 1 Water Input table'!AJ77 -> 53469344 | V30: =SUM(B30:R30) -> 1.0625354e+14 | X30: =V30-V72 -> 0
A31: Total returns flows | B31: =SUM(B28:B30) -> 1.3129272e+08 | C31: =SUM(C28:C30) -> 1.5279139e+14 | D31: =SUM(D28:D30) -> 4.3651444e+13 | E31: =SUM(E28:E30) -> 2.5170325e+13 | F31: =SUM(F28:F30) -> 1.3083901e+10 | G31: =SUM(G28:G30) -> 89965959 | H31: =SUM(H28:H30) -> 11114448 | I31: =SUM(I28:I30) -> 7569749.9 | ... R31: =SUM(R28:R30) -> 53469344 | V31: =SUM(V28:V30) -> 2.2324079e+14 | X31: =V31-V73 -> 0
A32: of which: Losses in distribution | B32: 0 | C32: 0 | D32: 0 | E32: 0 | F32: 0 | G32: 0 | H32: 0 | I32: 0 | J32: 0 | K32: =K85 -> 5.198701e+09 | L32: 0 | M32: 0 | N32: 0 | O32: 0 | P32: 0 | Q32: 0 | R32: 0 | V32: =SUM(B32:R32) -> 5.198701e+09
A33: (V) Evaporation of abstracted water, transpiration and water incorporated into products | B33: =SUM(B34:B36)+B39 -> 77375251 | C33: =SUM(C34:C36)+C39 -> 1.2661503e+13 | D33: =SUM(D34:D36)+D39 -> 1.2220473e+13 | E33: =SUM(E34:E36)+E39 -> 4.6925226e+12 | F33: =SUM(F34:F36)+F39 -> 2.8696701e+08 | G33: =SUM(G34:G36)+G39 -> 5559536.7 | H33: =SUM(H34:H36)+H39 -> 7817321.9 | I33: =SUM(I34:I36)+I39 -> 5876563.4 | ... R33: =SUM(R34:R36)+R39 -> 77664468 | V33: =SUM(B33:R33) -> 2.9598226e+13 | X33: =V33-V74 -> 0
A34: Evapotranspiration of abstracted water | B34: ='Table 1 Water Input table'!O78 -> 0 | C34: ='Table 1 Water Input table'!P78 -> 2.436785e+11 | D34: ='Table 1 Water Input table'!Q78 -> 7.5488603e+10 | E34: ='Table 1 Water Input table'!R78 -> 4.5160601e+10 | F34: ='Table 1 Water Input table'!S78 -> 45949676 | G34: ='Table 1 Water Input table'!T78 -> 184476.49 | H34: ='Table 1 Water Input table'!U78 -> 15669.079 | I34: ='Table 1 Water Input table'!V78 -> 9907.3846 | ... R34: ='Table 1 Water Input table'!AE78 -> 95053.9 | X34: =V34-V75 -> 0
A35: Transpiration | X35: =V35-V76 -> 0
A36: Water incorporated into products | X36: =V36-V77 -> 0
A37: Total supply | B37: =B17+B25+B31+B33 -> 4.712534e+08 | C37: =C17+C25+C31+C33 -> 3.352211e+14 | D37: =D17+D25+D31+D33 -> 1.0846402e+14 | E37: =E17+E25+E31+E33 -> 6.1325755e+13 | F37: =F17+F25+F31+F33 -> 2.6778402e+10 | G37: =G17+G25+G31+G33 -> 2.2404829e+08 | H37: =H17+H25+H31+H33 -> 29848250 | I37: =I17+I25+I31+I33 -> 20348682 | ... R37: =R17+R25+R31+R33 -> 1.3113381e+08 | U37: =U12 -> 2.5547719e+14 | V37: =V12+V17+V25+V31+V33 -> 7.6379342e+14 | W37: =V12+V17+V25+V31+V33 -> 7.6379342e+14 | X37: =V37-V78 -> 0
Y38: =V37-W37 -> 0
B39: 77375251 | C39: 1.2417825e+13 | D39: 1.2144984e+13 | E39: 4.647362e+12 | F39: 2.4101734e+08 | G39: 5375060.2 | H39: 7801652.8 | I39: 5866656 | J39: -73432364 | K39: 2.0840571e+10 | L39: 1.1720495e+08 | M39: 2288110.8 | N39: 17147239 | O39: 912386.39 | P39: 2298378.5 | Q39: 5648889.2 | R39: 77569414
Y40: (('Table 1 Water Input table'!N42-'Table 1 Water Input table'!O51)*0.6)
...

Sheet Graphs
A2: Water use '000 cubic metres | G2: Water use '000 cubic metres (others)
B3: 2015 | C3: 2016 | D3: 2017 | E3: 2018 | H3: 2015 | I3: 2016 | J3: 2017 | K3: 2018
A4: Agriculture (Rainfed crop) | B4: 1.4107677e+08 | C4: 1.2014738e+08 | D4: 1.3455552e+08 | E4: 1.3455552e+08 | G4: Agriculture (Irrigation) | H4: 74362.049 | I4: 190531.51 | J4: 133045.33 | K4: 155288.34
A5: Agriculture (Livestock) | B5: 68408768 | C5: 58277480 | D5: 65224922 | E5: 65224999 | G5: Agriculture (Fishing) | H5: 64589.5 | I5: 146500.38 | J5: 149664.64 | K5: 133791.98
A6: Agriculture (Forestry) | B6: 26168344 | C6: 22289468 | D6: 24962022 | E6: 24962028 | G6: Crude oil and Mining | H6: 131084.67 | I6: 4119.1856 | J6: 5201.2177 | K6: 16614.061
A7: Electricity | B7: 51920826 | C7: 87453417 | D7: 97363920 | E7: 1.0038233e+08 | G7: Manufacturing (Food and Beverages) | H7: 184161.23 | I7: 19794.383 | J7: 28800.952 | K7: 165271.22
A8: Water Supply; Sewerage and Waste Management Activities | B8: 1285079.7 | C8: 1097894 | D8: 1229214.4 | E8: 1228091.1 | G8: Manufacturing (Other) | H8: 10833.374 | I8: 15476.607 | J8: 20164.091 | K8: 20555.838
G9: Construction | H9: 42106.971 | I9: 15481.141 | J9: 16086.95 | K9: 148803.8
G10: Accommodation | H10: 3373.6287 | I10: 2815.8159 | J10: 4842.5625 | K10: 4666.0687
G11: Public Administration | H11: 17920.303 | I11: 21022.299 | J11: 37350.306 | K11: 36012.195
G12: Education | H12: 2352.5506 | I12: 1740.1594 | J12: 2918.2351 | K12: 2840.5588
G13: Health | H13: 3349.1346 | I13: 3106.7819 | J13: 5610.0051 | K13: 6238.3611
G14: Other | H14: 14773.28 | I14: 10444.06 | J14: 16640.671 | K14: 16481.827
G15: Households | H15: 278412.28 | I15: 89500.694 | J15: 157189.94 | K15: 150081.36
G16: Total | H16: 2.896871e+08 | I16: 2.8978617e+08 | J16: 3.2391312e+08 | K16: 3.2720962e+08
I17: =I16/H16-1 -> 0.00034197834 | J17: =J16/I16-1 -> 0.11776597 | K17: =K16/J16-1 -> 0.010177121
K18: =K16/H16-1 -> 0.12952775
A25: Water use '000 cubic metres (Dominant sectors)-shares | G25: Water use '000 cubic metres (Others)
B26: 2015 | C26: 2016 | D26: 2017 | E26: 2018 | H26: 2015 | I26: 2016 | J26: 2017 | K26: 2018
A27: Agriculture (Rainfed crop) | B27: =(B4/$H$16)*100 -> 48.699706 | C27: =(C4/$I$16)*100 -> 41.460701 | D27: =(D4/$J$16)*100 -> 41.540622 | E27: =(E4/$K$16)*100 -> 41.122117 | G27: Agriculture (Irrigation) | H27: =((H4/$H$16))*100 -> 0.025669782 | I27: =(I4/$I$16)*100 -> 0.065749 | J27: =(J4/$J$16)*100 -> 0.041074387 | K27: =(K4/$K$16)*100 -> 0.047458366
A28: Agriculture (Livestock) | B28: =(B5/$H$16)*100 -> 23.61471 | C28: =(C5/$I$16)*100 -> 20.110511 | D28: =(D5/$J$16)*100 -> 20.136549 | E28: =(E5/$K$16)*100 -> 19.933704 | G28: Agriculture (Fishing) | H28: =((H5/$H$16))*100 -> 0.022296298 | I28: =(I5/$I$16)*100 -> 0.050554648 | J28: =(J5/$J$16)*100 -> 0.04620518 | K28: =(K5/$K$16)*100 -> 0.040888767
A29: Agriculture (Forestry) | B29: =(B6/$H$16)*100 -> 9.0333133 | C29: =(C6/$I$16)*100 -> 7.6916948 | D29: =(D6/$J$16)*100 -> 7.7063943 | E29: =(E6/$K$16)*100 -> 7.6287575 | G29: Crude oil and Mining | H29: =((H6/$H$16))*100 -> 0.045250434 | I29: =(I6/$I$16)*100 -> 0.0014214569 | J29: =(J6/$J$16)*100 -> 0.0016057447 | K29: =(K6/$K$16)*100 -> 0.0050774978
A30: Electricity | B30: =(B7/$H$16)*100 -> 17.923071 | C30: =(C7/$I$16)*100 -> 30.178603 | D30: =(D7/$J$16)*100 -> 30.058653 | E30: =(E7/$K$16)*100 -> 30.678295 | G30: Manufacturing (Food and Beverages) | H30: =((H7/$H$16))*100 -> 0.063572465 | I30: =(I7/$I$16)*100 -> 0.006830686 | J30: =(J7/$J$16)*100 -> 0.0088915671 | K30: =(K7/$K$16)*100 -> 0.05050928
A31: Water Supply; Sewerage and Waste Management Activities | B31: =(B8/$H$16)*100 -> 0.44360957 | C31: =(C8/$I$16)*100 -> 0.37886349 | D31: =(D8/$J$16)*100 -> 0.37948894 | E31: =(E8/$K$16)*100 -> 0.37532243 | G31: Manufacturing (Other) | H31: =((H8/$H$16))*100 -> 0.0037396811 | I31: =(I8/$I$16)*100 -> 0.005340699 | J31: =(J8/$J$16)*100 -> 0.0062251542 | K31: =(K8/$K$16)*100 -> 0.0062821619
G32: Construction | H32: =((H9/$H$16))*100 -> 0.014535328 | I32: =(I9/$I$16)*100 -> 0.0053422636 | J32: =(J9/$J$16)*100 -> 0.0049664399 | K32: =(K9/$K$16)*100 -> 0.045476596
G33: Accommodation | H33: =((H10/$H$16))*100 -> 0.0011645768 | I33: =(I10/$I$16)*100 -> 0.00097168746 | J33: =(J10/$J$16)*100 -> 0.001495019 | K33: =(K10/$K$16)*100 -> 0.0014260182
G34: Public Administration | H34: =((H11/$H$16))*100 -> 0.0061860894 | I34: =(I11/$I$16)*100 -> 0.0072544176 | J34: =(J11/$J$16)*100 -> 0.011530964 | K34: =(K11/$K$16)*100 -> 0.011005848
G35: Education | H35: =((H12/$H$16))*100 -> 0.00081210056 | I35: =(I12/$I$16)*100 -> 0.00060049774 | J35: =(J12/$J$16)*100 -> 0.00090093144 | K35: =(K12/$K$16)*100 -> 0.00086811593
G36: Health | H36: =((H13/$H$16))*100 -> 0.0011561214 | I36: =(I13/$I$16)*100 -> 0.0010720946 | J36: =(J13/$J$16)*100 -> 0.0017319475 | K36: =(K13/$K$16)*100 -> 0.0019065335
G37: Other | H37: =((H14/$H$16))*100 -> 0.0050997367 | I37: =(I14/$I$16)*100 -> 0.0036040575 | J37: =(J14/$J$16)*100 -> 0.0051373871 | K37: =(K14/$K$16)*100 -> 0.005037085
G38: Households | H38: =((H15/$H$16))*100 -> 0.096107932 | I38: =(I15/$I$16)*100 -> 0.030885081 | J38: =(J15/$J$16)*100 -> 0.048528427 | K38: =(K15/$K$16)*100 -> 0.045867036
H39: =SUM(H27:H38,B27:B31) -> 100 | I39: =SUM(I27:I38,C27:C31) -> 100 | J39: =SUM(J27:J38,D27:D31) -> 100 | K39: =SUM(K27:K38,E27:E31) -> 100
A43: % of industry Value Added
B44: 2015 | C44: 2016 | D44: 2017 | E44: 2018
A45: Agriculture (Irrigation) | B45: 0.66808187 | C45: 0.63151493 | D45: 0.60748229 | E45: 0.62156786
A46: Agriculture (Rainfed crop) | B46: 12.693556 | C46: 11.998784 | D46: 11.542164 | E46: 11.809789
A47: Agriculture (Livestock) | B47: 3.9502041 | C47: 3.9922101 | D47: 3.1352759 | E47: 4.1287461
A48: Agriculture (Forestry) | B48: 3.7695617 | C48: 3.4049252 | D48: 2.5576367 | E48: 3.3807854
A49: Agriculture (Fishing) | B49: 1.4851259 | C49: 1.4545695 | D49: 1.1668478 | E49: 1.4331082
A50: Crude oil and Mining | B50: 0.62910131 | C50: 0.64705708 | D50: 0.42938763 | E50: 0.36163767
...

Sheet PSUT-Calc
B2: 2015 | C2: 2016 | D2: 2017 | E2: 2018 | I2: 1000
A3: Total abstraction | B3: 2.8967718e+11 | C3: 2.8977435e+11 | D3: 3.2390022e+11 | E3: 3.2719784e+11
A4: Total supply | B4: 2.5595536e+11 | C4: 2.6131664e+11 | D4: 2.9175571e+11 | E4: 2.9485471e+11
A5: Total use of water | B5: 2.896871e+11 | C5: 2.8978617e+11 | D5: 3.2391312e+11 | E5: 3.2720962e+11 | G5: =11 -> 11
A6: Consumption= Total use- Total Supply | B6: 3.3731746e+10 | C6: 2.8469525e+10 | D6: 3.2157411e+10 | E6: 3.2354909e+10
A7: All return flows to envt | B7: 2.8970021e+08 | C7: 2.8976503e+11 | D7: 2.9172991e+11 | E7: 2.9483116e+11
A8: o/w Losses in distribution- | B8: 0
B9: 0
A10: Balance identity -LHS | B10: 2.896871e+11 | C10: 2.8978617e+11 | D10: 3.2391312e+11 | E10: 3.2720962e+11
A11: Balance identity -RHS | B11: 2.896871e+11 | C11: 2.8978617e+11 | D11: 3.2391312e+11 | E11: 3.2720962e+11
A13: Percentage Change
A14: Total abstraction | C14: =C3/B3-1 -> 0.00033543661 | D14: =D3/C3-1 -> 0.11776705 | E14: =E3/D3-1 -> 0.010180995
A15: Total supply | C15: =C4/B4-1 -> 0.020946182 | D15: =D4/C4-1 -> 0.11648345 | E15: =E4/D4-1 -> 0.010621916
A16: Total use of water | C16: =C5/B5-1 -> 0.00034197834 | D16: =D5/C5-1 -> 0.11776597 | E16: =E5/D5-1 -> 0.010177121
A17: Consumption= Total use- Total Supply | C17: =C6/B6-1 -> -0.15600203 | D17: =D6/C6-1 -> 0.12953801 | E17: =E6/D6-1 -> 0.0061416174
A18: o/w Losses in distribution-
A20: Balance identity -LHS | C20: =C10/B10-1 -> 0.00034197834 | D20: =D10/C10-1 -> 0.11776597 | E20: =E10/D10-1 -> 0.010177121
A21: Balance identity -RHS | C21: =C11/B11-1 -> 0.00034197834 | D21: =D11/C11-1 -> 0.11776597 | E21: =E11/D11-1 -> 0.010177121
A24: Gross Water Input | B24: 2.8970021e+08 | C24: 2.8977686e+11 | D24: 3.2378416e+11 | E24: 3.2710201e+11
A25: Total abstracted water | B25: 2.8970021e+08 | C25: 2.8977686e+11 | D25: 3.2378416e+11 | E25: 3.2710201e+11
A26: Imports | B26: 0 | C26: 0 | D26: 0 | E26: 0
A29: Net Domestic Water
B31: 2.5590827e+08 | C31: 2.61293e+11 | D31: 2.9172991e+11 | E31: 2.9483116e+11 | L31: 220
A32: 2018
