Workbook
Name _Toc368579723: SYB_2015_Table_7.2.1!$B$4
Name Products: [1]RPCA1!$A$2:$E$228

Sheet TOC
A1: Content
A3: Worksheet | B3: Content
A5: 2012
A6: Table 1 | B6: Water Asset Table, 2012
A7: Table 2 | B7: Water_Asset_Table_Data_&_Method, 2012
A8: Table 3 | B8: Water Asset Table, 2012 - Balanced
A9: Table 4 | B9: Water_PSUT_Table_Data_&_Method, 2012
A10: Table 5 | B10: PSUT: Physical Supply & Use Table Water (detailed), 2012
A11: Table 6 | B11: RBM&E-2017_Study
A12: Table 9 | B12: WA_PHYSICAL Water - PSUT, timeseries
A13: Table 10 | B13: NA_Economic_data, timeseries
A14: Table 11 | B14: NA_Economic_data, timeseries - Processed
A15: Table 12 | B15: NA_Labour_Force_Data, timeseries
A16: Table 13 | B16: NA_INTEGRATED: Labour - Economic - Water data, timeseries
A17: Table 14 | B17: Water Sector Analysis - Sheets
A19: Analysis & timeseries
B20: Check by Closing Stocks
B21: Asset trends Charts I
B22: Asset trends Charts II
B23: PSUT trends Charts
B24: PSUT trends Charts & ISIC breakdown
A26: Indices | B26: Indicators
B27: Indicators
B28: IRWR
B29: TRWR
B30: Water availability / capita
B31: SDG 6.4.1 - Water Use Efficiency
B32: SDG 6.4.1 - Water Use Efficiency - Time Series
B33: SDG - Water Resources
B34: SDG 6.4.2 - Water stress
A37: 2013
A38: Table 14-A | B38: Water Asset Table, 2013
A39: Table 14-B | B39: Water_Asset_Table_Data_&_Method, 2013
A40: Table 14-C | B40: Water Asset Table, 2013 - Balanced
A41: Table 14-D | B41: Water_PSUT_Table_Data_&_Method, 2013
A42: Table 14-E | B42: PSUT: Physical Supply & Use Table Water (detailed), 2013
A44: 2014
A45: Table 15-A | B45: Water Asset Table, 2014
A46: Table 15-B | B46: Water_Asset_Table_Data_&_Method, 2014
A47: Table 15-C | B47: Water Asset Table, 2014 - Balanced
...

Sheet 2012NWRMP
A1: 000m3 (Consumptive Water demand) | B1: Agriculture | I1: Mining | K1: Manufacturing | P1: Water
A2: Year 2012 | B2: Fish ponds | C2: Irr. RWH | D2: Irr. Marshlands | E2: Irr. Surface water | F2: Irr. Dam | G2: Irr. Gr. Water | H2: Livestock | I2: Mining WS | K2: Coffee Washing Station | M2: Industry WS | O2: Other manufacturing | P2: Hydropower for Electricity | Q2: Household Urban DWS | R2: Household Rural DWS | T2: Total (000m3/yr) | V2: Population in 2012 Census
A3: CKIV (Lake Kivu, 2,425 km²) | B3: 135 | C3: 0 | D3: 440 | E3: 0 | F3: 0 | G3: 0 | H3: 2597 | I3: 562 | K3: 27 | M3: 1123 | P3: 56 | Q3: 2359 | R3: 20891 | T3: =SUM(B3:S3) -> 28190 | V3: 1415418
A4: CRUS (Rusizi, 1.005 km²) | B4: 60 | C4: 0 | D4: 890 | E4: 0 | F4: 0 | G4: 0 | H4: 585 | I4: 127 | K4: 11 | M4: 253 | P4: 0 | Q4: 435 | R4: 4774 | T4: =SUM(B4:S4) -> 7135 | V4: 318048
A5: NNYU (Upper Nyabarongo, 3,348 km²) | B5: 225 | C5: 44 | D5: 629 | E5: 0 | F5: 520 | G5: 0 | H5: 3775 | I5: 579 | K5: 4 | M5: 1157 | P5: 0 | Q5: 3606 | R5: 20746 | T5: =SUM(B5:S5) -> 31285 | V5: 1425492
A6: NMUK (Mukungwa, 1,949 km²) | B6: 30 | C6: 0 | D6: 0 | E6: 0 | F6: 0 | G6: 0 | H6: 2501 | I6: 490 | K6: 0 | M6: 981 | P6: 158 | Q6: 5443 | R6: 15987 | T6: =SUM(B6:S6) -> 25590 | V6: 1048631
A7: NNYL (Lower Nyabarongo, 3.304 km²) | B7: 420 | C7: 73 | D7: 1973 | E7: 0 | F7: 5938 | G7: 0 | H7: 4310 | I7: 840 | K7: 11 | M7: 1680 | P7: 570 | Q7: 19302 | R7: 20728 | T7: =SUM(B7:S7) -> 55845 | V7: 2181940
A8: NAKN (Akanyaru, 3,402 km²) | B8: 270 | C8: 157 | D8: 2804 | E8: 342 | F8: 17891 | G8: 0 | H8: 3766 | I8: 544 | K8: 5 | M8: 1088 | P8: 0 | Q8: 6771 | R8: 17245 | T8: =SUM(B8:S8) -> 50883 | V8: 1447480
A9: NAKU (Upper Akagera, 3.053 km²) | B9: 210 | C9: 208 | D9: 850 | E9: 13780 | F9: 1196 | G9: 0 | H9: 2460 | I9: 432 | K9: 7 | M9: 865 | P9: 0 | Q9: 7000 | R9: 12624 | T9: =SUM(B9:S9) -> 39632 | V9: 1318379
A10: NAKL (Lower Akagera, 4.288 km²) | B10: 105 | C10: 204 | D10: 1200 | E10: 4800 | F10: 2200 | G10: 0 | H10: 2165 | I10: 202 | K10: 1 | M10: 403 | P10: 0 | Q10: 847 | R10: 7498 | T10: =SUM(B10:S10) -> 19625 | V10: 725068
A11: NMUV (Muvumba, 1,568 km²) | B11: 105 | C11: 121 | D11: 3940 | E11: 3200 | F11: 2481 | G11: 0 | H11: 1457 | I11: 231 | K11: 0 | M11: 462 | P11: 0 | Q11: 1688 | R11: 8117 | T11: =SUM(B11:S11) -> 21802 | V11: 725068
A14: TOTAL FOR RWANDA (000m3/yr) | B14: =SUM(B3:B13) -> 1560 | C14: =SUM(C3:C13) -> 807 | D14: =SUM(D3:D13) -> 12726 | E14: =SUM(E3:E13) -> 22122 | F14: =SUM(F3:F13) -> 30226 | G14: =SUM(G3:G13) -> 0 | H14: =SUM(H3:H13) -> 23616 | I14: =SUM(I3:I13) -> 4007 | ... K14: =SUM(K3:K13) -> 66 | M14: =SUM(M3:M13) -> 8012 | N14: =SUM(N3:N13) -> 0 | O14: =SUM(O3:O13) -> 0 | P14: =SUM(P3:P13) -> 784 | Q14: =SUM(Q3:Q13) -> 47451 | R14: =SUM(R3:R13) -> 128610 | S14: =SUM(S3:S13) -> 0 | T14: =SUM(T3:T13) -> 279987 | U14: Abstraction of water 2012 | V14: =SUM(V3:V13) -> 10605524
A16: Total per Sector | B16: Agriculture | D16: =B14+C14+D14+E14+F14+G14+H14 -> 91057 | H16: Mining | I16: =I14+J14 -> 4007 | K16: Industry | M16: =K14+M14 -> 8078 | O16: Electricity | P16: =P14 -> 784 | Q16: Water Supply | R16: =Q14+R14 -> 176061 | T16: =R16+P16+M16+I16+D16 -> 279987
A18: Assets Accounts | D18: =D16-C14 -> 90250 | R18: =R16*0.85 -> 149651.85
A20: Consumptive Water demand | B20: Agriculture
A21: Year 2012 | B21: Rainfall | D21: Evaporation loss | F21: Surface water runoff | H21: Surface-water volume storage | I21: Groundwater recharge | K21: Groundwater volume storage | M21: Renewable resource | N21: Catch. Area (km2) | O21: Population
B22: (mm/yr) | C22: (MCM) | D22: (mm/yr) | E22: (MCM) | F22: (mm/yr) | G22: (MCM) | H22: (MCM) | I22: (mm/yr) | J22: (MCM) | K22: (MCM) | M22: ['000 m³] | Q22: Runoff | R22: Renewable water
A23: CKIV (Lake Kivu, 2,425 km²) | B23: 1240 | C23: =B23*N23*1000000/1000/1000000 -> 3007 | D23: 870 | E23: 2109 | F23: 370 | G23: 898 | H23: 550000 | I23: 250 | J23: 606 | K23: 2400 | L23: =K23+J23+H23+G23+E23+C23 -> 559020 | M23: 898000 | N23: 2425 | O23: 1415418 | P23: =+I23*N23/1000 -> 606.25 | Q23: =B23-D23 -> 370 | R23: =+F23*N23 -> 897250 | T23: .
A24: CRUS (Rusizi, 1.005 km²) | B24: 1295 | C24: 1301 | D24: 865 | E24: 869 | F24: 430 | G24: 432 | I24: 268 | J24: 269 | K24: 5000 | L24: =K24+J24+H24+G24+E24+C24 -> 7871 | M24: 432000 | N24: 1005 | O24: 318048 | P24: =+I24*N24/1000 -> 269.34 | Q24: =B24-D24 -> 430 | R24: =+F24*N24 -> 432150
A25: NNYU (Upper Nyabarongo, 3,348 km²) | B25: 1365 | C25: 4570 | D25: 980 | E25: 3281 | F25: 385 | G25: 1289 | I25: 292 | J25: 978 | K25: 25110 | L25: =K25+J25+H25+G25+E25+C25 -> 35228 | M25: 1290000 | N25: 3348 | O25: 1425492 | P25: =+I25*N25/1000 -> 977.616 | Q25: =B25-D25 -> 385 | R25: =+F25*N25 -> 1288980
A26: NMUK (Mukungwa, 1,949 km²) | B26: 1315 | C26: 2563 | D26: 851 | E26: 1659 | F26: 464 | G26: 904 | H26: 3508 | I26: 322 | J26: 628 | K26: 4872 | L26: =K26+J26+H26+G26+E26+C26 -> 14134 | M26: 905000 | N26: 1949 | O26: 1048631 | P26: =+I26*N26/1000 -> 627.578 | Q26: =B26-D26 -> 464 | R26: =+F26*N26 -> 904336
A27: NNYL (Lower Nyabarongo, 3.304 km²) | B27: 1191 | C27: 3935 | D27: 919 | E27: 3036 | F27: 272 | G27: 899 | H27: 330 | I27: 165 | J27: 545 | K27: 8673 | L27: =K27+J27+H27+G27+E27+C27 -> 17418 | M27: 899000 | N27: 3304 | O27: 2181940 | P27: =+I27*N27/1000 -> 545.16 | Q27: =B27-D27 -> 272 | R27: =+F27*N27 -> 898688
A28: NAKN (Akanyaru, 3,402 km²) | B28: 1225 | C28: 4167 | D28: 990 | E28: 3369 | F28: 235 | G28: 798 | I28: 156 | J28: 531 | K28: 5103 | L28: =K28+J28+H28+G28+E28+C28 -> 13968 | M28: 798000 | N28: 3402 | O28: 1447480 | P28: =+I28*N28/1000 -> 530.712 | Q28: =B28-D28 -> 235 | R28: =+F28*N28 -> 799470
A29: NAKU (Upper Akagera, 3.053 km²) | B29: 925 | C29: 2824 | D29: 760 | E29: 2320 | F29: 165 | G29: 504 | I29: 115 | J29: 351 | K29: 4580 | L29: =K29+J29+H29+G29+E29+C29 -> 10579 | M29: 504000 | N29: 3053 | O29: 1318379 | P29: =+I29*N29/1000 -> 351.095 | Q29: =B29-D29 -> 165 | R29: =+F29*N29 -> 503745
A30: NAKL (Lower Akagera, 4.288 km²) | B30: 835 | C30: 3580 | D30: 624 | E30: 2676 | F30: 211 | G30: 905 | I30: 125 | J30: 536 | K30: 4824 | L30: =K30+J30+H30+G30+E30+C30 -> 12521 | M30: 907000 | N30: 4288 | O30: 725068 | P30: =+I30*N30/1000 -> 536 | Q30: =B30-D30 -> 211 | R30: =+F30*N30 -> 904768
A31: NMUV (Muvumba, 1,568 km²) | B31: 995 | C31: 1560 | D31: 872 | E31: 1367 | F31: 123 | G31: 193 | I31: 71 | J31: 111.6 | K31: 1565 | L31: =K31+J31+H31+G31+E31+C31 -> 4796.6 | M31: 193000 | N31: 1568 | O31: 725068 | P31: =+I31*N31/1000 -> 111.328 | Q31: =B31-D31 -> 123 | R31: =+F31*N31 -> 192864
R33: =SUM(R23:R32) -> 6822251
A34: TOTAL FOR RWANDA (000m3/yr) | B34: =AVERAGE(B23:B31) -> 1154 | C34: =SUM(C23:C33) -> 27507 | D34: =AVERAGE(D23:D31) -> 859 | E34: =SUM(E23:E33) -> 20686 | F34: =AVERAGE(F23:F31) -> 295 | G34: =SUM(G23:G33) -> 6822 | H34: =SUM(H23:H33) -> 553838 | I34: =SUM(I23:I33) -> 1764 | J34: =SUM(J23:J33) -> 4555.6 | K34: =SUM(K23:K33) -> 62127 | L34: =SUM(L23:L33) -> 675535.6 | M34: =SUM(M23:M33) -> 6826000 | N34: =SUM(N23:N33) -> 24342 | O34: =SUM(O23:O33) -> 10605524 | P34: 10192072 | Q34: from water storage report
M35: =+M34*1000 -> 6826000000
N36: =M35/P34 -> 669.73624 | O36: m3/ca/yr
N37: =+N36/365 -> 1.8348938 | O37: m3/ca/day
A38: Year 2012 | B38: Renewable % of Prec. | N38: =+N36*1000/365 -> 1834.8938 | O38: l/ca/day
B39: (mm/yr) | D39: (MCM) | I39: Water Available for recharge | M39: =(I34/1000)*N34 -> 42939.288 | N39: m3/ca/yr
A40: CKIV (Lake Kivu, 2,425 km²) | B40: =+B23-D23 -> 370 | C40: =+B40/B23 -> 0.2983871 | D40: =+C23-E23 -> 898 | E40: =+I23/F23 -> 0.67567568 | I40: Water Available for recharge | M40: =(J36*1000000)/O34 -> 0 | N40: m3/ca/yr
A41: CRUS (Rusizi, 1.005 km²) | B41: =+B24-D24 -> 430 | C41: =+B41/B24 -> 0.33204633 | D41: =+C24-E24 -> 432 | E41: =+I24/F24 -> 0.62325581 | I41: Water Available for recharge | M41: =(J36*1000000)/(N34*100) -> 0 | N41: m3/ha/yr
A42: NNYU (Upper Nyabarongo, 3,348 km²) | B42: =+B25-D25 -> 385 | C42: =+B42/B25 -> 0.28205128 | D42: =+C25-E25 -> 1289 | E42: =+I25/F25 -> 0.75844156
A43: NMUK (Mukungwa, 1,949 km²) | B43: =+B26-D26 -> 464 | C43: =+B43/B26 -> 0.35285171 | D43: =+C26-E26 -> 904 | E43: =+I26/F26 -> 0.69396552 | I43: =(I28/1000)*(N28) -> 530.712
A44: NNYL (Lower Nyabarongo, 3.304 km²) | B44: =+B27-D27 -> 272 | C44: =+B44/B27 -> 0.22837951 | D44: =+C27-E27 -> 899 | E44: =+I27/F27 -> 0.60661765
A45: NAKN (Akanyaru, 3,402 km²) | B45: =+B28-D28 -> 235 | C45: =+B45/B28 -> 0.19183673 | D45: =+C28-E28 -> 798 | E45: =+I28/F28 -> 0.66382979
A46: NAKU (Upper Akagera, 3.053 km²) | B46: =+B29-D29 -> 165 | C46: =+B46/B29 -> 0.17837838 | D46: =+C29-E29 -> 504 | E46: =+I29/F29 -> 0.6969697
...

Sheet Lakes
A1: Stocks:
B2: Table 4: Sampled Lakes Area Volume estimations.
B3: For the rest of the eastern valley lakes, an approximation was adopted based on the average depth obtained from the Ihema, Rumira and Mirayi Lakes.
B4: The estimated average depth used to estimate the storage capacities of the remaining valley lakes was 4.14 meters depth.
B5: Table 5 provides the results of this estimation. The majority of the existing lakes are located in the Akagera Upstream and Akagara Downstream catchments.
I7: ?
B9: # | C9: Type | D9: Name | E9: Area sq.m | F9: Area sq.m (m2) | G9: Volume m3 | H9: Volume m3 | I9: Average depth calculated m (check:) | J9: Catchment
B10: 1 | C10: Lake | D10: Kishanju | E10: 5985696259 | F10: 598569.63 | G10: 2,478,078.25 | H10: 2478078.2 | I10: =+H10/F10 -> 4.14 | J10: Akagera downstream
B11: 2 | C11: Lake | D11: Muhari | E11: 8461370451 | F11: 846137.05 | G11: 3,503,007.37 | H11: 3503007.4 | I11: =+H11/F11 -> 4.14 | J11: Akagera downstream
B12: 3 | C12: Lake | D12: N/A | E12: 6713741109 | F12: 671374.11 | G12: 2,779,488.82 | H12: 2779488.8 | I12: =+H12/F12 -> 4.14 | J12: Akagera downstream
B13: 4 | C13: Lake | D13: N/A | E13: 1240145434 | F13: 1240145.4 | G13: 5,134,202.10 | H13: 5134202.1 | I13: =+H13/F13 -> 4.14 | J13: Akagera downstream
B14: 5 | C14: Lake | D14: N/A | E14: 5240879242 | F14: 524087.92 | G14: 2,169,724.01 | H14: 2169724 | I14: =+H14/F14 -> 4.14 | J14: Akagera downstream
B15: 6 | C15: Lake | D15: Kivumba | E15: 11202626.62 | F15: 11202627 | G15: 46,378,874.23 | H15: 46378874 | I15: =+H15/F15 -> 4.14 | J15: Akagera downstream
B16: 7 | C16: Lake | D16: Hago | E16: 17871953.05 | F16: 17871953 | G16: 73,989,885.64 | H16: 73989886 | I16: =+H16/F16 -> 4.14 | J16: Akagera downstream
B17: 8 | C17: Lake | D17: Cyambwe | E17: 22759797.77 | F17: 22759798 | G17: 94,225,562.78 | H17: 94225563 | I17: =+H17/F17 -> 4.14 | J17: Akagera downstream
B18: 9 | C18: Lake | D18: Mihindi | E18: 10476026.54 | F18: 10476027 | G18: 43,370,749.89 | H18: 43370750 | I18: =+H18/F18 -> 4.14 | J18: Akagera downstream
B19: 10 | C19: Lake | D19: Gishanda | E19: 2926052741 | F19: 292605.27 | G19: 1,211,385.84 | H19: 1211385.8 | I19: =+H19/F19 -> 4.14 | J19: Akagera downstream
B20: 11 | C20: Lake | D20: Rwakibali | E20: 3406910728 | F20: 3406910.7 | G20: 14,104,610.41 | H20: 14104610 | I20: =+H20/F20 -> 4.14 | J20: Akagera downstream
B21: 12 | C21: Lake | D21: N/A | E21: 2045633791 | F21: 2045633.8 | G21: 8,468,923.89 | H21: 8468923.9 | I21: =+H21/F21 -> 4.14 | J21: Akagera downstream
B22: 13 | C22: Lake | D22: Nasho | E22: 12723775.17 | F22: 12723775 | G22: 52,676,429.19 | H22: 52676429 | I22: =+H22/F22 -> 4.14 | J22: Akagera downstream
B23: 14 | C23: Lake | D23: Rwampanga | E23: 10142174.6 | F23: 10142175 | G23: 41,988,602.84 | H23: 41988603 | I23: =+H23/F23 -> 4.14 | J23: Akagera downstream
B24: 15 | C24: Lake | D24: Rwanyakizinga | E24: 22617508.52 | F24: 22617509 | G24: 93,636,485.29 | H24: 93636485 | I24: =+H24/F24 -> 4.14 | J24: Akagera downstream
B25: 16 | C25: Lake | D25: Kanaga | E25: 4355688614 | F25: 435568.86 | G25: 1,803,255.09 | H25: 1803255.1 | I25: =+H25/F25 -> 4.14 | J25: Akagera downstream
B26: 17 | C26: Lake | D26: Mugesera | E26: 44325011.45 | F26: 44325011 | G26: 183,505,547.40 | H26: 1.8350555e+08 | I26: =+H26/F26 -> 4.14 | J26: Akagera upstream
B27: 18 | C27: Lake | D27: Gashanga | E27: 1772827.23 | F27: 1772827.2 | G27: 7,339,504.73 | H27: 7339504.7 | I27: =+H27/F27 -> 4.14 | J27: Akagera upstream
B28: 19 | C28: Lake | D28: Bilira | E28: 5473955696 | F28: 5473955.7 | G28: 22,662,176.58 | H28: 22662177 | I28: =+H28/F28 -> 4.14 | J28: Akagera upstream
B29: 20 | C29: Lake | D29: Sake | E29: 16311884 | F29: 16311884 | G29: 67,531,201.29 | H29: 67531201 | I29: =+H29/F29 -> 4.14 | J29: Akagera upstream
B30: 21 | C30: Lake | D30: Kilimbi | E30: 2692706497 | F30: 2692706.5 | G30: 11,147,804.90 | H30: 11147805 | I30: =+H30/F30 -> 4.14 | J30: Akagera upstream
B31: 22 | C31: Lake | D31: Nyabugongwe | E31: 3230302142 | F31: 323030.21 | G31: 1,337,345.09 | H31: 1337345.1 | I31: =+H31/F31 -> 4.14 | J31: Akagera upstream
B32: 23 | C32: Lake | D32: Nyakabingo | E32: 1352628823 | F32: 135262.88 | G32: 559,988.33 | H32: 559988.33 | I32: =+H32/F32 -> 4.14 | J32: Akagera upstream
B33: 24 | C33: Lake | D33: Nyakabingo | E33: 2527406657 | F33: 252740.67 | G33: 1,046,346.36 | H33: 1046346.4 | I33: =+H33/F33 -> 4.14 | J33: Akagera upstream
B34: 25 | C34: Lake | D34: Cyohoha Nord | E34: 1879638967 | F34: 1879639 | G34: 7,781,705.32 | H34: 7781705.3 | I34: =+H34/F34 -> 4.14 | J34: Akanyaru
B35: 26 | C35: Lake | D35: Karago | E35: 1003163.93 | F35: 1003163.9 | G35: 4,153,098.67 | H35: 4153098.7 | I35: =+H35/F35 -> 4.14 | J35: Mukungwa
B36: 27 | C36: Lake | D36: Ntosho | E36: 2353036096 | F36: 235303.61 | G36: 974,156.94 | H36: 974156.94 | I36: =+H36/F36 -> 4.14 | J36: Mukungwa
B37: 28 | C37: Lake | D37: Bihinga | E37: 2043391163 | F37: 204339.12 | G37: 845,963.94 | H37: 845963.94 | I37: =+H37/F37 -> 4.14 | J37: Mukungwa
B38: 29 | C38: Lake | D38: Nyirakigugu | E38: 1550853432 | F38: 155085.34 | G38: 642,053.32 | H38: 642053.32 | I38: =+H38/F38 -> 4.14 | J38: Mukungwa
B39: 30 | C39: Lake | D39: Muhazi | E39: 35439908.56 | F39: 35439909 | G39: 146,721,221.40 | H39: 1.4672122e+08 | I39: =+H39/F39 -> 4.14 | J39: Nyabarongo downstream
F41: =SUM(F10:F40) -> 2.2805975e+08 | H41: =SUM(H10:H39) -> 9.4416738e+08
C44: TRANS-BOUNDARY LAKES | N44: VOLUMES (M3)
B45: 1 | C45: Lake | D45: Kivu | E45: 101059567533697 | F45: 101059567533697 | G45: 247,595,940,457.5577 | H45: 247,595,940,457.5577 | I45: Kivu | J45: 101059567533697 | K45: =J45/10 -> 1.0105957e+13 | N45: 2.4759594e+11
...

Sheet Rivers
B1: Stocks:
B3: Possible Methods:
B4: 1, First start from stocks in rivers from Rwanda Resources Masterplan 2012 (RWRMP2012) | D4: 1264 | E4: MCM
B8: 1, Discharge of 1 day for Rwanda (Easiest one based upon availability of the data as proposed by Mr. Gilbert). | D8: Questionable to use a water flow for estimating a stock
D9: ?????
B12: 2. Combine surface area of rivers (km2) * Average depth (m). Surface area is known from spatial data like from RCMRD for Rwanda 2010 or 2015 data (RCMRD landcover data). There are 4 categories of rivers. We woud liek to use those for making assessment. For the biggest rivers use the river depth data from the 6 or 10 hydro measuring stations. | D12: Surface of the water area (possible measurement like form NASA)
D13: Average weighed water depth
B16: 3. Combine length (km) of rivers times some measured average cross-section areas (m2) of rivers done in the country.
B20: 2nd and 3rd method allow to monitor change of the stock over time, showing change 2012 - 2013, etc.
B22: Flows (incoming & outgoing):
B24: Data from RNRA as measured at 3 rivers mainly Ruvubu river from Burundi; Muvumba river from Uganda at Kabare; and at Rusumo River from Uganda at Butaro station (Kinyababa river). (Ruvubu river at Rusumo (TO BE CONFIRMED BY IWRM IF INLOW OR NOT..?) from Burundi with 25.7087m3/s; Muvumba river coming from Kabare 16.3806m3/s) Total inflows: 42.089m3/s = 1,327,326,492.03m3/yr in 365days = 1,327.34Million m3/yr | D24: 25.7087m3/s; Muvumba river coming from Kabare 16.3806m3/s)
D25: Total inflows:
D26: 42.089 | E26: m3/s
E27: = 1,327,326,492.03m3/yr in 365days = 1,327.34Million m3/yr
B28: Kinyababa river at Burera data to be added ... and gauging station to be installed to measure and collect the data in future ...
A31: The observed increasing trends for St8 (Kagera catchment) might be attributed to the response (inflow) of Ruvubu river (av. Streamflow: 200 m3/s) from a large catchment (40%) in Burundi (Kyaruzi et al., 2005), and the catchment is beyond of this the study area analyzed.
A32: From Munyaneza et al., 2013
A34: Ruvubu river at Rusumo from Burundi with | E34: Average discharge | I34: 25.708682 | J34: m3/sec
A35: Muvumba river before entering to Akagera at Kabare | F35: Average dicharge 1966-1974: | I35: 8.0849032 | J35: m3/sec
A36: Rusumo Rugezi river at Butaro Ruhengeri | D36: Average dicharge 1956-1989: | I36: 1.3606323 | J36: m3/sec
A37: (Kinyababa river)
G38: Total inflows | I38: =SUM(I34:I37) -> 35.154217 | J38: m3/sec
N39: Seconds / year:
I40: =I38*3600*24*30*12 -> 1.0934368e+09 | J40: m3/yr | L40: =30*12 -> 360 | M40: days | N40: =(60*60)*24*30*12 -> 31104000
I42: =I40/1000000 -> 1093.4368 | J42: Million m3/yr
I45: =I38*3600*24*365 -> 1.1086234e+09 | J45: m3/yr | L45: =365 -> 365 | M45: days | N45: =(3600)*24*365 -> 31536000
I47: =I45/1000000 -> 1108.6234 | J47: Million m3/yr
I48: =I47/1000 -> 1.1086234 | J48: Billion m3/yr
H50: Compare to annual precipitation:
H51: 2012 | I51: 33.6 | J51: Billion m3/yr
H52: 2013 | I52: 31.934825 | J52: Billion m3/yr
H53: 2014 | I53: 31.966431 | J53: Billion m3/yr
H54: 2015 | I54: 32.027008 | J54: Billion m3/yr
H56: 2012 | I56: =+I$18/I51 -> 0 | J56: Share of External inflow in total water resources
H57: 2015 | I57: =+I$18/I54 -> 0
B58: Outflows
A59: Akanyaru river at Butare to Ngozi | D59: Average discharge 1955-2000: | H59: 13.149402 | I59: m3/sec
A60: Ruhwa river | H60: 2.7163968 | I60: m3/sec
A61: Rusizi river at Kamanyora
A62: Sebeya river to Lake Kivu at Gisenyi | E62: Average dicharge 1950-1997: | H62: 2.4240833 | I62: m3/sec | J62: =H62*3600*24*365 -> 76445891 | K62: =J62/1000000 -> 76.445891 | L62: mln m3
...

Sheet Artificial_reserv
B1: Stocks:
B2: Table: Artificial Reservoirs.
E4: Artificial water storages
H5: FINAL REPOR 2016; COMPANY: Senior Construction Company Ltd.; ASSESSMENT OF WATER STORAGE PER CAPITA IN RWANDA, 2016. | R5: Actual water stored in dams annually (1st of January YEAR - JJJJ):
D6: Large ponds (>120 cubic meters) | H6: Dams and Valley dams ( From UPDATED Report 2016! )
E7: YEAR ? | I7: Design Capacity (Reporting Year 2016 ?) | P7: Reservoir in operation | Q7: 2011 | R7: 2012 | S7: 2013 | T7: 2014 | U7: 2015 | V7: 2016 | W7: 2017 | X7: 2018
D8: District | E8: Total volume m3 | G8: Installation date of the Dam ? | H8: Name | I8: Volume m3 | P8: From Year 20JJ (?)
P9: Try to fill | Q9: Result from column K
D10: Gisagara | E10: 2040 | G10: ? | H10: Cyarubare | I10: 70000 | J10: For irrigation | P10: 2010 | Q10: =$I10 -> 70000 | R10: =$I10 -> 70000 | S10: =$I10 -> 70000 | T10: =$I10 -> 70000 | U10: =$I10 -> 70000 | V10: =$I10 -> 70000
D11: Nyanza | E11: 7320 | G11: ? | H11: Gacaca | I11: 2500000 | J11: For irrigation | Q11: =$I11 -> 2500000 | R11: =$I11 -> 2500000 | S11: =$I11 -> 2500000 | T11: =$I11 -> 2500000 | U11: =$I11 -> 2500000 | V11: =$I11 -> 2500000
D12: Muhanga | E12: 250 | G12: ? | H12: Kayonza-4 | I12: 1600000 | J12: For irrigation | Q12: =$I12 -> 1600000 | R12: =$I12 -> 1600000 | S12: =$I12 -> 1600000 | T12: =$I12 -> 1600000 | U12: =$I12 -> 1600000 | V12: =$I12 -> 1600000
D13: Nyamagabe | E13: 1080 | G13: ? | H13: Mahama | I13: 1000000 | J13: For irrigation | Q13: =$I13 -> 1000000 | R13: =$I13 -> 1000000 | S13: =$I13 -> 1000000 | T13: =$I13 -> 1000000 | U13: =$I13 -> 1000000 | V13: =$I13 -> 1000000
D14: Huye | E14: 1560 | G14: ? | H14: Ntende | I14: 700000 | J14: For irrigation | Q14: =$I14 -> 700000 | R14: =$I14 -> 700000 | S14: =$I14 -> 700000 | T14: =$I14 -> 700000 | U14: =$I14 -> 700000 | V14: =$I14 -> 700000
D15: Kamonyi | E15: 1440 | G15: ? | H15: Ruramira | I15: 1500000 | J15: For irrigation | Q15: =$I15 -> 1500000 | R15: =$I15 -> 1500000 | S15: =$I15 -> 1500000 | T15: =$I15 -> 1500000 | U15: =$I15 -> 1500000 | V15: =$I15 -> 1500000
D16: Rutsiro | E16: 120 | G16: ? | H16: Rurenge | I16: 2450000 | J16: For irrigation | Q16: =$I16 -> 2450000 | R16: =$I16 -> 2450000 | S16: =$I16 -> 2450000 | T16: =$I16 -> 2450000 | U16: =$I16 -> 2450000 | V16: =$I16 -> 2450000
D17: Ngororero | E17: 1320 | G17: ? | H17: Rwagitima-Ntende | I17: 700000 | J17: For irrigation | Q17: =$I17 -> 700000 | R17: =$I17 -> 700000 | S17: =$I17 -> 700000 | T17: =$I17 -> 700000 | U17: =$I17 -> 700000 | V17: =$I17 -> 700000
D18: Karongi | E18: 600 | G18: ? | H18: Rwangigo-Karangazi | I18: 3500000 | J18: For irrigation | T18: =$I18 -> 3500000 | U18: =$I18 -> 3500000 | V18: =$I18 -> 3500000
D19: Rulindo | E19: 2400 | G19: ? | H19: Rwinkwavu | I19: 1800000 | J19: For irrigation | Q19: =$I19 -> 1800000 | R19: =$I19 -> 1800000 | S19: =$I19 -> 1800000 | T19: =$I19 -> 1800000 | U19: =$I19 -> 1800000 | V19: =$I19 -> 1800000
D20: Gakenke | E20: 960 | G20: ? | H20: Rwinkwavu | I20: 4200000 | J20: For irrigation | Q20: =$I20 -> 4200000 | R20: =$I20 -> 4200000 | S20: =$I20 -> 4200000 | T20: =$I20 -> 4200000 | U20: =$I20 -> 4200000 | V20: =$I20 -> 4200000
D21: Gicumbi | E21: 2040 | G21: ? | H21: Bugugu | I21: 500000 | J21: For irrigation | Q21: =$I21 -> 500000 | R21: =$I21 -> 500000 | S21: =$I21 -> 500000 | T21: =$I21 -> 500000 | U21: =$I21 -> 500000 | V21: =$I21 -> 500000
D22: Kirehe | E22: 43520 | G22: ? | H22: Cyinuzi | I22: 318000 | J22: For irrigation | Q22: =$I22 -> 318000 | R22: =$I22 -> 318000 | S22: =$I22 -> 318000 | T22: =$I22 -> 318000 | U22: =$I22 -> 318000 | V22: =$I22 -> 318000
D23: Nyagatare | E23: 78880 | G23: ? | H23: Cyaruhogo | I23: 800000 | J23: For irrigation | Q23: =$I23 -> 800000 | R23: =$I23 -> 800000 | S23: =$I23 -> 800000 | T23: =$I23 -> 800000 | U23: =$I23 -> 800000 | V23: =$I23 -> 800000
D24: Kayonza | E24: 3960 | G24: ? | H24: Cyimpima | I24: 500000 | J24: For irrigation | Q24: =$I24 -> 500000 | R24: =$I24 -> 500000 | S24: =$I24 -> 500000 | T24: =$I24 -> 500000 | U24: =$I24 -> 500000 | V24: =$I24 -> 500000
D25: Rwamagana | E25: 6560 | G25: ? | H25: Gashara | I25: 360000 | J25: For irrigation | Q25: =$I25 -> 360000 | R25: =$I25 -> 360000 | S25: =$I25 -> 360000 | T25: =$I25 -> 360000 | U25: =$I25 -> 360000 | V25: =$I25 -> 360000
D26: Gatsibo | E26: 1930 | G26: ? | H26: Gitinga | I26: 850000 | J26: For irrigation | Q26: =$I26 -> 850000 | R26: =$I26 -> 850000 | S26: =$I26 -> 850000 | T26: =$I26 -> 850000 | U26: =$I26 -> 850000 | V26: =$I26 -> 850000
D27: Ngoma | E27: 1440 | G27: ? | H27: Kayonza | I27: 850000 | J27: For irrigation | Q27: =$I27 -> 850000 | R27: =$I27 -> 850000 | S27: =$I27 -> 850000 | T27: =$I27 -> 850000 | U27: =$I27 -> 850000 | V27: =$I27 -> 850000
D28: Gasabo | E28: 3240 | G28: ? | H28: Ngoma22 | I28: 960000 | J28: For irrigation | Q28: =$I28 -> 960000 | R28: =$I28 -> 960000 | S28: =$I28 -> 960000 | T28: =$I28 -> 960000 | U28: =$I28 -> 960000 | V28: =$I28 -> 960000
D29: Nyarugenge | E29: 120 | G29: ? | H29: Nyamugali | I29: 550000 | J29: For irrigation | Q29: =$I29 -> 550000 | R29: =$I29 -> 550000 | S29: =$I29 -> 550000 | T29: =$I29 -> 550000 | U29: =$I29 -> 550000 | V29: =$I29 -> 550000
G30: ? | H30: Rugenge, Karembo, Remera | I30: 530000 | J30: For irrigation | Q30: =$I30 -> 530000 | R30: =$I30 -> 530000 | S30: =$I30 -> 530000 | T30: =$I30 -> 530000 | U30: =$I30 -> 530000 | V30: =$I30 -> 530000
B31: Total | E31: =SUM(E10:E29) -> 160780 | G31: ? | H31: Rwamagana-34 | I31: 1000000 | J31: For irrigation | Q31: =$I31 -> 1000000 | R31: =$I31 -> 1000000 | S31: =$I31 -> 1000000 | T31: =$I31 -> 1000000 | U31: =$I31 -> 1000000 | V31: =$I31 -> 1000000
G32: ? | H32: Sagatare | I32: 280000 | J32: For irrigation | Q32: =$I32 -> 280000 | R32: =$I32 -> 280000 | S32: =$I32 -> 280000 | T32: =$I32 -> 280000 | U32: =$I32 -> 280000 | V32: =$I32 -> 280000
B33: Actual storage 01-01-YEAR, in Share of Storage capacity (ASSUMPTION) | E33: 0.9 | G33: ? | H33: Agasasa | I33: 374000 | J33: For irrigation | Q33: =$I33 -> 374000 | R33: =$I33 -> 374000 | S33: =$I33 -> 374000 | T33: =$I33 -> 374000 | U33: =$I33 -> 374000 | V33: =$I33 -> 374000
G34: ? | H34: Cyiri | I34: 950000 | J34: For irrigation | Q34: =$I34 -> 950000 | R34: =$I34 -> 950000 | S34: =$I34 -> 950000 | T34: =$I34 -> 950000 | U34: =$I34 -> 950000 | V34: =$I34 -> 950000
B35: Total water contained in artificial storage | E35: =+E31*E33 -> 144702 | G35: ? | H35: Kiruhura | I35: 60000 | J35: For irrigation | Q35: =$I35 -> 60000 | R35: =$I35 -> 60000 | S35: =$I35 -> 60000 | T35: =$I35 -> 60000 | U35: =$I35 -> 60000 | V35: =$I35 -> 60000
G36: ? | H36: Nyarubogo | I36: 450000 | J36: For irrigation | Q36: =$I36 -> 450000 | R36: =$I36 -> 450000 | S36: =$I36 -> 450000 | T36: =$I36 -> 450000 | U36: =$I36 -> 450000 | V36: =$I36 -> 450000
G37: ? | H37: Rwabikwano | I37: 150000 | J37: For irrigation | Q37: =$I37 -> 150000 | R37: =$I37 -> 150000 | S37: =$I37 -> 150000 | T37: =$I37 -> 150000 | U37: =$I37 -> 150000 | V37: =$I37 -> 150000
G38: ? | H38: Rwasave | I38: 120000 | J38: For irrigation | Q38: =$I38 -> 120000 | R38: =$I38 -> 120000 | S38: =$I38 -> 120000 | T38: =$I38 -> 120000 | U38: =$I38 -> 120000 | V38: =$I38 -> 120000
G39: ? | H39: Shyara/Nyarugenge | I39: 500000 | J39: For irrigation | Q39: =$I39 -> 500000 | R39: =$I39 -> 500000 | S39: =$I39 -> 500000 | T39: =$I39 -> 500000 | U39: =$I39 -> 500000 | V39: =$I39 -> 500000
G40: ? | H40: Kinoni 1 | I40: 250000 | J40: For irrigation | Q40: =$I40 -> 250000 | R40: =$I40 -> 250000 | S40: =$I40 -> 250000 | T40: =$I40 -> 250000 | U40: =$I40 -> 250000 | V40: =$I40 -> 250000
G41: ? | H41: Kinoni 2 | I41: 300000 | J41: For irrigation | Q41: =$I41 -> 300000 | R41: =$I41 -> 300000 | S41: =$I41 -> 300000 | T41: =$I41 -> 300000 | U41: =$I41 -> 300000 | V41: =$I41 -> 300000
...

Sheet GW&SOILW_2012
A1: Improved Water exchanged between the environment and the economy (abstractions) and within the economy (supply within the economy) for year 2012 based on NWRMP in 103 m3
A3: Water Stock calculation (1st of January for opening stock) & For closing stock 31 december of closing stock or simply 1st of January next year.
A4: Improved physical asset account for water resources Year 2012 in Million m3 | K4: Improved physical asset account for water resources Year 2013 in Million m3 | U4: Improved physical asset account for water resources Year 2014 in Million m3 | AE4: Improved physical asset account for water resources Year 2015 in Million m3
A7: Source: Land Use Matrix (Land Accounts results) | K7: Source: Land Use Matrix (Land Accounts results) | U7: Source: Land Use Matrix (Land Accounts results) | AE7: Source: Land Use Matrix (Land Accounts results)
C8: 26338 | D8: Km2 | E8: Rwanda size | M8: 26338 | N8: Km2 | O8: Rwanda size | W8: 26338 | X8: Km2 | Y8: Rwanda size | AG8: 26338 | AH8: Km2 | AI8: Rwanda size
C9: =C15+C16+C17+C18 -> 1553540.8 | D9: ha | E9: Total area of Agriculture sector | M9: =M15+M16+M17+M18 -> 1553540.8 | N9: ha | O9: Total area of Agriculture sector | W9: =W15+W16+W17+W18 -> 1563288.2 | X9: ha | Y9: Total area of Agriculture sector | AG9: =AG15+AG16+AG17+AG18 -> 1565439.2 | AH9: ha | AI9: Total area of Agriculture sector
C10: 1274 | D10: mm/yr | E10: Precipitation | G10: Source: Meteo Rwanda from 85 rain gauge stations countrywide | M10: 1212 | N10: mm/yr | O10: Precipitation | Q10: Source: Meteo Rwanda from 81 rain gauge stations countrywide | W10: 1213.7 | X10: mm/yr | Y10: Precipitation | AA10: Source: Meteo Rwanda from 59 rain gauge stations countrywide | AG10: 1260.4 | AH10: mm/yr | AI10: Precipitation | AK10: Source: Meteo Rwanda from 51 rain gauge stations countrywide
C11: 860 | D11: mm/yr | E11: Evapotranspiration | G11: Source: NWRMP, 2015 and Meteo Rwanda | M11: 824 | N11: mm/yr | O11: Evapotranspiration | Q11: Source: NWRMP, 2015 and Meteo Rwanda | W11: 850 | X11: mm/yr | Y11: Evapotranspiration | AA11: Source: Meteo Rwanda | AG11: 870 | AH11: mm/yr | AI11: Evapotranspiration | AK11: Source: Meteo Rwanda
C12: =(C9*10000*C11)/1000 -> 1.3360451e+10 | D12: m3 | M12: =+M9*10000*M11/1000 -> 1.2801176e+10 | N12: m3 | W12: =+W9*10000*W11/1000 -> 1.328795e+10 | X12: m3 | AG12: =+AG9*10000*AG11/1000 -> 1.3619321e+10 | AH12: m3
C13: =+C12/1000 -> 13360451 | D13: ' 000 m3 | G13: =C11/C10 -> 0.67503925 | M13: =+M12/1000 -> 12801176 | N13: ' 000 m3 | W13: =+W12/1000 -> 13287950 | X13: ' 000 m3 | AG13: =+AG12/1000 -> 13619321 | AH13: ' 000 m3 | AN13: =AG10*0.69 -> 869.676
B14: % | C14: =+C13/1000 -> 13360.451 | D14: MCM of ET | L14: % | M14: =+M13/1000 -> 12801.176 | N14: MCM of ET | Q14: From Land Use table we have: | V14: % | W14: =+W13/1000 -> 13287.95 | X14: MCM of ET | AF14: % | AG14: =+AG13/1000 -> 13619.321 | AH14: MCM of ET
A15: =B15*C$13 -> 10684321 | B15: =C15/C$9 -> 0.79969767 | C15: =B31 -> 1242362.9 | D15: Agriculture (crop/irrigation) | K15: =L15*M$13 -> 10237071 | L15: =M15/M$9 -> 0.79969767 | M15: =L31 -> 1242362.9 | N15: Agriculture (crop/irrigation) | U15: =V15*W$13 -> 10635036 | V15: =W15/W$9 -> 0.80035194 | W15: =V31 -> 1251180.8 | X15: Agriculture (crop/irrigation) | AE15: =AF15*AG$13 -> 10903752 | AF15: =AG15/AG$9 -> 0.80060911 | AG15: =AF31 -> 1253304.9 | AH15: Agriculture (crop/irrigation)
A16: =B16*C$13 -> 1035825.1 | B16: =C16/C$9 -> 0.077529206 | C16: =B37 -> 120444.78 | D16: Livestock | K16: =L16*M$13 -> 992465.01 | L16: =M16/M$9 -> 0.077529206 | M16: =L37 -> 120444.78 | N16: Livestock | U16: =V16*W$13 -> 1007952.5 | V16: =W16/W$9 -> 0.075854631 | W16: =V37 -> 118582.65 | X16: Livestock | AD16: =W10*0.7 -> 849.59 | AE16: =AF16*AG$13 -> 1031634.9 | AF16: =AG16/AG$9 -> 0.075747897 | AG16: =AF37 -> 118578.73 | AH16: Livestock
A17: =B17*C$13 -> 1639261.6 | B17: =C17/C$9 -> 0.12269508 | C17: =B35 -> 190611.82 | D17: Forest | K17: =L17*M$13 -> 1570641.4 | L17: =M17/M$9 -> 0.12269508 | M17: =L35 -> 190611.82 | N17: Forest | U17: =V17*W$13 -> 1643948 | V17: =W17/W$9 -> 0.1237172 | W17: =V35 -> 193405.64 | X17: Forest | AE17: =AF17*AG$13 -> 1682829.5 | AF17: =AG17/AG$9 -> 0.12356192 | AG17: =AF35 -> 193428.68 | AH17: Forest
A18: =B18*C$13 -> 1042.6277 | B18: =C18/C$9 -> 7.803836e-05 | C18: =B34 -> 121.23578 | D18: Fishing | K18: =L18*M$13 -> 998.98279 | L18: =M18/M$9 -> 7.803836e-05 | M18: =L34 -> 121.23578 | N18: Fishing | U18: =V18*W$13 -> 1012.888 | V18: =W18/W$9 -> 7.6226054e-05 | W18: =V34 -> 119.16329 | X18: Fishing | AE18: =AF18*AG$13 -> 1104.1485 | AF18: =AG18/AG$9 -> 8.1072216e-05 | AG18: =AF34 -> 126.91362 | AH18: Fishing
A20: However, Soil water for 2012 is | B20: =A15+A17+A16 -> 13359408 | C20: 000'm3 | K20: However, Soil water for 2013 is | L20: =K15+K17+K16 -> 12800177 | M20: 000'm3 | U20: However, Soil water for 2014 is | V20: =U15+U17+U16 -> 13286937 | W20: 000'm3 | AE20: However, Soil water for 2015 is | AF20: =AE15+AE17+AE16 -> 13618217 | AG20: 000'm3
A22: Areas (ha) for 2012 | C22: Actual ET (mm/y) | D22: ET per sector | E22: Actual ET (m3/y) | F22: Actual ET ("000"m3/y) | K22: Areas (ha) for 2013 | M22: Actual ET (mm/y) | N22: ET per sector | O22: Actual ET (m3/y) | P22: Actual ET ("000"m3/y) | U22: Areas (ha) for 2014 | W22: Actual ET (mm/y) | X22: ET per sector | Y22: Actual ET (m3/y) | Z22: Actual ET ("000"m3/y) | AE22: Areas (ha) for 2012 | AG22: Actual ET (mm/y) | AH22: ET per sector | AI22: Actual ET (m3/y) | AJ22: Actual ET ("000"m3/y)
A23: =C15 -> 1242362.9 | B23: Agriculture (crop/irrigation) | C23: 860 | D23: =A23*C23 -> 1.0684321e+09 | E23: =D23*10000/1000 -> 1.0684321e+10 | F23: =E23/1000 -> 10684321 | K23: 1242362.9 | L23: Agriculture (crop/irrigation) | M23: 824 | N23: =K23*M23 -> 1.0237071e+09 | O23: =N23*10000/1000 -> 1.0237071e+10 | P23: =O23/1000 -> 10237071 | U23: =V31 -> 1251180.8 | V23: Agriculture (crop/irrigation) | W23: 850 | X23: =U23*W23 -> 1.0635036e+09 | Y23: =X23*10000/1000 -> 1.0635036e+10 | Z23: =Y23/1000 -> 10635036 | AE23: =AF31 -> 1253304.9 | AF23: Agriculture (crop/irrigation) | AG23: 870 | AH23: =AE23*AG23 -> 1.0903752e+09 | AI23: =AH23*10000/1000 -> 1.0903752e+10 | AJ23: =AI23/1000 -> 10903752
A24: =C16 -> 120444.78 | B24: Livestock | C24: 860 | D24: =A24*C24 -> 1.0358251e+08 | E24: =D24*10000/1000 -> 1.0358251e+09 | F24: =E24/1000 -> 1035825.1 | K24: 120444.78 | L24: Livestock | M24: 824 | N24: =K24*M24 -> 99246499 | O24: =N24*10000/1000 -> 9.9246499e+08 | P24: =O24/1000 -> 992464.99 | U24: =V37 -> 118582.65 | V24: Livestock | W24: 850 | X24: =U24*W24 -> 1.0079525e+08 | Y24: =X24*10000/1000 -> 1.0079525e+09 | Z24: =Y24/1000 -> 1007952.5 | AE24: =AF37 -> 118578.73 | AF24: Livestock | AG24: 870 | AH24: =AE24*AG24 -> 1.0316349e+08 | AI24: =AH24*10000/1000 -> 1.0316349e+09 | AJ24: =AI24/1000 -> 1031634.9
A25: =C17 -> 190611.82 | B25: Forest | C25: 860 | D25: =A25*C25 -> 1.6392616e+08 | E25: =D25*10000/1000 -> 1.6392616e+09 | F25: =E25/1000 -> 1639261.6 | K25: 190611.82 | L25: Forest | M25: 824 | N25: =K25*M25 -> 1.5706414e+08 | O25: =N25*10000/1000 -> 1.5706414e+09 | P25: =O25/1000 -> 1570641.4 | U25: =V35 -> 193405.64 | V25: Forest | W25: 850 | X25: =U25*W25 -> 1.643948e+08 | Y25: =X25*10000/1000 -> 1.643948e+09 | Z25: =Y25/1000 -> 1643948 | AE25: =AF35 -> 193428.68 | AF25: Forest | AG25: 870 | AH25: =AE25*AG25 -> 1.6828295e+08 | AI25: =AH25*10000/1000 -> 1.6828295e+09 | AJ25: =AI25/1000 -> 1682829.5
A26: =C18 -> 121.23578 | B26: Fishing | C26: 860 | D26: =A26*C26 -> 104262.77 | E26: =D26*10000/1000 -> 1042627.7 | F26: =E26/1000 -> 1042.6277 | K26: 121.24 | L26: Fishing | M26: 824 | N26: =K26*M26 -> 99901.76 | O26: =N26*10000/1000 -> 999017.6 | P26: =O26/1000 -> 999.0176 | U26: =V34 -> 119.16329 | V26: Fishing | W26: 850 | X26: =U26*W26 -> 101288.8 | Y26: =X26*10000/1000 -> 1012888 | Z26: =Y26/1000 -> 1012.888 | AE26: =AF34 -> 126.91362 | AF26: Fishing | AG26: 870 | AH26: =AE26*AG26 -> 110414.85 | AI26: =AH26*10000/1000 -> 1104148.5 | AJ26: =AI26/1000 -> 1104.1485
U27: Source: Land Use Matrix (Land Accounts results) Cfr: Ngabirame Gabriel Land data analyst | AE27: Source: Land Use Matrix (Land Accounts results) Cfr: Ngabirame Gabriel Land data analyst
A28: Source: Land Use Matrix (Land Accounts results) Cfr: Ngabirame Gabriel Land data analyst | K28: Source: Land Use Matrix (Land Accounts results) Cfr: Ngabirame Gabriel Land data analyst
A29: total_parcels | B29: size_in_Ha | C29: land_use | K29: total_parcels | L29: size_in_Ha | M29: land_use | U29: total_parcels | V29: size_in_Ha | W29: land_use | AE29: total_parcels | AF29: size_in_Ha | AG29: land_use
K30: 1918 | L30: 6713.8837 | M30: Administrative | U30: 1973 | V30: 6908.085 | W30: Administrative | AE30: 1784 | AF30: 6519.6726 | AG30: Administrative
A31: 7107286 | B31: 1242362.9 | C31: Agriculture | K31: 7107286 | L31: 1242362.9 | M31: Agriculture | U31: 7251589 | V31: 1251180.8 | W31: Agriculture | AE31: 7300822 | AF31: 1253304.9 | AG31: Agriculture
A32: 59629 | B32: 8311.5019 | C32: Commercial | K32: 59629 | L32: 8311.5019 | M32: Commercial | U32: 60007 | V32: 8340.4227 | W32: Commercial | AE32: 59890 | AF32: 8364.3323 | AG32: Commercial
A33: 89737 | B33: 10754.163 | C33: Economic | K33: 89737 | L33: 10754.163 | M33: Economic | U33: 90118 | V33: 10615.161 | W33: Economic | AE33: 89913 | AF33: 10547.513 | AG33: Economic
A34: 161 | B34: 121.23578 | C34: Fishing | K34: 161 | L34: 121.23578 | M34: Fishing | U34: 180 | V34: 119.16329 | W34: Fishing | AE34: 188 | AF34: 126.91362 | AG34: Fishing
A35: 883327 | B35: 190611.82 | C35: Forestry | K35: 883327 | L35: 190611.82 | M35: Forestry | U35: 909044 | V35: 193405.64 | W35: Forestry | AE35: 916305 | AF35: 193428.68 | AG35: Forestry
A36: 19305 | B36: 3490.4319 | C36: Industrial | K36: 19305 | L36: 3490.4319 | M36: Industrial | U36: 19578 | V36: 3370.2322 | W36: Industrial | AE36: 19846 | AF36: 3217.827 | AG36: Industrial
A37: 40273 | B37: 120444.78 | C37: Livestock | K37: 40273 | L37: 120444.78 | M37: Livestock | U37: 40807 | V37: 118582.65 | W37: Livestock | AE37: 43848 | AF37: 118578.73 | AG37: Livestock
A38: 2474 | B38: 10689.797 | C38: Research/Scientific | K38: 2474 | L38: 10689.797 | M38: Research/Scientific | U38: 2552 | V38: 10412.553 | W38: Research/Scientific | AE38: 2650 | AF38: 10351.006 | AG38: Research/Scientific
A39: 1189279 | B39: 157741.69 | C39: Residential | K39: 1189279 | L39: 157741.69 | M39: Residential | U39: 1223911 | V39: 159816.74 | W39: Residential | AE39: 1340067 | AF39: 176012.64 | AG39: Residential
A40: 20270 | B40: 8190.7458 | C40: Social and culture | K40: 20270 | L40: 8190.7458 | M40: Social and culture | U40: 20829 | V40: 8360.5774 | W40: Social and culture | AE40: 21263 | AF40: 8805.6108 | AG40: Social and culture
A41: 3908 | B41: 852.46117 | C41: Tourism | K41: 3908 | L41: 852.46117 | M41: Tourism | U41: 3998 | V41: 926.59715 | W41: Tourism | AE41: 4021 | AF41: 1004.7989 | AG41: Tourism
A42: =SUM(A30:A41) -> 9415649 | B42: =SUM(B30:B41) -> 1753571.6 | K42: =SUM(K30:K41) -> 9417567 | L42: =SUM(L30:L41) -> 1760285.5 | U42: =SUM(U30:U41) -> 9624586 | V42: =SUM(V30:V41) -> 1772038.6 | AE42: =SUM(AE30:AE41) -> 9800597 | AF42: =SUM(AF30:AF41) -> 1790262.6
A45: Soil Water Stock calculation (1st of January for opening stock) & For closing stock 31 december of closing stock or simply 1st of January next year.
A46: =SUM(B31,B34,B35,B37,B41) -> 1554393.2 | B46: ha | C46: Selected area
A47: =SUM(B42) -> 1753571.6 | B47: ha | C47: Total area (LAIS 2013 figure, after that has been further improved)
...

Sheet Prec&ET2012
A1: 2012
A2: Rwanda size
A3: Total area of Agriculture sector
A4: Precipitation | B4: SEE worksheet: 'GW&SOILW_2012'
A5: Evapotranspiration
A7: Source: Meteo Rwanda from 85 rain gauge stations countrywide
A8: Source: NWRMP, 2015 and Meteo Rwanda
A9: Calculated rainfall for year 2012 as collected from Rwanda Meteo
A10: 1274.2 | B10: mm/yr | C10: 26338 | D10: km2
A11: 1.2742 | B11: m/yr | C11: 26338000000 | D11: m2
D12: =A11*C11 -> 33559879600 | E12: m3
D13: =+D12/1000000 -> 33559.88 | E13: Million m3/yr | F13: Total rainfall volume for yr 2012
B15: P on watersurface itself | C15: m2 | D15: m3 | E15: Sum P on water surface itself + Surroundings (m3)
A16: =A11 -> 1.2742 | B16: Lakes | C16: =(A$52)*10000 -> 1.6218321e+09 | D16: =(A$11)*C16 -> 2.0665384e+09 | E16: =SUM(D16,D25) -> 2.2048333e+09
B17: Rivers and streams | C17: =(A$56)*10000 -> 64620000 | D17: =(A$11)*C17 -> 82338804 | E17: =SUM(D17,D26) -> 2.6269654e+09
B18: Artificial reservoirs | C18: =(A$63)*10000 -> 19466932 | D18: =(A$11)*C18 -> 24804764 | E18: =SUM(D18,D27) -> 1.0778172e+08
E19: =SUM(E16:E18) -> 4.9395804e+09
E21: P on Surrounding areas to water surfaces (m3)
D22: =SUM(Asset_2012_Table!C9:E9)*1000000 -> 4.9395804e+09 | E22: Lakes, Rivers and streams, Artificial reservoirs
D23: =SUM(D12)-SUM(E16:E18) -> 2.8620299e+10 | E23: Soil water (Remainder)
D24: =(Runoff!K21) -> 2.7658985e+09 | E24: Of Which: To 'Runoff'
D25: =+(D$24)*5% -> 1.3829492e+08 | E25: Of Which: To 'Runoff' Lakes
D26: =+(D$24)*92% -> 2.5446266e+09 | E26: Of Which: To 'Runoff' rivers and streams
D27: =+(D$24)*3% -> 82976954 | E27: Of Which: To 'Runoff' 'Artificial Reservoirs'
A31: Source: Meteo Rwanda from 85 rain gauge stations countrywide
A32: Source: NWRMP, 2015 and Meteo Rwanda
A33: Calculated ET for year 2012 as collected from Rwanda Meteo
A34: 863.8 | B34: mm/yr | C34: 26338 | D34: km2
A35: 0.8638 | B35: m/yr | C35: 26338000000 | D35: m2
D36: =A35*C35 -> 22750764400 | E36: m3
D37: =+D36/1000000 -> 22750.764 | E37: Million m3/yr | F37: Total rainfall volume for yr 2012
B39: ET on watersurface itself | C39: m2 | D39: m3 | E39: Sum ET on water surface itself (m3)
A40: =A35 -> 0.8638 | B40: Lakes | C40: =(A$52)*10000 -> 1.6218321e+09 | D40: =(A$35)*C40 -> 1.4009385e+09 | E40: =SUM(D40) -> 1.4009385e+09
B41: Rivers and streams | C41: =(A$56)*10000 -> 64620000 | D41: =(A$35)*C41 -> 55818756 | E41: =SUM(D41) -> 55818756
B42: Artificial reservoirs | C42: =(A$63)*10000 -> 19466932 | D42: =(A$35)*C42 -> 16815536 | E42: =SUM(D42) -> 16815536
E43: =SUM(E40:E42) -> 1.4735728e+09
E44: =SUM(D36)-SUM(E40:E42) -> 2.1277192e+10 | F44: Soil water (Remainder)
A46: Total surface of water bodies
A47: According to Land Cover 2015
A48: 152002.94 | B48: ha | C48: Total area of surface water bodies from Land cover 2015; smaller than area of natural lakes from report water storage per capita!!??
...

Sheet Runoff
A1: NWRMP2012
A2: Assets Accounts
A4: Consumptive Water demand | B4: Agriculture
A5: Year 2012 | B5: Rainfall | D5: Evaporation loss | F5: R-NWRMP: Surface water runoff = SEEA-W 'Internal Flow' | H5: Of Which: To Groundwater recharge | J5: Of Which: To 'Runoff' | L5: Groundwater volume storage | M5: Surface-water volume storage | O5: Renewable resource | P5: Catch. Area (km2) | Q5: Population
B6: (mm/yr) | C6: (MCM) | D6: (mm/yr) | E6: (MCM) | F6: (mm/yr) | G6: (MCM) | H6: (mm/yr) | I6: (MCM) | J6: (mm/yr) | K6: (MCM) | L6: (MCM) | M6: (MCM) | N6: (MCM) | O6: ['000 m³] | S6: Runoff | T6: Renewable water
A7: CKIV (Lake Kivu, 2,425 km²) | B7: 1240 | C7: =B7*P7*1000000/1000/1000000 -> 3007 | D7: 870 | E7: =D7*P7*1000000/1000/1000000 -> 2109.75 | F7: =SUM(B7,-D7) -> 370 | G7: =+(F7*$P7)/1000 -> 897.25 | H7: 250 | I7: =+(H7*$P7)/1000 -> 606.25 | J7: =F7-H7 -> 120 | K7: =+(J7*$P7)/1000 -> 291 | L7: 2400 | M7: 550000 | N7: =L7+I7+M7+G7+E7+C7 -> 559020.25 | O7: 898000 | P7: 2425 | Q7: 1415418 | S7: =B7-D7 -> 370 | T7: =+F7*P7 -> 897250
A8: CRUS (Rusizi, 1.005 km²) | B8: 1295 | C8: =B8*P8*1000000/1000/1000000 -> 1301.475 | D8: 865 | E8: =D8*P8*1000000/1000/1000000 -> 869.325 | F8: =SUM(B8,-D8) -> 430 | G8: =+(F8*$P8)/1000 -> 432.15 | H8: 268 | I8: =+(H8*$P8)/1000 -> 269.34 | J8: =F8-H8 -> 162 | K8: =+(J8*$P8)/1000 -> 162.81 | L8: 5000 | N8: =L8+I8+M8+G8+E8+C8 -> 7872.29 | O8: 432000 | P8: 1005 | Q8: 318048 | S8: =B8-D8 -> 430 | T8: =+F8*P8 -> 432150
A9: NNYU (Upper Nyabarongo, 3,348 km²) | B9: 1365 | C9: =B9*P9*1000000/1000/1000000 -> 4570.02 | D9: 980 | E9: =D9*P9*1000000/1000/1000000 -> 3281.04 | F9: =SUM(B9,-D9) -> 385 | G9: =+(F9*$P9)/1000 -> 1288.98 | H9: 292 | I9: =+(H9*$P9)/1000 -> 977.616 | J9: =F9-H9 -> 93 | K9: =+(J9*$P9)/1000 -> 311.364 | L9: 25110 | N9: =L9+I9+M9+G9+E9+C9 -> 35227.656 | O9: 1290000 | P9: 3348 | Q9: 1425492 | S9: =B9-D9 -> 385 | T9: =+F9*P9 -> 1288980
A10: NMUK (Mukungwa, 1,949 km²) | B10: 1315 | C10: =B10*P10*1000000/1000/1000000 -> 2562.935 | D10: 851 | E10: =D10*P10*1000000/1000/1000000 -> 1658.599 | F10: =SUM(B10,-D10) -> 464 | G10: =+(F10*$P10)/1000 -> 904.336 | H10: 322 | I10: =+(H10*$P10)/1000 -> 627.578 | J10: =F10-H10 -> 142 | K10: =+(J10*$P10)/1000 -> 276.758 | L10: 4872 | M10: 3508 | N10: =L10+I10+M10+G10+E10+C10 -> 14133.448 | O10: 905000 | P10: 1949 | Q10: 1048631 | S10: =B10-D10 -> 464 | T10: =+F10*P10 -> 904336
A11: NNYL (Lower Nyabarongo, 3.304 km²) | B11: 1191 | C11: =B11*P11*1000000/1000/1000000 -> 3935.064 | D11: 919 | E11: =D11*P11*1000000/1000/1000000 -> 3036.376 | F11: =SUM(B11,-D11) -> 272 | G11: =+(F11*$P11)/1000 -> 898.688 | H11: 165 | I11: =+(H11*$P11)/1000 -> 545.16 | J11: =F11-H11 -> 107 | K11: =+(J11*$P11)/1000 -> 353.528 | L11: 8673 | M11: 330 | N11: =L11+I11+M11+G11+E11+C11 -> 17418.288 | O11: 899000 | P11: 3304 | Q11: 2181940 | S11: =B11-D11 -> 272 | T11: =+F11*P11 -> 898688
A12: NAKN (Akanyaru, 3,402 km²) | B12: 1225 | C12: =B12*P12*1000000/1000/1000000 -> 4167.45 | D12: 990 | E12: =D12*P12*1000000/1000/1000000 -> 3367.98 | F12: =SUM(B12,-D12) -> 235 | G12: =+(F12*$P12)/1000 -> 799.47 | H12: 156 | I12: =+(H12*$P12)/1000 -> 530.712 | J12: =F12-H12 -> 79 | K12: =+(J12*$P12)/1000 -> 268.758 | L12: 5103 | N12: =L12+I12+M12+G12+E12+C12 -> 13968.612 | O12: 798000 | P12: 3402 | Q12: 1447480 | S12: =B12-D12 -> 235 | T12: =+F12*P12 -> 799470
A13: NAKU (Upper Akagera, 3.053 km²) | B13: 925 | C13: =B13*P13*1000000/1000/1000000 -> 2824.025 | D13: 760 | E13: =D13*P13*1000000/1000/1000000 -> 2320.28 | F13: =SUM(B13,-D13) -> 165 | G13: =+(F13*$P13)/1000 -> 503.745 | H13: 115 | I13: =+(H13*$P13)/1000 -> 351.095 | J13: =F13-H13 -> 50 | K13: =+(J13*$P13)/1000 -> 152.65 | L13: 4580 | N13: =L13+I13+M13+G13+E13+C13 -> 10579.145 | O13: 504000 | P13: 3053 | Q13: 1318379 | S13: =B13-D13 -> 165 | T13: =+F13*P13 -> 503745
A14: NAKL (Lower Akagera, 4.288 km²) | B14: 835 | C14: =B14*P14*1000000/1000/1000000 -> 3580.48 | D14: 624 | E14: =D14*P14*1000000/1000/1000000 -> 2675.712 | F14: =SUM(B14,-D14) -> 211 | G14: =+(F14*$P14)/1000 -> 904.768 | H14: 125 | I14: =+(H14*$P14)/1000 -> 536 | J14: =F14-H14 -> 86 | K14: =+(J14*$P14)/1000 -> 368.768 | L14: 4824 | N14: =L14+I14+M14+G14+E14+C14 -> 12520.96 | O14: 907000 | P14: 4288 | Q14: 725068 | S14: =B14-D14 -> 211 | T14: =+F14*P14 -> 904768
A15: NMUV (Muvumba, 1,568 km²) | B15: 995 | C15: =B15*P15*1000000/1000/1000000 -> 1560.16 | D15: 872 | E15: =D15*P15*1000000/1000/1000000 -> 1367.296 | F15: =SUM(B15,-D15) -> 123 | G15: =+(F15*$P15)/1000 -> 192.864 | H15: 71 | I15: =+(H15*$P15)/1000 -> 111.328 | J15: =F15-H15 -> 52 | K15: =+(J15*$P15)/1000 -> 81.536 | L15: 1565 | N15: =L15+I15+M15+G15+E15+C15 -> 4796.648 | O15: 193000 | P15: 1568 | Q15: 725068 | S15: =B15-D15 -> 123 | T15: =+F15*P15 -> 192864
T17: =SUM(T7:T16) -> 6822251
A18: TOTAL FOR RWANDA (000m3/yr) | B18: =AVERAGE(B7:B15) -> 1154 | C18: =SUM(C7:C17) -> 27508.609 | D18: =AVERAGE(D7:D15) -> 859 | E18: =SUM(E7:E17) -> 20686.358 | F18: =AVERAGE(F7:F15) -> 295 | G18: =SUM(G7:G17) -> 6822.251 | H18: =AVERAGE(H7:H15) -> 196 | I18: =SUM(I7:I17) -> 4555.079 | J18: =AVERAGE(J7:J15) -> 99 | K18: =SUM(K7:K17) -> 2267.172 | L18: =SUM(L7:L17) -> 62127 | M18: =SUM(M7:M17) -> 553838 | N18: =SUM(N7:N17) -> 675537.3 | O18: =SUM(O7:O17) -> 6826000 | P18: =SUM(P7:P17) -> 24342 | Q18: =SUM(Q7:Q17) -> 10605524 | R18: 10192072 | S18: from water storage report
A19: Actual P for 2012 as per Meteo | C19: 33559.88 | F19: =SUM(B18,-D18) -> 295 | G19: =+G18*1000000 -> 6822251000 | K19: =(K18*C20) -> 2765.8985 | O19: =+O18*1000 -> 6826000000
A20: Difference RATIO to LTAA (20 yrs up to 2000) | C20: =(C19/C18) -> 1.2199773
K21: =K19*(1000000) -> 2.7658985e+09
A22: Index (P=100): | C22: =100*(C18/$C18) -> 100 | E22: =100*(E18/$C18) -> 75.199578 | G22: =100*(G18/$C18) -> 24.800422 | I22: =100*(I18/$C18) -> 16.55874 | K22: =100*(K18/$C18) -> 8.2416817
G23: =G19/R18 -> 669.36841 | O23: =O19/R18 -> 669.73624 | R23: m3/ca/yr
O24: =+O23/365 -> 1.8348938 | R24: m3/ca/day
A25: Year 2012 | B25: Renewable % of Prec. | O25: =+O23*1000/365 -> 1834.8938 | R25: l/ca/day
B26: (mm/yr) | D26: (MCM) | J26: Water Available for recharge | N26: =(H18/1000)*P18 -> 4771.032 | O26: m3/ca/yr
A27: CKIV (Lake Kivu, 2,425 km²) | B27: =+B7-D7 -> 370 | C27: =+B27/B7 -> 0.2983871 | D27: =+C7-E7 -> 897.25 | E27: =+H7/F7 -> 0.67567568 | J27: Water Available for recharge | N27: =(K23*1000000)/Q18 -> 0 | O27: m3/ca/yr
A28: CRUS (Rusizi, 1.005 km²) | B28: =+B8-D8 -> 430 | C28: =+B28/B8 -> 0.33204633 | D28: =+C8-E8 -> 432.15 | E28: =+H8/F8 -> 0.62325581 | J28: Water Available for recharge | N28: =(K23*1000000)/(P18*100) -> 0 | O28: m3/ha/yr
A29: NNYU (Upper Nyabarongo, 3,348 km²) | B29: =+B9-D9 -> 385 | C29: =+B29/B9 -> 0.28205128 | D29: =+C9-E9 -> 1288.98 | E29: =+H9/F9 -> 0.75844156
A30: NMUK (Mukungwa, 1,949 km²) | B30: =+B10-D10 -> 464 | C30: =+B30/B10 -> 0.35285171 | D30: =+C10-E10 -> 904.336 | E30: =+H10/F10 -> 0.69396552 | J30: =(H12/1000)*(P12) -> 530.712
A31: NNYL (Lower Nyabarongo, 3.304 km²) | B31: =+B11-D11 -> 272 | C31: =+B31/B11 -> 0.22837951 | D31: =+C11-E11 -> 898.688 | E31: =+H11/F11 -> 0.60661765
A32: NAKN (Akanyaru, 3,402 km²) | B32: =+B12-D12 -> 235 | C32: =+B32/B12 -> 0.19183673 | D32: =+C12-E12 -> 799.47 | E32: =+H12/F12 -> 0.66382979
A33: NAKU (Upper Akagera, 3.053 km²) | B33: =+B13-D13 -> 165 | C33: =+B33/B13 -> 0.17837838 | D33: =+C13-E13 -> 503.745 | E33: =+H13/F13 -> 0.6969697
A34: NAKL (Lower Akagera, 4.288 km²) | B34: =+B14-D14 -> 211 | C34: =+B34/B14 -> 0.25269461 | D34: =+C14-E14 -> 904.768 | E34: =+H14/F14 -> 0.59241706
A35: NMUV (Muvumba, 1,568 km²) | B35: =+B15-D15 -> 123 | C35: =+B35/B15 -> 0.12361809 | D35: =+C15-E15 -> 192.864 | E35: =+H15/F15 -> 0.57723577

Sheet Inflow
B1: INflows from other territories
B2: Inflows from other territory coming in (only) via the Rw rivers
B4: Data from RNRA as measured at 3 rivers, mainly:
B5: Ruvubu river from Burundi. It is a shared river, therfore we take 50% of this Ruvubu river! | C5: =+(25.7087*50%) -> 12.85435 | D5: m3/s
B6: Muvumba river from Uganda, data from WEAP model. | C6: 7.65 | D6: m3/s
B7: Akanyaru river partially from Burundi. It is river at the border, BUT ends fully in Rwanda. Measuring station is in Rwanda, far from the border. That is why TWG take 30% of the Akanyaru river as 'Inflow from Burundi'. | C7: =(21.518)*30% -> 6.4554 | F7: See Calculation in Excel: 'From water levels to Discharge'. File: 'Water_Level_to_Discharge_Calc__ RWANDA_RWAFA_2017-09-21__I'.
B8: Total inflows: | C8: =SUM(C5:C7) -> 26.95975
C9: =+C8*(3600*24*365) -> 8.5020268e+08 | D9: m3/yr (365days)
C10: =C9/1000000 -> 850.20268 | D10: Million m3/yr
B12: Kinyababa river at Burera data to be added ... and gauging station to be installed to measure and collect the data in future ...
B17: 2012
B18: Lake Kivu | C18: 10^9 * m3
B19: Net Inflow (or net outflow) to Rwanda from other territory via Lake KIVU:
B21: Inflows from incoming rivers in Rwanda to KIVU (draining to lake KIVU) (+):
B22: Known:
B24: From WEAP Uganda inflow …
B28: Gisenyi-Sebeya
B29: ..
B30: ..
B32: Unknown
B33: ..
B34: ..
B35: ..
B37: Outflow via Rwandan rivers draining lake KIVU (-/-):
... B42: Internal flow: Precipitation -/- EvapoTranspiration (ET):
C43: m | E43: km2 | F43: m2 | G43: m3
B44: P | C44: =+G44/1000000000 -> 1.359 | D44: 1.359 | E44: 1000 | F44: =+E44*1000000 -> 1000000000 | G44: =+D44*F44 -> 1359000000
B45: ET | C45: =+G45/1000000000 -> 1.582 | D45: 1.582 | E45: 1000 | F45: =+E45*1000000 -> 1000000000 | G45: =+D45*F45 -> 1582000000
B46: P -/- ET | C46: =+G46/1000000000 -> -0.223 | D46: =+D44-D45 -> -0.223 | E46: 1000 | F46: =+E46*1000000 -> 1000000000 | G46: =+D46*F46 -> -2.23e+08

Sheet Outflow
B1: Outflows to other territories
B2: Outflows to other from Rw rivers
D4: Outflow (m3/sec) | H4: Outflow (MCM/Year)
B6: Ruhwa river | C6: Previously we used: 17.8561570547727 from whatever source (?). Now we considered a recent study (2018) by REMA, TNC - Third National Communication on Climate Change for Water Resources Sector (including autors: Omar & Tetero) with a more recent estimate for the volume at the outlet: 256 m3/sec. We take 50% as this is Shared River (50/50 share on water volume) with Burundi. | D6: =(2.7)*50% -> 1.35 | H6: =D6*(3600*24*365)/1000000 -> 42.5736
B7: Rusizi river at KIVU Outlet | C7: At KIVU outlet. We take 50% as this is Shared River (50/50 share on water volume) with Congo. | D7: =(101.509099266037)*50% -> 50.75455 | H7: =D7*(3600*24*365)/1000000 -> 1600.5955 | I7: File: water levels and discharges from Alsaad__I
B8: Rubyiro at Bugarama | H8: 198.75564 | I8: File: water levels and discharges from Alsaad__I
B9: Umurindi river at Gatuna | C9: NO DATA (Recommendation to install Station) | D9: =(1.4) -> 1.4 | E9: m3/sec | H9: =D9*(3600*24*365)/1000000 -> 44.1504 | I9: WEAP-Model outcome, analaysed by Alsaad with technical 'Expert judgement'.
B10: Muvumba River at Kagitumba. | C10: Average dicharge 1970-1988: was 16.3814093390006 | D10: =(16.3814093390006) -> 16.381409 | E10: m3/sec | H10: =D10*(3600*24*365)/1000000 -> 516.60412
B11: Akagera river at Rusumo Station, this discharge of Akagera river at Rusumo Station is taken as an estimate for the Akagera Outlet (at Kagitumba). | C11: Average dicharge 1955-2000: 335.804765625 m3/sec. Now we considered a recent study (2018) by REMA, TNC - Third National Communication on Climate Change for Water Resources Sector (including autors: Omar & Tetero) with a more recent estimate for the volume at the outlet: 256 m3/sec. We take 50% as this is Shared River (50/50 share on water volume) with Tanzania. | D11: =(256)*50% -> 128 | E11: m3/sec | F11: =D11-150 -> -22 | H11: =D11*(3600*24*365)/1000000 -> 4036.608 | I11: Recommendation to install 2 main stations: 1.at the Outlet of Akagera at Kagitumba and; 2.at point in Akagera River just before Rweru Lake.
B14: Total Outflows | D14: =SUM(D6:D12) -> 197.88596 | E14: m3/sec | H14: =SUM(H6:H12) -> 6439.2872
D16: =D14*(3600*24*365) -> 6.2405316e+09 | E16: m3/yr | F16: =365 -> 365 | G16: days
D17: =D16/1000000 -> 6240.5316 | E17: Million m3/yr
D18: =D17/1000 -> 6.2405316 | E18: Billion m3/yr
B21: Rusizi river at Kamanyola | C21: TBD either KIVU outlet or at the border with Kamanyola | H21: 3040.0704 | I21: File: water levels and discharges from Alsaad__I

Sheet Closing_stocks
A2: Closing stock water resources
A3: Units in Million Cubic Meters | B3: Surface water | E3: Soil water | F3: Groundwater | G3: Total
B4: Lakes | C4: Rivers and streams | D4: Artificial reservoirs
A5: Closing stock water resources 2012 | B5: =+Asset_2012_Table!C24 -> 257690 | C5: =+Asset_2012_Table!D24 -> 1264 | D5: =+Asset_2012_Table!E24 -> 62.61347 | E5: =+Asset_2012_Table!F24 -> 3388.8608 | F5: =+Asset_2012_Table!G24 -> 62127 | G5: =+Asset_2012_Table!H24 -> 324532.47
A6: Closing stock water resources 2013 | B6: =+Asset_2013_Table!C24 -> 257248.31 | C6: =+Asset_2013_Table!D24 -> 1264 | D6: =+Asset_2013_Table!E24 -> 68.059209 | E6: =+Asset_2013_Table!F24 -> 3388.8608 | F6: =+Asset_2013_Table!G24 -> 62127 | G6: =+Asset_2013_Table!H24 -> 324096.23
A7: Closing stock water resources 2014 | B7: =+Asset_2014_Table!C24 -> 256806.61 | C7: =+Asset_2014_Table!D24 -> 1264 | D7: =+Asset_2014_Table!E24 -> 77.397325 | E7: =+Asset_2014_Table!F24 -> 3388.8608 | F7: =+Asset_2014_Table!G24 -> 62127 | G7: =+Asset_2014_Table!H24 -> 323663.87
A8: Closing stock water resources 2015 | B8: =+Asset_2015_Table!C24 -> 256364.92 | C8: =+Asset_2015_Table!D24 -> 1264 | D8: =+Asset_2015_Table!E24 -> 102.15047 | E8: =+Asset_2015_Table!F24 -> 3388.8608 | F8: =+Asset_2015_Table!G24 -> 62127 | G8: =+Asset_2015_Table!H24 -> 323246.93
A9: Trends (2012-2015) | B9: =(B8/B5)-1 -> -0.0051421432 | C9: =(C8/C5)-1 -> 0 | D9: =(D8/D5)-1 -> 0.63144557 | E9: =(E8/E5)-1 -> 0 | F9: =(F8/F5)-1 -> 0 | G9: =(G8/G5)-1 -> -0.0039612118
A12: Checks:
A13: Units in Million Cubic Meters | B13: Surface water | E13: Soil water | F13: Groundwater | G13: Total
B14: Lakes | C14: Rivers and streams | D14: Artificial reservoirs
A15: Closing stock water resources2012 | B15: =+Asset_2012_Table!C26 -> 257690 | C15: =+Asset_2012_Table!D26 -> 818.64426 | D15: =+Asset_2012_Table!E26 -> -19.184503 | E15: =+Asset_2012_Table!F26 -> 3551.6687 | F15: =+Asset_2012_Table!G26 -> 62309.29 | G15: =+Asset_2012_Table!H26 -> 324350.42
A16: Closing stock water resources2013 | B16: =+Asset_2013_Table!C26 -> 257248.31 | C16: =+Asset_2013_Table!D26 -> 815.49449 | D16: =+Asset_2013_Table!E26 -> -26.28868 | E16: =+Asset_2013_Table!F26 -> 2942.8046 | F16: =+Asset_2013_Table!G26 -> 62308.897 | G16: =+Asset_2013_Table!H26 -> 323289.21
A17: Closing stock water resources2014 | B17: =+Asset_2014_Table!C26 -> 256806.61 | C17: =+Asset_2014_Table!D26 -> 822.76328 | D17: =+Asset_2014_Table!E26 -> -32.372366 | E17: =+Asset_2014_Table!F26 -> 3684.1796 | F17: =+Asset_2014_Table!G26 -> 62308.507 | G17: =+Asset_2014_Table!H26 -> 323589.69
A18: Closing stock water resources2015 | B18: =+Asset_2015_Table!C26 -> 256364.92 | C18: =+Asset_2015_Table!D26 -> 823.00854 | D18: =+Asset_2015_Table!E26 -> -34.972385 | E18: =+Asset_2015_Table!F26 -> 3375.6355 | F18: =+Asset_2015_Table!G26 -> 62308.111 | G18: =+Asset_2015_Table!H26 -> 322836.7
A19: Closing stock water resources2016
A22: Closing stock water resources (after balancing)
A23: Units in Million Cubic Meters | B23: Surface water | E23: Soil water | F23: Groundwater | G23: Total
B24: Lakes | C24: Rivers and streams | D24: Artificial reservoirs
A25: Closing stock water resources2012 | B25: =+Asset_Tbl_Balance_2012!C24 -> 257690 | C25: =+Asset_Tbl_Balance_2012!D24 -> 1264 | D25: =+Asset_Tbl_Balance_2012!E24 -> 62.61347 | E25: =+Asset_Tbl_Balance_2012!F24 -> 3388.8608 | F25: =+Asset_Tbl_Balance_2012!G24 -> 62127 | G25: =+Asset_Tbl_Balance_2012!H24 -> 324532.47
A26: Closing stock water resources2013 | B26: =+Asset_Tbl_Balance_2013!C24 -> 257248.31 | C26: =+Asset_Tbl_Balance_2013!D24 -> 1264 | D26: =+Asset_Tbl_Balance_2013!E24 -> 68.059209 | E26: =+Asset_Tbl_Balance_2013!F24 -> 3388.8608 | F26: =+Asset_Tbl_Balance_2013!G24 -> 62127 | G26: =+Asset_Tbl_Balance_2013!H24 -> 324096.23
A27: Closing stock water resources2014 | B27: =+Asset_Tbl_Balance_2014!C24 -> 256806.61 | C27: =+Asset_Tbl_Balance_2014!D24 -> 1264 | D27: =+Asset_Tbl_Balance_2014!E24 -> 77.397325 | E27: =+Asset_Tbl_Balance_2014!F24 -> 3388.8608 | F27: =+Asset_Tbl_Balance_2014!G24 -> 62127 | G27: =+Asset_Tbl_Balance_2014!H24 -> 323663.87
A28: Closing stock water resources2015 | B28: =+Asset_Tbl_Balance_2015!C24 -> 256364.92 | C28: =+Asset_Tbl_Balance_2015!D24 -> 1264 | D28: =+Asset_Tbl_Balance_2015!E24 -> 102.15047 | E28: =+Asset_Tbl_Balance_2015!F24 -> 3388.8608 | F28: =+Asset_Tbl_Balance_2015!G24 -> 62127 | G28: =+Asset_Tbl_Balance_2015!H24 -> 323246.93
A29: Closing stock water resources2016

Sheet Asset_2012_Table
B1: SEEA Physical Asset Account for water resources, Year 2012 (Million m3)
B3: Units in Million Cubic Meters | C3: Surface water | F3: Soil water | G3: Groundwater | H3: Total | J3: Internal Renewable water resources | K3: Total Renewable water resources
C4: Lakes | D4: Rivers and streams | E4: Artificial reservoirs
B5: Opening stock water resources | C5: ='W-Assets_Data&Method_2012'!F3 -> 258131.69 | D5: ='W-Assets_Data&Method_2012'!F4 -> 1264 | E5: ='W-Assets_Data&Method_2012'!F5 -> 60.391466 | F5: ='W-Assets_Data&Method_2012'!F6 -> 3388.8608 | G5: ='W-Assets_Data&Method_2012'!F7 -> 62127 | H5: =SUM(C5:G5) -> 324971.95
B7: Additions to stock
B8: Returns of water | C8: ='W-Assets_Data&Method_2012'!F8 -> 0.91867446 | D8: ='W-Assets_Data&Method_2012'!F9 -> 321.53606 | E8: ='W-Assets_Data&Method_2012'!F10 -> 0 | F8: ='W-Assets_Data&Method_2012'!F11 -> 135.73415 | G8: ='W-Assets_Data&Method_2012'!F12 -> 1.1483431 | H8: =SUM(C8:G8) -> 459.33723
